2023-11-04 20:01:36,537 INFO    StreamThr :42709 [internal.py:wandb_internal():86] W&B internal server running at pid: 42709, started at: 2023-11-04 20:01:36.536270
2023-11-04 20:01:36,538 DEBUG   HandlerThread:42709 [handler.py:handle_request():146] handle_request: status
2023-11-04 20:01:36,542 INFO    WriterThread:42709 [datastore.py:open_for_write():85] open: /cluster/home/yutang/Deep-Knowledge-Tracing/DKT/KnowledgeTracing/evaluation/wandb/run-20231104_200136-w96e4u9y/run-w96e4u9y.wandb
2023-11-04 20:01:36,543 DEBUG   SenderThread:42709 [sender.py:send():380] send: header
2023-11-04 20:01:36,564 DEBUG   SenderThread:42709 [sender.py:send():380] send: run
2023-11-04 20:01:36,964 INFO    SenderThread:42709 [dir_watcher.py:__init__():211] watching files in: /cluster/home/yutang/Deep-Knowledge-Tracing/DKT/KnowledgeTracing/evaluation/wandb/run-20231104_200136-w96e4u9y/files
2023-11-04 20:01:36,964 INFO    SenderThread:42709 [sender.py:_start_run_threads():1122] run started: w96e4u9y with start time 1699124496.537534
2023-11-04 20:01:36,975 DEBUG   HandlerThread:42709 [handler.py:handle_request():146] handle_request: check_version
2023-11-04 20:01:36,975 DEBUG   SenderThread:42709 [sender.py:send_request():407] send_request: check_version
2023-11-04 20:01:37,042 DEBUG   HandlerThread:42709 [handler.py:handle_request():146] handle_request: run_start
2023-11-04 20:01:37,051 DEBUG   HandlerThread:42709 [system_info.py:__init__():32] System info init
2023-11-04 20:01:37,051 DEBUG   HandlerThread:42709 [system_info.py:__init__():47] System info init done
2023-11-04 20:01:37,051 INFO    HandlerThread:42709 [system_monitor.py:start():194] Starting system monitor
2023-11-04 20:01:37,051 INFO    SystemMonitor:42709 [system_monitor.py:_start():158] Starting system asset monitoring threads
2023-11-04 20:01:37,051 INFO    HandlerThread:42709 [system_monitor.py:probe():214] Collecting system info
2023-11-04 20:01:37,053 INFO    SystemMonitor:42709 [interfaces.py:start():190] Started cpu monitoring
2023-11-04 20:01:37,054 INFO    SystemMonitor:42709 [interfaces.py:start():190] Started disk monitoring
2023-11-04 20:01:37,055 INFO    SystemMonitor:42709 [interfaces.py:start():190] Started gpu monitoring
2023-11-04 20:01:37,057 INFO    SystemMonitor:42709 [interfaces.py:start():190] Started memory monitoring
2023-11-04 20:01:37,058 INFO    SystemMonitor:42709 [interfaces.py:start():190] Started network monitoring
2023-11-04 20:01:37,094 DEBUG   HandlerThread:42709 [system_info.py:probe():196] Probing system
2023-11-04 20:01:37,099 DEBUG   HandlerThread:42709 [system_info.py:_probe_git():181] Probing git
2023-11-04 20:01:37,118 DEBUG   HandlerThread:42709 [system_info.py:_probe_git():189] Probing git done
2023-11-04 20:01:37,119 DEBUG   HandlerThread:42709 [system_info.py:probe():244] Probing system done
2023-11-04 20:01:37,119 DEBUG   HandlerThread:42709 [system_monitor.py:probe():223] {'os': 'Linux-3.10.0-1160.95.1.el7.x86_64-x86_64-with-glibc2.17', 'python': '3.9.16', 'heartbeatAt': '2023-11-04T19:01:37.094102', 'startedAt': '2023-11-04T19:01:36.525453', 'docker': None, 'cuda': None, 'args': (), 'state': 'running', 'program': '/cluster/home/yutang/Deep-Knowledge-Tracing/DKT/KnowledgeTracing/evaluation/./run.py', 'codePathLocal': 'run.py', 'codePath': 'DKT/KnowledgeTracing/evaluation/run.py', 'git': {'remote': 'https://github.com/Bryanttt-tang/Deep-Knowledge-Tracing.git', 'commit': '19dbd40068fa359d502c625b58664f708d50a931'}, 'email': None, 'root': '/cluster/home/yutang/Deep-Knowledge-Tracing', 'host': 'eu-g3-001', 'username': 'yutang', 'executable': '/cluster/home/yutang/miniconda3/bin/python', 'cpu_count': 128, 'cpu_count_logical': 128, 'cpu_freq': {'current': 1605.46875, 'min': 1500.0, 'max': 2250.0}, 'cpu_freq_per_core': [{'current': 2250.0, 'min': 1500.0, 'max': 2250.0}, {'current': 1500.0, 'min': 1500.0, 'max': 2250.0}, {'current': 2250.0, 'min': 1500.0, 'max': 2250.0}, {'current': 2250.0, 'min': 1500.0, 'max': 2250.0}, {'current': 2250.0, 'min': 1500.0, 'max': 2250.0}, {'current': 1500.0, 'min': 1500.0, 'max': 2250.0}, {'current': 1500.0, 'min': 1500.0, 'max': 2250.0}, {'current': 1500.0, 'min': 1500.0, 'max': 2250.0}, {'current': 2250.0, 'min': 1500.0, 'max': 2250.0}, {'current': 2250.0, 'min': 1500.0, 'max': 2250.0}, {'current': 1500.0, 'min': 1500.0, 'max': 2250.0}, {'current': 1500.0, 'min': 1500.0, 'max': 2250.0}, {'current': 1500.0, 'min': 1500.0, 'max': 2250.0}, {'current': 1500.0, 'min': 1500.0, 'max': 2250.0}, {'current': 1500.0, 'min': 1500.0, 'max': 2250.0}, {'current': 1500.0, 'min': 1500.0, 'max': 2250.0}, {'current': 1500.0, 'min': 1500.0, 'max': 2250.0}, {'current': 1500.0, 'min': 1500.0, 'max': 2250.0}, {'current': 1500.0, 'min': 1500.0, 'max': 2250.0}, {'current': 1500.0, 'min': 1500.0, 'max': 2250.0}, {'current': 1500.0, 'min': 1500.0, 'max': 2250.0}, {'current': 1500.0, 'min': 1500.0, 'max': 2250.0}, {'current': 1500.0, 'min': 1500.0, 'max': 2250.0}, {'current': 1500.0, 'min': 1500.0, 'max': 2250.0}, {'current': 1500.0, 'min': 1500.0, 'max': 2250.0}, {'current': 1500.0, 'min': 1500.0, 'max': 2250.0}, {'current': 1500.0, 'min': 1500.0, 'max': 2250.0}, {'current': 1500.0, 'min': 1500.0, 'max': 2250.0}, {'current': 1500.0, 'min': 1500.0, 'max': 2250.0}, {'current': 1500.0, 'min': 1500.0, 'max': 2250.0}, {'current': 1500.0, 'min': 1500.0, 'max': 2250.0}, {'current': 1500.0, 'min': 1500.0, 'max': 2250.0}, {'current': 1500.0, 'min': 1500.0, 'max': 2250.0}, {'current': 1500.0, 'min': 1500.0, 'max': 2250.0}, {'current': 1500.0, 'min': 1500.0, 'max': 2250.0}, {'current': 1500.0, 'min': 1500.0, 'max': 2250.0}, {'current': 1500.0, 'min': 1500.0, 'max': 2250.0}, {'current': 1500.0, 'min': 1500.0, 'max': 2250.0}, {'current': 2000.0, 'min': 1500.0, 'max': 2250.0}, {'current': 1500.0, 'min': 1500.0, 'max': 2250.0}, {'current': 1500.0, 'min': 1500.0, 'max': 2250.0}, {'current': 1500.0, 'min': 1500.0, 'max': 2250.0}, {'current': 1500.0, 'min': 1500.0, 'max': 2250.0}, {'current': 1500.0, 'min': 1500.0, 'max': 2250.0}, {'current': 1500.0, 'min': 1500.0, 'max': 2250.0}, {'current': 1500.0, 'min': 1500.0, 'max': 2250.0}, {'current': 1500.0, 'min': 1500.0, 'max': 2250.0}, {'current': 1500.0, 'min': 1500.0, 'max': 2250.0}, {'current': 1500.0, 'min': 1500.0, 'max': 2250.0}, {'current': 1500.0, 'min': 1500.0, 'max': 2250.0}, {'current': 1500.0, 'min': 1500.0, 'max': 2250.0}, {'current': 1500.0, 'min': 1500.0, 'max': 2250.0}, {'current': 1500.0, 'min': 1500.0, 'max': 2250.0}, {'current': 1500.0, 'min': 1500.0, 'max': 2250.0}, {'current': 1500.0, 'min': 1500.0, 'max': 2250.0}, {'current': 1500.0, 'min': 1500.0, 'max': 2250.0}, {'current': 1500.0, 'min': 1500.0, 'max': 2250.0}, {'current': 1500.0, 'min': 1500.0, 'max': 2250.0}, {'current': 1500.0, 'min': 1500.0, 'max': 2250.0}, {'current': 1500.0, 'min': 1500.0, 'max': 2250.0}, {'current': 1500.0, 'min': 1500.0, 'max': 2250.0}, {'current': 1500.0, 'min': 1500.0, 'max': 2250.0}, {'current': 1500.0, 'min': 1500.0, 'max': 2250.0}, {'current': 1500.0, 'min': 1500.0, 'max': 2250.0}, {'current': 1500.0, 'min': 1500.0, 'max': 2250.0}, {'current': 1500.0, 'min': 1500.0, 'max': 2250.0}, {'current': 1500.0, 'min': 1500.0, 'max': 2250.0}, {'current': 1500.0, 'min': 1500.0, 'max': 2250.0}, {'current': 1500.0, 'min': 1500.0, 'max': 2250.0}, {'current': 1500.0, 'min': 1500.0, 'max': 2250.0}, {'current': 1500.0, 'min': 1500.0, 'max': 2250.0}, {'current': 1500.0, 'min': 1500.0, 'max': 2250.0}, {'current': 1500.0, 'min': 1500.0, 'max': 2250.0}, {'current': 1500.0, 'min': 1500.0, 'max': 2250.0}, {'current': 1500.0, 'min': 1500.0, 'max': 2250.0}, {'current': 2250.0, 'min': 1500.0, 'max': 2250.0}, {'current': 1500.0, 'min': 1500.0, 'max': 2250.0}, {'current': 1500.0, 'min': 1500.0, 'max': 2250.0}, {'current': 1500.0, 'min': 1500.0, 'max': 2250.0}, {'current': 1500.0, 'min': 1500.0, 'max': 2250.0}, {'current': 2000.0, 'min': 1500.0, 'max': 2250.0}, {'current': 2250.0, 'min': 1500.0, 'max': 2250.0}, {'current': 2250.0, 'min': 1500.0, 'max': 2250.0}, {'current': 1500.0, 'min': 1500.0, 'max': 2250.0}, {'current': 2250.0, 'min': 1500.0, 'max': 2250.0}, {'current': 1500.0, 'min': 1500.0, 'max': 2250.0}, {'current': 1500.0, 'min': 1500.0, 'max': 2250.0}, {'current': 2250.0, 'min': 1500.0, 'max': 2250.0}, {'current': 2250.0, 'min': 1500.0, 'max': 2250.0}, {'current': 1500.0, 'min': 1500.0, 'max': 2250.0}, {'current': 2000.0, 'min': 1500.0, 'max': 2250.0}, {'current': 2250.0, 'min': 1500.0, 'max': 2250.0}, {'current': 1500.0, 'min': 1500.0, 'max': 2250.0}, {'current': 1500.0, 'min': 1500.0, 'max': 2250.0}, {'current': 1500.0, 'min': 1500.0, 'max': 2250.0}, {'current': 2250.0, 'min': 1500.0, 'max': 2250.0}, {'current': 2250.0, 'min': 1500.0, 'max': 2250.0}, {'current': 2250.0, 'min': 1500.0, 'max': 2250.0}, {'current': 1500.0, 'min': 1500.0, 'max': 2250.0}, {'current': 1500.0, 'min': 1500.0, 'max': 2250.0}, {'current': 1500.0, 'min': 1500.0, 'max': 2250.0}, {'current': 1500.0, 'min': 1500.0, 'max': 2250.0}, {'current': 1500.0, 'min': 1500.0, 'max': 2250.0}, {'current': 1500.0, 'min': 1500.0, 'max': 2250.0}, {'current': 1500.0, 'min': 1500.0, 'max': 2250.0}, {'current': 1500.0, 'min': 1500.0, 'max': 2250.0}, {'current': 1500.0, 'min': 1500.0, 'max': 2250.0}, {'current': 1500.0, 'min': 1500.0, 'max': 2250.0}, {'current': 1500.0, 'min': 1500.0, 'max': 2250.0}, {'current': 1500.0, 'min': 1500.0, 'max': 2250.0}, {'current': 1500.0, 'min': 1500.0, 'max': 2250.0}, {'current': 1500.0, 'min': 1500.0, 'max': 2250.0}, {'current': 1500.0, 'min': 1500.0, 'max': 2250.0}, {'current': 1500.0, 'min': 1500.0, 'max': 2250.0}, {'current': 1500.0, 'min': 1500.0, 'max': 2250.0}, {'current': 1500.0, 'min': 1500.0, 'max': 2250.0}, {'current': 1500.0, 'min': 1500.0, 'max': 2250.0}, {'current': 1500.0, 'min': 1500.0, 'max': 2250.0}, {'current': 1500.0, 'min': 1500.0, 'max': 2250.0}, {'current': 1500.0, 'min': 1500.0, 'max': 2250.0}, {'current': 1500.0, 'min': 1500.0, 'max': 2250.0}, {'current': 1500.0, 'min': 1500.0, 'max': 2250.0}, {'current': 1500.0, 'min': 1500.0, 'max': 2250.0}, {'current': 1500.0, 'min': 1500.0, 'max': 2250.0}, {'current': 1500.0, 'min': 1500.0, 'max': 2250.0}, {'current': 1500.0, 'min': 1500.0, 'max': 2250.0}, {'current': 1500.0, 'min': 1500.0, 'max': 2250.0}, {'current': 1500.0, 'min': 1500.0, 'max': 2250.0}], 'disk': {'/': {'total': 10.0, 'used': 4.519817352294922}}, 'gpu': 'NVIDIA GeForce RTX 2080 Ti', 'gpu_count': 1, 'gpu_devices': [{'name': 'NVIDIA GeForce RTX 2080 Ti', 'memory_total': 11811160064}], 'memory': {'total': 501.5051078796387}}
2023-11-04 20:01:37,119 INFO    HandlerThread:42709 [system_monitor.py:probe():224] Finished collecting system info
2023-11-04 20:01:37,119 INFO    HandlerThread:42709 [system_monitor.py:probe():227] Publishing system info
2023-11-04 20:01:37,119 DEBUG   HandlerThread:42709 [system_info.py:_save_pip():52] Saving list of pip packages installed into the current environment
2023-11-04 20:01:37,120 DEBUG   HandlerThread:42709 [system_info.py:_save_pip():68] Saving pip packages done
2023-11-04 20:01:37,120 DEBUG   HandlerThread:42709 [system_info.py:_save_conda():75] Saving list of conda packages installed into the current environment
2023-11-04 20:01:37,968 INFO    Thread-12 :42709 [dir_watcher.py:_on_file_created():271] file/dir created: /cluster/home/yutang/Deep-Knowledge-Tracing/DKT/KnowledgeTracing/evaluation/wandb/run-20231104_200136-w96e4u9y/files/requirements.txt
2023-11-04 20:01:37,969 INFO    Thread-12 :42709 [dir_watcher.py:_on_file_created():271] file/dir created: /cluster/home/yutang/Deep-Knowledge-Tracing/DKT/KnowledgeTracing/evaluation/wandb/run-20231104_200136-w96e4u9y/files/conda-environment.yaml
2023-11-04 20:01:40,318 DEBUG   HandlerThread:42709 [system_info.py:_save_conda():87] Saving conda packages done
2023-11-04 20:01:40,321 INFO    HandlerThread:42709 [system_monitor.py:probe():229] Finished publishing system info
2023-11-04 20:01:40,327 DEBUG   SenderThread:42709 [sender.py:send():380] send: files
2023-11-04 20:01:40,327 INFO    SenderThread:42709 [sender.py:_save_file():1378] saving file wandb-metadata.json with policy now
2023-11-04 20:01:40,339 DEBUG   HandlerThread:42709 [handler.py:handle_request():146] handle_request: stop_status
2023-11-04 20:01:40,339 DEBUG   SenderThread:42709 [sender.py:send_request():407] send_request: stop_status
2023-11-04 20:01:40,339 DEBUG   HandlerThread:42709 [handler.py:handle_request():146] handle_request: internal_messages
2023-11-04 20:01:40,522 DEBUG   SenderThread:42709 [sender.py:send():380] send: telemetry
2023-11-04 20:01:40,633 ERROR   wandb-upload_0:42709 [internal_api.py:upload_file():2556] upload_file exception https://storage.googleapis.com/wandb-production.appspot.com/bryanttang/DKT-trial%201/w96e4u9y/wandb-metadata.json?Expires=1699210900&GoogleAccessId=gorilla-files-url-signer-man%40wandb-production.iam.gserviceaccount.com&Signature=FFKp6KRwxqtwRO4hH9sNqyOHzFnLn2BjM6zCR%2Bk5OhIbJ%2BYOSxkUfZMm%2FYZR%2B2tVE%2FcmVNSVnSJEkiu3RrZkzdQEnMkgp%2Bi0kVy%2BTWojmINkD%2BJ%2Bmc6XT4%2Bvw1u%2FGhAcU9Q3bmmj66F%2B9B146TbKj4reCfiTN2obFklIAH%2F9QiLTXGLhkob%2BF8IPen1tlk7XduEXjeRYhjtaEfX3JbExp6wSNSxq%2FJKI4o3cMI0LjqN3U37Sc3A1RxG%2BEaXo8gkTMlKnoVg3XxN21gu%2Bq1%2Byfr1ELNaPmwl0n86w7iMr1HriU44av0ogBNZlB2flv6GMTgnHyaFBMEHybYWXYzuKYw%3D%3D: HTTPSConnectionPool(host='storage.googleapis.com', port=443): Max retries exceeded with url: /wandb-production.appspot.com/bryanttang/DKT-trial%201/w96e4u9y/wandb-metadata.json?Expires=1699210900&GoogleAccessId=gorilla-files-url-signer-man%40wandb-production.iam.gserviceaccount.com&Signature=FFKp6KRwxqtwRO4hH9sNqyOHzFnLn2BjM6zCR%2Bk5OhIbJ%2BYOSxkUfZMm%2FYZR%2B2tVE%2FcmVNSVnSJEkiu3RrZkzdQEnMkgp%2Bi0kVy%2BTWojmINkD%2BJ%2Bmc6XT4%2Bvw1u%2FGhAcU9Q3bmmj66F%2B9B146TbKj4reCfiTN2obFklIAH%2F9QiLTXGLhkob%2BF8IPen1tlk7XduEXjeRYhjtaEfX3JbExp6wSNSxq%2FJKI4o3cMI0LjqN3U37Sc3A1RxG%2BEaXo8gkTMlKnoVg3XxN21gu%2Bq1%2Byfr1ELNaPmwl0n86w7iMr1HriU44av0ogBNZlB2flv6GMTgnHyaFBMEHybYWXYzuKYw%3D%3D (Caused by NewConnectionError('<urllib3.connection.HTTPSConnection object at 0x2b5c87ecc460>: Failed to establish a new connection: [Errno 101] Network is unreachable'))
2023-11-04 20:01:40,633 ERROR   wandb-upload_0:42709 [internal_api.py:upload_file():2558] upload_file request headers: {'User-Agent': 'python-requests/2.28.1', 'Accept-Encoding': 'gzip, deflate, br', 'Accept': '*/*', 'Connection': 'keep-alive', 'Content-Length': '14811'}
2023-11-04 20:01:40,633 ERROR   wandb-upload_0:42709 [internal_api.py:upload_file():2560] upload_file response body: 
2023-11-04 20:01:40,968 INFO    Thread-12 :42709 [dir_watcher.py:_on_file_modified():288] file/dir modified: /cluster/home/yutang/Deep-Knowledge-Tracing/DKT/KnowledgeTracing/evaluation/wandb/run-20231104_200136-w96e4u9y/files/conda-environment.yaml
2023-11-04 20:01:40,968 INFO    Thread-12 :42709 [dir_watcher.py:_on_file_created():271] file/dir created: /cluster/home/yutang/Deep-Knowledge-Tracing/DKT/KnowledgeTracing/evaluation/wandb/run-20231104_200136-w96e4u9y/files/output.log
2023-11-04 20:01:40,968 INFO    Thread-12 :42709 [dir_watcher.py:_on_file_created():271] file/dir created: /cluster/home/yutang/Deep-Knowledge-Tracing/DKT/KnowledgeTracing/evaluation/wandb/run-20231104_200136-w96e4u9y/files/wandb-metadata.json
2023-11-04 20:01:41,759 ERROR   wandb-upload_0:42709 [internal_api.py:upload_file():2556] upload_file exception https://storage.googleapis.com/wandb-production.appspot.com/bryanttang/DKT-trial%201/w96e4u9y/wandb-metadata.json?Expires=1699210900&GoogleAccessId=gorilla-files-url-signer-man%40wandb-production.iam.gserviceaccount.com&Signature=FFKp6KRwxqtwRO4hH9sNqyOHzFnLn2BjM6zCR%2Bk5OhIbJ%2BYOSxkUfZMm%2FYZR%2B2tVE%2FcmVNSVnSJEkiu3RrZkzdQEnMkgp%2Bi0kVy%2BTWojmINkD%2BJ%2Bmc6XT4%2Bvw1u%2FGhAcU9Q3bmmj66F%2B9B146TbKj4reCfiTN2obFklIAH%2F9QiLTXGLhkob%2BF8IPen1tlk7XduEXjeRYhjtaEfX3JbExp6wSNSxq%2FJKI4o3cMI0LjqN3U37Sc3A1RxG%2BEaXo8gkTMlKnoVg3XxN21gu%2Bq1%2Byfr1ELNaPmwl0n86w7iMr1HriU44av0ogBNZlB2flv6GMTgnHyaFBMEHybYWXYzuKYw%3D%3D: HTTPSConnectionPool(host='storage.googleapis.com', port=443): Max retries exceeded with url: /wandb-production.appspot.com/bryanttang/DKT-trial%201/w96e4u9y/wandb-metadata.json?Expires=1699210900&GoogleAccessId=gorilla-files-url-signer-man%40wandb-production.iam.gserviceaccount.com&Signature=FFKp6KRwxqtwRO4hH9sNqyOHzFnLn2BjM6zCR%2Bk5OhIbJ%2BYOSxkUfZMm%2FYZR%2B2tVE%2FcmVNSVnSJEkiu3RrZkzdQEnMkgp%2Bi0kVy%2BTWojmINkD%2BJ%2Bmc6XT4%2Bvw1u%2FGhAcU9Q3bmmj66F%2B9B146TbKj4reCfiTN2obFklIAH%2F9QiLTXGLhkob%2BF8IPen1tlk7XduEXjeRYhjtaEfX3JbExp6wSNSxq%2FJKI4o3cMI0LjqN3U37Sc3A1RxG%2BEaXo8gkTMlKnoVg3XxN21gu%2Bq1%2Byfr1ELNaPmwl0n86w7iMr1HriU44av0ogBNZlB2flv6GMTgnHyaFBMEHybYWXYzuKYw%3D%3D (Caused by NewConnectionError('<urllib3.connection.HTTPSConnection object at 0x2b5c87ed3340>: Failed to establish a new connection: [Errno 101] Network is unreachable'))
2023-11-04 20:01:41,760 ERROR   wandb-upload_0:42709 [internal_api.py:upload_file():2558] upload_file request headers: {'User-Agent': 'python-requests/2.28.1', 'Accept-Encoding': 'gzip, deflate, br', 'Accept': '*/*', 'Connection': 'keep-alive', 'Content-Length': '14811'}
2023-11-04 20:01:41,760 ERROR   wandb-upload_0:42709 [internal_api.py:upload_file():2560] upload_file response body: 
2023-11-04 20:01:42,525 DEBUG   HandlerThread:42709 [handler.py:handle_request():146] handle_request: status_report
2023-11-04 20:01:42,969 INFO    Thread-12 :42709 [dir_watcher.py:_on_file_modified():288] file/dir modified: /cluster/home/yutang/Deep-Knowledge-Tracing/DKT/KnowledgeTracing/evaluation/wandb/run-20231104_200136-w96e4u9y/files/output.log
2023-11-04 20:01:44,025 ERROR   wandb-upload_0:42709 [internal_api.py:upload_file():2556] upload_file exception https://storage.googleapis.com/wandb-production.appspot.com/bryanttang/DKT-trial%201/w96e4u9y/wandb-metadata.json?Expires=1699210900&GoogleAccessId=gorilla-files-url-signer-man%40wandb-production.iam.gserviceaccount.com&Signature=FFKp6KRwxqtwRO4hH9sNqyOHzFnLn2BjM6zCR%2Bk5OhIbJ%2BYOSxkUfZMm%2FYZR%2B2tVE%2FcmVNSVnSJEkiu3RrZkzdQEnMkgp%2Bi0kVy%2BTWojmINkD%2BJ%2Bmc6XT4%2Bvw1u%2FGhAcU9Q3bmmj66F%2B9B146TbKj4reCfiTN2obFklIAH%2F9QiLTXGLhkob%2BF8IPen1tlk7XduEXjeRYhjtaEfX3JbExp6wSNSxq%2FJKI4o3cMI0LjqN3U37Sc3A1RxG%2BEaXo8gkTMlKnoVg3XxN21gu%2Bq1%2Byfr1ELNaPmwl0n86w7iMr1HriU44av0ogBNZlB2flv6GMTgnHyaFBMEHybYWXYzuKYw%3D%3D: HTTPSConnectionPool(host='storage.googleapis.com', port=443): Max retries exceeded with url: /wandb-production.appspot.com/bryanttang/DKT-trial%201/w96e4u9y/wandb-metadata.json?Expires=1699210900&GoogleAccessId=gorilla-files-url-signer-man%40wandb-production.iam.gserviceaccount.com&Signature=FFKp6KRwxqtwRO4hH9sNqyOHzFnLn2BjM6zCR%2Bk5OhIbJ%2BYOSxkUfZMm%2FYZR%2B2tVE%2FcmVNSVnSJEkiu3RrZkzdQEnMkgp%2Bi0kVy%2BTWojmINkD%2BJ%2Bmc6XT4%2Bvw1u%2FGhAcU9Q3bmmj66F%2B9B146TbKj4reCfiTN2obFklIAH%2F9QiLTXGLhkob%2BF8IPen1tlk7XduEXjeRYhjtaEfX3JbExp6wSNSxq%2FJKI4o3cMI0LjqN3U37Sc3A1RxG%2BEaXo8gkTMlKnoVg3XxN21gu%2Bq1%2Byfr1ELNaPmwl0n86w7iMr1HriU44av0ogBNZlB2flv6GMTgnHyaFBMEHybYWXYzuKYw%3D%3D (Caused by NewConnectionError('<urllib3.connection.HTTPSConnection object at 0x2b5c87ed3220>: Failed to establish a new connection: [Errno 101] Network is unreachable'))
2023-11-04 20:01:44,025 ERROR   wandb-upload_0:42709 [internal_api.py:upload_file():2558] upload_file request headers: {'User-Agent': 'python-requests/2.28.1', 'Accept-Encoding': 'gzip, deflate, br', 'Accept': '*/*', 'Connection': 'keep-alive', 'Content-Length': '14811'}
2023-11-04 20:01:44,025 ERROR   wandb-upload_0:42709 [internal_api.py:upload_file():2560] upload_file response body: 
2023-11-04 20:01:44,025 INFO    wandb-upload_0:42709 [retry.py:__call__():172] Retry attempt failed:
Traceback (most recent call last):
  File "/cluster/home/yutang/miniconda3/lib/python3.9/site-packages/urllib3/connection.py", line 174, in _new_conn
    conn = connection.create_connection(
  File "/cluster/home/yutang/miniconda3/lib/python3.9/site-packages/urllib3/util/connection.py", line 95, in create_connection
    raise err
  File "/cluster/home/yutang/miniconda3/lib/python3.9/site-packages/urllib3/util/connection.py", line 85, in create_connection
    sock.connect(sa)
OSError: [Errno 101] Network is unreachable

During handling of the above exception, another exception occurred:

Traceback (most recent call last):
  File "/cluster/home/yutang/miniconda3/lib/python3.9/site-packages/urllib3/connectionpool.py", line 703, in urlopen
    httplib_response = self._make_request(
  File "/cluster/home/yutang/miniconda3/lib/python3.9/site-packages/urllib3/connectionpool.py", line 386, in _make_request
    self._validate_conn(conn)
  File "/cluster/home/yutang/miniconda3/lib/python3.9/site-packages/urllib3/connectionpool.py", line 1042, in _validate_conn
    conn.connect()
  File "/cluster/home/yutang/miniconda3/lib/python3.9/site-packages/urllib3/connection.py", line 358, in connect
    self.sock = conn = self._new_conn()
  File "/cluster/home/yutang/miniconda3/lib/python3.9/site-packages/urllib3/connection.py", line 186, in _new_conn
    raise NewConnectionError(
urllib3.exceptions.NewConnectionError: <urllib3.connection.HTTPSConnection object at 0x2b5c87ed3220>: Failed to establish a new connection: [Errno 101] Network is unreachable

During handling of the above exception, another exception occurred:

Traceback (most recent call last):
  File "/cluster/home/yutang/miniconda3/lib/python3.9/site-packages/requests/adapters.py", line 489, in send
    resp = conn.urlopen(
  File "/cluster/home/yutang/miniconda3/lib/python3.9/site-packages/urllib3/connectionpool.py", line 787, in urlopen
    retries = retries.increment(
  File "/cluster/home/yutang/miniconda3/lib/python3.9/site-packages/urllib3/util/retry.py", line 592, in increment
    raise MaxRetryError(_pool, url, error or ResponseError(cause))
urllib3.exceptions.MaxRetryError: HTTPSConnectionPool(host='storage.googleapis.com', port=443): Max retries exceeded with url: /wandb-production.appspot.com/bryanttang/DKT-trial%201/w96e4u9y/wandb-metadata.json?Expires=1699210900&GoogleAccessId=gorilla-files-url-signer-man%40wandb-production.iam.gserviceaccount.com&Signature=FFKp6KRwxqtwRO4hH9sNqyOHzFnLn2BjM6zCR%2Bk5OhIbJ%2BYOSxkUfZMm%2FYZR%2B2tVE%2FcmVNSVnSJEkiu3RrZkzdQEnMkgp%2Bi0kVy%2BTWojmINkD%2BJ%2Bmc6XT4%2Bvw1u%2FGhAcU9Q3bmmj66F%2B9B146TbKj4reCfiTN2obFklIAH%2F9QiLTXGLhkob%2BF8IPen1tlk7XduEXjeRYhjtaEfX3JbExp6wSNSxq%2FJKI4o3cMI0LjqN3U37Sc3A1RxG%2BEaXo8gkTMlKnoVg3XxN21gu%2Bq1%2Byfr1ELNaPmwl0n86w7iMr1HriU44av0ogBNZlB2flv6GMTgnHyaFBMEHybYWXYzuKYw%3D%3D (Caused by NewConnectionError('<urllib3.connection.HTTPSConnection object at 0x2b5c87ed3220>: Failed to establish a new connection: [Errno 101] Network is unreachable'))

During handling of the above exception, another exception occurred:

Traceback (most recent call last):
  File "/cluster/home/yutang/miniconda3/lib/python3.9/site-packages/wandb/sdk/internal/internal_api.py", line 2549, in upload_file
    response = self._upload_file_session.put(
  File "/cluster/home/yutang/miniconda3/lib/python3.9/site-packages/requests/sessions.py", line 647, in put
    return self.request("PUT", url, data=data, **kwargs)
  File "/cluster/home/yutang/miniconda3/lib/python3.9/site-packages/requests/sessions.py", line 587, in request
    resp = self.send(prep, **send_kwargs)
  File "/cluster/home/yutang/miniconda3/lib/python3.9/site-packages/requests/sessions.py", line 701, in send
    r = adapter.send(request, **kwargs)
  File "/cluster/home/yutang/miniconda3/lib/python3.9/site-packages/requests/adapters.py", line 565, in send
    raise ConnectionError(e, request=request)
requests.exceptions.ConnectionError: HTTPSConnectionPool(host='storage.googleapis.com', port=443): Max retries exceeded with url: /wandb-production.appspot.com/bryanttang/DKT-trial%201/w96e4u9y/wandb-metadata.json?Expires=1699210900&GoogleAccessId=gorilla-files-url-signer-man%40wandb-production.iam.gserviceaccount.com&Signature=FFKp6KRwxqtwRO4hH9sNqyOHzFnLn2BjM6zCR%2Bk5OhIbJ%2BYOSxkUfZMm%2FYZR%2B2tVE%2FcmVNSVnSJEkiu3RrZkzdQEnMkgp%2Bi0kVy%2BTWojmINkD%2BJ%2Bmc6XT4%2Bvw1u%2FGhAcU9Q3bmmj66F%2B9B146TbKj4reCfiTN2obFklIAH%2F9QiLTXGLhkob%2BF8IPen1tlk7XduEXjeRYhjtaEfX3JbExp6wSNSxq%2FJKI4o3cMI0LjqN3U37Sc3A1RxG%2BEaXo8gkTMlKnoVg3XxN21gu%2Bq1%2Byfr1ELNaPmwl0n86w7iMr1HriU44av0ogBNZlB2flv6GMTgnHyaFBMEHybYWXYzuKYw%3D%3D (Caused by NewConnectionError('<urllib3.connection.HTTPSConnection object at 0x2b5c87ed3220>: Failed to establish a new connection: [Errno 101] Network is unreachable'))

During handling of the above exception, another exception occurred:

Traceback (most recent call last):
  File "/cluster/home/yutang/miniconda3/lib/python3.9/site-packages/wandb/sdk/lib/retry.py", line 131, in __call__
    result = self._call_fn(*args, **kwargs)
  File "/cluster/home/yutang/miniconda3/lib/python3.9/site-packages/wandb/sdk/internal/internal_api.py", line 2580, in upload_file
    raise _e.with_traceback(sys.exc_info()[2])
  File "/cluster/home/yutang/miniconda3/lib/python3.9/site-packages/wandb/sdk/internal/internal_api.py", line 2549, in upload_file
    response = self._upload_file_session.put(
  File "/cluster/home/yutang/miniconda3/lib/python3.9/site-packages/requests/sessions.py", line 647, in put
    return self.request("PUT", url, data=data, **kwargs)
  File "/cluster/home/yutang/miniconda3/lib/python3.9/site-packages/requests/sessions.py", line 587, in request
    resp = self.send(prep, **send_kwargs)
  File "/cluster/home/yutang/miniconda3/lib/python3.9/site-packages/requests/sessions.py", line 701, in send
    r = adapter.send(request, **kwargs)
  File "/cluster/home/yutang/miniconda3/lib/python3.9/site-packages/requests/adapters.py", line 565, in send
    raise ConnectionError(e, request=request)
wandb.sdk.lib.retry.TransientError: None
2023-11-04 20:01:47,974 INFO    Thread-12 :42709 [dir_watcher.py:_on_file_modified():288] file/dir modified: /cluster/home/yutang/Deep-Knowledge-Tracing/DKT/KnowledgeTracing/evaluation/wandb/run-20231104_200136-w96e4u9y/files/output.log
2023-11-04 20:01:48,010 DEBUG   HandlerThread:42709 [handler.py:handle_request():146] handle_request: status_report
2023-11-04 20:01:48,093 ERROR   wandb-upload_0:42709 [internal_api.py:upload_file():2556] upload_file exception https://storage.googleapis.com/wandb-production.appspot.com/bryanttang/DKT-trial%201/w96e4u9y/wandb-metadata.json?Expires=1699210900&GoogleAccessId=gorilla-files-url-signer-man%40wandb-production.iam.gserviceaccount.com&Signature=FFKp6KRwxqtwRO4hH9sNqyOHzFnLn2BjM6zCR%2Bk5OhIbJ%2BYOSxkUfZMm%2FYZR%2B2tVE%2FcmVNSVnSJEkiu3RrZkzdQEnMkgp%2Bi0kVy%2BTWojmINkD%2BJ%2Bmc6XT4%2Bvw1u%2FGhAcU9Q3bmmj66F%2B9B146TbKj4reCfiTN2obFklIAH%2F9QiLTXGLhkob%2BF8IPen1tlk7XduEXjeRYhjtaEfX3JbExp6wSNSxq%2FJKI4o3cMI0LjqN3U37Sc3A1RxG%2BEaXo8gkTMlKnoVg3XxN21gu%2Bq1%2Byfr1ELNaPmwl0n86w7iMr1HriU44av0ogBNZlB2flv6GMTgnHyaFBMEHybYWXYzuKYw%3D%3D: HTTPSConnectionPool(host='storage.googleapis.com', port=443): Max retries exceeded with url: /wandb-production.appspot.com/bryanttang/DKT-trial%201/w96e4u9y/wandb-metadata.json?Expires=1699210900&GoogleAccessId=gorilla-files-url-signer-man%40wandb-production.iam.gserviceaccount.com&Signature=FFKp6KRwxqtwRO4hH9sNqyOHzFnLn2BjM6zCR%2Bk5OhIbJ%2BYOSxkUfZMm%2FYZR%2B2tVE%2FcmVNSVnSJEkiu3RrZkzdQEnMkgp%2Bi0kVy%2BTWojmINkD%2BJ%2Bmc6XT4%2Bvw1u%2FGhAcU9Q3bmmj66F%2B9B146TbKj4reCfiTN2obFklIAH%2F9QiLTXGLhkob%2BF8IPen1tlk7XduEXjeRYhjtaEfX3JbExp6wSNSxq%2FJKI4o3cMI0LjqN3U37Sc3A1RxG%2BEaXo8gkTMlKnoVg3XxN21gu%2Bq1%2Byfr1ELNaPmwl0n86w7iMr1HriU44av0ogBNZlB2flv6GMTgnHyaFBMEHybYWXYzuKYw%3D%3D (Caused by NewConnectionError('<urllib3.connection.HTTPSConnection object at 0x2b5c87ed3190>: Failed to establish a new connection: [Errno 101] Network is unreachable'))
2023-11-04 20:01:48,093 ERROR   wandb-upload_0:42709 [internal_api.py:upload_file():2558] upload_file request headers: {'User-Agent': 'python-requests/2.28.1', 'Accept-Encoding': 'gzip, deflate, br', 'Accept': '*/*', 'Connection': 'keep-alive', 'Content-Length': '14811'}
2023-11-04 20:01:48,093 ERROR   wandb-upload_0:42709 [internal_api.py:upload_file():2560] upload_file response body: 
2023-11-04 20:01:49,977 INFO    Thread-12 :42709 [dir_watcher.py:_on_file_modified():288] file/dir modified: /cluster/home/yutang/Deep-Knowledge-Tracing/DKT/KnowledgeTracing/evaluation/wandb/run-20231104_200136-w96e4u9y/files/output.log
2023-11-04 20:01:53,011 DEBUG   HandlerThread:42709 [handler.py:handle_request():146] handle_request: status_report
2023-11-04 20:01:55,339 DEBUG   HandlerThread:42709 [handler.py:handle_request():146] handle_request: stop_status
2023-11-04 20:01:55,340 DEBUG   SenderThread:42709 [sender.py:send_request():407] send_request: stop_status
2023-11-04 20:01:55,344 DEBUG   HandlerThread:42709 [handler.py:handle_request():146] handle_request: internal_messages
2023-11-04 20:01:55,982 INFO    Thread-12 :42709 [dir_watcher.py:_on_file_modified():288] file/dir modified: /cluster/home/yutang/Deep-Knowledge-Tracing/DKT/KnowledgeTracing/evaluation/wandb/run-20231104_200136-w96e4u9y/files/output.log
2023-11-04 20:01:57,896 ERROR   wandb-upload_0:42709 [internal_api.py:upload_file():2556] upload_file exception https://storage.googleapis.com/wandb-production.appspot.com/bryanttang/DKT-trial%201/w96e4u9y/wandb-metadata.json?Expires=1699210900&GoogleAccessId=gorilla-files-url-signer-man%40wandb-production.iam.gserviceaccount.com&Signature=FFKp6KRwxqtwRO4hH9sNqyOHzFnLn2BjM6zCR%2Bk5OhIbJ%2BYOSxkUfZMm%2FYZR%2B2tVE%2FcmVNSVnSJEkiu3RrZkzdQEnMkgp%2Bi0kVy%2BTWojmINkD%2BJ%2Bmc6XT4%2Bvw1u%2FGhAcU9Q3bmmj66F%2B9B146TbKj4reCfiTN2obFklIAH%2F9QiLTXGLhkob%2BF8IPen1tlk7XduEXjeRYhjtaEfX3JbExp6wSNSxq%2FJKI4o3cMI0LjqN3U37Sc3A1RxG%2BEaXo8gkTMlKnoVg3XxN21gu%2Bq1%2Byfr1ELNaPmwl0n86w7iMr1HriU44av0ogBNZlB2flv6GMTgnHyaFBMEHybYWXYzuKYw%3D%3D: HTTPSConnectionPool(host='storage.googleapis.com', port=443): Max retries exceeded with url: /wandb-production.appspot.com/bryanttang/DKT-trial%201/w96e4u9y/wandb-metadata.json?Expires=1699210900&GoogleAccessId=gorilla-files-url-signer-man%40wandb-production.iam.gserviceaccount.com&Signature=FFKp6KRwxqtwRO4hH9sNqyOHzFnLn2BjM6zCR%2Bk5OhIbJ%2BYOSxkUfZMm%2FYZR%2B2tVE%2FcmVNSVnSJEkiu3RrZkzdQEnMkgp%2Bi0kVy%2BTWojmINkD%2BJ%2Bmc6XT4%2Bvw1u%2FGhAcU9Q3bmmj66F%2B9B146TbKj4reCfiTN2obFklIAH%2F9QiLTXGLhkob%2BF8IPen1tlk7XduEXjeRYhjtaEfX3JbExp6wSNSxq%2FJKI4o3cMI0LjqN3U37Sc3A1RxG%2BEaXo8gkTMlKnoVg3XxN21gu%2Bq1%2Byfr1ELNaPmwl0n86w7iMr1HriU44av0ogBNZlB2flv6GMTgnHyaFBMEHybYWXYzuKYw%3D%3D (Caused by NewConnectionError('<urllib3.connection.HTTPSConnection object at 0x2b5c87eeb280>: Failed to establish a new connection: [Errno 101] Network is unreachable'))
2023-11-04 20:01:57,896 ERROR   wandb-upload_0:42709 [internal_api.py:upload_file():2558] upload_file request headers: {'User-Agent': 'python-requests/2.28.1', 'Accept-Encoding': 'gzip, deflate, br', 'Accept': '*/*', 'Connection': 'keep-alive', 'Content-Length': '14811'}
2023-11-04 20:01:57,896 ERROR   wandb-upload_0:42709 [internal_api.py:upload_file():2560] upload_file response body: 
2023-11-04 20:01:58,546 DEBUG   HandlerThread:42709 [handler.py:handle_request():146] handle_request: status_report
2023-11-04 20:02:01,989 INFO    Thread-12 :42709 [dir_watcher.py:_on_file_modified():288] file/dir modified: /cluster/home/yutang/Deep-Knowledge-Tracing/DKT/KnowledgeTracing/evaluation/wandb/run-20231104_200136-w96e4u9y/files/output.log
2023-11-04 20:02:03,763 DEBUG   HandlerThread:42709 [handler.py:handle_request():146] handle_request: status_report
2023-11-04 20:02:07,995 INFO    Thread-12 :42709 [dir_watcher.py:_on_file_modified():288] file/dir modified: /cluster/home/yutang/Deep-Knowledge-Tracing/DKT/KnowledgeTracing/evaluation/wandb/run-20231104_200136-w96e4u9y/files/output.log
2023-11-04 20:02:09,001 DEBUG   HandlerThread:42709 [handler.py:handle_request():146] handle_request: status_report
2023-11-04 20:02:09,197 DEBUG   SenderThread:42709 [sender.py:send():380] send: exit
2023-11-04 20:02:09,197 INFO    SenderThread:42709 [sender.py:send_exit():585] handling exit code: 1
2023-11-04 20:02:09,197 INFO    SenderThread:42709 [sender.py:send_exit():587] handling runtime: 31
2023-11-04 20:02:09,199 INFO    SenderThread:42709 [sender.py:_save_file():1378] saving file wandb-summary.json with policy end
2023-11-04 20:02:09,199 INFO    SenderThread:42709 [sender.py:send_exit():593] send defer
2023-11-04 20:02:09,199 DEBUG   HandlerThread:42709 [handler.py:handle_request():146] handle_request: defer
2023-11-04 20:02:09,199 INFO    HandlerThread:42709 [handler.py:handle_request_defer():172] handle defer: 0
2023-11-04 20:02:09,200 DEBUG   SenderThread:42709 [sender.py:send_request():407] send_request: defer
2023-11-04 20:02:09,200 INFO    SenderThread:42709 [sender.py:send_request_defer():609] handle sender defer: 0
2023-11-04 20:02:09,200 INFO    SenderThread:42709 [sender.py:transition_state():613] send defer: 1
2023-11-04 20:02:09,200 DEBUG   HandlerThread:42709 [handler.py:handle_request():146] handle_request: defer
2023-11-04 20:02:09,200 INFO    HandlerThread:42709 [handler.py:handle_request_defer():172] handle defer: 1
2023-11-04 20:02:09,200 DEBUG   SenderThread:42709 [sender.py:send_request():407] send_request: defer
2023-11-04 20:02:09,200 INFO    SenderThread:42709 [sender.py:send_request_defer():609] handle sender defer: 1
2023-11-04 20:02:09,200 INFO    SenderThread:42709 [sender.py:transition_state():613] send defer: 2
2023-11-04 20:02:09,200 DEBUG   HandlerThread:42709 [handler.py:handle_request():146] handle_request: defer
2023-11-04 20:02:09,200 INFO    HandlerThread:42709 [handler.py:handle_request_defer():172] handle defer: 2
2023-11-04 20:02:09,200 INFO    HandlerThread:42709 [system_monitor.py:finish():203] Stopping system monitor
2023-11-04 20:02:09,200 DEBUG   SystemMonitor:42709 [system_monitor.py:_start():172] Starting system metrics aggregation loop
2023-11-04 20:02:09,201 DEBUG   SystemMonitor:42709 [system_monitor.py:_start():179] Finished system metrics aggregation loop
2023-11-04 20:02:09,201 DEBUG   SystemMonitor:42709 [system_monitor.py:_start():183] Publishing last batch of metrics
2023-11-04 20:02:09,203 INFO    HandlerThread:42709 [interfaces.py:finish():202] Joined cpu monitor
2023-11-04 20:02:09,203 INFO    HandlerThread:42709 [interfaces.py:finish():202] Joined disk monitor
2023-11-04 20:02:09,345 INFO    HandlerThread:42709 [interfaces.py:finish():202] Joined gpu monitor
2023-11-04 20:02:09,346 INFO    HandlerThread:42709 [interfaces.py:finish():202] Joined memory monitor
2023-11-04 20:02:09,346 INFO    HandlerThread:42709 [interfaces.py:finish():202] Joined network monitor
2023-11-04 20:02:09,346 DEBUG   SenderThread:42709 [sender.py:send_request():407] send_request: defer
2023-11-04 20:02:09,346 INFO    SenderThread:42709 [sender.py:send_request_defer():609] handle sender defer: 2
2023-11-04 20:02:09,346 INFO    SenderThread:42709 [sender.py:transition_state():613] send defer: 3
2023-11-04 20:02:09,346 DEBUG   SenderThread:42709 [sender.py:send():380] send: stats
2023-11-04 20:02:09,347 DEBUG   HandlerThread:42709 [handler.py:handle_request():146] handle_request: defer
2023-11-04 20:02:09,347 INFO    HandlerThread:42709 [handler.py:handle_request_defer():172] handle defer: 3
2023-11-04 20:02:09,347 DEBUG   SenderThread:42709 [sender.py:send_request():407] send_request: defer
2023-11-04 20:02:09,347 INFO    SenderThread:42709 [sender.py:send_request_defer():609] handle sender defer: 3
2023-11-04 20:02:09,347 INFO    SenderThread:42709 [sender.py:transition_state():613] send defer: 4
2023-11-04 20:02:09,348 DEBUG   HandlerThread:42709 [handler.py:handle_request():146] handle_request: defer
2023-11-04 20:02:09,348 INFO    HandlerThread:42709 [handler.py:handle_request_defer():172] handle defer: 4
2023-11-04 20:02:09,348 DEBUG   SenderThread:42709 [sender.py:send_request():407] send_request: defer
2023-11-04 20:02:09,348 INFO    SenderThread:42709 [sender.py:send_request_defer():609] handle sender defer: 4
2023-11-04 20:02:09,348 INFO    SenderThread:42709 [sender.py:transition_state():613] send defer: 5
2023-11-04 20:02:09,348 DEBUG   HandlerThread:42709 [handler.py:handle_request():146] handle_request: defer
2023-11-04 20:02:09,348 INFO    HandlerThread:42709 [handler.py:handle_request_defer():172] handle defer: 5
2023-11-04 20:02:09,348 DEBUG   SenderThread:42709 [sender.py:send():380] send: summary
2023-11-04 20:02:09,350 INFO    SenderThread:42709 [sender.py:_save_file():1378] saving file wandb-summary.json with policy end
2023-11-04 20:02:09,350 DEBUG   SenderThread:42709 [sender.py:send_request():407] send_request: defer
2023-11-04 20:02:09,350 INFO    SenderThread:42709 [sender.py:send_request_defer():609] handle sender defer: 5
2023-11-04 20:02:09,350 INFO    SenderThread:42709 [sender.py:transition_state():613] send defer: 6
2023-11-04 20:02:09,350 DEBUG   HandlerThread:42709 [handler.py:handle_request():146] handle_request: defer
2023-11-04 20:02:09,350 INFO    HandlerThread:42709 [handler.py:handle_request_defer():172] handle defer: 6
2023-11-04 20:02:09,350 DEBUG   SenderThread:42709 [sender.py:send_request():407] send_request: defer
2023-11-04 20:02:09,351 INFO    SenderThread:42709 [sender.py:send_request_defer():609] handle sender defer: 6
2023-11-04 20:02:09,351 INFO    SenderThread:42709 [sender.py:transition_state():613] send defer: 7
2023-11-04 20:02:09,351 DEBUG   HandlerThread:42709 [handler.py:handle_request():146] handle_request: status_report
2023-11-04 20:02:09,351 DEBUG   HandlerThread:42709 [handler.py:handle_request():146] handle_request: defer
2023-11-04 20:02:09,351 INFO    HandlerThread:42709 [handler.py:handle_request_defer():172] handle defer: 7
2023-11-04 20:02:09,351 DEBUG   SenderThread:42709 [sender.py:send_request():407] send_request: defer
2023-11-04 20:02:09,351 INFO    SenderThread:42709 [sender.py:send_request_defer():609] handle sender defer: 7
2023-11-04 20:02:10,005 INFO    Thread-12 :42709 [dir_watcher.py:_on_file_modified():288] file/dir modified: /cluster/home/yutang/Deep-Knowledge-Tracing/DKT/KnowledgeTracing/evaluation/wandb/run-20231104_200136-w96e4u9y/files/config.yaml
2023-11-04 20:02:10,005 INFO    Thread-12 :42709 [dir_watcher.py:_on_file_created():271] file/dir created: /cluster/home/yutang/Deep-Knowledge-Tracing/DKT/KnowledgeTracing/evaluation/wandb/run-20231104_200136-w96e4u9y/files/wandb-summary.json
2023-11-04 20:02:10,006 DEBUG   HandlerThread:42709 [handler.py:handle_request():146] handle_request: poll_exit
2023-11-04 20:02:11,052 INFO    SenderThread:42709 [sender.py:transition_state():613] send defer: 8
2023-11-04 20:02:11,053 DEBUG   SenderThread:42709 [sender.py:send_request():407] send_request: poll_exit
2023-11-04 20:02:11,053 DEBUG   HandlerThread:42709 [handler.py:handle_request():146] handle_request: defer
2023-11-04 20:02:11,053 INFO    HandlerThread:42709 [handler.py:handle_request_defer():172] handle defer: 8
2023-11-04 20:02:11,054 DEBUG   SenderThread:42709 [sender.py:send_request():407] send_request: defer
2023-11-04 20:02:11,054 INFO    SenderThread:42709 [sender.py:send_request_defer():609] handle sender defer: 8
2023-11-04 20:02:11,054 INFO    SenderThread:42709 [job_builder.py:build():281] Attempting to build job artifact
2023-11-04 20:02:11,055 INFO    SenderThread:42709 [job_builder.py:_get_source_type():393] is repo sourced job
2023-11-04 20:02:11,060 INFO    SenderThread:42709 [job_builder.py:build():369] adding wandb-job metadata file
2023-11-04 20:02:11,068 INFO    SenderThread:42709 [sender.py:transition_state():613] send defer: 9
2023-11-04 20:02:11,068 DEBUG   HandlerThread:42709 [handler.py:handle_request():146] handle_request: defer
2023-11-04 20:02:11,068 DEBUG   SenderThread:42709 [sender.py:send():380] send: artifact
2023-11-04 20:02:11,068 INFO    HandlerThread:42709 [handler.py:handle_request_defer():172] handle defer: 9
2023-11-04 20:02:12,006 INFO    Thread-12 :42709 [dir_watcher.py:_on_file_modified():288] file/dir modified: /cluster/home/yutang/Deep-Knowledge-Tracing/DKT/KnowledgeTracing/evaluation/wandb/run-20231104_200136-w96e4u9y/files/output.log
2023-11-04 20:02:12,086 ERROR   wandb-upload_1:42709 [internal_api.py:upload_file():2556] upload_file exception https://storage.googleapis.com/wandb-artifacts-prod/wandb_artifacts/112721340/628302132/102cc8ee8286496275f91b42827e86ae?Expires=1699210932&GoogleAccessId=gorilla-files-url-signer-man%40wandb-production.iam.gserviceaccount.com&Signature=DHQiOOynaHkb%2Bn3%2FNxqNACHlg2ZmX7iAHx5IZl%2B4hBIUN5HG3xyFiTeLjAJogTffYVemlZWzY7tWbcQ5f06GtNtgChjMfzPR8omXmuAdxQypx8Et1zwniMibYX1eXWuNUEpOpWYnNcwGRGFBrfw36uGx91wUgAtPsi82MGDHWuTRPuLpktgPAY8v46TFrkQUnQlkQB7P2qopWkoO5HwJTOlIDKxuYJAHaehhk%2FDEFzlxN18IyLly6E3cfOaX1elS%2F4APHxq2I%2FvOxU2GLGR5jQkkhXeshZU%2FdzNaNqxX9z%2FxpJClux4iBsSGlnSlyALL2ERyeQIb8VfFhYfxg%2B2EKg%3D%3D: HTTPSConnectionPool(host='storage.googleapis.com', port=443): Max retries exceeded with url: /wandb-artifacts-prod/wandb_artifacts/112721340/628302132/102cc8ee8286496275f91b42827e86ae?Expires=1699210932&GoogleAccessId=gorilla-files-url-signer-man%40wandb-production.iam.gserviceaccount.com&Signature=DHQiOOynaHkb%2Bn3%2FNxqNACHlg2ZmX7iAHx5IZl%2B4hBIUN5HG3xyFiTeLjAJogTffYVemlZWzY7tWbcQ5f06GtNtgChjMfzPR8omXmuAdxQypx8Et1zwniMibYX1eXWuNUEpOpWYnNcwGRGFBrfw36uGx91wUgAtPsi82MGDHWuTRPuLpktgPAY8v46TFrkQUnQlkQB7P2qopWkoO5HwJTOlIDKxuYJAHaehhk%2FDEFzlxN18IyLly6E3cfOaX1elS%2F4APHxq2I%2FvOxU2GLGR5jQkkhXeshZU%2FdzNaNqxX9z%2FxpJClux4iBsSGlnSlyALL2ERyeQIb8VfFhYfxg%2B2EKg%3D%3D (Caused by NewConnectionError('<urllib3.connection.HTTPSConnection object at 0x2b5cb2bd15e0>: Failed to establish a new connection: [Errno 101] Network is unreachable'))
2023-11-04 20:02:12,086 ERROR   wandb-upload_1:42709 [internal_api.py:upload_file():2558] upload_file request headers: {'User-Agent': 'python-requests/2.28.1', 'Accept-Encoding': 'gzip, deflate, br', 'Accept': '*/*', 'Connection': 'keep-alive', 'Content-MD5': 'ECzI7oKGSWJ1+RtCgn6Grg==', 'Content-Type': 'text/plain; charset=utf-8', 'Content-Length': '1756'}
2023-11-04 20:02:12,086 ERROR   wandb-upload_1:42709 [internal_api.py:upload_file():2560] upload_file response body: 
2023-11-04 20:02:12,086 ERROR   wandb-upload_2:42709 [internal_api.py:upload_file():2556] upload_file exception https://storage.googleapis.com/wandb-artifacts-prod/wandb_artifacts/112721340/628302132/736d2e841e706f032bb0b718411a8b04?Expires=1699210931&GoogleAccessId=gorilla-files-url-signer-man%40wandb-production.iam.gserviceaccount.com&Signature=PR2HKa1qmYLkYTk1fKaQ88CMcVkdDKu0nCX47FeLHzKpWMSKKbG7FMIxr0kSL84Y%2BChRJp%2BicbNTb23lfFomBgly2R1RKuTaoiIswxTdtdn1nyfuEG8BOCNFXgzUxlxC5jOUdD4RkZH6zzkiWwnFkGliPkghD%2BEx4PyKnIqYBP0sID4qXHx15u%2B074ISe8ex6mJQRwBunUCw3B85h8j9pgqVrM1T75%2F%2FRiFzGRJgxCgKbQPzhYQEypuCsTIs9BELNYskQqY2Wbu2dy2%2BDjkYus2OmtkTEElBCVewA%2FnSuIdrAYp90%2BLTUBwJI94buJNLOMVh8KzjFrTpUqso%2BLJDSg%3D%3D: HTTPSConnectionPool(host='storage.googleapis.com', port=443): Max retries exceeded with url: /wandb-artifacts-prod/wandb_artifacts/112721340/628302132/736d2e841e706f032bb0b718411a8b04?Expires=1699210931&GoogleAccessId=gorilla-files-url-signer-man%40wandb-production.iam.gserviceaccount.com&Signature=PR2HKa1qmYLkYTk1fKaQ88CMcVkdDKu0nCX47FeLHzKpWMSKKbG7FMIxr0kSL84Y%2BChRJp%2BicbNTb23lfFomBgly2R1RKuTaoiIswxTdtdn1nyfuEG8BOCNFXgzUxlxC5jOUdD4RkZH6zzkiWwnFkGliPkghD%2BEx4PyKnIqYBP0sID4qXHx15u%2B074ISe8ex6mJQRwBunUCw3B85h8j9pgqVrM1T75%2F%2FRiFzGRJgxCgKbQPzhYQEypuCsTIs9BELNYskQqY2Wbu2dy2%2BDjkYus2OmtkTEElBCVewA%2FnSuIdrAYp90%2BLTUBwJI94buJNLOMVh8KzjFrTpUqso%2BLJDSg%3D%3D (Caused by NewConnectionError('<urllib3.connection.HTTPSConnection object at 0x2b5cb2bd17f0>: Failed to establish a new connection: [Errno 101] Network is unreachable'))
2023-11-04 20:02:12,086 ERROR   wandb-upload_2:42709 [internal_api.py:upload_file():2558] upload_file request headers: {'User-Agent': 'python-requests/2.28.1', 'Accept-Encoding': 'gzip, deflate, br', 'Accept': '*/*', 'Connection': 'keep-alive', 'Content-MD5': 'c20uhB5wbwMrsLcYQRqLBA==', 'Content-Type': 'application/json', 'Content-Length': '648'}
2023-11-04 20:02:12,086 ERROR   wandb-upload_2:42709 [internal_api.py:upload_file():2560] upload_file response body: 
2023-11-04 20:02:13,148 ERROR   wandb-upload_1:42709 [internal_api.py:upload_file():2556] upload_file exception https://storage.googleapis.com/wandb-artifacts-prod/wandb_artifacts/112721340/628302132/102cc8ee8286496275f91b42827e86ae?Expires=1699210932&GoogleAccessId=gorilla-files-url-signer-man%40wandb-production.iam.gserviceaccount.com&Signature=DHQiOOynaHkb%2Bn3%2FNxqNACHlg2ZmX7iAHx5IZl%2B4hBIUN5HG3xyFiTeLjAJogTffYVemlZWzY7tWbcQ5f06GtNtgChjMfzPR8omXmuAdxQypx8Et1zwniMibYX1eXWuNUEpOpWYnNcwGRGFBrfw36uGx91wUgAtPsi82MGDHWuTRPuLpktgPAY8v46TFrkQUnQlkQB7P2qopWkoO5HwJTOlIDKxuYJAHaehhk%2FDEFzlxN18IyLly6E3cfOaX1elS%2F4APHxq2I%2FvOxU2GLGR5jQkkhXeshZU%2FdzNaNqxX9z%2FxpJClux4iBsSGlnSlyALL2ERyeQIb8VfFhYfxg%2B2EKg%3D%3D: HTTPSConnectionPool(host='storage.googleapis.com', port=443): Max retries exceeded with url: /wandb-artifacts-prod/wandb_artifacts/112721340/628302132/102cc8ee8286496275f91b42827e86ae?Expires=1699210932&GoogleAccessId=gorilla-files-url-signer-man%40wandb-production.iam.gserviceaccount.com&Signature=DHQiOOynaHkb%2Bn3%2FNxqNACHlg2ZmX7iAHx5IZl%2B4hBIUN5HG3xyFiTeLjAJogTffYVemlZWzY7tWbcQ5f06GtNtgChjMfzPR8omXmuAdxQypx8Et1zwniMibYX1eXWuNUEpOpWYnNcwGRGFBrfw36uGx91wUgAtPsi82MGDHWuTRPuLpktgPAY8v46TFrkQUnQlkQB7P2qopWkoO5HwJTOlIDKxuYJAHaehhk%2FDEFzlxN18IyLly6E3cfOaX1elS%2F4APHxq2I%2FvOxU2GLGR5jQkkhXeshZU%2FdzNaNqxX9z%2FxpJClux4iBsSGlnSlyALL2ERyeQIb8VfFhYfxg%2B2EKg%3D%3D (Caused by NewConnectionError('<urllib3.connection.HTTPSConnection object at 0x2b5c87eeb640>: Failed to establish a new connection: [Errno 101] Network is unreachable'))
2023-11-04 20:02:13,148 ERROR   wandb-upload_1:42709 [internal_api.py:upload_file():2558] upload_file request headers: {'User-Agent': 'python-requests/2.28.1', 'Accept-Encoding': 'gzip, deflate, br', 'Accept': '*/*', 'Connection': 'keep-alive', 'Content-MD5': 'ECzI7oKGSWJ1+RtCgn6Grg==', 'Content-Type': 'text/plain; charset=utf-8', 'Content-Length': '1756'}
2023-11-04 20:02:13,148 ERROR   wandb-upload_1:42709 [internal_api.py:upload_file():2560] upload_file response body: 
2023-11-04 20:02:13,247 ERROR   wandb-upload_2:42709 [internal_api.py:upload_file():2556] upload_file exception https://storage.googleapis.com/wandb-artifacts-prod/wandb_artifacts/112721340/628302132/736d2e841e706f032bb0b718411a8b04?Expires=1699210931&GoogleAccessId=gorilla-files-url-signer-man%40wandb-production.iam.gserviceaccount.com&Signature=PR2HKa1qmYLkYTk1fKaQ88CMcVkdDKu0nCX47FeLHzKpWMSKKbG7FMIxr0kSL84Y%2BChRJp%2BicbNTb23lfFomBgly2R1RKuTaoiIswxTdtdn1nyfuEG8BOCNFXgzUxlxC5jOUdD4RkZH6zzkiWwnFkGliPkghD%2BEx4PyKnIqYBP0sID4qXHx15u%2B074ISe8ex6mJQRwBunUCw3B85h8j9pgqVrM1T75%2F%2FRiFzGRJgxCgKbQPzhYQEypuCsTIs9BELNYskQqY2Wbu2dy2%2BDjkYus2OmtkTEElBCVewA%2FnSuIdrAYp90%2BLTUBwJI94buJNLOMVh8KzjFrTpUqso%2BLJDSg%3D%3D: HTTPSConnectionPool(host='storage.googleapis.com', port=443): Max retries exceeded with url: /wandb-artifacts-prod/wandb_artifacts/112721340/628302132/736d2e841e706f032bb0b718411a8b04?Expires=1699210931&GoogleAccessId=gorilla-files-url-signer-man%40wandb-production.iam.gserviceaccount.com&Signature=PR2HKa1qmYLkYTk1fKaQ88CMcVkdDKu0nCX47FeLHzKpWMSKKbG7FMIxr0kSL84Y%2BChRJp%2BicbNTb23lfFomBgly2R1RKuTaoiIswxTdtdn1nyfuEG8BOCNFXgzUxlxC5jOUdD4RkZH6zzkiWwnFkGliPkghD%2BEx4PyKnIqYBP0sID4qXHx15u%2B074ISe8ex6mJQRwBunUCw3B85h8j9pgqVrM1T75%2F%2FRiFzGRJgxCgKbQPzhYQEypuCsTIs9BELNYskQqY2Wbu2dy2%2BDjkYus2OmtkTEElBCVewA%2FnSuIdrAYp90%2BLTUBwJI94buJNLOMVh8KzjFrTpUqso%2BLJDSg%3D%3D (Caused by NewConnectionError('<urllib3.connection.HTTPSConnection object at 0x2b5cb2bd18b0>: Failed to establish a new connection: [Errno 101] Network is unreachable'))
2023-11-04 20:02:13,248 ERROR   wandb-upload_2:42709 [internal_api.py:upload_file():2558] upload_file request headers: {'User-Agent': 'python-requests/2.28.1', 'Accept-Encoding': 'gzip, deflate, br', 'Accept': '*/*', 'Connection': 'keep-alive', 'Content-MD5': 'c20uhB5wbwMrsLcYQRqLBA==', 'Content-Type': 'application/json', 'Content-Length': '648'}
2023-11-04 20:02:13,248 ERROR   wandb-upload_2:42709 [internal_api.py:upload_file():2560] upload_file response body: 
2023-11-04 20:02:14,560 ERROR   wandb-upload_0:42709 [internal_api.py:upload_file():2556] upload_file exception https://storage.googleapis.com/wandb-production.appspot.com/bryanttang/DKT-trial%201/w96e4u9y/wandb-metadata.json?Expires=1699210900&GoogleAccessId=gorilla-files-url-signer-man%40wandb-production.iam.gserviceaccount.com&Signature=FFKp6KRwxqtwRO4hH9sNqyOHzFnLn2BjM6zCR%2Bk5OhIbJ%2BYOSxkUfZMm%2FYZR%2B2tVE%2FcmVNSVnSJEkiu3RrZkzdQEnMkgp%2Bi0kVy%2BTWojmINkD%2BJ%2Bmc6XT4%2Bvw1u%2FGhAcU9Q3bmmj66F%2B9B146TbKj4reCfiTN2obFklIAH%2F9QiLTXGLhkob%2BF8IPen1tlk7XduEXjeRYhjtaEfX3JbExp6wSNSxq%2FJKI4o3cMI0LjqN3U37Sc3A1RxG%2BEaXo8gkTMlKnoVg3XxN21gu%2Bq1%2Byfr1ELNaPmwl0n86w7iMr1HriU44av0ogBNZlB2flv6GMTgnHyaFBMEHybYWXYzuKYw%3D%3D: HTTPSConnectionPool(host='storage.googleapis.com', port=443): Max retries exceeded with url: /wandb-production.appspot.com/bryanttang/DKT-trial%201/w96e4u9y/wandb-metadata.json?Expires=1699210900&GoogleAccessId=gorilla-files-url-signer-man%40wandb-production.iam.gserviceaccount.com&Signature=FFKp6KRwxqtwRO4hH9sNqyOHzFnLn2BjM6zCR%2Bk5OhIbJ%2BYOSxkUfZMm%2FYZR%2B2tVE%2FcmVNSVnSJEkiu3RrZkzdQEnMkgp%2Bi0kVy%2BTWojmINkD%2BJ%2Bmc6XT4%2Bvw1u%2FGhAcU9Q3bmmj66F%2B9B146TbKj4reCfiTN2obFklIAH%2F9QiLTXGLhkob%2BF8IPen1tlk7XduEXjeRYhjtaEfX3JbExp6wSNSxq%2FJKI4o3cMI0LjqN3U37Sc3A1RxG%2BEaXo8gkTMlKnoVg3XxN21gu%2Bq1%2Byfr1ELNaPmwl0n86w7iMr1HriU44av0ogBNZlB2flv6GMTgnHyaFBMEHybYWXYzuKYw%3D%3D (Caused by NewConnectionError('<urllib3.connection.HTTPSConnection object at 0x2b5cb2bd1c70>: Failed to establish a new connection: [Errno 101] Network is unreachable'))
2023-11-04 20:02:14,560 ERROR   wandb-upload_0:42709 [internal_api.py:upload_file():2558] upload_file request headers: {'User-Agent': 'python-requests/2.28.1', 'Accept-Encoding': 'gzip, deflate, br', 'Accept': '*/*', 'Connection': 'keep-alive', 'Content-Length': '14811'}
2023-11-04 20:02:14,560 ERROR   wandb-upload_0:42709 [internal_api.py:upload_file():2560] upload_file response body: 
2023-11-04 20:02:15,008 DEBUG   HandlerThread:42709 [handler.py:handle_request():146] handle_request: keepalive
2023-11-04 20:02:15,432 ERROR   wandb-upload_2:42709 [internal_api.py:upload_file():2556] upload_file exception https://storage.googleapis.com/wandb-artifacts-prod/wandb_artifacts/112721340/628302132/736d2e841e706f032bb0b718411a8b04?Expires=1699210931&GoogleAccessId=gorilla-files-url-signer-man%40wandb-production.iam.gserviceaccount.com&Signature=PR2HKa1qmYLkYTk1fKaQ88CMcVkdDKu0nCX47FeLHzKpWMSKKbG7FMIxr0kSL84Y%2BChRJp%2BicbNTb23lfFomBgly2R1RKuTaoiIswxTdtdn1nyfuEG8BOCNFXgzUxlxC5jOUdD4RkZH6zzkiWwnFkGliPkghD%2BEx4PyKnIqYBP0sID4qXHx15u%2B074ISe8ex6mJQRwBunUCw3B85h8j9pgqVrM1T75%2F%2FRiFzGRJgxCgKbQPzhYQEypuCsTIs9BELNYskQqY2Wbu2dy2%2BDjkYus2OmtkTEElBCVewA%2FnSuIdrAYp90%2BLTUBwJI94buJNLOMVh8KzjFrTpUqso%2BLJDSg%3D%3D: HTTPSConnectionPool(host='storage.googleapis.com', port=443): Max retries exceeded with url: /wandb-artifacts-prod/wandb_artifacts/112721340/628302132/736d2e841e706f032bb0b718411a8b04?Expires=1699210931&GoogleAccessId=gorilla-files-url-signer-man%40wandb-production.iam.gserviceaccount.com&Signature=PR2HKa1qmYLkYTk1fKaQ88CMcVkdDKu0nCX47FeLHzKpWMSKKbG7FMIxr0kSL84Y%2BChRJp%2BicbNTb23lfFomBgly2R1RKuTaoiIswxTdtdn1nyfuEG8BOCNFXgzUxlxC5jOUdD4RkZH6zzkiWwnFkGliPkghD%2BEx4PyKnIqYBP0sID4qXHx15u%2B074ISe8ex6mJQRwBunUCw3B85h8j9pgqVrM1T75%2F%2FRiFzGRJgxCgKbQPzhYQEypuCsTIs9BELNYskQqY2Wbu2dy2%2BDjkYus2OmtkTEElBCVewA%2FnSuIdrAYp90%2BLTUBwJI94buJNLOMVh8KzjFrTpUqso%2BLJDSg%3D%3D (Caused by NewConnectionError('<urllib3.connection.HTTPSConnection object at 0x2b5c87eeb8b0>: Failed to establish a new connection: [Errno 101] Network is unreachable'))
2023-11-04 20:02:15,432 ERROR   wandb-upload_2:42709 [internal_api.py:upload_file():2558] upload_file request headers: {'User-Agent': 'python-requests/2.28.1', 'Accept-Encoding': 'gzip, deflate, br', 'Accept': '*/*', 'Connection': 'keep-alive', 'Content-MD5': 'c20uhB5wbwMrsLcYQRqLBA==', 'Content-Type': 'application/json', 'Content-Length': '648'}
2023-11-04 20:02:15,432 ERROR   wandb-upload_2:42709 [internal_api.py:upload_file():2560] upload_file response body: 
2023-11-04 20:02:15,432 INFO    wandb-upload_2:42709 [retry.py:__call__():172] Retry attempt failed:
Traceback (most recent call last):
  File "/cluster/home/yutang/miniconda3/lib/python3.9/site-packages/urllib3/connection.py", line 174, in _new_conn
    conn = connection.create_connection(
  File "/cluster/home/yutang/miniconda3/lib/python3.9/site-packages/urllib3/util/connection.py", line 95, in create_connection
    raise err
  File "/cluster/home/yutang/miniconda3/lib/python3.9/site-packages/urllib3/util/connection.py", line 85, in create_connection
    sock.connect(sa)
OSError: [Errno 101] Network is unreachable

During handling of the above exception, another exception occurred:

Traceback (most recent call last):
  File "/cluster/home/yutang/miniconda3/lib/python3.9/site-packages/urllib3/connectionpool.py", line 703, in urlopen
    httplib_response = self._make_request(
  File "/cluster/home/yutang/miniconda3/lib/python3.9/site-packages/urllib3/connectionpool.py", line 386, in _make_request
    self._validate_conn(conn)
  File "/cluster/home/yutang/miniconda3/lib/python3.9/site-packages/urllib3/connectionpool.py", line 1042, in _validate_conn
    conn.connect()
  File "/cluster/home/yutang/miniconda3/lib/python3.9/site-packages/urllib3/connection.py", line 358, in connect
    self.sock = conn = self._new_conn()
  File "/cluster/home/yutang/miniconda3/lib/python3.9/site-packages/urllib3/connection.py", line 186, in _new_conn
    raise NewConnectionError(
urllib3.exceptions.NewConnectionError: <urllib3.connection.HTTPSConnection object at 0x2b5c87eeb8b0>: Failed to establish a new connection: [Errno 101] Network is unreachable

During handling of the above exception, another exception occurred:

Traceback (most recent call last):
  File "/cluster/home/yutang/miniconda3/lib/python3.9/site-packages/requests/adapters.py", line 489, in send
    resp = conn.urlopen(
  File "/cluster/home/yutang/miniconda3/lib/python3.9/site-packages/urllib3/connectionpool.py", line 787, in urlopen
    retries = retries.increment(
  File "/cluster/home/yutang/miniconda3/lib/python3.9/site-packages/urllib3/util/retry.py", line 592, in increment
    raise MaxRetryError(_pool, url, error or ResponseError(cause))
urllib3.exceptions.MaxRetryError: HTTPSConnectionPool(host='storage.googleapis.com', port=443): Max retries exceeded with url: /wandb-artifacts-prod/wandb_artifacts/112721340/628302132/736d2e841e706f032bb0b718411a8b04?Expires=1699210931&GoogleAccessId=gorilla-files-url-signer-man%40wandb-production.iam.gserviceaccount.com&Signature=PR2HKa1qmYLkYTk1fKaQ88CMcVkdDKu0nCX47FeLHzKpWMSKKbG7FMIxr0kSL84Y%2BChRJp%2BicbNTb23lfFomBgly2R1RKuTaoiIswxTdtdn1nyfuEG8BOCNFXgzUxlxC5jOUdD4RkZH6zzkiWwnFkGliPkghD%2BEx4PyKnIqYBP0sID4qXHx15u%2B074ISe8ex6mJQRwBunUCw3B85h8j9pgqVrM1T75%2F%2FRiFzGRJgxCgKbQPzhYQEypuCsTIs9BELNYskQqY2Wbu2dy2%2BDjkYus2OmtkTEElBCVewA%2FnSuIdrAYp90%2BLTUBwJI94buJNLOMVh8KzjFrTpUqso%2BLJDSg%3D%3D (Caused by NewConnectionError('<urllib3.connection.HTTPSConnection object at 0x2b5c87eeb8b0>: Failed to establish a new connection: [Errno 101] Network is unreachable'))

During handling of the above exception, another exception occurred:

Traceback (most recent call last):
  File "/cluster/home/yutang/miniconda3/lib/python3.9/site-packages/wandb/sdk/internal/internal_api.py", line 2549, in upload_file
    response = self._upload_file_session.put(
  File "/cluster/home/yutang/miniconda3/lib/python3.9/site-packages/requests/sessions.py", line 647, in put
    return self.request("PUT", url, data=data, **kwargs)
  File "/cluster/home/yutang/miniconda3/lib/python3.9/site-packages/requests/sessions.py", line 587, in request
    resp = self.send(prep, **send_kwargs)
  File "/cluster/home/yutang/miniconda3/lib/python3.9/site-packages/requests/sessions.py", line 701, in send
    r = adapter.send(request, **kwargs)
  File "/cluster/home/yutang/miniconda3/lib/python3.9/site-packages/requests/adapters.py", line 565, in send
    raise ConnectionError(e, request=request)
requests.exceptions.ConnectionError: HTTPSConnectionPool(host='storage.googleapis.com', port=443): Max retries exceeded with url: /wandb-artifacts-prod/wandb_artifacts/112721340/628302132/736d2e841e706f032bb0b718411a8b04?Expires=1699210931&GoogleAccessId=gorilla-files-url-signer-man%40wandb-production.iam.gserviceaccount.com&Signature=PR2HKa1qmYLkYTk1fKaQ88CMcVkdDKu0nCX47FeLHzKpWMSKKbG7FMIxr0kSL84Y%2BChRJp%2BicbNTb23lfFomBgly2R1RKuTaoiIswxTdtdn1nyfuEG8BOCNFXgzUxlxC5jOUdD4RkZH6zzkiWwnFkGliPkghD%2BEx4PyKnIqYBP0sID4qXHx15u%2B074ISe8ex6mJQRwBunUCw3B85h8j9pgqVrM1T75%2F%2FRiFzGRJgxCgKbQPzhYQEypuCsTIs9BELNYskQqY2Wbu2dy2%2BDjkYus2OmtkTEElBCVewA%2FnSuIdrAYp90%2BLTUBwJI94buJNLOMVh8KzjFrTpUqso%2BLJDSg%3D%3D (Caused by NewConnectionError('<urllib3.connection.HTTPSConnection object at 0x2b5c87eeb8b0>: Failed to establish a new connection: [Errno 101] Network is unreachable'))

During handling of the above exception, another exception occurred:

Traceback (most recent call last):
  File "/cluster/home/yutang/miniconda3/lib/python3.9/site-packages/wandb/sdk/lib/retry.py", line 131, in __call__
    result = self._call_fn(*args, **kwargs)
  File "/cluster/home/yutang/miniconda3/lib/python3.9/site-packages/wandb/sdk/internal/internal_api.py", line 2580, in upload_file
    raise _e.with_traceback(sys.exc_info()[2])
  File "/cluster/home/yutang/miniconda3/lib/python3.9/site-packages/wandb/sdk/internal/internal_api.py", line 2549, in upload_file
    response = self._upload_file_session.put(
  File "/cluster/home/yutang/miniconda3/lib/python3.9/site-packages/requests/sessions.py", line 647, in put
    return self.request("PUT", url, data=data, **kwargs)
  File "/cluster/home/yutang/miniconda3/lib/python3.9/site-packages/requests/sessions.py", line 587, in request
    resp = self.send(prep, **send_kwargs)
  File "/cluster/home/yutang/miniconda3/lib/python3.9/site-packages/requests/sessions.py", line 701, in send
    r = adapter.send(request, **kwargs)
  File "/cluster/home/yutang/miniconda3/lib/python3.9/site-packages/requests/adapters.py", line 565, in send
    raise ConnectionError(e, request=request)
wandb.sdk.lib.retry.TransientError: None
2023-11-04 20:02:15,637 ERROR   wandb-upload_1:42709 [internal_api.py:upload_file():2556] upload_file exception https://storage.googleapis.com/wandb-artifacts-prod/wandb_artifacts/112721340/628302132/102cc8ee8286496275f91b42827e86ae?Expires=1699210932&GoogleAccessId=gorilla-files-url-signer-man%40wandb-production.iam.gserviceaccount.com&Signature=DHQiOOynaHkb%2Bn3%2FNxqNACHlg2ZmX7iAHx5IZl%2B4hBIUN5HG3xyFiTeLjAJogTffYVemlZWzY7tWbcQ5f06GtNtgChjMfzPR8omXmuAdxQypx8Et1zwniMibYX1eXWuNUEpOpWYnNcwGRGFBrfw36uGx91wUgAtPsi82MGDHWuTRPuLpktgPAY8v46TFrkQUnQlkQB7P2qopWkoO5HwJTOlIDKxuYJAHaehhk%2FDEFzlxN18IyLly6E3cfOaX1elS%2F4APHxq2I%2FvOxU2GLGR5jQkkhXeshZU%2FdzNaNqxX9z%2FxpJClux4iBsSGlnSlyALL2ERyeQIb8VfFhYfxg%2B2EKg%3D%3D: HTTPSConnectionPool(host='storage.googleapis.com', port=443): Max retries exceeded with url: /wandb-artifacts-prod/wandb_artifacts/112721340/628302132/102cc8ee8286496275f91b42827e86ae?Expires=1699210932&GoogleAccessId=gorilla-files-url-signer-man%40wandb-production.iam.gserviceaccount.com&Signature=DHQiOOynaHkb%2Bn3%2FNxqNACHlg2ZmX7iAHx5IZl%2B4hBIUN5HG3xyFiTeLjAJogTffYVemlZWzY7tWbcQ5f06GtNtgChjMfzPR8omXmuAdxQypx8Et1zwniMibYX1eXWuNUEpOpWYnNcwGRGFBrfw36uGx91wUgAtPsi82MGDHWuTRPuLpktgPAY8v46TFrkQUnQlkQB7P2qopWkoO5HwJTOlIDKxuYJAHaehhk%2FDEFzlxN18IyLly6E3cfOaX1elS%2F4APHxq2I%2FvOxU2GLGR5jQkkhXeshZU%2FdzNaNqxX9z%2FxpJClux4iBsSGlnSlyALL2ERyeQIb8VfFhYfxg%2B2EKg%3D%3D (Caused by NewConnectionError('<urllib3.connection.HTTPSConnection object at 0x2b5cb2bdaa30>: Failed to establish a new connection: [Errno 101] Network is unreachable'))
2023-11-04 20:02:15,637 ERROR   wandb-upload_1:42709 [internal_api.py:upload_file():2558] upload_file request headers: {'User-Agent': 'python-requests/2.28.1', 'Accept-Encoding': 'gzip, deflate, br', 'Accept': '*/*', 'Connection': 'keep-alive', 'Content-MD5': 'ECzI7oKGSWJ1+RtCgn6Grg==', 'Content-Type': 'text/plain; charset=utf-8', 'Content-Length': '1756'}
2023-11-04 20:02:15,637 ERROR   wandb-upload_1:42709 [internal_api.py:upload_file():2560] upload_file response body: 
2023-11-04 20:02:15,638 INFO    wandb-upload_1:42709 [retry.py:__call__():172] Retry attempt failed:
Traceback (most recent call last):
  File "/cluster/home/yutang/miniconda3/lib/python3.9/site-packages/urllib3/connection.py", line 174, in _new_conn
    conn = connection.create_connection(
  File "/cluster/home/yutang/miniconda3/lib/python3.9/site-packages/urllib3/util/connection.py", line 95, in create_connection
    raise err
  File "/cluster/home/yutang/miniconda3/lib/python3.9/site-packages/urllib3/util/connection.py", line 85, in create_connection
    sock.connect(sa)
OSError: [Errno 101] Network is unreachable

During handling of the above exception, another exception occurred:

Traceback (most recent call last):
  File "/cluster/home/yutang/miniconda3/lib/python3.9/site-packages/urllib3/connectionpool.py", line 703, in urlopen
    httplib_response = self._make_request(
  File "/cluster/home/yutang/miniconda3/lib/python3.9/site-packages/urllib3/connectionpool.py", line 386, in _make_request
    self._validate_conn(conn)
  File "/cluster/home/yutang/miniconda3/lib/python3.9/site-packages/urllib3/connectionpool.py", line 1042, in _validate_conn
    conn.connect()
  File "/cluster/home/yutang/miniconda3/lib/python3.9/site-packages/urllib3/connection.py", line 358, in connect
    self.sock = conn = self._new_conn()
  File "/cluster/home/yutang/miniconda3/lib/python3.9/site-packages/urllib3/connection.py", line 186, in _new_conn
    raise NewConnectionError(
urllib3.exceptions.NewConnectionError: <urllib3.connection.HTTPSConnection object at 0x2b5cb2bdaa30>: Failed to establish a new connection: [Errno 101] Network is unreachable

During handling of the above exception, another exception occurred:

Traceback (most recent call last):
  File "/cluster/home/yutang/miniconda3/lib/python3.9/site-packages/requests/adapters.py", line 489, in send
    resp = conn.urlopen(
  File "/cluster/home/yutang/miniconda3/lib/python3.9/site-packages/urllib3/connectionpool.py", line 787, in urlopen
    retries = retries.increment(
  File "/cluster/home/yutang/miniconda3/lib/python3.9/site-packages/urllib3/util/retry.py", line 592, in increment
    raise MaxRetryError(_pool, url, error or ResponseError(cause))
urllib3.exceptions.MaxRetryError: HTTPSConnectionPool(host='storage.googleapis.com', port=443): Max retries exceeded with url: /wandb-artifacts-prod/wandb_artifacts/112721340/628302132/102cc8ee8286496275f91b42827e86ae?Expires=1699210932&GoogleAccessId=gorilla-files-url-signer-man%40wandb-production.iam.gserviceaccount.com&Signature=DHQiOOynaHkb%2Bn3%2FNxqNACHlg2ZmX7iAHx5IZl%2B4hBIUN5HG3xyFiTeLjAJogTffYVemlZWzY7tWbcQ5f06GtNtgChjMfzPR8omXmuAdxQypx8Et1zwniMibYX1eXWuNUEpOpWYnNcwGRGFBrfw36uGx91wUgAtPsi82MGDHWuTRPuLpktgPAY8v46TFrkQUnQlkQB7P2qopWkoO5HwJTOlIDKxuYJAHaehhk%2FDEFzlxN18IyLly6E3cfOaX1elS%2F4APHxq2I%2FvOxU2GLGR5jQkkhXeshZU%2FdzNaNqxX9z%2FxpJClux4iBsSGlnSlyALL2ERyeQIb8VfFhYfxg%2B2EKg%3D%3D (Caused by NewConnectionError('<urllib3.connection.HTTPSConnection object at 0x2b5cb2bdaa30>: Failed to establish a new connection: [Errno 101] Network is unreachable'))

During handling of the above exception, another exception occurred:

Traceback (most recent call last):
  File "/cluster/home/yutang/miniconda3/lib/python3.9/site-packages/wandb/sdk/internal/internal_api.py", line 2549, in upload_file
    response = self._upload_file_session.put(
  File "/cluster/home/yutang/miniconda3/lib/python3.9/site-packages/requests/sessions.py", line 647, in put
    return self.request("PUT", url, data=data, **kwargs)
  File "/cluster/home/yutang/miniconda3/lib/python3.9/site-packages/requests/sessions.py", line 587, in request
    resp = self.send(prep, **send_kwargs)
  File "/cluster/home/yutang/miniconda3/lib/python3.9/site-packages/requests/sessions.py", line 701, in send
    r = adapter.send(request, **kwargs)
  File "/cluster/home/yutang/miniconda3/lib/python3.9/site-packages/requests/adapters.py", line 565, in send
    raise ConnectionError(e, request=request)
requests.exceptions.ConnectionError: HTTPSConnectionPool(host='storage.googleapis.com', port=443): Max retries exceeded with url: /wandb-artifacts-prod/wandb_artifacts/112721340/628302132/102cc8ee8286496275f91b42827e86ae?Expires=1699210932&GoogleAccessId=gorilla-files-url-signer-man%40wandb-production.iam.gserviceaccount.com&Signature=DHQiOOynaHkb%2Bn3%2FNxqNACHlg2ZmX7iAHx5IZl%2B4hBIUN5HG3xyFiTeLjAJogTffYVemlZWzY7tWbcQ5f06GtNtgChjMfzPR8omXmuAdxQypx8Et1zwniMibYX1eXWuNUEpOpWYnNcwGRGFBrfw36uGx91wUgAtPsi82MGDHWuTRPuLpktgPAY8v46TFrkQUnQlkQB7P2qopWkoO5HwJTOlIDKxuYJAHaehhk%2FDEFzlxN18IyLly6E3cfOaX1elS%2F4APHxq2I%2FvOxU2GLGR5jQkkhXeshZU%2FdzNaNqxX9z%2FxpJClux4iBsSGlnSlyALL2ERyeQIb8VfFhYfxg%2B2EKg%3D%3D (Caused by NewConnectionError('<urllib3.connection.HTTPSConnection object at 0x2b5cb2bdaa30>: Failed to establish a new connection: [Errno 101] Network is unreachable'))

During handling of the above exception, another exception occurred:

Traceback (most recent call last):
  File "/cluster/home/yutang/miniconda3/lib/python3.9/site-packages/wandb/sdk/lib/retry.py", line 131, in __call__
    result = self._call_fn(*args, **kwargs)
  File "/cluster/home/yutang/miniconda3/lib/python3.9/site-packages/wandb/sdk/internal/internal_api.py", line 2580, in upload_file
    raise _e.with_traceback(sys.exc_info()[2])
  File "/cluster/home/yutang/miniconda3/lib/python3.9/site-packages/wandb/sdk/internal/internal_api.py", line 2549, in upload_file
    response = self._upload_file_session.put(
  File "/cluster/home/yutang/miniconda3/lib/python3.9/site-packages/requests/sessions.py", line 647, in put
    return self.request("PUT", url, data=data, **kwargs)
  File "/cluster/home/yutang/miniconda3/lib/python3.9/site-packages/requests/sessions.py", line 587, in request
    resp = self.send(prep, **send_kwargs)
  File "/cluster/home/yutang/miniconda3/lib/python3.9/site-packages/requests/sessions.py", line 701, in send
    r = adapter.send(request, **kwargs)
  File "/cluster/home/yutang/miniconda3/lib/python3.9/site-packages/requests/adapters.py", line 565, in send
    raise ConnectionError(e, request=request)
wandb.sdk.lib.retry.TransientError: None
2023-11-04 20:02:19,945 ERROR   wandb-upload_2:42709 [internal_api.py:upload_file():2556] upload_file exception https://storage.googleapis.com/wandb-artifacts-prod/wandb_artifacts/112721340/628302132/736d2e841e706f032bb0b718411a8b04?Expires=1699210931&GoogleAccessId=gorilla-files-url-signer-man%40wandb-production.iam.gserviceaccount.com&Signature=PR2HKa1qmYLkYTk1fKaQ88CMcVkdDKu0nCX47FeLHzKpWMSKKbG7FMIxr0kSL84Y%2BChRJp%2BicbNTb23lfFomBgly2R1RKuTaoiIswxTdtdn1nyfuEG8BOCNFXgzUxlxC5jOUdD4RkZH6zzkiWwnFkGliPkghD%2BEx4PyKnIqYBP0sID4qXHx15u%2B074ISe8ex6mJQRwBunUCw3B85h8j9pgqVrM1T75%2F%2FRiFzGRJgxCgKbQPzhYQEypuCsTIs9BELNYskQqY2Wbu2dy2%2BDjkYus2OmtkTEElBCVewA%2FnSuIdrAYp90%2BLTUBwJI94buJNLOMVh8KzjFrTpUqso%2BLJDSg%3D%3D: HTTPSConnectionPool(host='storage.googleapis.com', port=443): Max retries exceeded with url: /wandb-artifacts-prod/wandb_artifacts/112721340/628302132/736d2e841e706f032bb0b718411a8b04?Expires=1699210931&GoogleAccessId=gorilla-files-url-signer-man%40wandb-production.iam.gserviceaccount.com&Signature=PR2HKa1qmYLkYTk1fKaQ88CMcVkdDKu0nCX47FeLHzKpWMSKKbG7FMIxr0kSL84Y%2BChRJp%2BicbNTb23lfFomBgly2R1RKuTaoiIswxTdtdn1nyfuEG8BOCNFXgzUxlxC5jOUdD4RkZH6zzkiWwnFkGliPkghD%2BEx4PyKnIqYBP0sID4qXHx15u%2B074ISe8ex6mJQRwBunUCw3B85h8j9pgqVrM1T75%2F%2FRiFzGRJgxCgKbQPzhYQEypuCsTIs9BELNYskQqY2Wbu2dy2%2BDjkYus2OmtkTEElBCVewA%2FnSuIdrAYp90%2BLTUBwJI94buJNLOMVh8KzjFrTpUqso%2BLJDSg%3D%3D (Caused by NewConnectionError('<urllib3.connection.HTTPSConnection object at 0x2b5cb2be40a0>: Failed to establish a new connection: [Errno 101] Network is unreachable'))
2023-11-04 20:02:19,945 ERROR   wandb-upload_2:42709 [internal_api.py:upload_file():2558] upload_file request headers: {'User-Agent': 'python-requests/2.28.1', 'Accept-Encoding': 'gzip, deflate, br', 'Accept': '*/*', 'Connection': 'keep-alive', 'Content-MD5': 'c20uhB5wbwMrsLcYQRqLBA==', 'Content-Type': 'application/json', 'Content-Length': '648'}
2023-11-04 20:02:19,945 ERROR   wandb-upload_2:42709 [internal_api.py:upload_file():2560] upload_file response body: 
2023-11-04 20:02:20,010 DEBUG   HandlerThread:42709 [handler.py:handle_request():146] handle_request: keepalive
2023-11-04 20:02:20,349 ERROR   wandb-upload_1:42709 [internal_api.py:upload_file():2556] upload_file exception https://storage.googleapis.com/wandb-artifacts-prod/wandb_artifacts/112721340/628302132/102cc8ee8286496275f91b42827e86ae?Expires=1699210932&GoogleAccessId=gorilla-files-url-signer-man%40wandb-production.iam.gserviceaccount.com&Signature=DHQiOOynaHkb%2Bn3%2FNxqNACHlg2ZmX7iAHx5IZl%2B4hBIUN5HG3xyFiTeLjAJogTffYVemlZWzY7tWbcQ5f06GtNtgChjMfzPR8omXmuAdxQypx8Et1zwniMibYX1eXWuNUEpOpWYnNcwGRGFBrfw36uGx91wUgAtPsi82MGDHWuTRPuLpktgPAY8v46TFrkQUnQlkQB7P2qopWkoO5HwJTOlIDKxuYJAHaehhk%2FDEFzlxN18IyLly6E3cfOaX1elS%2F4APHxq2I%2FvOxU2GLGR5jQkkhXeshZU%2FdzNaNqxX9z%2FxpJClux4iBsSGlnSlyALL2ERyeQIb8VfFhYfxg%2B2EKg%3D%3D: HTTPSConnectionPool(host='storage.googleapis.com', port=443): Max retries exceeded with url: /wandb-artifacts-prod/wandb_artifacts/112721340/628302132/102cc8ee8286496275f91b42827e86ae?Expires=1699210932&GoogleAccessId=gorilla-files-url-signer-man%40wandb-production.iam.gserviceaccount.com&Signature=DHQiOOynaHkb%2Bn3%2FNxqNACHlg2ZmX7iAHx5IZl%2B4hBIUN5HG3xyFiTeLjAJogTffYVemlZWzY7tWbcQ5f06GtNtgChjMfzPR8omXmuAdxQypx8Et1zwniMibYX1eXWuNUEpOpWYnNcwGRGFBrfw36uGx91wUgAtPsi82MGDHWuTRPuLpktgPAY8v46TFrkQUnQlkQB7P2qopWkoO5HwJTOlIDKxuYJAHaehhk%2FDEFzlxN18IyLly6E3cfOaX1elS%2F4APHxq2I%2FvOxU2GLGR5jQkkhXeshZU%2FdzNaNqxX9z%2FxpJClux4iBsSGlnSlyALL2ERyeQIb8VfFhYfxg%2B2EKg%3D%3D (Caused by NewConnectionError('<urllib3.connection.HTTPSConnection object at 0x2b5cb2be41f0>: Failed to establish a new connection: [Errno 101] Network is unreachable'))
2023-11-04 20:02:20,349 ERROR   wandb-upload_1:42709 [internal_api.py:upload_file():2558] upload_file request headers: {'User-Agent': 'python-requests/2.28.1', 'Accept-Encoding': 'gzip, deflate, br', 'Accept': '*/*', 'Connection': 'keep-alive', 'Content-MD5': 'ECzI7oKGSWJ1+RtCgn6Grg==', 'Content-Type': 'text/plain; charset=utf-8', 'Content-Length': '1756'}
2023-11-04 20:02:20,349 ERROR   wandb-upload_1:42709 [internal_api.py:upload_file():2560] upload_file response body: 
2023-11-04 20:02:25,011 DEBUG   HandlerThread:42709 [handler.py:handle_request():146] handle_request: keepalive
2023-11-04 20:02:29,083 ERROR   wandb-upload_2:42709 [internal_api.py:upload_file():2556] upload_file exception https://storage.googleapis.com/wandb-artifacts-prod/wandb_artifacts/112721340/628302132/736d2e841e706f032bb0b718411a8b04?Expires=1699210931&GoogleAccessId=gorilla-files-url-signer-man%40wandb-production.iam.gserviceaccount.com&Signature=PR2HKa1qmYLkYTk1fKaQ88CMcVkdDKu0nCX47FeLHzKpWMSKKbG7FMIxr0kSL84Y%2BChRJp%2BicbNTb23lfFomBgly2R1RKuTaoiIswxTdtdn1nyfuEG8BOCNFXgzUxlxC5jOUdD4RkZH6zzkiWwnFkGliPkghD%2BEx4PyKnIqYBP0sID4qXHx15u%2B074ISe8ex6mJQRwBunUCw3B85h8j9pgqVrM1T75%2F%2FRiFzGRJgxCgKbQPzhYQEypuCsTIs9BELNYskQqY2Wbu2dy2%2BDjkYus2OmtkTEElBCVewA%2FnSuIdrAYp90%2BLTUBwJI94buJNLOMVh8KzjFrTpUqso%2BLJDSg%3D%3D: HTTPSConnectionPool(host='storage.googleapis.com', port=443): Max retries exceeded with url: /wandb-artifacts-prod/wandb_artifacts/112721340/628302132/736d2e841e706f032bb0b718411a8b04?Expires=1699210931&GoogleAccessId=gorilla-files-url-signer-man%40wandb-production.iam.gserviceaccount.com&Signature=PR2HKa1qmYLkYTk1fKaQ88CMcVkdDKu0nCX47FeLHzKpWMSKKbG7FMIxr0kSL84Y%2BChRJp%2BicbNTb23lfFomBgly2R1RKuTaoiIswxTdtdn1nyfuEG8BOCNFXgzUxlxC5jOUdD4RkZH6zzkiWwnFkGliPkghD%2BEx4PyKnIqYBP0sID4qXHx15u%2B074ISe8ex6mJQRwBunUCw3B85h8j9pgqVrM1T75%2F%2FRiFzGRJgxCgKbQPzhYQEypuCsTIs9BELNYskQqY2Wbu2dy2%2BDjkYus2OmtkTEElBCVewA%2FnSuIdrAYp90%2BLTUBwJI94buJNLOMVh8KzjFrTpUqso%2BLJDSg%3D%3D (Caused by NewConnectionError('<urllib3.connection.HTTPSConnection object at 0x2b5cb2be9130>: Failed to establish a new connection: [Errno 101] Network is unreachable'))
2023-11-04 20:02:29,083 ERROR   wandb-upload_2:42709 [internal_api.py:upload_file():2558] upload_file request headers: {'User-Agent': 'python-requests/2.28.1', 'Accept-Encoding': 'gzip, deflate, br', 'Accept': '*/*', 'Connection': 'keep-alive', 'Content-MD5': 'c20uhB5wbwMrsLcYQRqLBA==', 'Content-Type': 'application/json', 'Content-Length': '648'}
2023-11-04 20:02:29,083 ERROR   wandb-upload_2:42709 [internal_api.py:upload_file():2560] upload_file response body: 
2023-11-04 20:02:30,012 DEBUG   HandlerThread:42709 [handler.py:handle_request():146] handle_request: keepalive
2023-11-04 20:02:30,224 ERROR   wandb-upload_1:42709 [internal_api.py:upload_file():2556] upload_file exception https://storage.googleapis.com/wandb-artifacts-prod/wandb_artifacts/112721340/628302132/102cc8ee8286496275f91b42827e86ae?Expires=1699210932&GoogleAccessId=gorilla-files-url-signer-man%40wandb-production.iam.gserviceaccount.com&Signature=DHQiOOynaHkb%2Bn3%2FNxqNACHlg2ZmX7iAHx5IZl%2B4hBIUN5HG3xyFiTeLjAJogTffYVemlZWzY7tWbcQ5f06GtNtgChjMfzPR8omXmuAdxQypx8Et1zwniMibYX1eXWuNUEpOpWYnNcwGRGFBrfw36uGx91wUgAtPsi82MGDHWuTRPuLpktgPAY8v46TFrkQUnQlkQB7P2qopWkoO5HwJTOlIDKxuYJAHaehhk%2FDEFzlxN18IyLly6E3cfOaX1elS%2F4APHxq2I%2FvOxU2GLGR5jQkkhXeshZU%2FdzNaNqxX9z%2FxpJClux4iBsSGlnSlyALL2ERyeQIb8VfFhYfxg%2B2EKg%3D%3D: HTTPSConnectionPool(host='storage.googleapis.com', port=443): Max retries exceeded with url: /wandb-artifacts-prod/wandb_artifacts/112721340/628302132/102cc8ee8286496275f91b42827e86ae?Expires=1699210932&GoogleAccessId=gorilla-files-url-signer-man%40wandb-production.iam.gserviceaccount.com&Signature=DHQiOOynaHkb%2Bn3%2FNxqNACHlg2ZmX7iAHx5IZl%2B4hBIUN5HG3xyFiTeLjAJogTffYVemlZWzY7tWbcQ5f06GtNtgChjMfzPR8omXmuAdxQypx8Et1zwniMibYX1eXWuNUEpOpWYnNcwGRGFBrfw36uGx91wUgAtPsi82MGDHWuTRPuLpktgPAY8v46TFrkQUnQlkQB7P2qopWkoO5HwJTOlIDKxuYJAHaehhk%2FDEFzlxN18IyLly6E3cfOaX1elS%2F4APHxq2I%2FvOxU2GLGR5jQkkhXeshZU%2FdzNaNqxX9z%2FxpJClux4iBsSGlnSlyALL2ERyeQIb8VfFhYfxg%2B2EKg%3D%3D (Caused by NewConnectionError('<urllib3.connection.HTTPSConnection object at 0x2b5cb2be4280>: Failed to establish a new connection: [Errno 101] Network is unreachable'))
2023-11-04 20:02:30,224 ERROR   wandb-upload_1:42709 [internal_api.py:upload_file():2558] upload_file request headers: {'User-Agent': 'python-requests/2.28.1', 'Accept-Encoding': 'gzip, deflate, br', 'Accept': '*/*', 'Connection': 'keep-alive', 'Content-MD5': 'ECzI7oKGSWJ1+RtCgn6Grg==', 'Content-Type': 'text/plain; charset=utf-8', 'Content-Length': '1756'}
2023-11-04 20:02:30,224 ERROR   wandb-upload_1:42709 [internal_api.py:upload_file():2560] upload_file response body: 
2023-11-04 20:02:35,015 DEBUG   HandlerThread:42709 [handler.py:handle_request():146] handle_request: keepalive
2023-11-04 20:02:40,016 DEBUG   HandlerThread:42709 [handler.py:handle_request():146] handle_request: keepalive
2023-11-04 20:02:45,018 DEBUG   HandlerThread:42709 [handler.py:handle_request():146] handle_request: keepalive
2023-11-04 20:02:47,717 ERROR   wandb-upload_1:42709 [internal_api.py:upload_file():2556] upload_file exception https://storage.googleapis.com/wandb-artifacts-prod/wandb_artifacts/112721340/628302132/102cc8ee8286496275f91b42827e86ae?Expires=1699210932&GoogleAccessId=gorilla-files-url-signer-man%40wandb-production.iam.gserviceaccount.com&Signature=DHQiOOynaHkb%2Bn3%2FNxqNACHlg2ZmX7iAHx5IZl%2B4hBIUN5HG3xyFiTeLjAJogTffYVemlZWzY7tWbcQ5f06GtNtgChjMfzPR8omXmuAdxQypx8Et1zwniMibYX1eXWuNUEpOpWYnNcwGRGFBrfw36uGx91wUgAtPsi82MGDHWuTRPuLpktgPAY8v46TFrkQUnQlkQB7P2qopWkoO5HwJTOlIDKxuYJAHaehhk%2FDEFzlxN18IyLly6E3cfOaX1elS%2F4APHxq2I%2FvOxU2GLGR5jQkkhXeshZU%2FdzNaNqxX9z%2FxpJClux4iBsSGlnSlyALL2ERyeQIb8VfFhYfxg%2B2EKg%3D%3D: HTTPSConnectionPool(host='storage.googleapis.com', port=443): Max retries exceeded with url: /wandb-artifacts-prod/wandb_artifacts/112721340/628302132/102cc8ee8286496275f91b42827e86ae?Expires=1699210932&GoogleAccessId=gorilla-files-url-signer-man%40wandb-production.iam.gserviceaccount.com&Signature=DHQiOOynaHkb%2Bn3%2FNxqNACHlg2ZmX7iAHx5IZl%2B4hBIUN5HG3xyFiTeLjAJogTffYVemlZWzY7tWbcQ5f06GtNtgChjMfzPR8omXmuAdxQypx8Et1zwniMibYX1eXWuNUEpOpWYnNcwGRGFBrfw36uGx91wUgAtPsi82MGDHWuTRPuLpktgPAY8v46TFrkQUnQlkQB7P2qopWkoO5HwJTOlIDKxuYJAHaehhk%2FDEFzlxN18IyLly6E3cfOaX1elS%2F4APHxq2I%2FvOxU2GLGR5jQkkhXeshZU%2FdzNaNqxX9z%2FxpJClux4iBsSGlnSlyALL2ERyeQIb8VfFhYfxg%2B2EKg%3D%3D (Caused by NewConnectionError('<urllib3.connection.HTTPSConnection object at 0x2b5cb2bda370>: Failed to establish a new connection: [Errno 101] Network is unreachable'))
2023-11-04 20:02:47,717 ERROR   wandb-upload_1:42709 [internal_api.py:upload_file():2558] upload_file request headers: {'User-Agent': 'python-requests/2.28.1', 'Accept-Encoding': 'gzip, deflate, br', 'Accept': '*/*', 'Connection': 'keep-alive', 'Content-MD5': 'ECzI7oKGSWJ1+RtCgn6Grg==', 'Content-Type': 'text/plain; charset=utf-8', 'Content-Length': '1756'}
2023-11-04 20:02:47,717 ERROR   wandb-upload_1:42709 [internal_api.py:upload_file():2560] upload_file response body: 
2023-11-04 20:02:48,199 ERROR   wandb-upload_2:42709 [internal_api.py:upload_file():2556] upload_file exception https://storage.googleapis.com/wandb-artifacts-prod/wandb_artifacts/112721340/628302132/736d2e841e706f032bb0b718411a8b04?Expires=1699210931&GoogleAccessId=gorilla-files-url-signer-man%40wandb-production.iam.gserviceaccount.com&Signature=PR2HKa1qmYLkYTk1fKaQ88CMcVkdDKu0nCX47FeLHzKpWMSKKbG7FMIxr0kSL84Y%2BChRJp%2BicbNTb23lfFomBgly2R1RKuTaoiIswxTdtdn1nyfuEG8BOCNFXgzUxlxC5jOUdD4RkZH6zzkiWwnFkGliPkghD%2BEx4PyKnIqYBP0sID4qXHx15u%2B074ISe8ex6mJQRwBunUCw3B85h8j9pgqVrM1T75%2F%2FRiFzGRJgxCgKbQPzhYQEypuCsTIs9BELNYskQqY2Wbu2dy2%2BDjkYus2OmtkTEElBCVewA%2FnSuIdrAYp90%2BLTUBwJI94buJNLOMVh8KzjFrTpUqso%2BLJDSg%3D%3D: HTTPSConnectionPool(host='storage.googleapis.com', port=443): Max retries exceeded with url: /wandb-artifacts-prod/wandb_artifacts/112721340/628302132/736d2e841e706f032bb0b718411a8b04?Expires=1699210931&GoogleAccessId=gorilla-files-url-signer-man%40wandb-production.iam.gserviceaccount.com&Signature=PR2HKa1qmYLkYTk1fKaQ88CMcVkdDKu0nCX47FeLHzKpWMSKKbG7FMIxr0kSL84Y%2BChRJp%2BicbNTb23lfFomBgly2R1RKuTaoiIswxTdtdn1nyfuEG8BOCNFXgzUxlxC5jOUdD4RkZH6zzkiWwnFkGliPkghD%2BEx4PyKnIqYBP0sID4qXHx15u%2B074ISe8ex6mJQRwBunUCw3B85h8j9pgqVrM1T75%2F%2FRiFzGRJgxCgKbQPzhYQEypuCsTIs9BELNYskQqY2Wbu2dy2%2BDjkYus2OmtkTEElBCVewA%2FnSuIdrAYp90%2BLTUBwJI94buJNLOMVh8KzjFrTpUqso%2BLJDSg%3D%3D (Caused by NewConnectionError('<urllib3.connection.HTTPSConnection object at 0x2b5cb2bda250>: Failed to establish a new connection: [Errno 101] Network is unreachable'))
2023-11-04 20:02:48,199 ERROR   wandb-upload_2:42709 [internal_api.py:upload_file():2558] upload_file request headers: {'User-Agent': 'python-requests/2.28.1', 'Accept-Encoding': 'gzip, deflate, br', 'Accept': '*/*', 'Connection': 'keep-alive', 'Content-MD5': 'c20uhB5wbwMrsLcYQRqLBA==', 'Content-Type': 'application/json', 'Content-Length': '648'}
2023-11-04 20:02:48,199 ERROR   wandb-upload_2:42709 [internal_api.py:upload_file():2560] upload_file response body: 
2023-11-04 20:02:48,866 ERROR   wandb-upload_0:42709 [internal_api.py:upload_file():2556] upload_file exception https://storage.googleapis.com/wandb-production.appspot.com/bryanttang/DKT-trial%201/w96e4u9y/wandb-metadata.json?Expires=1699210900&GoogleAccessId=gorilla-files-url-signer-man%40wandb-production.iam.gserviceaccount.com&Signature=FFKp6KRwxqtwRO4hH9sNqyOHzFnLn2BjM6zCR%2Bk5OhIbJ%2BYOSxkUfZMm%2FYZR%2B2tVE%2FcmVNSVnSJEkiu3RrZkzdQEnMkgp%2Bi0kVy%2BTWojmINkD%2BJ%2Bmc6XT4%2Bvw1u%2FGhAcU9Q3bmmj66F%2B9B146TbKj4reCfiTN2obFklIAH%2F9QiLTXGLhkob%2BF8IPen1tlk7XduEXjeRYhjtaEfX3JbExp6wSNSxq%2FJKI4o3cMI0LjqN3U37Sc3A1RxG%2BEaXo8gkTMlKnoVg3XxN21gu%2Bq1%2Byfr1ELNaPmwl0n86w7iMr1HriU44av0ogBNZlB2flv6GMTgnHyaFBMEHybYWXYzuKYw%3D%3D: HTTPSConnectionPool(host='storage.googleapis.com', port=443): Max retries exceeded with url: /wandb-production.appspot.com/bryanttang/DKT-trial%201/w96e4u9y/wandb-metadata.json?Expires=1699210900&GoogleAccessId=gorilla-files-url-signer-man%40wandb-production.iam.gserviceaccount.com&Signature=FFKp6KRwxqtwRO4hH9sNqyOHzFnLn2BjM6zCR%2Bk5OhIbJ%2BYOSxkUfZMm%2FYZR%2B2tVE%2FcmVNSVnSJEkiu3RrZkzdQEnMkgp%2Bi0kVy%2BTWojmINkD%2BJ%2Bmc6XT4%2Bvw1u%2FGhAcU9Q3bmmj66F%2B9B146TbKj4reCfiTN2obFklIAH%2F9QiLTXGLhkob%2BF8IPen1tlk7XduEXjeRYhjtaEfX3JbExp6wSNSxq%2FJKI4o3cMI0LjqN3U37Sc3A1RxG%2BEaXo8gkTMlKnoVg3XxN21gu%2Bq1%2Byfr1ELNaPmwl0n86w7iMr1HriU44av0ogBNZlB2flv6GMTgnHyaFBMEHybYWXYzuKYw%3D%3D (Caused by NewConnectionError('<urllib3.connection.HTTPSConnection object at 0x2b5cb2bd1700>: Failed to establish a new connection: [Errno 101] Network is unreachable'))
2023-11-04 20:02:48,866 ERROR   wandb-upload_0:42709 [internal_api.py:upload_file():2558] upload_file request headers: {'User-Agent': 'python-requests/2.28.1', 'Accept-Encoding': 'gzip, deflate, br', 'Accept': '*/*', 'Connection': 'keep-alive', 'Content-Length': '14811'}
2023-11-04 20:02:48,866 ERROR   wandb-upload_0:42709 [internal_api.py:upload_file():2560] upload_file response body: 
2023-11-04 20:02:50,020 DEBUG   HandlerThread:42709 [handler.py:handle_request():146] handle_request: keepalive
2023-11-04 20:02:55,021 DEBUG   HandlerThread:42709 [handler.py:handle_request():146] handle_request: keepalive
2023-11-04 20:03:00,022 DEBUG   HandlerThread:42709 [handler.py:handle_request():146] handle_request: keepalive
2023-11-04 20:03:05,024 DEBUG   HandlerThread:42709 [handler.py:handle_request():146] handle_request: keepalive
2023-11-04 20:03:10,026 DEBUG   HandlerThread:42709 [handler.py:handle_request():146] handle_request: keepalive
2023-11-04 20:03:15,028 DEBUG   HandlerThread:42709 [handler.py:handle_request():146] handle_request: keepalive
2023-11-04 20:03:20,030 DEBUG   HandlerThread:42709 [handler.py:handle_request():146] handle_request: keepalive
2023-11-04 20:03:22,854 ERROR   wandb-upload_2:42709 [internal_api.py:upload_file():2556] upload_file exception https://storage.googleapis.com/wandb-artifacts-prod/wandb_artifacts/112721340/628302132/736d2e841e706f032bb0b718411a8b04?Expires=1699210931&GoogleAccessId=gorilla-files-url-signer-man%40wandb-production.iam.gserviceaccount.com&Signature=PR2HKa1qmYLkYTk1fKaQ88CMcVkdDKu0nCX47FeLHzKpWMSKKbG7FMIxr0kSL84Y%2BChRJp%2BicbNTb23lfFomBgly2R1RKuTaoiIswxTdtdn1nyfuEG8BOCNFXgzUxlxC5jOUdD4RkZH6zzkiWwnFkGliPkghD%2BEx4PyKnIqYBP0sID4qXHx15u%2B074ISe8ex6mJQRwBunUCw3B85h8j9pgqVrM1T75%2F%2FRiFzGRJgxCgKbQPzhYQEypuCsTIs9BELNYskQqY2Wbu2dy2%2BDjkYus2OmtkTEElBCVewA%2FnSuIdrAYp90%2BLTUBwJI94buJNLOMVh8KzjFrTpUqso%2BLJDSg%3D%3D: HTTPSConnectionPool(host='storage.googleapis.com', port=443): Max retries exceeded with url: /wandb-artifacts-prod/wandb_artifacts/112721340/628302132/736d2e841e706f032bb0b718411a8b04?Expires=1699210931&GoogleAccessId=gorilla-files-url-signer-man%40wandb-production.iam.gserviceaccount.com&Signature=PR2HKa1qmYLkYTk1fKaQ88CMcVkdDKu0nCX47FeLHzKpWMSKKbG7FMIxr0kSL84Y%2BChRJp%2BicbNTb23lfFomBgly2R1RKuTaoiIswxTdtdn1nyfuEG8BOCNFXgzUxlxC5jOUdD4RkZH6zzkiWwnFkGliPkghD%2BEx4PyKnIqYBP0sID4qXHx15u%2B074ISe8ex6mJQRwBunUCw3B85h8j9pgqVrM1T75%2F%2FRiFzGRJgxCgKbQPzhYQEypuCsTIs9BELNYskQqY2Wbu2dy2%2BDjkYus2OmtkTEElBCVewA%2FnSuIdrAYp90%2BLTUBwJI94buJNLOMVh8KzjFrTpUqso%2BLJDSg%3D%3D (Caused by NewConnectionError('<urllib3.connection.HTTPSConnection object at 0x2b5cb2bee130>: Failed to establish a new connection: [Errno 101] Network is unreachable'))
2023-11-04 20:03:22,854 ERROR   wandb-upload_2:42709 [internal_api.py:upload_file():2558] upload_file request headers: {'User-Agent': 'python-requests/2.28.1', 'Accept-Encoding': 'gzip, deflate, br', 'Accept': '*/*', 'Connection': 'keep-alive', 'Content-MD5': 'c20uhB5wbwMrsLcYQRqLBA==', 'Content-Type': 'application/json', 'Content-Length': '648'}
2023-11-04 20:03:22,854 ERROR   wandb-upload_2:42709 [internal_api.py:upload_file():2560] upload_file response body: 
2023-11-04 20:03:25,031 DEBUG   HandlerThread:42709 [handler.py:handle_request():146] handle_request: keepalive
2023-11-04 20:03:26,185 ERROR   wandb-upload_1:42709 [internal_api.py:upload_file():2556] upload_file exception https://storage.googleapis.com/wandb-artifacts-prod/wandb_artifacts/112721340/628302132/102cc8ee8286496275f91b42827e86ae?Expires=1699210932&GoogleAccessId=gorilla-files-url-signer-man%40wandb-production.iam.gserviceaccount.com&Signature=DHQiOOynaHkb%2Bn3%2FNxqNACHlg2ZmX7iAHx5IZl%2B4hBIUN5HG3xyFiTeLjAJogTffYVemlZWzY7tWbcQ5f06GtNtgChjMfzPR8omXmuAdxQypx8Et1zwniMibYX1eXWuNUEpOpWYnNcwGRGFBrfw36uGx91wUgAtPsi82MGDHWuTRPuLpktgPAY8v46TFrkQUnQlkQB7P2qopWkoO5HwJTOlIDKxuYJAHaehhk%2FDEFzlxN18IyLly6E3cfOaX1elS%2F4APHxq2I%2FvOxU2GLGR5jQkkhXeshZU%2FdzNaNqxX9z%2FxpJClux4iBsSGlnSlyALL2ERyeQIb8VfFhYfxg%2B2EKg%3D%3D: HTTPSConnectionPool(host='storage.googleapis.com', port=443): Max retries exceeded with url: /wandb-artifacts-prod/wandb_artifacts/112721340/628302132/102cc8ee8286496275f91b42827e86ae?Expires=1699210932&GoogleAccessId=gorilla-files-url-signer-man%40wandb-production.iam.gserviceaccount.com&Signature=DHQiOOynaHkb%2Bn3%2FNxqNACHlg2ZmX7iAHx5IZl%2B4hBIUN5HG3xyFiTeLjAJogTffYVemlZWzY7tWbcQ5f06GtNtgChjMfzPR8omXmuAdxQypx8Et1zwniMibYX1eXWuNUEpOpWYnNcwGRGFBrfw36uGx91wUgAtPsi82MGDHWuTRPuLpktgPAY8v46TFrkQUnQlkQB7P2qopWkoO5HwJTOlIDKxuYJAHaehhk%2FDEFzlxN18IyLly6E3cfOaX1elS%2F4APHxq2I%2FvOxU2GLGR5jQkkhXeshZU%2FdzNaNqxX9z%2FxpJClux4iBsSGlnSlyALL2ERyeQIb8VfFhYfxg%2B2EKg%3D%3D (Caused by NewConnectionError('<urllib3.connection.HTTPSConnection object at 0x2b5cb2beedf0>: Failed to establish a new connection: [Errno 101] Network is unreachable'))
2023-11-04 20:03:26,185 ERROR   wandb-upload_1:42709 [internal_api.py:upload_file():2558] upload_file request headers: {'User-Agent': 'python-requests/2.28.1', 'Accept-Encoding': 'gzip, deflate, br', 'Accept': '*/*', 'Connection': 'keep-alive', 'Content-MD5': 'ECzI7oKGSWJ1+RtCgn6Grg==', 'Content-Type': 'text/plain; charset=utf-8', 'Content-Length': '1756'}
2023-11-04 20:03:26,185 ERROR   wandb-upload_1:42709 [internal_api.py:upload_file():2560] upload_file response body: 
2023-11-04 20:03:30,033 DEBUG   HandlerThread:42709 [handler.py:handle_request():146] handle_request: keepalive
2023-11-04 20:03:35,035 DEBUG   HandlerThread:42709 [handler.py:handle_request():146] handle_request: keepalive
