2023-11-04 20:07:44,893 INFO    StreamThr :70939 [internal.py:wandb_internal():86] W&B internal server running at pid: 70939, started at: 2023-11-04 20:07:44.891598
2023-11-04 20:07:44,894 DEBUG   HandlerThread:70939 [handler.py:handle_request():146] handle_request: status
2023-11-04 20:07:44,896 INFO    WriterThread:70939 [datastore.py:open_for_write():85] open: /cluster/home/yutang/Deep-Knowledge-Tracing/DKT/KnowledgeTracing/evaluation/wandb/run-20231104_200744-6vrr841v/run-6vrr841v.wandb
2023-11-04 20:07:44,898 DEBUG   SenderThread:70939 [sender.py:send():380] send: header
2023-11-04 20:07:44,917 DEBUG   SenderThread:70939 [sender.py:send():380] send: run
2023-11-04 20:07:45,319 INFO    SenderThread:70939 [dir_watcher.py:__init__():211] watching files in: /cluster/home/yutang/Deep-Knowledge-Tracing/DKT/KnowledgeTracing/evaluation/wandb/run-20231104_200744-6vrr841v/files
2023-11-04 20:07:45,319 INFO    SenderThread:70939 [sender.py:_start_run_threads():1122] run started: 6vrr841v with start time 1699124864.892426
2023-11-04 20:07:45,331 DEBUG   HandlerThread:70939 [handler.py:handle_request():146] handle_request: check_version
2023-11-04 20:07:45,331 DEBUG   SenderThread:70939 [sender.py:send_request():407] send_request: check_version
2023-11-04 20:07:45,400 DEBUG   HandlerThread:70939 [handler.py:handle_request():146] handle_request: run_start
2023-11-04 20:07:45,410 DEBUG   HandlerThread:70939 [system_info.py:__init__():32] System info init
2023-11-04 20:07:45,410 DEBUG   HandlerThread:70939 [system_info.py:__init__():47] System info init done
2023-11-04 20:07:45,410 INFO    HandlerThread:70939 [system_monitor.py:start():194] Starting system monitor
2023-11-04 20:07:45,410 INFO    SystemMonitor:70939 [system_monitor.py:_start():158] Starting system asset monitoring threads
2023-11-04 20:07:45,410 INFO    HandlerThread:70939 [system_monitor.py:probe():214] Collecting system info
2023-11-04 20:07:45,410 INFO    SystemMonitor:70939 [interfaces.py:start():190] Started cpu monitoring
2023-11-04 20:07:45,411 INFO    SystemMonitor:70939 [interfaces.py:start():190] Started disk monitoring
2023-11-04 20:07:45,412 INFO    SystemMonitor:70939 [interfaces.py:start():190] Started gpu monitoring
2023-11-04 20:07:45,415 INFO    SystemMonitor:70939 [interfaces.py:start():190] Started memory monitoring
2023-11-04 20:07:45,416 INFO    SystemMonitor:70939 [interfaces.py:start():190] Started network monitoring
2023-11-04 20:07:45,450 DEBUG   HandlerThread:70939 [system_info.py:probe():196] Probing system
2023-11-04 20:07:45,455 DEBUG   HandlerThread:70939 [system_info.py:_probe_git():181] Probing git
2023-11-04 20:07:45,473 DEBUG   HandlerThread:70939 [system_info.py:_probe_git():189] Probing git done
2023-11-04 20:07:45,473 DEBUG   HandlerThread:70939 [system_info.py:probe():244] Probing system done
2023-11-04 20:07:45,474 DEBUG   HandlerThread:70939 [system_monitor.py:probe():223] {'os': 'Linux-3.10.0-1160.95.1.el7.x86_64-x86_64-with-glibc2.17', 'python': '3.9.16', 'heartbeatAt': '2023-11-04T19:07:45.450621', 'startedAt': '2023-11-04T19:07:44.880804', 'docker': None, 'cuda': None, 'args': (), 'state': 'running', 'program': '/cluster/home/yutang/Deep-Knowledge-Tracing/DKT/KnowledgeTracing/evaluation/./run.py', 'codePathLocal': 'run.py', 'codePath': 'DKT/KnowledgeTracing/evaluation/run.py', 'git': {'remote': 'https://github.com/Bryanttt-tang/Deep-Knowledge-Tracing.git', 'commit': '19dbd40068fa359d502c625b58664f708d50a931'}, 'email': None, 'root': '/cluster/home/yutang/Deep-Knowledge-Tracing', 'host': 'eu-g3-001', 'username': 'yutang', 'executable': '/cluster/home/yutang/miniconda3/bin/python', 'cpu_count': 128, 'cpu_count_logical': 128, 'cpu_freq': {'current': 1574.21875, 'min': 1500.0, 'max': 2250.0}, 'cpu_freq_per_core': [{'current': 1500.0, 'min': 1500.0, 'max': 2250.0}, {'current': 1500.0, 'min': 1500.0, 'max': 2250.0}, {'current': 1500.0, 'min': 1500.0, 'max': 2250.0}, {'current': 1500.0, 'min': 1500.0, 'max': 2250.0}, {'current': 2000.0, 'min': 1500.0, 'max': 2250.0}, {'current': 2250.0, 'min': 1500.0, 'max': 2250.0}, {'current': 2250.0, 'min': 1500.0, 'max': 2250.0}, {'current': 2250.0, 'min': 1500.0, 'max': 2250.0}, {'current': 2000.0, 'min': 1500.0, 'max': 2250.0}, {'current': 1500.0, 'min': 1500.0, 'max': 2250.0}, {'current': 1500.0, 'min': 1500.0, 'max': 2250.0}, {'current': 1500.0, 'min': 1500.0, 'max': 2250.0}, {'current': 1500.0, 'min': 1500.0, 'max': 2250.0}, {'current': 1500.0, 'min': 1500.0, 'max': 2250.0}, {'current': 1500.0, 'min': 1500.0, 'max': 2250.0}, {'current': 1500.0, 'min': 1500.0, 'max': 2250.0}, {'current': 1500.0, 'min': 1500.0, 'max': 2250.0}, {'current': 1500.0, 'min': 1500.0, 'max': 2250.0}, {'current': 1500.0, 'min': 1500.0, 'max': 2250.0}, {'current': 1500.0, 'min': 1500.0, 'max': 2250.0}, {'current': 1500.0, 'min': 1500.0, 'max': 2250.0}, {'current': 1500.0, 'min': 1500.0, 'max': 2250.0}, {'current': 1500.0, 'min': 1500.0, 'max': 2250.0}, {'current': 1500.0, 'min': 1500.0, 'max': 2250.0}, {'current': 1500.0, 'min': 1500.0, 'max': 2250.0}, {'current': 1500.0, 'min': 1500.0, 'max': 2250.0}, {'current': 1500.0, 'min': 1500.0, 'max': 2250.0}, {'current': 1500.0, 'min': 1500.0, 'max': 2250.0}, {'current': 2000.0, 'min': 1500.0, 'max': 2250.0}, {'current': 1500.0, 'min': 1500.0, 'max': 2250.0}, {'current': 2000.0, 'min': 1500.0, 'max': 2250.0}, {'current': 1500.0, 'min': 1500.0, 'max': 2250.0}, {'current': 1500.0, 'min': 1500.0, 'max': 2250.0}, {'current': 1500.0, 'min': 1500.0, 'max': 2250.0}, {'current': 1500.0, 'min': 1500.0, 'max': 2250.0}, {'current': 1500.0, 'min': 1500.0, 'max': 2250.0}, {'current': 1500.0, 'min': 1500.0, 'max': 2250.0}, {'current': 1500.0, 'min': 1500.0, 'max': 2250.0}, {'current': 1500.0, 'min': 1500.0, 'max': 2250.0}, {'current': 1500.0, 'min': 1500.0, 'max': 2250.0}, {'current': 1500.0, 'min': 1500.0, 'max': 2250.0}, {'current': 1500.0, 'min': 1500.0, 'max': 2250.0}, {'current': 1500.0, 'min': 1500.0, 'max': 2250.0}, {'current': 1500.0, 'min': 1500.0, 'max': 2250.0}, {'current': 1500.0, 'min': 1500.0, 'max': 2250.0}, {'current': 1500.0, 'min': 1500.0, 'max': 2250.0}, {'current': 1500.0, 'min': 1500.0, 'max': 2250.0}, {'current': 1500.0, 'min': 1500.0, 'max': 2250.0}, {'current': 1500.0, 'min': 1500.0, 'max': 2250.0}, {'current': 1500.0, 'min': 1500.0, 'max': 2250.0}, {'current': 1500.0, 'min': 1500.0, 'max': 2250.0}, {'current': 1500.0, 'min': 1500.0, 'max': 2250.0}, {'current': 1500.0, 'min': 1500.0, 'max': 2250.0}, {'current': 1500.0, 'min': 1500.0, 'max': 2250.0}, {'current': 1500.0, 'min': 1500.0, 'max': 2250.0}, {'current': 1500.0, 'min': 1500.0, 'max': 2250.0}, {'current': 1500.0, 'min': 1500.0, 'max': 2250.0}, {'current': 1500.0, 'min': 1500.0, 'max': 2250.0}, {'current': 1500.0, 'min': 1500.0, 'max': 2250.0}, {'current': 1500.0, 'min': 1500.0, 'max': 2250.0}, {'current': 1500.0, 'min': 1500.0, 'max': 2250.0}, {'current': 1500.0, 'min': 1500.0, 'max': 2250.0}, {'current': 1500.0, 'min': 1500.0, 'max': 2250.0}, {'current': 1500.0, 'min': 1500.0, 'max': 2250.0}, {'current': 2250.0, 'min': 1500.0, 'max': 2250.0}, {'current': 1500.0, 'min': 1500.0, 'max': 2250.0}, {'current': 2250.0, 'min': 1500.0, 'max': 2250.0}, {'current': 1500.0, 'min': 1500.0, 'max': 2250.0}, {'current': 2000.0, 'min': 1500.0, 'max': 2250.0}, {'current': 1500.0, 'min': 1500.0, 'max': 2250.0}, {'current': 1500.0, 'min': 1500.0, 'max': 2250.0}, {'current': 1500.0, 'min': 1500.0, 'max': 2250.0}, {'current': 2000.0, 'min': 1500.0, 'max': 2250.0}, {'current': 2000.0, 'min': 1500.0, 'max': 2250.0}, {'current': 2000.0, 'min': 1500.0, 'max': 2250.0}, {'current': 1500.0, 'min': 1500.0, 'max': 2250.0}, {'current': 1500.0, 'min': 1500.0, 'max': 2250.0}, {'current': 1500.0, 'min': 1500.0, 'max': 2250.0}, {'current': 1500.0, 'min': 1500.0, 'max': 2250.0}, {'current': 1500.0, 'min': 1500.0, 'max': 2250.0}, {'current': 2250.0, 'min': 1500.0, 'max': 2250.0}, {'current': 1500.0, 'min': 1500.0, 'max': 2250.0}, {'current': 1500.0, 'min': 1500.0, 'max': 2250.0}, {'current': 1500.0, 'min': 1500.0, 'max': 2250.0}, {'current': 1500.0, 'min': 1500.0, 'max': 2250.0}, {'current': 1500.0, 'min': 1500.0, 'max': 2250.0}, {'current': 1500.0, 'min': 1500.0, 'max': 2250.0}, {'current': 1500.0, 'min': 1500.0, 'max': 2250.0}, {'current': 1500.0, 'min': 1500.0, 'max': 2250.0}, {'current': 1500.0, 'min': 1500.0, 'max': 2250.0}, {'current': 2250.0, 'min': 1500.0, 'max': 2250.0}, {'current': 1500.0, 'min': 1500.0, 'max': 2250.0}, {'current': 1500.0, 'min': 1500.0, 'max': 2250.0}, {'current': 1500.0, 'min': 1500.0, 'max': 2250.0}, {'current': 1500.0, 'min': 1500.0, 'max': 2250.0}, {'current': 1500.0, 'min': 1500.0, 'max': 2250.0}, {'current': 1500.0, 'min': 1500.0, 'max': 2250.0}, {'current': 1500.0, 'min': 1500.0, 'max': 2250.0}, {'current': 1500.0, 'min': 1500.0, 'max': 2250.0}, {'current': 1500.0, 'min': 1500.0, 'max': 2250.0}, {'current': 1500.0, 'min': 1500.0, 'max': 2250.0}, {'current': 1500.0, 'min': 1500.0, 'max': 2250.0}, {'current': 1500.0, 'min': 1500.0, 'max': 2250.0}, {'current': 1500.0, 'min': 1500.0, 'max': 2250.0}, {'current': 1500.0, 'min': 1500.0, 'max': 2250.0}, {'current': 1500.0, 'min': 1500.0, 'max': 2250.0}, {'current': 1500.0, 'min': 1500.0, 'max': 2250.0}, {'current': 1500.0, 'min': 1500.0, 'max': 2250.0}, {'current': 1500.0, 'min': 1500.0, 'max': 2250.0}, {'current': 1500.0, 'min': 1500.0, 'max': 2250.0}, {'current': 1500.0, 'min': 1500.0, 'max': 2250.0}, {'current': 1500.0, 'min': 1500.0, 'max': 2250.0}, {'current': 1500.0, 'min': 1500.0, 'max': 2250.0}, {'current': 1500.0, 'min': 1500.0, 'max': 2250.0}, {'current': 1500.0, 'min': 1500.0, 'max': 2250.0}, {'current': 1500.0, 'min': 1500.0, 'max': 2250.0}, {'current': 1500.0, 'min': 1500.0, 'max': 2250.0}, {'current': 1500.0, 'min': 1500.0, 'max': 2250.0}, {'current': 1500.0, 'min': 1500.0, 'max': 2250.0}, {'current': 1500.0, 'min': 1500.0, 'max': 2250.0}, {'current': 1500.0, 'min': 1500.0, 'max': 2250.0}, {'current': 1500.0, 'min': 1500.0, 'max': 2250.0}, {'current': 1500.0, 'min': 1500.0, 'max': 2250.0}, {'current': 1500.0, 'min': 1500.0, 'max': 2250.0}, {'current': 1500.0, 'min': 1500.0, 'max': 2250.0}, {'current': 1500.0, 'min': 1500.0, 'max': 2250.0}, {'current': 1500.0, 'min': 1500.0, 'max': 2250.0}, {'current': 1500.0, 'min': 1500.0, 'max': 2250.0}], 'disk': {'/': {'total': 10.0, 'used': 4.519813537597656}}, 'gpu': 'NVIDIA GeForce RTX 2080 Ti', 'gpu_count': 1, 'gpu_devices': [{'name': 'NVIDIA GeForce RTX 2080 Ti', 'memory_total': 11811160064}], 'memory': {'total': 501.5051078796387}}
2023-11-04 20:07:45,474 INFO    HandlerThread:70939 [system_monitor.py:probe():224] Finished collecting system info
2023-11-04 20:07:45,474 INFO    HandlerThread:70939 [system_monitor.py:probe():227] Publishing system info
2023-11-04 20:07:45,474 DEBUG   HandlerThread:70939 [system_info.py:_save_pip():52] Saving list of pip packages installed into the current environment
2023-11-04 20:07:45,475 DEBUG   HandlerThread:70939 [system_info.py:_save_pip():68] Saving pip packages done
2023-11-04 20:07:45,475 DEBUG   HandlerThread:70939 [system_info.py:_save_conda():75] Saving list of conda packages installed into the current environment
2023-11-04 20:07:46,323 INFO    Thread-12 :70939 [dir_watcher.py:_on_file_created():271] file/dir created: /cluster/home/yutang/Deep-Knowledge-Tracing/DKT/KnowledgeTracing/evaluation/wandb/run-20231104_200744-6vrr841v/files/requirements.txt
2023-11-04 20:07:46,323 INFO    Thread-12 :70939 [dir_watcher.py:_on_file_created():271] file/dir created: /cluster/home/yutang/Deep-Knowledge-Tracing/DKT/KnowledgeTracing/evaluation/wandb/run-20231104_200744-6vrr841v/files/conda-environment.yaml
2023-11-04 20:07:48,127 DEBUG   HandlerThread:70939 [system_info.py:_save_conda():87] Saving conda packages done
2023-11-04 20:07:48,130 INFO    HandlerThread:70939 [system_monitor.py:probe():229] Finished publishing system info
2023-11-04 20:07:48,135 DEBUG   SenderThread:70939 [sender.py:send():380] send: files
2023-11-04 20:07:48,135 INFO    SenderThread:70939 [sender.py:_save_file():1378] saving file wandb-metadata.json with policy now
2023-11-04 20:07:48,149 DEBUG   HandlerThread:70939 [handler.py:handle_request():146] handle_request: stop_status
2023-11-04 20:07:48,149 DEBUG   SenderThread:70939 [sender.py:send_request():407] send_request: stop_status
2023-11-04 20:07:48,153 DEBUG   HandlerThread:70939 [handler.py:handle_request():146] handle_request: internal_messages
2023-11-04 20:07:48,321 INFO    Thread-12 :70939 [dir_watcher.py:_on_file_modified():288] file/dir modified: /cluster/home/yutang/Deep-Knowledge-Tracing/DKT/KnowledgeTracing/evaluation/wandb/run-20231104_200744-6vrr841v/files/conda-environment.yaml
2023-11-04 20:07:48,321 INFO    Thread-12 :70939 [dir_watcher.py:_on_file_created():271] file/dir created: /cluster/home/yutang/Deep-Knowledge-Tracing/DKT/KnowledgeTracing/evaluation/wandb/run-20231104_200744-6vrr841v/files/wandb-metadata.json
2023-11-04 20:07:48,401 DEBUG   SenderThread:70939 [sender.py:send():380] send: telemetry
2023-11-04 20:07:48,429 ERROR   wandb-upload_0:70939 [internal_api.py:upload_file():2556] upload_file exception https://storage.googleapis.com/wandb-production.appspot.com/bryanttang/DKT-trial%201/6vrr841v/wandb-metadata.json?Expires=1699211268&GoogleAccessId=gorilla-files-url-signer-man%40wandb-production.iam.gserviceaccount.com&Signature=vdJEEcja8gjpAmCYudZAM3SaB%2Byil1rBe9Vpxz%2BDL2Oqckxw3FSjQxnGcmgh4WEdL3tq5mqqLlj8KBjtBOrb61BC7vq8bJfWJV9Ckjq3ju3JHcFpTJF8fKLny2uH7KJrTdYogD70%2FGbPqkc7oyL9G1mxlrAD5Svj3zfHGI0Ztpk0OEk1%2F81uRhQt%2FgxnsGAPMM24kS5RX4RtNOdAsIHEOP7uh4se9mMPh%2BiOskiBLEA7U%2B8gNc%2FpFrVNFuK%2FUtWT0ZHMSYbmiez4gG2JVyRQ3Tq8AXZWbyuu9FsKJzQ90MOdYMyQfLPsM6Iso%2ByBeYDY%2FQbdukgbltoecr8LWUUkyg%3D%3D: HTTPSConnectionPool(host='storage.googleapis.com', port=443): Max retries exceeded with url: /wandb-production.appspot.com/bryanttang/DKT-trial%201/6vrr841v/wandb-metadata.json?Expires=1699211268&GoogleAccessId=gorilla-files-url-signer-man%40wandb-production.iam.gserviceaccount.com&Signature=vdJEEcja8gjpAmCYudZAM3SaB%2Byil1rBe9Vpxz%2BDL2Oqckxw3FSjQxnGcmgh4WEdL3tq5mqqLlj8KBjtBOrb61BC7vq8bJfWJV9Ckjq3ju3JHcFpTJF8fKLny2uH7KJrTdYogD70%2FGbPqkc7oyL9G1mxlrAD5Svj3zfHGI0Ztpk0OEk1%2F81uRhQt%2FgxnsGAPMM24kS5RX4RtNOdAsIHEOP7uh4se9mMPh%2BiOskiBLEA7U%2B8gNc%2FpFrVNFuK%2FUtWT0ZHMSYbmiez4gG2JVyRQ3Tq8AXZWbyuu9FsKJzQ90MOdYMyQfLPsM6Iso%2ByBeYDY%2FQbdukgbltoecr8LWUUkyg%3D%3D (Caused by NewConnectionError('<urllib3.connection.HTTPSConnection object at 0x2b2afbebff10>: Failed to establish a new connection: [Errno 101] Network is unreachable'))
2023-11-04 20:07:48,429 ERROR   wandb-upload_0:70939 [internal_api.py:upload_file():2558] upload_file request headers: {'User-Agent': 'python-requests/2.28.1', 'Accept-Encoding': 'gzip, deflate, br', 'Accept': '*/*', 'Connection': 'keep-alive', 'Content-Length': '14811'}
2023-11-04 20:07:48,429 ERROR   wandb-upload_0:70939 [internal_api.py:upload_file():2560] upload_file response body: 
2023-11-04 20:07:49,322 INFO    Thread-12 :70939 [dir_watcher.py:_on_file_created():271] file/dir created: /cluster/home/yutang/Deep-Knowledge-Tracing/DKT/KnowledgeTracing/evaluation/wandb/run-20231104_200744-6vrr841v/files/output.log
2023-11-04 20:07:49,537 ERROR   wandb-upload_0:70939 [internal_api.py:upload_file():2556] upload_file exception https://storage.googleapis.com/wandb-production.appspot.com/bryanttang/DKT-trial%201/6vrr841v/wandb-metadata.json?Expires=1699211268&GoogleAccessId=gorilla-files-url-signer-man%40wandb-production.iam.gserviceaccount.com&Signature=vdJEEcja8gjpAmCYudZAM3SaB%2Byil1rBe9Vpxz%2BDL2Oqckxw3FSjQxnGcmgh4WEdL3tq5mqqLlj8KBjtBOrb61BC7vq8bJfWJV9Ckjq3ju3JHcFpTJF8fKLny2uH7KJrTdYogD70%2FGbPqkc7oyL9G1mxlrAD5Svj3zfHGI0Ztpk0OEk1%2F81uRhQt%2FgxnsGAPMM24kS5RX4RtNOdAsIHEOP7uh4se9mMPh%2BiOskiBLEA7U%2B8gNc%2FpFrVNFuK%2FUtWT0ZHMSYbmiez4gG2JVyRQ3Tq8AXZWbyuu9FsKJzQ90MOdYMyQfLPsM6Iso%2ByBeYDY%2FQbdukgbltoecr8LWUUkyg%3D%3D: HTTPSConnectionPool(host='storage.googleapis.com', port=443): Max retries exceeded with url: /wandb-production.appspot.com/bryanttang/DKT-trial%201/6vrr841v/wandb-metadata.json?Expires=1699211268&GoogleAccessId=gorilla-files-url-signer-man%40wandb-production.iam.gserviceaccount.com&Signature=vdJEEcja8gjpAmCYudZAM3SaB%2Byil1rBe9Vpxz%2BDL2Oqckxw3FSjQxnGcmgh4WEdL3tq5mqqLlj8KBjtBOrb61BC7vq8bJfWJV9Ckjq3ju3JHcFpTJF8fKLny2uH7KJrTdYogD70%2FGbPqkc7oyL9G1mxlrAD5Svj3zfHGI0Ztpk0OEk1%2F81uRhQt%2FgxnsGAPMM24kS5RX4RtNOdAsIHEOP7uh4se9mMPh%2BiOskiBLEA7U%2B8gNc%2FpFrVNFuK%2FUtWT0ZHMSYbmiez4gG2JVyRQ3Tq8AXZWbyuu9FsKJzQ90MOdYMyQfLPsM6Iso%2ByBeYDY%2FQbdukgbltoecr8LWUUkyg%3D%3D (Caused by NewConnectionError('<urllib3.connection.HTTPSConnection object at 0x2b2afbf0d4c0>: Failed to establish a new connection: [Errno 101] Network is unreachable'))
2023-11-04 20:07:49,537 ERROR   wandb-upload_0:70939 [internal_api.py:upload_file():2558] upload_file request headers: {'User-Agent': 'python-requests/2.28.1', 'Accept-Encoding': 'gzip, deflate, br', 'Accept': '*/*', 'Connection': 'keep-alive', 'Content-Length': '14811'}
2023-11-04 20:07:49,537 ERROR   wandb-upload_0:70939 [internal_api.py:upload_file():2560] upload_file response body: 
2023-11-04 20:07:50,022 DEBUG   HandlerThread:70939 [handler.py:handle_request():146] handle_request: status_report
2023-11-04 20:07:51,324 INFO    Thread-12 :70939 [dir_watcher.py:_on_file_modified():288] file/dir modified: /cluster/home/yutang/Deep-Knowledge-Tracing/DKT/KnowledgeTracing/evaluation/wandb/run-20231104_200744-6vrr841v/files/output.log
2023-11-04 20:07:51,695 ERROR   wandb-upload_0:70939 [internal_api.py:upload_file():2556] upload_file exception https://storage.googleapis.com/wandb-production.appspot.com/bryanttang/DKT-trial%201/6vrr841v/wandb-metadata.json?Expires=1699211268&GoogleAccessId=gorilla-files-url-signer-man%40wandb-production.iam.gserviceaccount.com&Signature=vdJEEcja8gjpAmCYudZAM3SaB%2Byil1rBe9Vpxz%2BDL2Oqckxw3FSjQxnGcmgh4WEdL3tq5mqqLlj8KBjtBOrb61BC7vq8bJfWJV9Ckjq3ju3JHcFpTJF8fKLny2uH7KJrTdYogD70%2FGbPqkc7oyL9G1mxlrAD5Svj3zfHGI0Ztpk0OEk1%2F81uRhQt%2FgxnsGAPMM24kS5RX4RtNOdAsIHEOP7uh4se9mMPh%2BiOskiBLEA7U%2B8gNc%2FpFrVNFuK%2FUtWT0ZHMSYbmiez4gG2JVyRQ3Tq8AXZWbyuu9FsKJzQ90MOdYMyQfLPsM6Iso%2ByBeYDY%2FQbdukgbltoecr8LWUUkyg%3D%3D: HTTPSConnectionPool(host='storage.googleapis.com', port=443): Max retries exceeded with url: /wandb-production.appspot.com/bryanttang/DKT-trial%201/6vrr841v/wandb-metadata.json?Expires=1699211268&GoogleAccessId=gorilla-files-url-signer-man%40wandb-production.iam.gserviceaccount.com&Signature=vdJEEcja8gjpAmCYudZAM3SaB%2Byil1rBe9Vpxz%2BDL2Oqckxw3FSjQxnGcmgh4WEdL3tq5mqqLlj8KBjtBOrb61BC7vq8bJfWJV9Ckjq3ju3JHcFpTJF8fKLny2uH7KJrTdYogD70%2FGbPqkc7oyL9G1mxlrAD5Svj3zfHGI0Ztpk0OEk1%2F81uRhQt%2FgxnsGAPMM24kS5RX4RtNOdAsIHEOP7uh4se9mMPh%2BiOskiBLEA7U%2B8gNc%2FpFrVNFuK%2FUtWT0ZHMSYbmiez4gG2JVyRQ3Tq8AXZWbyuu9FsKJzQ90MOdYMyQfLPsM6Iso%2ByBeYDY%2FQbdukgbltoecr8LWUUkyg%3D%3D (Caused by NewConnectionError('<urllib3.connection.HTTPSConnection object at 0x2b2afbf0dc70>: Failed to establish a new connection: [Errno 101] Network is unreachable'))
2023-11-04 20:07:51,695 ERROR   wandb-upload_0:70939 [internal_api.py:upload_file():2558] upload_file request headers: {'User-Agent': 'python-requests/2.28.1', 'Accept-Encoding': 'gzip, deflate, br', 'Accept': '*/*', 'Connection': 'keep-alive', 'Content-Length': '14811'}
2023-11-04 20:07:51,695 ERROR   wandb-upload_0:70939 [internal_api.py:upload_file():2560] upload_file response body: 
2023-11-04 20:07:51,695 INFO    wandb-upload_0:70939 [retry.py:__call__():172] Retry attempt failed:
Traceback (most recent call last):
  File "/cluster/home/yutang/miniconda3/lib/python3.9/site-packages/urllib3/connection.py", line 174, in _new_conn
    conn = connection.create_connection(
  File "/cluster/home/yutang/miniconda3/lib/python3.9/site-packages/urllib3/util/connection.py", line 95, in create_connection
    raise err
  File "/cluster/home/yutang/miniconda3/lib/python3.9/site-packages/urllib3/util/connection.py", line 85, in create_connection
    sock.connect(sa)
OSError: [Errno 101] Network is unreachable

During handling of the above exception, another exception occurred:

Traceback (most recent call last):
  File "/cluster/home/yutang/miniconda3/lib/python3.9/site-packages/urllib3/connectionpool.py", line 703, in urlopen
    httplib_response = self._make_request(
  File "/cluster/home/yutang/miniconda3/lib/python3.9/site-packages/urllib3/connectionpool.py", line 386, in _make_request
    self._validate_conn(conn)
  File "/cluster/home/yutang/miniconda3/lib/python3.9/site-packages/urllib3/connectionpool.py", line 1042, in _validate_conn
    conn.connect()
  File "/cluster/home/yutang/miniconda3/lib/python3.9/site-packages/urllib3/connection.py", line 358, in connect
    self.sock = conn = self._new_conn()
  File "/cluster/home/yutang/miniconda3/lib/python3.9/site-packages/urllib3/connection.py", line 186, in _new_conn
    raise NewConnectionError(
urllib3.exceptions.NewConnectionError: <urllib3.connection.HTTPSConnection object at 0x2b2afbf0dc70>: Failed to establish a new connection: [Errno 101] Network is unreachable

During handling of the above exception, another exception occurred:

Traceback (most recent call last):
  File "/cluster/home/yutang/miniconda3/lib/python3.9/site-packages/requests/adapters.py", line 489, in send
    resp = conn.urlopen(
  File "/cluster/home/yutang/miniconda3/lib/python3.9/site-packages/urllib3/connectionpool.py", line 787, in urlopen
    retries = retries.increment(
  File "/cluster/home/yutang/miniconda3/lib/python3.9/site-packages/urllib3/util/retry.py", line 592, in increment
    raise MaxRetryError(_pool, url, error or ResponseError(cause))
urllib3.exceptions.MaxRetryError: HTTPSConnectionPool(host='storage.googleapis.com', port=443): Max retries exceeded with url: /wandb-production.appspot.com/bryanttang/DKT-trial%201/6vrr841v/wandb-metadata.json?Expires=1699211268&GoogleAccessId=gorilla-files-url-signer-man%40wandb-production.iam.gserviceaccount.com&Signature=vdJEEcja8gjpAmCYudZAM3SaB%2Byil1rBe9Vpxz%2BDL2Oqckxw3FSjQxnGcmgh4WEdL3tq5mqqLlj8KBjtBOrb61BC7vq8bJfWJV9Ckjq3ju3JHcFpTJF8fKLny2uH7KJrTdYogD70%2FGbPqkc7oyL9G1mxlrAD5Svj3zfHGI0Ztpk0OEk1%2F81uRhQt%2FgxnsGAPMM24kS5RX4RtNOdAsIHEOP7uh4se9mMPh%2BiOskiBLEA7U%2B8gNc%2FpFrVNFuK%2FUtWT0ZHMSYbmiez4gG2JVyRQ3Tq8AXZWbyuu9FsKJzQ90MOdYMyQfLPsM6Iso%2ByBeYDY%2FQbdukgbltoecr8LWUUkyg%3D%3D (Caused by NewConnectionError('<urllib3.connection.HTTPSConnection object at 0x2b2afbf0dc70>: Failed to establish a new connection: [Errno 101] Network is unreachable'))

During handling of the above exception, another exception occurred:

Traceback (most recent call last):
  File "/cluster/home/yutang/miniconda3/lib/python3.9/site-packages/wandb/sdk/internal/internal_api.py", line 2549, in upload_file
    response = self._upload_file_session.put(
  File "/cluster/home/yutang/miniconda3/lib/python3.9/site-packages/requests/sessions.py", line 647, in put
    return self.request("PUT", url, data=data, **kwargs)
  File "/cluster/home/yutang/miniconda3/lib/python3.9/site-packages/requests/sessions.py", line 587, in request
    resp = self.send(prep, **send_kwargs)
  File "/cluster/home/yutang/miniconda3/lib/python3.9/site-packages/requests/sessions.py", line 701, in send
    r = adapter.send(request, **kwargs)
  File "/cluster/home/yutang/miniconda3/lib/python3.9/site-packages/requests/adapters.py", line 565, in send
    raise ConnectionError(e, request=request)
requests.exceptions.ConnectionError: HTTPSConnectionPool(host='storage.googleapis.com', port=443): Max retries exceeded with url: /wandb-production.appspot.com/bryanttang/DKT-trial%201/6vrr841v/wandb-metadata.json?Expires=1699211268&GoogleAccessId=gorilla-files-url-signer-man%40wandb-production.iam.gserviceaccount.com&Signature=vdJEEcja8gjpAmCYudZAM3SaB%2Byil1rBe9Vpxz%2BDL2Oqckxw3FSjQxnGcmgh4WEdL3tq5mqqLlj8KBjtBOrb61BC7vq8bJfWJV9Ckjq3ju3JHcFpTJF8fKLny2uH7KJrTdYogD70%2FGbPqkc7oyL9G1mxlrAD5Svj3zfHGI0Ztpk0OEk1%2F81uRhQt%2FgxnsGAPMM24kS5RX4RtNOdAsIHEOP7uh4se9mMPh%2BiOskiBLEA7U%2B8gNc%2FpFrVNFuK%2FUtWT0ZHMSYbmiez4gG2JVyRQ3Tq8AXZWbyuu9FsKJzQ90MOdYMyQfLPsM6Iso%2ByBeYDY%2FQbdukgbltoecr8LWUUkyg%3D%3D (Caused by NewConnectionError('<urllib3.connection.HTTPSConnection object at 0x2b2afbf0dc70>: Failed to establish a new connection: [Errno 101] Network is unreachable'))

During handling of the above exception, another exception occurred:

Traceback (most recent call last):
  File "/cluster/home/yutang/miniconda3/lib/python3.9/site-packages/wandb/sdk/lib/retry.py", line 131, in __call__
    result = self._call_fn(*args, **kwargs)
  File "/cluster/home/yutang/miniconda3/lib/python3.9/site-packages/wandb/sdk/internal/internal_api.py", line 2580, in upload_file
    raise _e.with_traceback(sys.exc_info()[2])
  File "/cluster/home/yutang/miniconda3/lib/python3.9/site-packages/wandb/sdk/internal/internal_api.py", line 2549, in upload_file
    response = self._upload_file_session.put(
  File "/cluster/home/yutang/miniconda3/lib/python3.9/site-packages/requests/sessions.py", line 647, in put
    return self.request("PUT", url, data=data, **kwargs)
  File "/cluster/home/yutang/miniconda3/lib/python3.9/site-packages/requests/sessions.py", line 587, in request
    resp = self.send(prep, **send_kwargs)
  File "/cluster/home/yutang/miniconda3/lib/python3.9/site-packages/requests/sessions.py", line 701, in send
    r = adapter.send(request, **kwargs)
  File "/cluster/home/yutang/miniconda3/lib/python3.9/site-packages/requests/adapters.py", line 565, in send
    raise ConnectionError(e, request=request)
wandb.sdk.lib.retry.TransientError: None
2023-11-04 20:07:52,325 INFO    Thread-12 :70939 [dir_watcher.py:_on_file_modified():288] file/dir modified: /cluster/home/yutang/Deep-Knowledge-Tracing/DKT/KnowledgeTracing/evaluation/wandb/run-20231104_200744-6vrr841v/files/output.log
2023-11-04 20:07:55,023 DEBUG   HandlerThread:70939 [handler.py:handle_request():146] handle_request: status_report
2023-11-04 20:07:56,248 ERROR   wandb-upload_0:70939 [internal_api.py:upload_file():2556] upload_file exception https://storage.googleapis.com/wandb-production.appspot.com/bryanttang/DKT-trial%201/6vrr841v/wandb-metadata.json?Expires=1699211268&GoogleAccessId=gorilla-files-url-signer-man%40wandb-production.iam.gserviceaccount.com&Signature=vdJEEcja8gjpAmCYudZAM3SaB%2Byil1rBe9Vpxz%2BDL2Oqckxw3FSjQxnGcmgh4WEdL3tq5mqqLlj8KBjtBOrb61BC7vq8bJfWJV9Ckjq3ju3JHcFpTJF8fKLny2uH7KJrTdYogD70%2FGbPqkc7oyL9G1mxlrAD5Svj3zfHGI0Ztpk0OEk1%2F81uRhQt%2FgxnsGAPMM24kS5RX4RtNOdAsIHEOP7uh4se9mMPh%2BiOskiBLEA7U%2B8gNc%2FpFrVNFuK%2FUtWT0ZHMSYbmiez4gG2JVyRQ3Tq8AXZWbyuu9FsKJzQ90MOdYMyQfLPsM6Iso%2ByBeYDY%2FQbdukgbltoecr8LWUUkyg%3D%3D: HTTPSConnectionPool(host='storage.googleapis.com', port=443): Max retries exceeded with url: /wandb-production.appspot.com/bryanttang/DKT-trial%201/6vrr841v/wandb-metadata.json?Expires=1699211268&GoogleAccessId=gorilla-files-url-signer-man%40wandb-production.iam.gserviceaccount.com&Signature=vdJEEcja8gjpAmCYudZAM3SaB%2Byil1rBe9Vpxz%2BDL2Oqckxw3FSjQxnGcmgh4WEdL3tq5mqqLlj8KBjtBOrb61BC7vq8bJfWJV9Ckjq3ju3JHcFpTJF8fKLny2uH7KJrTdYogD70%2FGbPqkc7oyL9G1mxlrAD5Svj3zfHGI0Ztpk0OEk1%2F81uRhQt%2FgxnsGAPMM24kS5RX4RtNOdAsIHEOP7uh4se9mMPh%2BiOskiBLEA7U%2B8gNc%2FpFrVNFuK%2FUtWT0ZHMSYbmiez4gG2JVyRQ3Tq8AXZWbyuu9FsKJzQ90MOdYMyQfLPsM6Iso%2ByBeYDY%2FQbdukgbltoecr8LWUUkyg%3D%3D (Caused by NewConnectionError('<urllib3.connection.HTTPSConnection object at 0x2b2afbebfaf0>: Failed to establish a new connection: [Errno 101] Network is unreachable'))
2023-11-04 20:07:56,248 ERROR   wandb-upload_0:70939 [internal_api.py:upload_file():2558] upload_file request headers: {'User-Agent': 'python-requests/2.28.1', 'Accept-Encoding': 'gzip, deflate, br', 'Accept': '*/*', 'Connection': 'keep-alive', 'Content-Length': '14811'}
2023-11-04 20:07:56,248 ERROR   wandb-upload_0:70939 [internal_api.py:upload_file():2560] upload_file response body: 
2023-11-04 20:07:58,331 INFO    Thread-12 :70939 [dir_watcher.py:_on_file_modified():288] file/dir modified: /cluster/home/yutang/Deep-Knowledge-Tracing/DKT/KnowledgeTracing/evaluation/wandb/run-20231104_200744-6vrr841v/files/output.log
2023-11-04 20:08:00,870 DEBUG   HandlerThread:70939 [handler.py:handle_request():146] handle_request: status_report
2023-11-04 20:08:03,150 DEBUG   HandlerThread:70939 [handler.py:handle_request():146] handle_request: stop_status
2023-11-04 20:08:03,150 DEBUG   HandlerThread:70939 [handler.py:handle_request():146] handle_request: internal_messages
2023-11-04 20:08:03,151 DEBUG   SenderThread:70939 [sender.py:send_request():407] send_request: stop_status
2023-11-04 20:08:05,415 ERROR   wandb-upload_0:70939 [internal_api.py:upload_file():2556] upload_file exception https://storage.googleapis.com/wandb-production.appspot.com/bryanttang/DKT-trial%201/6vrr841v/wandb-metadata.json?Expires=1699211268&GoogleAccessId=gorilla-files-url-signer-man%40wandb-production.iam.gserviceaccount.com&Signature=vdJEEcja8gjpAmCYudZAM3SaB%2Byil1rBe9Vpxz%2BDL2Oqckxw3FSjQxnGcmgh4WEdL3tq5mqqLlj8KBjtBOrb61BC7vq8bJfWJV9Ckjq3ju3JHcFpTJF8fKLny2uH7KJrTdYogD70%2FGbPqkc7oyL9G1mxlrAD5Svj3zfHGI0Ztpk0OEk1%2F81uRhQt%2FgxnsGAPMM24kS5RX4RtNOdAsIHEOP7uh4se9mMPh%2BiOskiBLEA7U%2B8gNc%2FpFrVNFuK%2FUtWT0ZHMSYbmiez4gG2JVyRQ3Tq8AXZWbyuu9FsKJzQ90MOdYMyQfLPsM6Iso%2ByBeYDY%2FQbdukgbltoecr8LWUUkyg%3D%3D: HTTPSConnectionPool(host='storage.googleapis.com', port=443): Max retries exceeded with url: /wandb-production.appspot.com/bryanttang/DKT-trial%201/6vrr841v/wandb-metadata.json?Expires=1699211268&GoogleAccessId=gorilla-files-url-signer-man%40wandb-production.iam.gserviceaccount.com&Signature=vdJEEcja8gjpAmCYudZAM3SaB%2Byil1rBe9Vpxz%2BDL2Oqckxw3FSjQxnGcmgh4WEdL3tq5mqqLlj8KBjtBOrb61BC7vq8bJfWJV9Ckjq3ju3JHcFpTJF8fKLny2uH7KJrTdYogD70%2FGbPqkc7oyL9G1mxlrAD5Svj3zfHGI0Ztpk0OEk1%2F81uRhQt%2FgxnsGAPMM24kS5RX4RtNOdAsIHEOP7uh4se9mMPh%2BiOskiBLEA7U%2B8gNc%2FpFrVNFuK%2FUtWT0ZHMSYbmiez4gG2JVyRQ3Tq8AXZWbyuu9FsKJzQ90MOdYMyQfLPsM6Iso%2ByBeYDY%2FQbdukgbltoecr8LWUUkyg%3D%3D (Caused by NewConnectionError('<urllib3.connection.HTTPSConnection object at 0x2b2afbef8820>: Failed to establish a new connection: [Errno 101] Network is unreachable'))
2023-11-04 20:08:05,416 ERROR   wandb-upload_0:70939 [internal_api.py:upload_file():2558] upload_file request headers: {'User-Agent': 'python-requests/2.28.1', 'Accept-Encoding': 'gzip, deflate, br', 'Accept': '*/*', 'Connection': 'keep-alive', 'Content-Length': '14811'}
2023-11-04 20:08:05,416 ERROR   wandb-upload_0:70939 [internal_api.py:upload_file():2560] upload_file response body: 
2023-11-04 20:08:06,339 INFO    Thread-12 :70939 [dir_watcher.py:_on_file_modified():288] file/dir modified: /cluster/home/yutang/Deep-Knowledge-Tracing/DKT/KnowledgeTracing/evaluation/wandb/run-20231104_200744-6vrr841v/files/output.log
2023-11-04 20:08:06,701 DEBUG   HandlerThread:70939 [handler.py:handle_request():146] handle_request: status_report
2023-11-04 20:08:10,343 INFO    Thread-12 :70939 [dir_watcher.py:_on_file_modified():288] file/dir modified: /cluster/home/yutang/Deep-Knowledge-Tracing/DKT/KnowledgeTracing/evaluation/wandb/run-20231104_200744-6vrr841v/files/output.log
2023-11-04 20:08:12,471 DEBUG   HandlerThread:70939 [handler.py:handle_request():146] handle_request: status_report
2023-11-04 20:08:16,125 DEBUG   SenderThread:70939 [sender.py:send():380] send: exit
2023-11-04 20:08:16,125 INFO    SenderThread:70939 [sender.py:send_exit():585] handling exit code: 1
2023-11-04 20:08:16,126 INFO    SenderThread:70939 [sender.py:send_exit():587] handling runtime: 30
2023-11-04 20:08:16,127 INFO    SenderThread:70939 [sender.py:_save_file():1378] saving file wandb-summary.json with policy end
2023-11-04 20:08:16,127 INFO    SenderThread:70939 [sender.py:send_exit():593] send defer
2023-11-04 20:08:16,128 DEBUG   HandlerThread:70939 [handler.py:handle_request():146] handle_request: defer
2023-11-04 20:08:16,128 INFO    HandlerThread:70939 [handler.py:handle_request_defer():172] handle defer: 0
2023-11-04 20:08:16,128 DEBUG   SenderThread:70939 [sender.py:send_request():407] send_request: defer
2023-11-04 20:08:16,128 INFO    SenderThread:70939 [sender.py:send_request_defer():609] handle sender defer: 0
2023-11-04 20:08:16,128 INFO    SenderThread:70939 [sender.py:transition_state():613] send defer: 1
2023-11-04 20:08:16,128 DEBUG   HandlerThread:70939 [handler.py:handle_request():146] handle_request: defer
2023-11-04 20:08:16,128 INFO    HandlerThread:70939 [handler.py:handle_request_defer():172] handle defer: 1
2023-11-04 20:08:16,128 DEBUG   SenderThread:70939 [sender.py:send_request():407] send_request: defer
2023-11-04 20:08:16,128 INFO    SenderThread:70939 [sender.py:send_request_defer():609] handle sender defer: 1
2023-11-04 20:08:16,129 INFO    SenderThread:70939 [sender.py:transition_state():613] send defer: 2
2023-11-04 20:08:16,129 DEBUG   HandlerThread:70939 [handler.py:handle_request():146] handle_request: defer
2023-11-04 20:08:16,129 INFO    HandlerThread:70939 [handler.py:handle_request_defer():172] handle defer: 2
2023-11-04 20:08:16,129 INFO    HandlerThread:70939 [system_monitor.py:finish():203] Stopping system monitor
2023-11-04 20:08:16,129 DEBUG   SystemMonitor:70939 [system_monitor.py:_start():172] Starting system metrics aggregation loop
2023-11-04 20:08:16,133 DEBUG   SystemMonitor:70939 [system_monitor.py:_start():179] Finished system metrics aggregation loop
2023-11-04 20:08:16,133 DEBUG   SystemMonitor:70939 [system_monitor.py:_start():183] Publishing last batch of metrics
2023-11-04 20:08:16,135 INFO    HandlerThread:70939 [interfaces.py:finish():202] Joined cpu monitor
2023-11-04 20:08:16,135 INFO    HandlerThread:70939 [interfaces.py:finish():202] Joined disk monitor
2023-11-04 20:08:16,274 INFO    HandlerThread:70939 [interfaces.py:finish():202] Joined gpu monitor
2023-11-04 20:08:16,274 INFO    HandlerThread:70939 [interfaces.py:finish():202] Joined memory monitor
2023-11-04 20:08:16,274 INFO    HandlerThread:70939 [interfaces.py:finish():202] Joined network monitor
2023-11-04 20:08:16,275 DEBUG   SenderThread:70939 [sender.py:send_request():407] send_request: defer
2023-11-04 20:08:16,275 INFO    SenderThread:70939 [sender.py:send_request_defer():609] handle sender defer: 2
2023-11-04 20:08:16,275 INFO    SenderThread:70939 [sender.py:transition_state():613] send defer: 3
2023-11-04 20:08:16,275 DEBUG   SenderThread:70939 [sender.py:send():380] send: stats
2023-11-04 20:08:16,275 DEBUG   HandlerThread:70939 [handler.py:handle_request():146] handle_request: defer
2023-11-04 20:08:16,276 INFO    HandlerThread:70939 [handler.py:handle_request_defer():172] handle defer: 3
2023-11-04 20:08:16,277 DEBUG   SenderThread:70939 [sender.py:send_request():407] send_request: defer
2023-11-04 20:08:16,277 INFO    SenderThread:70939 [sender.py:send_request_defer():609] handle sender defer: 3
2023-11-04 20:08:16,277 INFO    SenderThread:70939 [sender.py:transition_state():613] send defer: 4
2023-11-04 20:08:16,277 DEBUG   HandlerThread:70939 [handler.py:handle_request():146] handle_request: defer
2023-11-04 20:08:16,277 INFO    HandlerThread:70939 [handler.py:handle_request_defer():172] handle defer: 4
2023-11-04 20:08:16,277 DEBUG   SenderThread:70939 [sender.py:send_request():407] send_request: defer
2023-11-04 20:08:16,277 INFO    SenderThread:70939 [sender.py:send_request_defer():609] handle sender defer: 4
2023-11-04 20:08:16,277 INFO    SenderThread:70939 [sender.py:transition_state():613] send defer: 5
2023-11-04 20:08:16,277 DEBUG   HandlerThread:70939 [handler.py:handle_request():146] handle_request: defer
2023-11-04 20:08:16,277 INFO    HandlerThread:70939 [handler.py:handle_request_defer():172] handle defer: 5
2023-11-04 20:08:16,277 DEBUG   SenderThread:70939 [sender.py:send():380] send: summary
2023-11-04 20:08:16,278 INFO    SenderThread:70939 [sender.py:_save_file():1378] saving file wandb-summary.json with policy end
2023-11-04 20:08:16,278 DEBUG   SenderThread:70939 [sender.py:send_request():407] send_request: defer
2023-11-04 20:08:16,278 INFO    SenderThread:70939 [sender.py:send_request_defer():609] handle sender defer: 5
2023-11-04 20:08:16,278 INFO    SenderThread:70939 [sender.py:transition_state():613] send defer: 6
2023-11-04 20:08:16,279 DEBUG   HandlerThread:70939 [handler.py:handle_request():146] handle_request: defer
2023-11-04 20:08:16,279 INFO    HandlerThread:70939 [handler.py:handle_request_defer():172] handle defer: 6
2023-11-04 20:08:16,279 DEBUG   SenderThread:70939 [sender.py:send_request():407] send_request: defer
2023-11-04 20:08:16,279 INFO    SenderThread:70939 [sender.py:send_request_defer():609] handle sender defer: 6
2023-11-04 20:08:16,284 DEBUG   HandlerThread:70939 [handler.py:handle_request():146] handle_request: status_report
2023-11-04 20:08:16,348 INFO    Thread-12 :70939 [dir_watcher.py:_on_file_modified():288] file/dir modified: /cluster/home/yutang/Deep-Knowledge-Tracing/DKT/KnowledgeTracing/evaluation/wandb/run-20231104_200744-6vrr841v/files/output.log
2023-11-04 20:08:16,349 INFO    Thread-12 :70939 [dir_watcher.py:_on_file_created():271] file/dir created: /cluster/home/yutang/Deep-Knowledge-Tracing/DKT/KnowledgeTracing/evaluation/wandb/run-20231104_200744-6vrr841v/files/wandb-summary.json
2023-11-04 20:08:16,470 INFO    SenderThread:70939 [sender.py:transition_state():613] send defer: 7
2023-11-04 20:08:16,470 DEBUG   HandlerThread:70939 [handler.py:handle_request():146] handle_request: defer
2023-11-04 20:08:16,470 INFO    HandlerThread:70939 [handler.py:handle_request_defer():172] handle defer: 7
2023-11-04 20:08:16,470 DEBUG   SenderThread:70939 [sender.py:send_request():407] send_request: defer
2023-11-04 20:08:16,470 INFO    SenderThread:70939 [sender.py:send_request_defer():609] handle sender defer: 7
2023-11-04 20:08:17,124 DEBUG   HandlerThread:70939 [handler.py:handle_request():146] handle_request: poll_exit
2023-11-04 20:08:17,349 INFO    Thread-12 :70939 [dir_watcher.py:_on_file_modified():288] file/dir modified: /cluster/home/yutang/Deep-Knowledge-Tracing/DKT/KnowledgeTracing/evaluation/wandb/run-20231104_200744-6vrr841v/files/config.yaml
2023-11-04 20:08:17,350 INFO    Thread-12 :70939 [dir_watcher.py:_on_file_modified():288] file/dir modified: /cluster/home/yutang/Deep-Knowledge-Tracing/DKT/KnowledgeTracing/evaluation/wandb/run-20231104_200744-6vrr841v/files/output.log
2023-11-04 20:08:18,350 INFO    Thread-12 :70939 [dir_watcher.py:_on_file_modified():288] file/dir modified: /cluster/home/yutang/Deep-Knowledge-Tracing/DKT/KnowledgeTracing/evaluation/wandb/run-20231104_200744-6vrr841v/files/output.log
2023-11-04 20:08:20,067 INFO    SenderThread:70939 [sender.py:transition_state():613] send defer: 8
2023-11-04 20:08:20,067 DEBUG   SenderThread:70939 [sender.py:send_request():407] send_request: poll_exit
2023-11-04 20:08:20,067 DEBUG   HandlerThread:70939 [handler.py:handle_request():146] handle_request: defer
2023-11-04 20:08:20,068 INFO    HandlerThread:70939 [handler.py:handle_request_defer():172] handle defer: 8
2023-11-04 20:08:20,068 DEBUG   SenderThread:70939 [sender.py:send_request():407] send_request: defer
2023-11-04 20:08:20,068 INFO    SenderThread:70939 [sender.py:send_request_defer():609] handle sender defer: 8
2023-11-04 20:08:20,068 INFO    SenderThread:70939 [job_builder.py:build():281] Attempting to build job artifact
2023-11-04 20:08:20,069 INFO    SenderThread:70939 [job_builder.py:_get_source_type():393] is repo sourced job
2023-11-04 20:08:20,072 INFO    SenderThread:70939 [job_builder.py:build():369] adding wandb-job metadata file
2023-11-04 20:08:20,079 INFO    SenderThread:70939 [sender.py:transition_state():613] send defer: 9
2023-11-04 20:08:20,079 DEBUG   HandlerThread:70939 [handler.py:handle_request():146] handle_request: defer
2023-11-04 20:08:20,079 INFO    HandlerThread:70939 [handler.py:handle_request_defer():172] handle defer: 9
2023-11-04 20:08:20,079 DEBUG   SenderThread:70939 [sender.py:send():380] send: artifact
2023-11-04 20:08:20,352 INFO    Thread-12 :70939 [dir_watcher.py:_on_file_modified():288] file/dir modified: /cluster/home/yutang/Deep-Knowledge-Tracing/DKT/KnowledgeTracing/evaluation/wandb/run-20231104_200744-6vrr841v/files/output.log
2023-11-04 20:08:21,061 ERROR   wandb-upload_1:70939 [internal_api.py:upload_file():2556] upload_file exception https://storage.googleapis.com/wandb-artifacts-prod/wandb_artifacts/112721340/628306709/102cc8ee8286496275f91b42827e86ae?Expires=1699211300&GoogleAccessId=gorilla-files-url-signer-man%40wandb-production.iam.gserviceaccount.com&Signature=LFm1xDTSK8GqAoFfKYQRGLO1pTEJRH5twY4y6lz9hN4muwVVpgOG%2FSaJ%2F4UGIUE7sYK4wPS%2B%2Frt2k7iix8gfP%2FATEzQAOcSlzlfgcjMy8PBb8V55JV3zo1sj1tkFTgGlPNGjzdyBBxuOCNwzEklObf0tURbSBSZm%2Fn9oVy%2BMuBNon%2FEfMCh05ycVgeMSMqJl%2FL5XuPAC%2FodcOb%2FHYFUyIHg5I0RjR8ZkIyeh0a2sbiRKgMOtrkquuKcNZJPA4pUPrslB5t03F1XDFuLvX0zgEabEbW4GMfbtlkQ2MTFTG5OmjIYHNntOJTXCasTJ7ImaEG%2BKY%2FIZRBTsI09Adu3Raw%3D%3D: HTTPSConnectionPool(host='storage.googleapis.com', port=443): Max retries exceeded with url: /wandb-artifacts-prod/wandb_artifacts/112721340/628306709/102cc8ee8286496275f91b42827e86ae?Expires=1699211300&GoogleAccessId=gorilla-files-url-signer-man%40wandb-production.iam.gserviceaccount.com&Signature=LFm1xDTSK8GqAoFfKYQRGLO1pTEJRH5twY4y6lz9hN4muwVVpgOG%2FSaJ%2F4UGIUE7sYK4wPS%2B%2Frt2k7iix8gfP%2FATEzQAOcSlzlfgcjMy8PBb8V55JV3zo1sj1tkFTgGlPNGjzdyBBxuOCNwzEklObf0tURbSBSZm%2Fn9oVy%2BMuBNon%2FEfMCh05ycVgeMSMqJl%2FL5XuPAC%2FodcOb%2FHYFUyIHg5I0RjR8ZkIyeh0a2sbiRKgMOtrkquuKcNZJPA4pUPrslB5t03F1XDFuLvX0zgEabEbW4GMfbtlkQ2MTFTG5OmjIYHNntOJTXCasTJ7ImaEG%2BKY%2FIZRBTsI09Adu3Raw%3D%3D (Caused by NewConnectionError('<urllib3.connection.HTTPSConnection object at 0x2b2b22e10670>: Failed to establish a new connection: [Errno 101] Network is unreachable'))
2023-11-04 20:08:21,061 ERROR   wandb-upload_1:70939 [internal_api.py:upload_file():2558] upload_file request headers: {'User-Agent': 'python-requests/2.28.1', 'Accept-Encoding': 'gzip, deflate, br', 'Accept': '*/*', 'Connection': 'keep-alive', 'Content-MD5': 'ECzI7oKGSWJ1+RtCgn6Grg==', 'Content-Type': 'text/plain; charset=utf-8', 'Content-Length': '1756'}
2023-11-04 20:08:21,061 ERROR   wandb-upload_1:70939 [internal_api.py:upload_file():2560] upload_file response body: 
2023-11-04 20:08:21,063 ERROR   wandb-upload_2:70939 [internal_api.py:upload_file():2556] upload_file exception https://storage.googleapis.com/wandb-artifacts-prod/wandb_artifacts/112721340/628306709/736d2e841e706f032bb0b718411a8b04?Expires=1699211300&GoogleAccessId=gorilla-files-url-signer-man%40wandb-production.iam.gserviceaccount.com&Signature=oqaU%2BaAVxafCwLP3oNOLzbX%2FNUtowVrBhTOa2aZ3TG4EAoTMW80M3xq17U61fNbnkiaDhwWWSSNlZjaM%2BK5Vl1GdBhSdtyrCySenUVsB%2BwGsYLjwOuBULxXPJiQaG9QXtCADtVk02TN0fi4Ppkayyx78PqfHNA7M%2FaOzDoPWpU4h%2BWaeIv67L8k0S%2BMYOVnkI9HsaorIMS9qCAulyk%2F5r6p9Nrzxa4l9UYxRYwQ2cg268Zi0o%2BiWyvzaH9EDFCoON%2BaT90wGWlNR30tBGWginzvX%2BgYis5rJCXi1i5daHyaYmO8wKuGz3WCNy6FDLaWlHn9J0bsCQm1Yp36KdSTJSQ%3D%3D: HTTPSConnectionPool(host='storage.googleapis.com', port=443): Max retries exceeded with url: /wandb-artifacts-prod/wandb_artifacts/112721340/628306709/736d2e841e706f032bb0b718411a8b04?Expires=1699211300&GoogleAccessId=gorilla-files-url-signer-man%40wandb-production.iam.gserviceaccount.com&Signature=oqaU%2BaAVxafCwLP3oNOLzbX%2FNUtowVrBhTOa2aZ3TG4EAoTMW80M3xq17U61fNbnkiaDhwWWSSNlZjaM%2BK5Vl1GdBhSdtyrCySenUVsB%2BwGsYLjwOuBULxXPJiQaG9QXtCADtVk02TN0fi4Ppkayyx78PqfHNA7M%2FaOzDoPWpU4h%2BWaeIv67L8k0S%2BMYOVnkI9HsaorIMS9qCAulyk%2F5r6p9Nrzxa4l9UYxRYwQ2cg268Zi0o%2BiWyvzaH9EDFCoON%2BaT90wGWlNR30tBGWginzvX%2BgYis5rJCXi1i5daHyaYmO8wKuGz3WCNy6FDLaWlHn9J0bsCQm1Yp36KdSTJSQ%3D%3D (Caused by NewConnectionError('<urllib3.connection.HTTPSConnection object at 0x2b2b22e10be0>: Failed to establish a new connection: [Errno 101] Network is unreachable'))
2023-11-04 20:08:21,063 ERROR   wandb-upload_2:70939 [internal_api.py:upload_file():2558] upload_file request headers: {'User-Agent': 'python-requests/2.28.1', 'Accept-Encoding': 'gzip, deflate, br', 'Accept': '*/*', 'Connection': 'keep-alive', 'Content-MD5': 'c20uhB5wbwMrsLcYQRqLBA==', 'Content-Type': 'application/json', 'Content-Length': '648'}
2023-11-04 20:08:21,063 ERROR   wandb-upload_2:70939 [internal_api.py:upload_file():2560] upload_file response body: 
2023-11-04 20:08:22,126 DEBUG   HandlerThread:70939 [handler.py:handle_request():146] handle_request: keepalive
2023-11-04 20:08:22,210 ERROR   wandb-upload_1:70939 [internal_api.py:upload_file():2556] upload_file exception https://storage.googleapis.com/wandb-artifacts-prod/wandb_artifacts/112721340/628306709/102cc8ee8286496275f91b42827e86ae?Expires=1699211300&GoogleAccessId=gorilla-files-url-signer-man%40wandb-production.iam.gserviceaccount.com&Signature=LFm1xDTSK8GqAoFfKYQRGLO1pTEJRH5twY4y6lz9hN4muwVVpgOG%2FSaJ%2F4UGIUE7sYK4wPS%2B%2Frt2k7iix8gfP%2FATEzQAOcSlzlfgcjMy8PBb8V55JV3zo1sj1tkFTgGlPNGjzdyBBxuOCNwzEklObf0tURbSBSZm%2Fn9oVy%2BMuBNon%2FEfMCh05ycVgeMSMqJl%2FL5XuPAC%2FodcOb%2FHYFUyIHg5I0RjR8ZkIyeh0a2sbiRKgMOtrkquuKcNZJPA4pUPrslB5t03F1XDFuLvX0zgEabEbW4GMfbtlkQ2MTFTG5OmjIYHNntOJTXCasTJ7ImaEG%2BKY%2FIZRBTsI09Adu3Raw%3D%3D: HTTPSConnectionPool(host='storage.googleapis.com', port=443): Max retries exceeded with url: /wandb-artifacts-prod/wandb_artifacts/112721340/628306709/102cc8ee8286496275f91b42827e86ae?Expires=1699211300&GoogleAccessId=gorilla-files-url-signer-man%40wandb-production.iam.gserviceaccount.com&Signature=LFm1xDTSK8GqAoFfKYQRGLO1pTEJRH5twY4y6lz9hN4muwVVpgOG%2FSaJ%2F4UGIUE7sYK4wPS%2B%2Frt2k7iix8gfP%2FATEzQAOcSlzlfgcjMy8PBb8V55JV3zo1sj1tkFTgGlPNGjzdyBBxuOCNwzEklObf0tURbSBSZm%2Fn9oVy%2BMuBNon%2FEfMCh05ycVgeMSMqJl%2FL5XuPAC%2FodcOb%2FHYFUyIHg5I0RjR8ZkIyeh0a2sbiRKgMOtrkquuKcNZJPA4pUPrslB5t03F1XDFuLvX0zgEabEbW4GMfbtlkQ2MTFTG5OmjIYHNntOJTXCasTJ7ImaEG%2BKY%2FIZRBTsI09Adu3Raw%3D%3D (Caused by NewConnectionError('<urllib3.connection.HTTPSConnection object at 0x2b2afbf2d400>: Failed to establish a new connection: [Errno 101] Network is unreachable'))
2023-11-04 20:08:22,210 ERROR   wandb-upload_1:70939 [internal_api.py:upload_file():2558] upload_file request headers: {'User-Agent': 'python-requests/2.28.1', 'Accept-Encoding': 'gzip, deflate, br', 'Accept': '*/*', 'Connection': 'keep-alive', 'Content-MD5': 'ECzI7oKGSWJ1+RtCgn6Grg==', 'Content-Type': 'text/plain; charset=utf-8', 'Content-Length': '1756'}
2023-11-04 20:08:22,211 ERROR   wandb-upload_1:70939 [internal_api.py:upload_file():2560] upload_file response body: 
2023-11-04 20:08:22,300 ERROR   wandb-upload_2:70939 [internal_api.py:upload_file():2556] upload_file exception https://storage.googleapis.com/wandb-artifacts-prod/wandb_artifacts/112721340/628306709/736d2e841e706f032bb0b718411a8b04?Expires=1699211300&GoogleAccessId=gorilla-files-url-signer-man%40wandb-production.iam.gserviceaccount.com&Signature=oqaU%2BaAVxafCwLP3oNOLzbX%2FNUtowVrBhTOa2aZ3TG4EAoTMW80M3xq17U61fNbnkiaDhwWWSSNlZjaM%2BK5Vl1GdBhSdtyrCySenUVsB%2BwGsYLjwOuBULxXPJiQaG9QXtCADtVk02TN0fi4Ppkayyx78PqfHNA7M%2FaOzDoPWpU4h%2BWaeIv67L8k0S%2BMYOVnkI9HsaorIMS9qCAulyk%2F5r6p9Nrzxa4l9UYxRYwQ2cg268Zi0o%2BiWyvzaH9EDFCoON%2BaT90wGWlNR30tBGWginzvX%2BgYis5rJCXi1i5daHyaYmO8wKuGz3WCNy6FDLaWlHn9J0bsCQm1Yp36KdSTJSQ%3D%3D: HTTPSConnectionPool(host='storage.googleapis.com', port=443): Max retries exceeded with url: /wandb-artifacts-prod/wandb_artifacts/112721340/628306709/736d2e841e706f032bb0b718411a8b04?Expires=1699211300&GoogleAccessId=gorilla-files-url-signer-man%40wandb-production.iam.gserviceaccount.com&Signature=oqaU%2BaAVxafCwLP3oNOLzbX%2FNUtowVrBhTOa2aZ3TG4EAoTMW80M3xq17U61fNbnkiaDhwWWSSNlZjaM%2BK5Vl1GdBhSdtyrCySenUVsB%2BwGsYLjwOuBULxXPJiQaG9QXtCADtVk02TN0fi4Ppkayyx78PqfHNA7M%2FaOzDoPWpU4h%2BWaeIv67L8k0S%2BMYOVnkI9HsaorIMS9qCAulyk%2F5r6p9Nrzxa4l9UYxRYwQ2cg268Zi0o%2BiWyvzaH9EDFCoON%2BaT90wGWlNR30tBGWginzvX%2BgYis5rJCXi1i5daHyaYmO8wKuGz3WCNy6FDLaWlHn9J0bsCQm1Yp36KdSTJSQ%3D%3D (Caused by NewConnectionError('<urllib3.connection.HTTPSConnection object at 0x2b2b22e10910>: Failed to establish a new connection: [Errno 101] Network is unreachable'))
2023-11-04 20:08:22,300 ERROR   wandb-upload_2:70939 [internal_api.py:upload_file():2558] upload_file request headers: {'User-Agent': 'python-requests/2.28.1', 'Accept-Encoding': 'gzip, deflate, br', 'Accept': '*/*', 'Connection': 'keep-alive', 'Content-MD5': 'c20uhB5wbwMrsLcYQRqLBA==', 'Content-Type': 'application/json', 'Content-Length': '648'}
2023-11-04 20:08:22,300 ERROR   wandb-upload_2:70939 [internal_api.py:upload_file():2560] upload_file response body: 
2023-11-04 20:08:23,261 ERROR   wandb-upload_0:70939 [internal_api.py:upload_file():2556] upload_file exception https://storage.googleapis.com/wandb-production.appspot.com/bryanttang/DKT-trial%201/6vrr841v/wandb-metadata.json?Expires=1699211268&GoogleAccessId=gorilla-files-url-signer-man%40wandb-production.iam.gserviceaccount.com&Signature=vdJEEcja8gjpAmCYudZAM3SaB%2Byil1rBe9Vpxz%2BDL2Oqckxw3FSjQxnGcmgh4WEdL3tq5mqqLlj8KBjtBOrb61BC7vq8bJfWJV9Ckjq3ju3JHcFpTJF8fKLny2uH7KJrTdYogD70%2FGbPqkc7oyL9G1mxlrAD5Svj3zfHGI0Ztpk0OEk1%2F81uRhQt%2FgxnsGAPMM24kS5RX4RtNOdAsIHEOP7uh4se9mMPh%2BiOskiBLEA7U%2B8gNc%2FpFrVNFuK%2FUtWT0ZHMSYbmiez4gG2JVyRQ3Tq8AXZWbyuu9FsKJzQ90MOdYMyQfLPsM6Iso%2ByBeYDY%2FQbdukgbltoecr8LWUUkyg%3D%3D: HTTPSConnectionPool(host='storage.googleapis.com', port=443): Max retries exceeded with url: /wandb-production.appspot.com/bryanttang/DKT-trial%201/6vrr841v/wandb-metadata.json?Expires=1699211268&GoogleAccessId=gorilla-files-url-signer-man%40wandb-production.iam.gserviceaccount.com&Signature=vdJEEcja8gjpAmCYudZAM3SaB%2Byil1rBe9Vpxz%2BDL2Oqckxw3FSjQxnGcmgh4WEdL3tq5mqqLlj8KBjtBOrb61BC7vq8bJfWJV9Ckjq3ju3JHcFpTJF8fKLny2uH7KJrTdYogD70%2FGbPqkc7oyL9G1mxlrAD5Svj3zfHGI0Ztpk0OEk1%2F81uRhQt%2FgxnsGAPMM24kS5RX4RtNOdAsIHEOP7uh4se9mMPh%2BiOskiBLEA7U%2B8gNc%2FpFrVNFuK%2FUtWT0ZHMSYbmiez4gG2JVyRQ3Tq8AXZWbyuu9FsKJzQ90MOdYMyQfLPsM6Iso%2ByBeYDY%2FQbdukgbltoecr8LWUUkyg%3D%3D (Caused by NewConnectionError('<urllib3.connection.HTTPSConnection object at 0x2b2b22e081c0>: Failed to establish a new connection: [Errno 101] Network is unreachable'))
2023-11-04 20:08:23,262 ERROR   wandb-upload_0:70939 [internal_api.py:upload_file():2558] upload_file request headers: {'User-Agent': 'python-requests/2.28.1', 'Accept-Encoding': 'gzip, deflate, br', 'Accept': '*/*', 'Connection': 'keep-alive', 'Content-Length': '14811'}
2023-11-04 20:08:23,262 ERROR   wandb-upload_0:70939 [internal_api.py:upload_file():2560] upload_file response body: 
2023-11-04 20:08:24,419 ERROR   wandb-upload_2:70939 [internal_api.py:upload_file():2556] upload_file exception https://storage.googleapis.com/wandb-artifacts-prod/wandb_artifacts/112721340/628306709/736d2e841e706f032bb0b718411a8b04?Expires=1699211300&GoogleAccessId=gorilla-files-url-signer-man%40wandb-production.iam.gserviceaccount.com&Signature=oqaU%2BaAVxafCwLP3oNOLzbX%2FNUtowVrBhTOa2aZ3TG4EAoTMW80M3xq17U61fNbnkiaDhwWWSSNlZjaM%2BK5Vl1GdBhSdtyrCySenUVsB%2BwGsYLjwOuBULxXPJiQaG9QXtCADtVk02TN0fi4Ppkayyx78PqfHNA7M%2FaOzDoPWpU4h%2BWaeIv67L8k0S%2BMYOVnkI9HsaorIMS9qCAulyk%2F5r6p9Nrzxa4l9UYxRYwQ2cg268Zi0o%2BiWyvzaH9EDFCoON%2BaT90wGWlNR30tBGWginzvX%2BgYis5rJCXi1i5daHyaYmO8wKuGz3WCNy6FDLaWlHn9J0bsCQm1Yp36KdSTJSQ%3D%3D: HTTPSConnectionPool(host='storage.googleapis.com', port=443): Max retries exceeded with url: /wandb-artifacts-prod/wandb_artifacts/112721340/628306709/736d2e841e706f032bb0b718411a8b04?Expires=1699211300&GoogleAccessId=gorilla-files-url-signer-man%40wandb-production.iam.gserviceaccount.com&Signature=oqaU%2BaAVxafCwLP3oNOLzbX%2FNUtowVrBhTOa2aZ3TG4EAoTMW80M3xq17U61fNbnkiaDhwWWSSNlZjaM%2BK5Vl1GdBhSdtyrCySenUVsB%2BwGsYLjwOuBULxXPJiQaG9QXtCADtVk02TN0fi4Ppkayyx78PqfHNA7M%2FaOzDoPWpU4h%2BWaeIv67L8k0S%2BMYOVnkI9HsaorIMS9qCAulyk%2F5r6p9Nrzxa4l9UYxRYwQ2cg268Zi0o%2BiWyvzaH9EDFCoON%2BaT90wGWlNR30tBGWginzvX%2BgYis5rJCXi1i5daHyaYmO8wKuGz3WCNy6FDLaWlHn9J0bsCQm1Yp36KdSTJSQ%3D%3D (Caused by NewConnectionError('<urllib3.connection.HTTPSConnection object at 0x2b2b22e087f0>: Failed to establish a new connection: [Errno 101] Network is unreachable'))
2023-11-04 20:08:24,419 ERROR   wandb-upload_2:70939 [internal_api.py:upload_file():2558] upload_file request headers: {'User-Agent': 'python-requests/2.28.1', 'Accept-Encoding': 'gzip, deflate, br', 'Accept': '*/*', 'Connection': 'keep-alive', 'Content-MD5': 'c20uhB5wbwMrsLcYQRqLBA==', 'Content-Type': 'application/json', 'Content-Length': '648'}
2023-11-04 20:08:24,419 ERROR   wandb-upload_2:70939 [internal_api.py:upload_file():2560] upload_file response body: 
2023-11-04 20:08:24,419 INFO    wandb-upload_2:70939 [retry.py:__call__():172] Retry attempt failed:
Traceback (most recent call last):
  File "/cluster/home/yutang/miniconda3/lib/python3.9/site-packages/urllib3/connection.py", line 174, in _new_conn
    conn = connection.create_connection(
  File "/cluster/home/yutang/miniconda3/lib/python3.9/site-packages/urllib3/util/connection.py", line 95, in create_connection
    raise err
  File "/cluster/home/yutang/miniconda3/lib/python3.9/site-packages/urllib3/util/connection.py", line 85, in create_connection
    sock.connect(sa)
OSError: [Errno 101] Network is unreachable

During handling of the above exception, another exception occurred:

Traceback (most recent call last):
  File "/cluster/home/yutang/miniconda3/lib/python3.9/site-packages/urllib3/connectionpool.py", line 703, in urlopen
    httplib_response = self._make_request(
  File "/cluster/home/yutang/miniconda3/lib/python3.9/site-packages/urllib3/connectionpool.py", line 386, in _make_request
    self._validate_conn(conn)
  File "/cluster/home/yutang/miniconda3/lib/python3.9/site-packages/urllib3/connectionpool.py", line 1042, in _validate_conn
    conn.connect()
  File "/cluster/home/yutang/miniconda3/lib/python3.9/site-packages/urllib3/connection.py", line 358, in connect
    self.sock = conn = self._new_conn()
  File "/cluster/home/yutang/miniconda3/lib/python3.9/site-packages/urllib3/connection.py", line 186, in _new_conn
    raise NewConnectionError(
urllib3.exceptions.NewConnectionError: <urllib3.connection.HTTPSConnection object at 0x2b2b22e087f0>: Failed to establish a new connection: [Errno 101] Network is unreachable

During handling of the above exception, another exception occurred:

Traceback (most recent call last):
  File "/cluster/home/yutang/miniconda3/lib/python3.9/site-packages/requests/adapters.py", line 489, in send
    resp = conn.urlopen(
  File "/cluster/home/yutang/miniconda3/lib/python3.9/site-packages/urllib3/connectionpool.py", line 787, in urlopen
    retries = retries.increment(
  File "/cluster/home/yutang/miniconda3/lib/python3.9/site-packages/urllib3/util/retry.py", line 592, in increment
    raise MaxRetryError(_pool, url, error or ResponseError(cause))
urllib3.exceptions.MaxRetryError: HTTPSConnectionPool(host='storage.googleapis.com', port=443): Max retries exceeded with url: /wandb-artifacts-prod/wandb_artifacts/112721340/628306709/736d2e841e706f032bb0b718411a8b04?Expires=1699211300&GoogleAccessId=gorilla-files-url-signer-man%40wandb-production.iam.gserviceaccount.com&Signature=oqaU%2BaAVxafCwLP3oNOLzbX%2FNUtowVrBhTOa2aZ3TG4EAoTMW80M3xq17U61fNbnkiaDhwWWSSNlZjaM%2BK5Vl1GdBhSdtyrCySenUVsB%2BwGsYLjwOuBULxXPJiQaG9QXtCADtVk02TN0fi4Ppkayyx78PqfHNA7M%2FaOzDoPWpU4h%2BWaeIv67L8k0S%2BMYOVnkI9HsaorIMS9qCAulyk%2F5r6p9Nrzxa4l9UYxRYwQ2cg268Zi0o%2BiWyvzaH9EDFCoON%2BaT90wGWlNR30tBGWginzvX%2BgYis5rJCXi1i5daHyaYmO8wKuGz3WCNy6FDLaWlHn9J0bsCQm1Yp36KdSTJSQ%3D%3D (Caused by NewConnectionError('<urllib3.connection.HTTPSConnection object at 0x2b2b22e087f0>: Failed to establish a new connection: [Errno 101] Network is unreachable'))

During handling of the above exception, another exception occurred:

Traceback (most recent call last):
  File "/cluster/home/yutang/miniconda3/lib/python3.9/site-packages/wandb/sdk/internal/internal_api.py", line 2549, in upload_file
    response = self._upload_file_session.put(
  File "/cluster/home/yutang/miniconda3/lib/python3.9/site-packages/requests/sessions.py", line 647, in put
    return self.request("PUT", url, data=data, **kwargs)
  File "/cluster/home/yutang/miniconda3/lib/python3.9/site-packages/requests/sessions.py", line 587, in request
    resp = self.send(prep, **send_kwargs)
  File "/cluster/home/yutang/miniconda3/lib/python3.9/site-packages/requests/sessions.py", line 701, in send
    r = adapter.send(request, **kwargs)
  File "/cluster/home/yutang/miniconda3/lib/python3.9/site-packages/requests/adapters.py", line 565, in send
    raise ConnectionError(e, request=request)
requests.exceptions.ConnectionError: HTTPSConnectionPool(host='storage.googleapis.com', port=443): Max retries exceeded with url: /wandb-artifacts-prod/wandb_artifacts/112721340/628306709/736d2e841e706f032bb0b718411a8b04?Expires=1699211300&GoogleAccessId=gorilla-files-url-signer-man%40wandb-production.iam.gserviceaccount.com&Signature=oqaU%2BaAVxafCwLP3oNOLzbX%2FNUtowVrBhTOa2aZ3TG4EAoTMW80M3xq17U61fNbnkiaDhwWWSSNlZjaM%2BK5Vl1GdBhSdtyrCySenUVsB%2BwGsYLjwOuBULxXPJiQaG9QXtCADtVk02TN0fi4Ppkayyx78PqfHNA7M%2FaOzDoPWpU4h%2BWaeIv67L8k0S%2BMYOVnkI9HsaorIMS9qCAulyk%2F5r6p9Nrzxa4l9UYxRYwQ2cg268Zi0o%2BiWyvzaH9EDFCoON%2BaT90wGWlNR30tBGWginzvX%2BgYis5rJCXi1i5daHyaYmO8wKuGz3WCNy6FDLaWlHn9J0bsCQm1Yp36KdSTJSQ%3D%3D (Caused by NewConnectionError('<urllib3.connection.HTTPSConnection object at 0x2b2b22e087f0>: Failed to establish a new connection: [Errno 101] Network is unreachable'))

During handling of the above exception, another exception occurred:

Traceback (most recent call last):
  File "/cluster/home/yutang/miniconda3/lib/python3.9/site-packages/wandb/sdk/lib/retry.py", line 131, in __call__
    result = self._call_fn(*args, **kwargs)
  File "/cluster/home/yutang/miniconda3/lib/python3.9/site-packages/wandb/sdk/internal/internal_api.py", line 2580, in upload_file
    raise _e.with_traceback(sys.exc_info()[2])
  File "/cluster/home/yutang/miniconda3/lib/python3.9/site-packages/wandb/sdk/internal/internal_api.py", line 2549, in upload_file
    response = self._upload_file_session.put(
  File "/cluster/home/yutang/miniconda3/lib/python3.9/site-packages/requests/sessions.py", line 647, in put
    return self.request("PUT", url, data=data, **kwargs)
  File "/cluster/home/yutang/miniconda3/lib/python3.9/site-packages/requests/sessions.py", line 587, in request
    resp = self.send(prep, **send_kwargs)
  File "/cluster/home/yutang/miniconda3/lib/python3.9/site-packages/requests/sessions.py", line 701, in send
    r = adapter.send(request, **kwargs)
  File "/cluster/home/yutang/miniconda3/lib/python3.9/site-packages/requests/adapters.py", line 565, in send
    raise ConnectionError(e, request=request)
wandb.sdk.lib.retry.TransientError: None
2023-11-04 20:08:24,665 ERROR   wandb-upload_1:70939 [internal_api.py:upload_file():2556] upload_file exception https://storage.googleapis.com/wandb-artifacts-prod/wandb_artifacts/112721340/628306709/102cc8ee8286496275f91b42827e86ae?Expires=1699211300&GoogleAccessId=gorilla-files-url-signer-man%40wandb-production.iam.gserviceaccount.com&Signature=LFm1xDTSK8GqAoFfKYQRGLO1pTEJRH5twY4y6lz9hN4muwVVpgOG%2FSaJ%2F4UGIUE7sYK4wPS%2B%2Frt2k7iix8gfP%2FATEzQAOcSlzlfgcjMy8PBb8V55JV3zo1sj1tkFTgGlPNGjzdyBBxuOCNwzEklObf0tURbSBSZm%2Fn9oVy%2BMuBNon%2FEfMCh05ycVgeMSMqJl%2FL5XuPAC%2FodcOb%2FHYFUyIHg5I0RjR8ZkIyeh0a2sbiRKgMOtrkquuKcNZJPA4pUPrslB5t03F1XDFuLvX0zgEabEbW4GMfbtlkQ2MTFTG5OmjIYHNntOJTXCasTJ7ImaEG%2BKY%2FIZRBTsI09Adu3Raw%3D%3D: HTTPSConnectionPool(host='storage.googleapis.com', port=443): Max retries exceeded with url: /wandb-artifacts-prod/wandb_artifacts/112721340/628306709/102cc8ee8286496275f91b42827e86ae?Expires=1699211300&GoogleAccessId=gorilla-files-url-signer-man%40wandb-production.iam.gserviceaccount.com&Signature=LFm1xDTSK8GqAoFfKYQRGLO1pTEJRH5twY4y6lz9hN4muwVVpgOG%2FSaJ%2F4UGIUE7sYK4wPS%2B%2Frt2k7iix8gfP%2FATEzQAOcSlzlfgcjMy8PBb8V55JV3zo1sj1tkFTgGlPNGjzdyBBxuOCNwzEklObf0tURbSBSZm%2Fn9oVy%2BMuBNon%2FEfMCh05ycVgeMSMqJl%2FL5XuPAC%2FodcOb%2FHYFUyIHg5I0RjR8ZkIyeh0a2sbiRKgMOtrkquuKcNZJPA4pUPrslB5t03F1XDFuLvX0zgEabEbW4GMfbtlkQ2MTFTG5OmjIYHNntOJTXCasTJ7ImaEG%2BKY%2FIZRBTsI09Adu3Raw%3D%3D (Caused by NewConnectionError('<urllib3.connection.HTTPSConnection object at 0x2b2b22e08fa0>: Failed to establish a new connection: [Errno 101] Network is unreachable'))
2023-11-04 20:08:24,665 ERROR   wandb-upload_1:70939 [internal_api.py:upload_file():2558] upload_file request headers: {'User-Agent': 'python-requests/2.28.1', 'Accept-Encoding': 'gzip, deflate, br', 'Accept': '*/*', 'Connection': 'keep-alive', 'Content-MD5': 'ECzI7oKGSWJ1+RtCgn6Grg==', 'Content-Type': 'text/plain; charset=utf-8', 'Content-Length': '1756'}
2023-11-04 20:08:24,665 ERROR   wandb-upload_1:70939 [internal_api.py:upload_file():2560] upload_file response body: 
2023-11-04 20:08:24,666 INFO    wandb-upload_1:70939 [retry.py:__call__():172] Retry attempt failed:
Traceback (most recent call last):
  File "/cluster/home/yutang/miniconda3/lib/python3.9/site-packages/urllib3/connection.py", line 174, in _new_conn
    conn = connection.create_connection(
  File "/cluster/home/yutang/miniconda3/lib/python3.9/site-packages/urllib3/util/connection.py", line 95, in create_connection
    raise err
  File "/cluster/home/yutang/miniconda3/lib/python3.9/site-packages/urllib3/util/connection.py", line 85, in create_connection
    sock.connect(sa)
OSError: [Errno 101] Network is unreachable

During handling of the above exception, another exception occurred:

Traceback (most recent call last):
  File "/cluster/home/yutang/miniconda3/lib/python3.9/site-packages/urllib3/connectionpool.py", line 703, in urlopen
    httplib_response = self._make_request(
  File "/cluster/home/yutang/miniconda3/lib/python3.9/site-packages/urllib3/connectionpool.py", line 386, in _make_request
    self._validate_conn(conn)
  File "/cluster/home/yutang/miniconda3/lib/python3.9/site-packages/urllib3/connectionpool.py", line 1042, in _validate_conn
    conn.connect()
  File "/cluster/home/yutang/miniconda3/lib/python3.9/site-packages/urllib3/connection.py", line 358, in connect
    self.sock = conn = self._new_conn()
  File "/cluster/home/yutang/miniconda3/lib/python3.9/site-packages/urllib3/connection.py", line 186, in _new_conn
    raise NewConnectionError(
urllib3.exceptions.NewConnectionError: <urllib3.connection.HTTPSConnection object at 0x2b2b22e08fa0>: Failed to establish a new connection: [Errno 101] Network is unreachable

During handling of the above exception, another exception occurred:

Traceback (most recent call last):
  File "/cluster/home/yutang/miniconda3/lib/python3.9/site-packages/requests/adapters.py", line 489, in send
    resp = conn.urlopen(
  File "/cluster/home/yutang/miniconda3/lib/python3.9/site-packages/urllib3/connectionpool.py", line 787, in urlopen
    retries = retries.increment(
  File "/cluster/home/yutang/miniconda3/lib/python3.9/site-packages/urllib3/util/retry.py", line 592, in increment
    raise MaxRetryError(_pool, url, error or ResponseError(cause))
urllib3.exceptions.MaxRetryError: HTTPSConnectionPool(host='storage.googleapis.com', port=443): Max retries exceeded with url: /wandb-artifacts-prod/wandb_artifacts/112721340/628306709/102cc8ee8286496275f91b42827e86ae?Expires=1699211300&GoogleAccessId=gorilla-files-url-signer-man%40wandb-production.iam.gserviceaccount.com&Signature=LFm1xDTSK8GqAoFfKYQRGLO1pTEJRH5twY4y6lz9hN4muwVVpgOG%2FSaJ%2F4UGIUE7sYK4wPS%2B%2Frt2k7iix8gfP%2FATEzQAOcSlzlfgcjMy8PBb8V55JV3zo1sj1tkFTgGlPNGjzdyBBxuOCNwzEklObf0tURbSBSZm%2Fn9oVy%2BMuBNon%2FEfMCh05ycVgeMSMqJl%2FL5XuPAC%2FodcOb%2FHYFUyIHg5I0RjR8ZkIyeh0a2sbiRKgMOtrkquuKcNZJPA4pUPrslB5t03F1XDFuLvX0zgEabEbW4GMfbtlkQ2MTFTG5OmjIYHNntOJTXCasTJ7ImaEG%2BKY%2FIZRBTsI09Adu3Raw%3D%3D (Caused by NewConnectionError('<urllib3.connection.HTTPSConnection object at 0x2b2b22e08fa0>: Failed to establish a new connection: [Errno 101] Network is unreachable'))

During handling of the above exception, another exception occurred:

Traceback (most recent call last):
  File "/cluster/home/yutang/miniconda3/lib/python3.9/site-packages/wandb/sdk/internal/internal_api.py", line 2549, in upload_file
    response = self._upload_file_session.put(
  File "/cluster/home/yutang/miniconda3/lib/python3.9/site-packages/requests/sessions.py", line 647, in put
    return self.request("PUT", url, data=data, **kwargs)
  File "/cluster/home/yutang/miniconda3/lib/python3.9/site-packages/requests/sessions.py", line 587, in request
    resp = self.send(prep, **send_kwargs)
  File "/cluster/home/yutang/miniconda3/lib/python3.9/site-packages/requests/sessions.py", line 701, in send
    r = adapter.send(request, **kwargs)
  File "/cluster/home/yutang/miniconda3/lib/python3.9/site-packages/requests/adapters.py", line 565, in send
    raise ConnectionError(e, request=request)
requests.exceptions.ConnectionError: HTTPSConnectionPool(host='storage.googleapis.com', port=443): Max retries exceeded with url: /wandb-artifacts-prod/wandb_artifacts/112721340/628306709/102cc8ee8286496275f91b42827e86ae?Expires=1699211300&GoogleAccessId=gorilla-files-url-signer-man%40wandb-production.iam.gserviceaccount.com&Signature=LFm1xDTSK8GqAoFfKYQRGLO1pTEJRH5twY4y6lz9hN4muwVVpgOG%2FSaJ%2F4UGIUE7sYK4wPS%2B%2Frt2k7iix8gfP%2FATEzQAOcSlzlfgcjMy8PBb8V55JV3zo1sj1tkFTgGlPNGjzdyBBxuOCNwzEklObf0tURbSBSZm%2Fn9oVy%2BMuBNon%2FEfMCh05ycVgeMSMqJl%2FL5XuPAC%2FodcOb%2FHYFUyIHg5I0RjR8ZkIyeh0a2sbiRKgMOtrkquuKcNZJPA4pUPrslB5t03F1XDFuLvX0zgEabEbW4GMfbtlkQ2MTFTG5OmjIYHNntOJTXCasTJ7ImaEG%2BKY%2FIZRBTsI09Adu3Raw%3D%3D (Caused by NewConnectionError('<urllib3.connection.HTTPSConnection object at 0x2b2b22e08fa0>: Failed to establish a new connection: [Errno 101] Network is unreachable'))

During handling of the above exception, another exception occurred:

Traceback (most recent call last):
  File "/cluster/home/yutang/miniconda3/lib/python3.9/site-packages/wandb/sdk/lib/retry.py", line 131, in __call__
    result = self._call_fn(*args, **kwargs)
  File "/cluster/home/yutang/miniconda3/lib/python3.9/site-packages/wandb/sdk/internal/internal_api.py", line 2580, in upload_file
    raise _e.with_traceback(sys.exc_info()[2])
  File "/cluster/home/yutang/miniconda3/lib/python3.9/site-packages/wandb/sdk/internal/internal_api.py", line 2549, in upload_file
    response = self._upload_file_session.put(
  File "/cluster/home/yutang/miniconda3/lib/python3.9/site-packages/requests/sessions.py", line 647, in put
    return self.request("PUT", url, data=data, **kwargs)
  File "/cluster/home/yutang/miniconda3/lib/python3.9/site-packages/requests/sessions.py", line 587, in request
    resp = self.send(prep, **send_kwargs)
  File "/cluster/home/yutang/miniconda3/lib/python3.9/site-packages/requests/sessions.py", line 701, in send
    r = adapter.send(request, **kwargs)
  File "/cluster/home/yutang/miniconda3/lib/python3.9/site-packages/requests/adapters.py", line 565, in send
    raise ConnectionError(e, request=request)
wandb.sdk.lib.retry.TransientError: None
2023-11-04 20:08:27,127 DEBUG   HandlerThread:70939 [handler.py:handle_request():146] handle_request: keepalive
2023-11-04 20:08:29,283 ERROR   wandb-upload_2:70939 [internal_api.py:upload_file():2556] upload_file exception https://storage.googleapis.com/wandb-artifacts-prod/wandb_artifacts/112721340/628306709/736d2e841e706f032bb0b718411a8b04?Expires=1699211300&GoogleAccessId=gorilla-files-url-signer-man%40wandb-production.iam.gserviceaccount.com&Signature=oqaU%2BaAVxafCwLP3oNOLzbX%2FNUtowVrBhTOa2aZ3TG4EAoTMW80M3xq17U61fNbnkiaDhwWWSSNlZjaM%2BK5Vl1GdBhSdtyrCySenUVsB%2BwGsYLjwOuBULxXPJiQaG9QXtCADtVk02TN0fi4Ppkayyx78PqfHNA7M%2FaOzDoPWpU4h%2BWaeIv67L8k0S%2BMYOVnkI9HsaorIMS9qCAulyk%2F5r6p9Nrzxa4l9UYxRYwQ2cg268Zi0o%2BiWyvzaH9EDFCoON%2BaT90wGWlNR30tBGWginzvX%2BgYis5rJCXi1i5daHyaYmO8wKuGz3WCNy6FDLaWlHn9J0bsCQm1Yp36KdSTJSQ%3D%3D: HTTPSConnectionPool(host='storage.googleapis.com', port=443): Max retries exceeded with url: /wandb-artifacts-prod/wandb_artifacts/112721340/628306709/736d2e841e706f032bb0b718411a8b04?Expires=1699211300&GoogleAccessId=gorilla-files-url-signer-man%40wandb-production.iam.gserviceaccount.com&Signature=oqaU%2BaAVxafCwLP3oNOLzbX%2FNUtowVrBhTOa2aZ3TG4EAoTMW80M3xq17U61fNbnkiaDhwWWSSNlZjaM%2BK5Vl1GdBhSdtyrCySenUVsB%2BwGsYLjwOuBULxXPJiQaG9QXtCADtVk02TN0fi4Ppkayyx78PqfHNA7M%2FaOzDoPWpU4h%2BWaeIv67L8k0S%2BMYOVnkI9HsaorIMS9qCAulyk%2F5r6p9Nrzxa4l9UYxRYwQ2cg268Zi0o%2BiWyvzaH9EDFCoON%2BaT90wGWlNR30tBGWginzvX%2BgYis5rJCXi1i5daHyaYmO8wKuGz3WCNy6FDLaWlHn9J0bsCQm1Yp36KdSTJSQ%3D%3D (Caused by NewConnectionError('<urllib3.connection.HTTPSConnection object at 0x2b2b22e26550>: Failed to establish a new connection: [Errno 101] Network is unreachable'))
2023-11-04 20:08:29,283 ERROR   wandb-upload_2:70939 [internal_api.py:upload_file():2558] upload_file request headers: {'User-Agent': 'python-requests/2.28.1', 'Accept-Encoding': 'gzip, deflate, br', 'Accept': '*/*', 'Connection': 'keep-alive', 'Content-MD5': 'c20uhB5wbwMrsLcYQRqLBA==', 'Content-Type': 'application/json', 'Content-Length': '648'}
2023-11-04 20:08:29,283 ERROR   wandb-upload_2:70939 [internal_api.py:upload_file():2560] upload_file response body: 
2023-11-04 20:08:29,298 ERROR   wandb-upload_1:70939 [internal_api.py:upload_file():2556] upload_file exception https://storage.googleapis.com/wandb-artifacts-prod/wandb_artifacts/112721340/628306709/102cc8ee8286496275f91b42827e86ae?Expires=1699211300&GoogleAccessId=gorilla-files-url-signer-man%40wandb-production.iam.gserviceaccount.com&Signature=LFm1xDTSK8GqAoFfKYQRGLO1pTEJRH5twY4y6lz9hN4muwVVpgOG%2FSaJ%2F4UGIUE7sYK4wPS%2B%2Frt2k7iix8gfP%2FATEzQAOcSlzlfgcjMy8PBb8V55JV3zo1sj1tkFTgGlPNGjzdyBBxuOCNwzEklObf0tURbSBSZm%2Fn9oVy%2BMuBNon%2FEfMCh05ycVgeMSMqJl%2FL5XuPAC%2FodcOb%2FHYFUyIHg5I0RjR8ZkIyeh0a2sbiRKgMOtrkquuKcNZJPA4pUPrslB5t03F1XDFuLvX0zgEabEbW4GMfbtlkQ2MTFTG5OmjIYHNntOJTXCasTJ7ImaEG%2BKY%2FIZRBTsI09Adu3Raw%3D%3D: HTTPSConnectionPool(host='storage.googleapis.com', port=443): Max retries exceeded with url: /wandb-artifacts-prod/wandb_artifacts/112721340/628306709/102cc8ee8286496275f91b42827e86ae?Expires=1699211300&GoogleAccessId=gorilla-files-url-signer-man%40wandb-production.iam.gserviceaccount.com&Signature=LFm1xDTSK8GqAoFfKYQRGLO1pTEJRH5twY4y6lz9hN4muwVVpgOG%2FSaJ%2F4UGIUE7sYK4wPS%2B%2Frt2k7iix8gfP%2FATEzQAOcSlzlfgcjMy8PBb8V55JV3zo1sj1tkFTgGlPNGjzdyBBxuOCNwzEklObf0tURbSBSZm%2Fn9oVy%2BMuBNon%2FEfMCh05ycVgeMSMqJl%2FL5XuPAC%2FodcOb%2FHYFUyIHg5I0RjR8ZkIyeh0a2sbiRKgMOtrkquuKcNZJPA4pUPrslB5t03F1XDFuLvX0zgEabEbW4GMfbtlkQ2MTFTG5OmjIYHNntOJTXCasTJ7ImaEG%2BKY%2FIZRBTsI09Adu3Raw%3D%3D (Caused by NewConnectionError('<urllib3.connection.HTTPSConnection object at 0x2b2b22e26dc0>: Failed to establish a new connection: [Errno 101] Network is unreachable'))
2023-11-04 20:08:29,298 ERROR   wandb-upload_1:70939 [internal_api.py:upload_file():2558] upload_file request headers: {'User-Agent': 'python-requests/2.28.1', 'Accept-Encoding': 'gzip, deflate, br', 'Accept': '*/*', 'Connection': 'keep-alive', 'Content-MD5': 'ECzI7oKGSWJ1+RtCgn6Grg==', 'Content-Type': 'text/plain; charset=utf-8', 'Content-Length': '1756'}
2023-11-04 20:08:29,298 ERROR   wandb-upload_1:70939 [internal_api.py:upload_file():2560] upload_file response body: 
2023-11-04 20:08:32,129 DEBUG   HandlerThread:70939 [handler.py:handle_request():146] handle_request: keepalive
2023-11-04 20:08:37,131 DEBUG   HandlerThread:70939 [handler.py:handle_request():146] handle_request: keepalive
2023-11-04 20:08:37,472 ERROR   wandb-upload_2:70939 [internal_api.py:upload_file():2556] upload_file exception https://storage.googleapis.com/wandb-artifacts-prod/wandb_artifacts/112721340/628306709/736d2e841e706f032bb0b718411a8b04?Expires=1699211300&GoogleAccessId=gorilla-files-url-signer-man%40wandb-production.iam.gserviceaccount.com&Signature=oqaU%2BaAVxafCwLP3oNOLzbX%2FNUtowVrBhTOa2aZ3TG4EAoTMW80M3xq17U61fNbnkiaDhwWWSSNlZjaM%2BK5Vl1GdBhSdtyrCySenUVsB%2BwGsYLjwOuBULxXPJiQaG9QXtCADtVk02TN0fi4Ppkayyx78PqfHNA7M%2FaOzDoPWpU4h%2BWaeIv67L8k0S%2BMYOVnkI9HsaorIMS9qCAulyk%2F5r6p9Nrzxa4l9UYxRYwQ2cg268Zi0o%2BiWyvzaH9EDFCoON%2BaT90wGWlNR30tBGWginzvX%2BgYis5rJCXi1i5daHyaYmO8wKuGz3WCNy6FDLaWlHn9J0bsCQm1Yp36KdSTJSQ%3D%3D: HTTPSConnectionPool(host='storage.googleapis.com', port=443): Max retries exceeded with url: /wandb-artifacts-prod/wandb_artifacts/112721340/628306709/736d2e841e706f032bb0b718411a8b04?Expires=1699211300&GoogleAccessId=gorilla-files-url-signer-man%40wandb-production.iam.gserviceaccount.com&Signature=oqaU%2BaAVxafCwLP3oNOLzbX%2FNUtowVrBhTOa2aZ3TG4EAoTMW80M3xq17U61fNbnkiaDhwWWSSNlZjaM%2BK5Vl1GdBhSdtyrCySenUVsB%2BwGsYLjwOuBULxXPJiQaG9QXtCADtVk02TN0fi4Ppkayyx78PqfHNA7M%2FaOzDoPWpU4h%2BWaeIv67L8k0S%2BMYOVnkI9HsaorIMS9qCAulyk%2F5r6p9Nrzxa4l9UYxRYwQ2cg268Zi0o%2BiWyvzaH9EDFCoON%2BaT90wGWlNR30tBGWginzvX%2BgYis5rJCXi1i5daHyaYmO8wKuGz3WCNy6FDLaWlHn9J0bsCQm1Yp36KdSTJSQ%3D%3D (Caused by NewConnectionError('<urllib3.connection.HTTPSConnection object at 0x2b2b22e2a5e0>: Failed to establish a new connection: [Errno 101] Network is unreachable'))
2023-11-04 20:08:37,472 ERROR   wandb-upload_2:70939 [internal_api.py:upload_file():2558] upload_file request headers: {'User-Agent': 'python-requests/2.28.1', 'Accept-Encoding': 'gzip, deflate, br', 'Accept': '*/*', 'Connection': 'keep-alive', 'Content-MD5': 'c20uhB5wbwMrsLcYQRqLBA==', 'Content-Type': 'application/json', 'Content-Length': '648'}
2023-11-04 20:08:37,472 ERROR   wandb-upload_2:70939 [internal_api.py:upload_file():2560] upload_file response body: 
2023-11-04 20:08:39,072 ERROR   wandb-upload_1:70939 [internal_api.py:upload_file():2556] upload_file exception https://storage.googleapis.com/wandb-artifacts-prod/wandb_artifacts/112721340/628306709/102cc8ee8286496275f91b42827e86ae?Expires=1699211300&GoogleAccessId=gorilla-files-url-signer-man%40wandb-production.iam.gserviceaccount.com&Signature=LFm1xDTSK8GqAoFfKYQRGLO1pTEJRH5twY4y6lz9hN4muwVVpgOG%2FSaJ%2F4UGIUE7sYK4wPS%2B%2Frt2k7iix8gfP%2FATEzQAOcSlzlfgcjMy8PBb8V55JV3zo1sj1tkFTgGlPNGjzdyBBxuOCNwzEklObf0tURbSBSZm%2Fn9oVy%2BMuBNon%2FEfMCh05ycVgeMSMqJl%2FL5XuPAC%2FodcOb%2FHYFUyIHg5I0RjR8ZkIyeh0a2sbiRKgMOtrkquuKcNZJPA4pUPrslB5t03F1XDFuLvX0zgEabEbW4GMfbtlkQ2MTFTG5OmjIYHNntOJTXCasTJ7ImaEG%2BKY%2FIZRBTsI09Adu3Raw%3D%3D: HTTPSConnectionPool(host='storage.googleapis.com', port=443): Max retries exceeded with url: /wandb-artifacts-prod/wandb_artifacts/112721340/628306709/102cc8ee8286496275f91b42827e86ae?Expires=1699211300&GoogleAccessId=gorilla-files-url-signer-man%40wandb-production.iam.gserviceaccount.com&Signature=LFm1xDTSK8GqAoFfKYQRGLO1pTEJRH5twY4y6lz9hN4muwVVpgOG%2FSaJ%2F4UGIUE7sYK4wPS%2B%2Frt2k7iix8gfP%2FATEzQAOcSlzlfgcjMy8PBb8V55JV3zo1sj1tkFTgGlPNGjzdyBBxuOCNwzEklObf0tURbSBSZm%2Fn9oVy%2BMuBNon%2FEfMCh05ycVgeMSMqJl%2FL5XuPAC%2FodcOb%2FHYFUyIHg5I0RjR8ZkIyeh0a2sbiRKgMOtrkquuKcNZJPA4pUPrslB5t03F1XDFuLvX0zgEabEbW4GMfbtlkQ2MTFTG5OmjIYHNntOJTXCasTJ7ImaEG%2BKY%2FIZRBTsI09Adu3Raw%3D%3D (Caused by NewConnectionError('<urllib3.connection.HTTPSConnection object at 0x2b2b22e26550>: Failed to establish a new connection: [Errno 101] Network is unreachable'))
2023-11-04 20:08:39,072 ERROR   wandb-upload_1:70939 [internal_api.py:upload_file():2558] upload_file request headers: {'User-Agent': 'python-requests/2.28.1', 'Accept-Encoding': 'gzip, deflate, br', 'Accept': '*/*', 'Connection': 'keep-alive', 'Content-MD5': 'ECzI7oKGSWJ1+RtCgn6Grg==', 'Content-Type': 'text/plain; charset=utf-8', 'Content-Length': '1756'}
2023-11-04 20:08:39,072 ERROR   wandb-upload_1:70939 [internal_api.py:upload_file():2560] upload_file response body: 
2023-11-04 20:08:42,132 DEBUG   HandlerThread:70939 [handler.py:handle_request():146] handle_request: keepalive
2023-11-04 20:08:47,134 DEBUG   HandlerThread:70939 [handler.py:handle_request():146] handle_request: keepalive
2023-11-04 20:08:52,136 DEBUG   HandlerThread:70939 [handler.py:handle_request():146] handle_request: keepalive
2023-11-04 20:08:55,656 ERROR   wandb-upload_2:70939 [internal_api.py:upload_file():2556] upload_file exception https://storage.googleapis.com/wandb-artifacts-prod/wandb_artifacts/112721340/628306709/736d2e841e706f032bb0b718411a8b04?Expires=1699211300&GoogleAccessId=gorilla-files-url-signer-man%40wandb-production.iam.gserviceaccount.com&Signature=oqaU%2BaAVxafCwLP3oNOLzbX%2FNUtowVrBhTOa2aZ3TG4EAoTMW80M3xq17U61fNbnkiaDhwWWSSNlZjaM%2BK5Vl1GdBhSdtyrCySenUVsB%2BwGsYLjwOuBULxXPJiQaG9QXtCADtVk02TN0fi4Ppkayyx78PqfHNA7M%2FaOzDoPWpU4h%2BWaeIv67L8k0S%2BMYOVnkI9HsaorIMS9qCAulyk%2F5r6p9Nrzxa4l9UYxRYwQ2cg268Zi0o%2BiWyvzaH9EDFCoON%2BaT90wGWlNR30tBGWginzvX%2BgYis5rJCXi1i5daHyaYmO8wKuGz3WCNy6FDLaWlHn9J0bsCQm1Yp36KdSTJSQ%3D%3D: HTTPSConnectionPool(host='storage.googleapis.com', port=443): Max retries exceeded with url: /wandb-artifacts-prod/wandb_artifacts/112721340/628306709/736d2e841e706f032bb0b718411a8b04?Expires=1699211300&GoogleAccessId=gorilla-files-url-signer-man%40wandb-production.iam.gserviceaccount.com&Signature=oqaU%2BaAVxafCwLP3oNOLzbX%2FNUtowVrBhTOa2aZ3TG4EAoTMW80M3xq17U61fNbnkiaDhwWWSSNlZjaM%2BK5Vl1GdBhSdtyrCySenUVsB%2BwGsYLjwOuBULxXPJiQaG9QXtCADtVk02TN0fi4Ppkayyx78PqfHNA7M%2FaOzDoPWpU4h%2BWaeIv67L8k0S%2BMYOVnkI9HsaorIMS9qCAulyk%2F5r6p9Nrzxa4l9UYxRYwQ2cg268Zi0o%2BiWyvzaH9EDFCoON%2BaT90wGWlNR30tBGWginzvX%2BgYis5rJCXi1i5daHyaYmO8wKuGz3WCNy6FDLaWlHn9J0bsCQm1Yp36KdSTJSQ%3D%3D (Caused by NewConnectionError('<urllib3.connection.HTTPSConnection object at 0x2b2b22e08f10>: Failed to establish a new connection: [Errno 101] Network is unreachable'))
2023-11-04 20:08:55,656 ERROR   wandb-upload_2:70939 [internal_api.py:upload_file():2558] upload_file request headers: {'User-Agent': 'python-requests/2.28.1', 'Accept-Encoding': 'gzip, deflate, br', 'Accept': '*/*', 'Connection': 'keep-alive', 'Content-MD5': 'c20uhB5wbwMrsLcYQRqLBA==', 'Content-Type': 'application/json', 'Content-Length': '648'}
2023-11-04 20:08:55,656 ERROR   wandb-upload_2:70939 [internal_api.py:upload_file():2560] upload_file response body: 
2023-11-04 20:08:55,718 ERROR   wandb-upload_1:70939 [internal_api.py:upload_file():2556] upload_file exception https://storage.googleapis.com/wandb-artifacts-prod/wandb_artifacts/112721340/628306709/102cc8ee8286496275f91b42827e86ae?Expires=1699211300&GoogleAccessId=gorilla-files-url-signer-man%40wandb-production.iam.gserviceaccount.com&Signature=LFm1xDTSK8GqAoFfKYQRGLO1pTEJRH5twY4y6lz9hN4muwVVpgOG%2FSaJ%2F4UGIUE7sYK4wPS%2B%2Frt2k7iix8gfP%2FATEzQAOcSlzlfgcjMy8PBb8V55JV3zo1sj1tkFTgGlPNGjzdyBBxuOCNwzEklObf0tURbSBSZm%2Fn9oVy%2BMuBNon%2FEfMCh05ycVgeMSMqJl%2FL5XuPAC%2FodcOb%2FHYFUyIHg5I0RjR8ZkIyeh0a2sbiRKgMOtrkquuKcNZJPA4pUPrslB5t03F1XDFuLvX0zgEabEbW4GMfbtlkQ2MTFTG5OmjIYHNntOJTXCasTJ7ImaEG%2BKY%2FIZRBTsI09Adu3Raw%3D%3D: HTTPSConnectionPool(host='storage.googleapis.com', port=443): Max retries exceeded with url: /wandb-artifacts-prod/wandb_artifacts/112721340/628306709/102cc8ee8286496275f91b42827e86ae?Expires=1699211300&GoogleAccessId=gorilla-files-url-signer-man%40wandb-production.iam.gserviceaccount.com&Signature=LFm1xDTSK8GqAoFfKYQRGLO1pTEJRH5twY4y6lz9hN4muwVVpgOG%2FSaJ%2F4UGIUE7sYK4wPS%2B%2Frt2k7iix8gfP%2FATEzQAOcSlzlfgcjMy8PBb8V55JV3zo1sj1tkFTgGlPNGjzdyBBxuOCNwzEklObf0tURbSBSZm%2Fn9oVy%2BMuBNon%2FEfMCh05ycVgeMSMqJl%2FL5XuPAC%2FodcOb%2FHYFUyIHg5I0RjR8ZkIyeh0a2sbiRKgMOtrkquuKcNZJPA4pUPrslB5t03F1XDFuLvX0zgEabEbW4GMfbtlkQ2MTFTG5OmjIYHNntOJTXCasTJ7ImaEG%2BKY%2FIZRBTsI09Adu3Raw%3D%3D (Caused by NewConnectionError('<urllib3.connection.HTTPSConnection object at 0x2b2b22e10fa0>: Failed to establish a new connection: [Errno 101] Network is unreachable'))
2023-11-04 20:08:55,718 ERROR   wandb-upload_1:70939 [internal_api.py:upload_file():2558] upload_file request headers: {'User-Agent': 'python-requests/2.28.1', 'Accept-Encoding': 'gzip, deflate, br', 'Accept': '*/*', 'Connection': 'keep-alive', 'Content-MD5': 'ECzI7oKGSWJ1+RtCgn6Grg==', 'Content-Type': 'text/plain; charset=utf-8', 'Content-Length': '1756'}
2023-11-04 20:08:55,718 ERROR   wandb-upload_1:70939 [internal_api.py:upload_file():2560] upload_file response body: 
2023-11-04 20:08:56,624 ERROR   wandb-upload_0:70939 [internal_api.py:upload_file():2556] upload_file exception https://storage.googleapis.com/wandb-production.appspot.com/bryanttang/DKT-trial%201/6vrr841v/wandb-metadata.json?Expires=1699211268&GoogleAccessId=gorilla-files-url-signer-man%40wandb-production.iam.gserviceaccount.com&Signature=vdJEEcja8gjpAmCYudZAM3SaB%2Byil1rBe9Vpxz%2BDL2Oqckxw3FSjQxnGcmgh4WEdL3tq5mqqLlj8KBjtBOrb61BC7vq8bJfWJV9Ckjq3ju3JHcFpTJF8fKLny2uH7KJrTdYogD70%2FGbPqkc7oyL9G1mxlrAD5Svj3zfHGI0Ztpk0OEk1%2F81uRhQt%2FgxnsGAPMM24kS5RX4RtNOdAsIHEOP7uh4se9mMPh%2BiOskiBLEA7U%2B8gNc%2FpFrVNFuK%2FUtWT0ZHMSYbmiez4gG2JVyRQ3Tq8AXZWbyuu9FsKJzQ90MOdYMyQfLPsM6Iso%2ByBeYDY%2FQbdukgbltoecr8LWUUkyg%3D%3D: HTTPSConnectionPool(host='storage.googleapis.com', port=443): Max retries exceeded with url: /wandb-production.appspot.com/bryanttang/DKT-trial%201/6vrr841v/wandb-metadata.json?Expires=1699211268&GoogleAccessId=gorilla-files-url-signer-man%40wandb-production.iam.gserviceaccount.com&Signature=vdJEEcja8gjpAmCYudZAM3SaB%2Byil1rBe9Vpxz%2BDL2Oqckxw3FSjQxnGcmgh4WEdL3tq5mqqLlj8KBjtBOrb61BC7vq8bJfWJV9Ckjq3ju3JHcFpTJF8fKLny2uH7KJrTdYogD70%2FGbPqkc7oyL9G1mxlrAD5Svj3zfHGI0Ztpk0OEk1%2F81uRhQt%2FgxnsGAPMM24kS5RX4RtNOdAsIHEOP7uh4se9mMPh%2BiOskiBLEA7U%2B8gNc%2FpFrVNFuK%2FUtWT0ZHMSYbmiez4gG2JVyRQ3Tq8AXZWbyuu9FsKJzQ90MOdYMyQfLPsM6Iso%2ByBeYDY%2FQbdukgbltoecr8LWUUkyg%3D%3D (Caused by NewConnectionError('<urllib3.connection.HTTPSConnection object at 0x2b2b22e10b80>: Failed to establish a new connection: [Errno 101] Network is unreachable'))
2023-11-04 20:08:56,624 ERROR   wandb-upload_0:70939 [internal_api.py:upload_file():2558] upload_file request headers: {'User-Agent': 'python-requests/2.28.1', 'Accept-Encoding': 'gzip, deflate, br', 'Accept': '*/*', 'Connection': 'keep-alive', 'Content-Length': '14811'}
2023-11-04 20:08:56,624 ERROR   wandb-upload_0:70939 [internal_api.py:upload_file():2560] upload_file response body: 
2023-11-04 20:08:57,138 DEBUG   HandlerThread:70939 [handler.py:handle_request():146] handle_request: keepalive
2023-11-04 20:09:02,139 DEBUG   HandlerThread:70939 [handler.py:handle_request():146] handle_request: keepalive
2023-11-04 20:09:07,141 DEBUG   HandlerThread:70939 [handler.py:handle_request():146] handle_request: keepalive
2023-11-04 20:09:12,142 DEBUG   HandlerThread:70939 [handler.py:handle_request():146] handle_request: keepalive
2023-11-04 20:09:17,145 DEBUG   HandlerThread:70939 [handler.py:handle_request():146] handle_request: keepalive
2023-11-04 20:09:22,146 DEBUG   HandlerThread:70939 [handler.py:handle_request():146] handle_request: keepalive
