2023-12-15 17:27:09,294 INFO    StreamThr :10647 [internal.py:wandb_internal():86] W&B internal server running at pid: 10647, started at: 2023-12-15 17:27:09.293504
2023-12-15 17:27:09,296 DEBUG   HandlerThread:10647 [handler.py:handle_request():146] handle_request: status
2023-12-15 17:27:09,298 INFO    WriterThread:10647 [datastore.py:open_for_write():85] open: /cluster/home/yutang/Deep-Knowledge-Tracing/DKT/KnowledgeTracing/evaluation/wandb/run-20231215_172709-9eekgqhp/run-9eekgqhp.wandb
2023-12-15 17:27:09,300 DEBUG   SenderThread:10647 [sender.py:send():380] send: header
2023-12-15 17:27:09,326 DEBUG   SenderThread:10647 [sender.py:send():380] send: run
2023-12-15 17:27:09,760 INFO    SenderThread:10647 [dir_watcher.py:__init__():211] watching files in: /cluster/home/yutang/Deep-Knowledge-Tracing/DKT/KnowledgeTracing/evaluation/wandb/run-20231215_172709-9eekgqhp/files
2023-12-15 17:27:09,760 INFO    SenderThread:10647 [sender.py:_start_run_threads():1122] run started: 9eekgqhp with start time 1702657629.294624
2023-12-15 17:27:09,774 DEBUG   HandlerThread:10647 [handler.py:handle_request():146] handle_request: check_version
2023-12-15 17:27:09,774 DEBUG   SenderThread:10647 [sender.py:send_request():407] send_request: check_version
2023-12-15 17:27:09,842 DEBUG   HandlerThread:10647 [handler.py:handle_request():146] handle_request: run_start
2023-12-15 17:27:09,852 DEBUG   HandlerThread:10647 [system_info.py:__init__():32] System info init
2023-12-15 17:27:09,852 DEBUG   HandlerThread:10647 [system_info.py:__init__():47] System info init done
2023-12-15 17:27:09,852 INFO    HandlerThread:10647 [system_monitor.py:start():194] Starting system monitor
2023-12-15 17:27:09,852 INFO    SystemMonitor:10647 [system_monitor.py:_start():158] Starting system asset monitoring threads
2023-12-15 17:27:09,852 INFO    HandlerThread:10647 [system_monitor.py:probe():214] Collecting system info
2023-12-15 17:27:09,859 INFO    SystemMonitor:10647 [interfaces.py:start():190] Started cpu monitoring
2023-12-15 17:27:09,860 INFO    SystemMonitor:10647 [interfaces.py:start():190] Started disk monitoring
2023-12-15 17:27:09,864 INFO    SystemMonitor:10647 [interfaces.py:start():190] Started gpu monitoring
2023-12-15 17:27:09,868 INFO    SystemMonitor:10647 [interfaces.py:start():190] Started memory monitoring
2023-12-15 17:27:09,868 INFO    SystemMonitor:10647 [interfaces.py:start():190] Started network monitoring
2023-12-15 17:27:09,900 DEBUG   HandlerThread:10647 [system_info.py:probe():196] Probing system
2023-12-15 17:27:09,906 DEBUG   HandlerThread:10647 [system_info.py:_probe_git():181] Probing git
2023-12-15 17:27:09,928 DEBUG   HandlerThread:10647 [system_info.py:_probe_git():189] Probing git done
2023-12-15 17:27:09,928 DEBUG   HandlerThread:10647 [system_info.py:probe():244] Probing system done
2023-12-15 17:27:09,928 DEBUG   HandlerThread:10647 [system_monitor.py:probe():223] {'os': 'Linux-3.10.0-1160.102.1.el7.x86_64-x86_64-with-glibc2.17', 'python': '3.9.16', 'heartbeatAt': '2023-12-15T16:27:09.900880', 'startedAt': '2023-12-15T16:27:09.281401', 'docker': None, 'cuda': None, 'args': (), 'state': 'running', 'program': '/cluster/home/yutang/Deep-Knowledge-Tracing/DKT/KnowledgeTracing/evaluation/./run.py', 'codePathLocal': 'run.py', 'codePath': 'DKT/KnowledgeTracing/evaluation/run.py', 'git': {'remote': 'https://github.com/Bryanttt-tang/Deep-Knowledge-Tracing.git', 'commit': 'accff8eed41d068b8d87513cc471c3143a1140c6'}, 'email': 'tangyu990628@gmail.com', 'root': '/cluster/home/yutang/Deep-Knowledge-Tracing', 'host': 'eu-g4-001', 'username': 'yutang', 'executable': '/cluster/home/yutang/miniconda3/bin/python', 'cpu_count': 128, 'cpu_count_logical': 128, 'cpu_freq': {'current': 1699.21875, 'min': 1500.0, 'max': 2250.0}, 'cpu_freq_per_core': [{'current': 2000.0, 'min': 1500.0, 'max': 2250.0}, {'current': 2000.0, 'min': 1500.0, 'max': 2250.0}, {'current': 1500.0, 'min': 1500.0, 'max': 2250.0}, {'current': 2250.0, 'min': 1500.0, 'max': 2250.0}, {'current': 1500.0, 'min': 1500.0, 'max': 2250.0}, {'current': 2000.0, 'min': 1500.0, 'max': 2250.0}, {'current': 2000.0, 'min': 1500.0, 'max': 2250.0}, {'current': 2000.0, 'min': 1500.0, 'max': 2250.0}, {'current': 2000.0, 'min': 1500.0, 'max': 2250.0}, {'current': 2000.0, 'min': 1500.0, 'max': 2250.0}, {'current': 2000.0, 'min': 1500.0, 'max': 2250.0}, {'current': 2000.0, 'min': 1500.0, 'max': 2250.0}, {'current': 2000.0, 'min': 1500.0, 'max': 2250.0}, {'current': 2000.0, 'min': 1500.0, 'max': 2250.0}, {'current': 1500.0, 'min': 1500.0, 'max': 2250.0}, {'current': 1500.0, 'min': 1500.0, 'max': 2250.0}, {'current': 2250.0, 'min': 1500.0, 'max': 2250.0}, {'current': 2000.0, 'min': 1500.0, 'max': 2250.0}, {'current': 1500.0, 'min': 1500.0, 'max': 2250.0}, {'current': 1500.0, 'min': 1500.0, 'max': 2250.0}, {'current': 2000.0, 'min': 1500.0, 'max': 2250.0}, {'current': 1500.0, 'min': 1500.0, 'max': 2250.0}, {'current': 2250.0, 'min': 1500.0, 'max': 2250.0}, {'current': 2000.0, 'min': 1500.0, 'max': 2250.0}, {'current': 1500.0, 'min': 1500.0, 'max': 2250.0}, {'current': 1500.0, 'min': 1500.0, 'max': 2250.0}, {'current': 1500.0, 'min': 1500.0, 'max': 2250.0}, {'current': 2000.0, 'min': 1500.0, 'max': 2250.0}, {'current': 2000.0, 'min': 1500.0, 'max': 2250.0}, {'current': 1500.0, 'min': 1500.0, 'max': 2250.0}, {'current': 2000.0, 'min': 1500.0, 'max': 2250.0}, {'current': 2250.0, 'min': 1500.0, 'max': 2250.0}, {'current': 1500.0, 'min': 1500.0, 'max': 2250.0}, {'current': 1500.0, 'min': 1500.0, 'max': 2250.0}, {'current': 1500.0, 'min': 1500.0, 'max': 2250.0}, {'current': 1500.0, 'min': 1500.0, 'max': 2250.0}, {'current': 1500.0, 'min': 1500.0, 'max': 2250.0}, {'current': 1500.0, 'min': 1500.0, 'max': 2250.0}, {'current': 1500.0, 'min': 1500.0, 'max': 2250.0}, {'current': 1500.0, 'min': 1500.0, 'max': 2250.0}, {'current': 1500.0, 'min': 1500.0, 'max': 2250.0}, {'current': 1500.0, 'min': 1500.0, 'max': 2250.0}, {'current': 1500.0, 'min': 1500.0, 'max': 2250.0}, {'current': 1500.0, 'min': 1500.0, 'max': 2250.0}, {'current': 1500.0, 'min': 1500.0, 'max': 2250.0}, {'current': 1500.0, 'min': 1500.0, 'max': 2250.0}, {'current': 1500.0, 'min': 1500.0, 'max': 2250.0}, {'current': 1500.0, 'min': 1500.0, 'max': 2250.0}, {'current': 1500.0, 'min': 1500.0, 'max': 2250.0}, {'current': 1500.0, 'min': 1500.0, 'max': 2250.0}, {'current': 1500.0, 'min': 1500.0, 'max': 2250.0}, {'current': 1500.0, 'min': 1500.0, 'max': 2250.0}, {'current': 1500.0, 'min': 1500.0, 'max': 2250.0}, {'current': 1500.0, 'min': 1500.0, 'max': 2250.0}, {'current': 2000.0, 'min': 1500.0, 'max': 2250.0}, {'current': 1500.0, 'min': 1500.0, 'max': 2250.0}, {'current': 1500.0, 'min': 1500.0, 'max': 2250.0}, {'current': 1500.0, 'min': 1500.0, 'max': 2250.0}, {'current': 1500.0, 'min': 1500.0, 'max': 2250.0}, {'current': 1500.0, 'min': 1500.0, 'max': 2250.0}, {'current': 1500.0, 'min': 1500.0, 'max': 2250.0}, {'current': 1500.0, 'min': 1500.0, 'max': 2250.0}, {'current': 1500.0, 'min': 1500.0, 'max': 2250.0}, {'current': 1500.0, 'min': 1500.0, 'max': 2250.0}, {'current': 1500.0, 'min': 1500.0, 'max': 2250.0}, {'current': 2000.0, 'min': 1500.0, 'max': 2250.0}, {'current': 2250.0, 'min': 1500.0, 'max': 2250.0}, {'current': 1500.0, 'min': 1500.0, 'max': 2250.0}, {'current': 2000.0, 'min': 1500.0, 'max': 2250.0}, {'current': 2000.0, 'min': 1500.0, 'max': 2250.0}, {'current': 1500.0, 'min': 1500.0, 'max': 2250.0}, {'current': 2000.0, 'min': 1500.0, 'max': 2250.0}, {'current': 1500.0, 'min': 1500.0, 'max': 2250.0}, {'current': 1500.0, 'min': 1500.0, 'max': 2250.0}, {'current': 2250.0, 'min': 1500.0, 'max': 2250.0}, {'current': 2250.0, 'min': 1500.0, 'max': 2250.0}, {'current': 2250.0, 'min': 1500.0, 'max': 2250.0}, {'current': 2250.0, 'min': 1500.0, 'max': 2250.0}, {'current': 2250.0, 'min': 1500.0, 'max': 2250.0}, {'current': 2250.0, 'min': 1500.0, 'max': 2250.0}, {'current': 1500.0, 'min': 1500.0, 'max': 2250.0}, {'current': 1500.0, 'min': 1500.0, 'max': 2250.0}, {'current': 1500.0, 'min': 1500.0, 'max': 2250.0}, {'current': 1500.0, 'min': 1500.0, 'max': 2250.0}, {'current': 1500.0, 'min': 1500.0, 'max': 2250.0}, {'current': 2000.0, 'min': 1500.0, 'max': 2250.0}, {'current': 2000.0, 'min': 1500.0, 'max': 2250.0}, {'current': 2000.0, 'min': 1500.0, 'max': 2250.0}, {'current': 1500.0, 'min': 1500.0, 'max': 2250.0}, {'current': 1500.0, 'min': 1500.0, 'max': 2250.0}, {'current': 2000.0, 'min': 1500.0, 'max': 2250.0}, {'current': 2000.0, 'min': 1500.0, 'max': 2250.0}, {'current': 2250.0, 'min': 1500.0, 'max': 2250.0}, {'current': 2000.0, 'min': 1500.0, 'max': 2250.0}, {'current': 2000.0, 'min': 1500.0, 'max': 2250.0}, {'current': 2000.0, 'min': 1500.0, 'max': 2250.0}, {'current': 1500.0, 'min': 1500.0, 'max': 2250.0}, {'current': 1500.0, 'min': 1500.0, 'max': 2250.0}, {'current': 1500.0, 'min': 1500.0, 'max': 2250.0}, {'current': 1500.0, 'min': 1500.0, 'max': 2250.0}, {'current': 1500.0, 'min': 1500.0, 'max': 2250.0}, {'current': 1500.0, 'min': 1500.0, 'max': 2250.0}, {'current': 1500.0, 'min': 1500.0, 'max': 2250.0}, {'current': 1500.0, 'min': 1500.0, 'max': 2250.0}, {'current': 1500.0, 'min': 1500.0, 'max': 2250.0}, {'current': 1500.0, 'min': 1500.0, 'max': 2250.0}, {'current': 1500.0, 'min': 1500.0, 'max': 2250.0}, {'current': 1500.0, 'min': 1500.0, 'max': 2250.0}, {'current': 1500.0, 'min': 1500.0, 'max': 2250.0}, {'current': 1500.0, 'min': 1500.0, 'max': 2250.0}, {'current': 1500.0, 'min': 1500.0, 'max': 2250.0}, {'current': 1500.0, 'min': 1500.0, 'max': 2250.0}, {'current': 1500.0, 'min': 1500.0, 'max': 2250.0}, {'current': 1500.0, 'min': 1500.0, 'max': 2250.0}, {'current': 1500.0, 'min': 1500.0, 'max': 2250.0}, {'current': 1500.0, 'min': 1500.0, 'max': 2250.0}, {'current': 1500.0, 'min': 1500.0, 'max': 2250.0}, {'current': 1500.0, 'min': 1500.0, 'max': 2250.0}, {'current': 1500.0, 'min': 1500.0, 'max': 2250.0}, {'current': 1500.0, 'min': 1500.0, 'max': 2250.0}, {'current': 1500.0, 'min': 1500.0, 'max': 2250.0}, {'current': 2250.0, 'min': 1500.0, 'max': 2250.0}, {'current': 1500.0, 'min': 1500.0, 'max': 2250.0}, {'current': 1500.0, 'min': 1500.0, 'max': 2250.0}, {'current': 1500.0, 'min': 1500.0, 'max': 2250.0}, {'current': 1500.0, 'min': 1500.0, 'max': 2250.0}, {'current': 1500.0, 'min': 1500.0, 'max': 2250.0}, {'current': 1500.0, 'min': 1500.0, 'max': 2250.0}], 'disk': {'/': {'total': 10.0, 'used': 4.609809875488281}}, 'gpu': 'NVIDIA GeForce RTX 3090', 'gpu_count': 1, 'gpu_devices': [{'name': 'NVIDIA GeForce RTX 3090', 'memory_total': 25769803776}], 'memory': {'total': 501.51181411743164}}
2023-12-15 17:27:09,929 INFO    HandlerThread:10647 [system_monitor.py:probe():224] Finished collecting system info
2023-12-15 17:27:09,929 INFO    HandlerThread:10647 [system_monitor.py:probe():227] Publishing system info
2023-12-15 17:27:09,929 DEBUG   HandlerThread:10647 [system_info.py:_save_pip():52] Saving list of pip packages installed into the current environment
2023-12-15 17:27:09,930 DEBUG   HandlerThread:10647 [system_info.py:_save_pip():68] Saving pip packages done
2023-12-15 17:27:09,930 DEBUG   HandlerThread:10647 [system_info.py:_save_conda():75] Saving list of conda packages installed into the current environment
2023-12-15 17:27:10,764 INFO    Thread-12 :10647 [dir_watcher.py:_on_file_created():271] file/dir created: /cluster/home/yutang/Deep-Knowledge-Tracing/DKT/KnowledgeTracing/evaluation/wandb/run-20231215_172709-9eekgqhp/files/requirements.txt
2023-12-15 17:27:10,764 INFO    Thread-12 :10647 [dir_watcher.py:_on_file_created():271] file/dir created: /cluster/home/yutang/Deep-Knowledge-Tracing/DKT/KnowledgeTracing/evaluation/wandb/run-20231215_172709-9eekgqhp/files/conda-environment.yaml
2023-12-15 17:27:12,983 DEBUG   HandlerThread:10647 [system_info.py:_save_conda():87] Saving conda packages done
2023-12-15 17:27:12,986 INFO    HandlerThread:10647 [system_monitor.py:probe():229] Finished publishing system info
2023-12-15 17:27:12,991 DEBUG   SenderThread:10647 [sender.py:send():380] send: files
2023-12-15 17:27:12,991 INFO    SenderThread:10647 [sender.py:_save_file():1378] saving file wandb-metadata.json with policy now
2023-12-15 17:27:13,004 DEBUG   SenderThread:10647 [sender.py:send():380] send: telemetry
2023-12-15 17:27:13,044 DEBUG   HandlerThread:10647 [handler.py:handle_request():146] handle_request: stop_status
2023-12-15 17:27:13,044 DEBUG   HandlerThread:10647 [handler.py:handle_request():146] handle_request: internal_messages
2023-12-15 17:27:13,044 DEBUG   SenderThread:10647 [sender.py:send_request():407] send_request: stop_status
2023-12-15 17:27:13,290 DEBUG   SenderThread:10647 [sender.py:send():380] send: exit
2023-12-15 17:27:13,290 INFO    SenderThread:10647 [sender.py:send_exit():585] handling exit code: 1
2023-12-15 17:27:13,290 INFO    SenderThread:10647 [sender.py:send_exit():587] handling runtime: 3
2023-12-15 17:27:13,294 INFO    SenderThread:10647 [sender.py:_save_file():1378] saving file wandb-summary.json with policy end
2023-12-15 17:27:13,294 INFO    SenderThread:10647 [sender.py:send_exit():593] send defer
2023-12-15 17:27:13,295 DEBUG   HandlerThread:10647 [handler.py:handle_request():146] handle_request: defer
2023-12-15 17:27:13,295 INFO    HandlerThread:10647 [handler.py:handle_request_defer():172] handle defer: 0
2023-12-15 17:27:13,298 DEBUG   SenderThread:10647 [sender.py:send_request():407] send_request: defer
2023-12-15 17:27:13,298 INFO    SenderThread:10647 [sender.py:send_request_defer():609] handle sender defer: 0
2023-12-15 17:27:13,298 INFO    SenderThread:10647 [sender.py:transition_state():613] send defer: 1
2023-12-15 17:27:13,299 DEBUG   HandlerThread:10647 [handler.py:handle_request():146] handle_request: defer
2023-12-15 17:27:13,299 INFO    HandlerThread:10647 [handler.py:handle_request_defer():172] handle defer: 1
2023-12-15 17:27:13,299 DEBUG   SenderThread:10647 [sender.py:send_request():407] send_request: defer
2023-12-15 17:27:13,299 INFO    SenderThread:10647 [sender.py:send_request_defer():609] handle sender defer: 1
2023-12-15 17:27:13,299 INFO    SenderThread:10647 [sender.py:transition_state():613] send defer: 2
2023-12-15 17:27:13,299 DEBUG   HandlerThread:10647 [handler.py:handle_request():146] handle_request: defer
2023-12-15 17:27:13,299 INFO    HandlerThread:10647 [handler.py:handle_request_defer():172] handle defer: 2
2023-12-15 17:27:13,299 INFO    HandlerThread:10647 [system_monitor.py:finish():203] Stopping system monitor
2023-12-15 17:27:13,299 DEBUG   SystemMonitor:10647 [system_monitor.py:_start():172] Starting system metrics aggregation loop
2023-12-15 17:27:13,299 DEBUG   SystemMonitor:10647 [system_monitor.py:_start():179] Finished system metrics aggregation loop
2023-12-15 17:27:13,300 DEBUG   SystemMonitor:10647 [system_monitor.py:_start():183] Publishing last batch of metrics
2023-12-15 17:27:13,301 INFO    HandlerThread:10647 [interfaces.py:finish():202] Joined cpu monitor
2023-12-15 17:27:13,306 INFO    HandlerThread:10647 [interfaces.py:finish():202] Joined disk monitor
2023-12-15 17:27:13,315 ERROR   wandb-upload_0:10647 [internal_api.py:upload_file():2556] upload_file exception https://storage.googleapis.com/wandb-production.appspot.com/bryant-tang-ethz/DKT-trial%201/9eekgqhp/wandb-metadata.json?Expires=1702744033&GoogleAccessId=gorilla-files-url-signer-man%40wandb-production.iam.gserviceaccount.com&Signature=fegoYMfhWi%2BTDz1a3zzHD%2BIbpiF53bhEtxIb5YVugk308fWYTH%2F%2BhSserivSmCe7AQn3fJqp%2FRbigYGriOxJpUOZrCILoVCr4kBJ8%2FGvSIB9rqRZMh1OzJMPmYweNifG9ftvLeh2M6I8IyURJr5AmrXijbGIt%2FwmyGuNU2a%2F1idrbqxSqI49rNpcoiLkHz8GFGR4IVSarZwWRBBjICqH2BKdjsmQ33%2Bm2r1264r8ewh%2FDbwZn3V2wuDOFdj1UoKaXBOt1JCStB1ksp9yPnORFJ10JgbR5oavFEdnfE7qO33B4MMgqwPjhQRq65jOuU0oPRfInKK3%2B9AmtoO%2BHksEEQ%3D%3D: HTTPSConnectionPool(host='storage.googleapis.com', port=443): Max retries exceeded with url: /wandb-production.appspot.com/bryant-tang-ethz/DKT-trial%201/9eekgqhp/wandb-metadata.json?Expires=1702744033&GoogleAccessId=gorilla-files-url-signer-man%40wandb-production.iam.gserviceaccount.com&Signature=fegoYMfhWi%2BTDz1a3zzHD%2BIbpiF53bhEtxIb5YVugk308fWYTH%2F%2BhSserivSmCe7AQn3fJqp%2FRbigYGriOxJpUOZrCILoVCr4kBJ8%2FGvSIB9rqRZMh1OzJMPmYweNifG9ftvLeh2M6I8IyURJr5AmrXijbGIt%2FwmyGuNU2a%2F1idrbqxSqI49rNpcoiLkHz8GFGR4IVSarZwWRBBjICqH2BKdjsmQ33%2Bm2r1264r8ewh%2FDbwZn3V2wuDOFdj1UoKaXBOt1JCStB1ksp9yPnORFJ10JgbR5oavFEdnfE7qO33B4MMgqwPjhQRq65jOuU0oPRfInKK3%2B9AmtoO%2BHksEEQ%3D%3D (Caused by NewConnectionError('<urllib3.connection.HTTPSConnection object at 0x2b0853f95730>: Failed to establish a new connection: [Errno 101] Network is unreachable'))
2023-12-15 17:27:13,316 ERROR   wandb-upload_0:10647 [internal_api.py:upload_file():2558] upload_file request headers: {'User-Agent': 'python-requests/2.28.1', 'Accept-Encoding': 'gzip, deflate, br', 'Accept': '*/*', 'Connection': 'keep-alive', 'Content-Length': '14827'}
2023-12-15 17:27:13,316 ERROR   wandb-upload_0:10647 [internal_api.py:upload_file():2560] upload_file response body: 
2023-12-15 17:27:13,458 INFO    HandlerThread:10647 [interfaces.py:finish():202] Joined gpu monitor
2023-12-15 17:27:13,458 INFO    HandlerThread:10647 [interfaces.py:finish():202] Joined memory monitor
2023-12-15 17:27:13,458 INFO    HandlerThread:10647 [interfaces.py:finish():202] Joined network monitor
2023-12-15 17:27:13,459 DEBUG   SenderThread:10647 [sender.py:send_request():407] send_request: defer
2023-12-15 17:27:13,459 INFO    SenderThread:10647 [sender.py:send_request_defer():609] handle sender defer: 2
2023-12-15 17:27:13,459 INFO    SenderThread:10647 [sender.py:transition_state():613] send defer: 3
2023-12-15 17:27:13,459 DEBUG   HandlerThread:10647 [handler.py:handle_request():146] handle_request: defer
2023-12-15 17:27:13,459 INFO    HandlerThread:10647 [handler.py:handle_request_defer():172] handle defer: 3
2023-12-15 17:27:13,459 DEBUG   SenderThread:10647 [sender.py:send_request():407] send_request: defer
2023-12-15 17:27:13,459 INFO    SenderThread:10647 [sender.py:send_request_defer():609] handle sender defer: 3
2023-12-15 17:27:13,459 INFO    SenderThread:10647 [sender.py:transition_state():613] send defer: 4
2023-12-15 17:27:13,459 DEBUG   HandlerThread:10647 [handler.py:handle_request():146] handle_request: defer
2023-12-15 17:27:13,459 INFO    HandlerThread:10647 [handler.py:handle_request_defer():172] handle defer: 4
2023-12-15 17:27:13,459 DEBUG   SenderThread:10647 [sender.py:send_request():407] send_request: defer
2023-12-15 17:27:13,459 INFO    SenderThread:10647 [sender.py:send_request_defer():609] handle sender defer: 4
2023-12-15 17:27:13,460 INFO    SenderThread:10647 [sender.py:transition_state():613] send defer: 5
2023-12-15 17:27:13,460 DEBUG   HandlerThread:10647 [handler.py:handle_request():146] handle_request: defer
2023-12-15 17:27:13,460 INFO    HandlerThread:10647 [handler.py:handle_request_defer():172] handle defer: 5
2023-12-15 17:27:13,460 DEBUG   SenderThread:10647 [sender.py:send():380] send: summary
2023-12-15 17:27:13,461 INFO    SenderThread:10647 [sender.py:_save_file():1378] saving file wandb-summary.json with policy end
2023-12-15 17:27:13,461 DEBUG   SenderThread:10647 [sender.py:send_request():407] send_request: defer
2023-12-15 17:27:13,461 INFO    SenderThread:10647 [sender.py:send_request_defer():609] handle sender defer: 5
2023-12-15 17:27:13,461 INFO    SenderThread:10647 [sender.py:transition_state():613] send defer: 6
2023-12-15 17:27:13,461 DEBUG   HandlerThread:10647 [handler.py:handle_request():146] handle_request: defer
2023-12-15 17:27:13,461 INFO    HandlerThread:10647 [handler.py:handle_request_defer():172] handle defer: 6
2023-12-15 17:27:13,461 DEBUG   SenderThread:10647 [sender.py:send_request():407] send_request: defer
2023-12-15 17:27:13,461 INFO    SenderThread:10647 [sender.py:send_request_defer():609] handle sender defer: 6
2023-12-15 17:27:13,465 DEBUG   HandlerThread:10647 [handler.py:handle_request():146] handle_request: status_report
2023-12-15 17:27:13,677 INFO    SenderThread:10647 [sender.py:transition_state():613] send defer: 7
2023-12-15 17:27:13,677 DEBUG   HandlerThread:10647 [handler.py:handle_request():146] handle_request: defer
2023-12-15 17:27:13,677 INFO    HandlerThread:10647 [handler.py:handle_request_defer():172] handle defer: 7
2023-12-15 17:27:13,677 DEBUG   SenderThread:10647 [sender.py:send_request():407] send_request: defer
2023-12-15 17:27:13,677 INFO    SenderThread:10647 [sender.py:send_request_defer():609] handle sender defer: 7
2023-12-15 17:27:13,763 INFO    Thread-12 :10647 [dir_watcher.py:_on_file_modified():288] file/dir modified: /cluster/home/yutang/Deep-Knowledge-Tracing/DKT/KnowledgeTracing/evaluation/wandb/run-20231215_172709-9eekgqhp/files/conda-environment.yaml
2023-12-15 17:27:13,763 INFO    Thread-12 :10647 [dir_watcher.py:_on_file_modified():288] file/dir modified: /cluster/home/yutang/Deep-Knowledge-Tracing/DKT/KnowledgeTracing/evaluation/wandb/run-20231215_172709-9eekgqhp/files/config.yaml
2023-12-15 17:27:13,763 INFO    Thread-12 :10647 [dir_watcher.py:_on_file_created():271] file/dir created: /cluster/home/yutang/Deep-Knowledge-Tracing/DKT/KnowledgeTracing/evaluation/wandb/run-20231215_172709-9eekgqhp/files/wandb-summary.json
2023-12-15 17:27:13,763 INFO    Thread-12 :10647 [dir_watcher.py:_on_file_created():271] file/dir created: /cluster/home/yutang/Deep-Knowledge-Tracing/DKT/KnowledgeTracing/evaluation/wandb/run-20231215_172709-9eekgqhp/files/output.log
2023-12-15 17:27:13,764 INFO    Thread-12 :10647 [dir_watcher.py:_on_file_created():271] file/dir created: /cluster/home/yutang/Deep-Knowledge-Tracing/DKT/KnowledgeTracing/evaluation/wandb/run-20231215_172709-9eekgqhp/files/wandb-metadata.json
2023-12-15 17:27:14,050 DEBUG   HandlerThread:10647 [handler.py:handle_request():146] handle_request: poll_exit
2023-12-15 17:27:14,483 ERROR   wandb-upload_0:10647 [internal_api.py:upload_file():2556] upload_file exception https://storage.googleapis.com/wandb-production.appspot.com/bryant-tang-ethz/DKT-trial%201/9eekgqhp/wandb-metadata.json?Expires=1702744033&GoogleAccessId=gorilla-files-url-signer-man%40wandb-production.iam.gserviceaccount.com&Signature=fegoYMfhWi%2BTDz1a3zzHD%2BIbpiF53bhEtxIb5YVugk308fWYTH%2F%2BhSserivSmCe7AQn3fJqp%2FRbigYGriOxJpUOZrCILoVCr4kBJ8%2FGvSIB9rqRZMh1OzJMPmYweNifG9ftvLeh2M6I8IyURJr5AmrXijbGIt%2FwmyGuNU2a%2F1idrbqxSqI49rNpcoiLkHz8GFGR4IVSarZwWRBBjICqH2BKdjsmQ33%2Bm2r1264r8ewh%2FDbwZn3V2wuDOFdj1UoKaXBOt1JCStB1ksp9yPnORFJ10JgbR5oavFEdnfE7qO33B4MMgqwPjhQRq65jOuU0oPRfInKK3%2B9AmtoO%2BHksEEQ%3D%3D: HTTPSConnectionPool(host='storage.googleapis.com', port=443): Max retries exceeded with url: /wandb-production.appspot.com/bryant-tang-ethz/DKT-trial%201/9eekgqhp/wandb-metadata.json?Expires=1702744033&GoogleAccessId=gorilla-files-url-signer-man%40wandb-production.iam.gserviceaccount.com&Signature=fegoYMfhWi%2BTDz1a3zzHD%2BIbpiF53bhEtxIb5YVugk308fWYTH%2F%2BhSserivSmCe7AQn3fJqp%2FRbigYGriOxJpUOZrCILoVCr4kBJ8%2FGvSIB9rqRZMh1OzJMPmYweNifG9ftvLeh2M6I8IyURJr5AmrXijbGIt%2FwmyGuNU2a%2F1idrbqxSqI49rNpcoiLkHz8GFGR4IVSarZwWRBBjICqH2BKdjsmQ33%2Bm2r1264r8ewh%2FDbwZn3V2wuDOFdj1UoKaXBOt1JCStB1ksp9yPnORFJ10JgbR5oavFEdnfE7qO33B4MMgqwPjhQRq65jOuU0oPRfInKK3%2B9AmtoO%2BHksEEQ%3D%3D (Caused by NewConnectionError('<urllib3.connection.HTTPSConnection object at 0x2b0853f2f640>: Failed to establish a new connection: [Errno 101] Network is unreachable'))
2023-12-15 17:27:14,483 ERROR   wandb-upload_0:10647 [internal_api.py:upload_file():2558] upload_file request headers: {'User-Agent': 'python-requests/2.28.1', 'Accept-Encoding': 'gzip, deflate, br', 'Accept': '*/*', 'Connection': 'keep-alive', 'Content-Length': '14827'}
2023-12-15 17:27:14,483 ERROR   wandb-upload_0:10647 [internal_api.py:upload_file():2560] upload_file response body: 
2023-12-15 17:27:15,764 INFO    Thread-12 :10647 [dir_watcher.py:_on_file_modified():288] file/dir modified: /cluster/home/yutang/Deep-Knowledge-Tracing/DKT/KnowledgeTracing/evaluation/wandb/run-20231215_172709-9eekgqhp/files/output.log
2023-12-15 17:27:16,845 ERROR   wandb-upload_0:10647 [internal_api.py:upload_file():2556] upload_file exception https://storage.googleapis.com/wandb-production.appspot.com/bryant-tang-ethz/DKT-trial%201/9eekgqhp/wandb-metadata.json?Expires=1702744033&GoogleAccessId=gorilla-files-url-signer-man%40wandb-production.iam.gserviceaccount.com&Signature=fegoYMfhWi%2BTDz1a3zzHD%2BIbpiF53bhEtxIb5YVugk308fWYTH%2F%2BhSserivSmCe7AQn3fJqp%2FRbigYGriOxJpUOZrCILoVCr4kBJ8%2FGvSIB9rqRZMh1OzJMPmYweNifG9ftvLeh2M6I8IyURJr5AmrXijbGIt%2FwmyGuNU2a%2F1idrbqxSqI49rNpcoiLkHz8GFGR4IVSarZwWRBBjICqH2BKdjsmQ33%2Bm2r1264r8ewh%2FDbwZn3V2wuDOFdj1UoKaXBOt1JCStB1ksp9yPnORFJ10JgbR5oavFEdnfE7qO33B4MMgqwPjhQRq65jOuU0oPRfInKK3%2B9AmtoO%2BHksEEQ%3D%3D: HTTPSConnectionPool(host='storage.googleapis.com', port=443): Max retries exceeded with url: /wandb-production.appspot.com/bryant-tang-ethz/DKT-trial%201/9eekgqhp/wandb-metadata.json?Expires=1702744033&GoogleAccessId=gorilla-files-url-signer-man%40wandb-production.iam.gserviceaccount.com&Signature=fegoYMfhWi%2BTDz1a3zzHD%2BIbpiF53bhEtxIb5YVugk308fWYTH%2F%2BhSserivSmCe7AQn3fJqp%2FRbigYGriOxJpUOZrCILoVCr4kBJ8%2FGvSIB9rqRZMh1OzJMPmYweNifG9ftvLeh2M6I8IyURJr5AmrXijbGIt%2FwmyGuNU2a%2F1idrbqxSqI49rNpcoiLkHz8GFGR4IVSarZwWRBBjICqH2BKdjsmQ33%2Bm2r1264r8ewh%2FDbwZn3V2wuDOFdj1UoKaXBOt1JCStB1ksp9yPnORFJ10JgbR5oavFEdnfE7qO33B4MMgqwPjhQRq65jOuU0oPRfInKK3%2B9AmtoO%2BHksEEQ%3D%3D (Caused by NewConnectionError('<urllib3.connection.HTTPSConnection object at 0x2b0853f2f250>: Failed to establish a new connection: [Errno 101] Network is unreachable'))
2023-12-15 17:27:16,845 ERROR   wandb-upload_0:10647 [internal_api.py:upload_file():2558] upload_file request headers: {'User-Agent': 'python-requests/2.28.1', 'Accept-Encoding': 'gzip, deflate, br', 'Accept': '*/*', 'Connection': 'keep-alive', 'Content-Length': '14827'}
2023-12-15 17:27:16,845 ERROR   wandb-upload_0:10647 [internal_api.py:upload_file():2560] upload_file response body: 
2023-12-15 17:27:16,845 INFO    wandb-upload_0:10647 [retry.py:__call__():172] Retry attempt failed:
Traceback (most recent call last):
  File "/cluster/home/yutang/miniconda3/lib/python3.9/site-packages/urllib3/connection.py", line 174, in _new_conn
    conn = connection.create_connection(
  File "/cluster/home/yutang/miniconda3/lib/python3.9/site-packages/urllib3/util/connection.py", line 95, in create_connection
    raise err
  File "/cluster/home/yutang/miniconda3/lib/python3.9/site-packages/urllib3/util/connection.py", line 85, in create_connection
    sock.connect(sa)
OSError: [Errno 101] Network is unreachable

During handling of the above exception, another exception occurred:

Traceback (most recent call last):
  File "/cluster/home/yutang/miniconda3/lib/python3.9/site-packages/urllib3/connectionpool.py", line 703, in urlopen
    httplib_response = self._make_request(
  File "/cluster/home/yutang/miniconda3/lib/python3.9/site-packages/urllib3/connectionpool.py", line 386, in _make_request
    self._validate_conn(conn)
  File "/cluster/home/yutang/miniconda3/lib/python3.9/site-packages/urllib3/connectionpool.py", line 1042, in _validate_conn
    conn.connect()
  File "/cluster/home/yutang/miniconda3/lib/python3.9/site-packages/urllib3/connection.py", line 358, in connect
    self.sock = conn = self._new_conn()
  File "/cluster/home/yutang/miniconda3/lib/python3.9/site-packages/urllib3/connection.py", line 186, in _new_conn
    raise NewConnectionError(
urllib3.exceptions.NewConnectionError: <urllib3.connection.HTTPSConnection object at 0x2b0853f2f250>: Failed to establish a new connection: [Errno 101] Network is unreachable

During handling of the above exception, another exception occurred:

Traceback (most recent call last):
  File "/cluster/home/yutang/miniconda3/lib/python3.9/site-packages/requests/adapters.py", line 489, in send
    resp = conn.urlopen(
  File "/cluster/home/yutang/miniconda3/lib/python3.9/site-packages/urllib3/connectionpool.py", line 787, in urlopen
    retries = retries.increment(
  File "/cluster/home/yutang/miniconda3/lib/python3.9/site-packages/urllib3/util/retry.py", line 592, in increment
    raise MaxRetryError(_pool, url, error or ResponseError(cause))
urllib3.exceptions.MaxRetryError: HTTPSConnectionPool(host='storage.googleapis.com', port=443): Max retries exceeded with url: /wandb-production.appspot.com/bryant-tang-ethz/DKT-trial%201/9eekgqhp/wandb-metadata.json?Expires=1702744033&GoogleAccessId=gorilla-files-url-signer-man%40wandb-production.iam.gserviceaccount.com&Signature=fegoYMfhWi%2BTDz1a3zzHD%2BIbpiF53bhEtxIb5YVugk308fWYTH%2F%2BhSserivSmCe7AQn3fJqp%2FRbigYGriOxJpUOZrCILoVCr4kBJ8%2FGvSIB9rqRZMh1OzJMPmYweNifG9ftvLeh2M6I8IyURJr5AmrXijbGIt%2FwmyGuNU2a%2F1idrbqxSqI49rNpcoiLkHz8GFGR4IVSarZwWRBBjICqH2BKdjsmQ33%2Bm2r1264r8ewh%2FDbwZn3V2wuDOFdj1UoKaXBOt1JCStB1ksp9yPnORFJ10JgbR5oavFEdnfE7qO33B4MMgqwPjhQRq65jOuU0oPRfInKK3%2B9AmtoO%2BHksEEQ%3D%3D (Caused by NewConnectionError('<urllib3.connection.HTTPSConnection object at 0x2b0853f2f250>: Failed to establish a new connection: [Errno 101] Network is unreachable'))

During handling of the above exception, another exception occurred:

Traceback (most recent call last):
  File "/cluster/home/yutang/miniconda3/lib/python3.9/site-packages/wandb/sdk/internal/internal_api.py", line 2549, in upload_file
    response = self._upload_file_session.put(
  File "/cluster/home/yutang/miniconda3/lib/python3.9/site-packages/requests/sessions.py", line 647, in put
    return self.request("PUT", url, data=data, **kwargs)
  File "/cluster/home/yutang/miniconda3/lib/python3.9/site-packages/requests/sessions.py", line 587, in request
    resp = self.send(prep, **send_kwargs)
  File "/cluster/home/yutang/miniconda3/lib/python3.9/site-packages/requests/sessions.py", line 701, in send
    r = adapter.send(request, **kwargs)
  File "/cluster/home/yutang/miniconda3/lib/python3.9/site-packages/requests/adapters.py", line 565, in send
    raise ConnectionError(e, request=request)
requests.exceptions.ConnectionError: HTTPSConnectionPool(host='storage.googleapis.com', port=443): Max retries exceeded with url: /wandb-production.appspot.com/bryant-tang-ethz/DKT-trial%201/9eekgqhp/wandb-metadata.json?Expires=1702744033&GoogleAccessId=gorilla-files-url-signer-man%40wandb-production.iam.gserviceaccount.com&Signature=fegoYMfhWi%2BTDz1a3zzHD%2BIbpiF53bhEtxIb5YVugk308fWYTH%2F%2BhSserivSmCe7AQn3fJqp%2FRbigYGriOxJpUOZrCILoVCr4kBJ8%2FGvSIB9rqRZMh1OzJMPmYweNifG9ftvLeh2M6I8IyURJr5AmrXijbGIt%2FwmyGuNU2a%2F1idrbqxSqI49rNpcoiLkHz8GFGR4IVSarZwWRBBjICqH2BKdjsmQ33%2Bm2r1264r8ewh%2FDbwZn3V2wuDOFdj1UoKaXBOt1JCStB1ksp9yPnORFJ10JgbR5oavFEdnfE7qO33B4MMgqwPjhQRq65jOuU0oPRfInKK3%2B9AmtoO%2BHksEEQ%3D%3D (Caused by NewConnectionError('<urllib3.connection.HTTPSConnection object at 0x2b0853f2f250>: Failed to establish a new connection: [Errno 101] Network is unreachable'))

During handling of the above exception, another exception occurred:

Traceback (most recent call last):
  File "/cluster/home/yutang/miniconda3/lib/python3.9/site-packages/wandb/sdk/lib/retry.py", line 131, in __call__
    result = self._call_fn(*args, **kwargs)
  File "/cluster/home/yutang/miniconda3/lib/python3.9/site-packages/wandb/sdk/internal/internal_api.py", line 2580, in upload_file
    raise _e.with_traceback(sys.exc_info()[2])
  File "/cluster/home/yutang/miniconda3/lib/python3.9/site-packages/wandb/sdk/internal/internal_api.py", line 2549, in upload_file
    response = self._upload_file_session.put(
  File "/cluster/home/yutang/miniconda3/lib/python3.9/site-packages/requests/sessions.py", line 647, in put
    return self.request("PUT", url, data=data, **kwargs)
  File "/cluster/home/yutang/miniconda3/lib/python3.9/site-packages/requests/sessions.py", line 587, in request
    resp = self.send(prep, **send_kwargs)
  File "/cluster/home/yutang/miniconda3/lib/python3.9/site-packages/requests/sessions.py", line 701, in send
    r = adapter.send(request, **kwargs)
  File "/cluster/home/yutang/miniconda3/lib/python3.9/site-packages/requests/adapters.py", line 565, in send
    raise ConnectionError(e, request=request)
wandb.sdk.lib.retry.TransientError: None
2023-12-15 17:27:17,297 INFO    SenderThread:10647 [sender.py:transition_state():613] send defer: 8
2023-12-15 17:27:17,297 DEBUG   SenderThread:10647 [sender.py:send_request():407] send_request: poll_exit
2023-12-15 17:27:17,297 DEBUG   HandlerThread:10647 [handler.py:handle_request():146] handle_request: defer
2023-12-15 17:27:17,298 INFO    HandlerThread:10647 [handler.py:handle_request_defer():172] handle defer: 8
2023-12-15 17:27:17,298 DEBUG   SenderThread:10647 [sender.py:send_request():407] send_request: defer
2023-12-15 17:27:17,298 INFO    SenderThread:10647 [sender.py:send_request_defer():609] handle sender defer: 8
2023-12-15 17:27:17,298 INFO    SenderThread:10647 [job_builder.py:build():281] Attempting to build job artifact
2023-12-15 17:27:17,299 INFO    SenderThread:10647 [job_builder.py:_get_source_type():393] is repo sourced job
2023-12-15 17:27:17,303 INFO    SenderThread:10647 [job_builder.py:build():369] adding wandb-job metadata file
2023-12-15 17:27:17,310 INFO    SenderThread:10647 [sender.py:transition_state():613] send defer: 9
2023-12-15 17:27:17,310 DEBUG   HandlerThread:10647 [handler.py:handle_request():146] handle_request: defer
2023-12-15 17:27:17,311 DEBUG   SenderThread:10647 [sender.py:send():380] send: artifact
2023-12-15 17:27:17,311 INFO    HandlerThread:10647 [handler.py:handle_request_defer():172] handle defer: 9
2023-12-15 17:27:17,766 INFO    Thread-12 :10647 [dir_watcher.py:_on_file_modified():288] file/dir modified: /cluster/home/yutang/Deep-Knowledge-Tracing/DKT/KnowledgeTracing/evaluation/wandb/run-20231215_172709-9eekgqhp/files/output.log
2023-12-15 17:27:18,342 ERROR   wandb-upload_1:10647 [internal_api.py:upload_file():2556] upload_file exception https://storage.googleapis.com/wandb-artifacts-prod/wandb_artifacts/120300447/667873143/521e54ab95c254e02c4ef790d5def9ec?Expires=1702744038&GoogleAccessId=gorilla-files-url-signer-man%40wandb-production.iam.gserviceaccount.com&Signature=s3vot08iBEXAP00FH%2B6dl9WPoOvaPb25xr0rrLYQdha1xoBTRzpFQErDALKDiaGTY99S8N5eUtpqJVC%2BHxjOxJ%2BqBJBvDD09ET7WGrAgvVP6UftMpj2kVNFaKQTUGEjyw6LntStF2ur%2F8Z2gBujTIsJa%2BdgyyvGLv5R%2BdQzBVerY4mDEcWSbY9cALcB9K2A6GsKgTqXOi13FgsqWC4uNdnLsLEqBLpUmwUrDQmQlKwgGz82nnWsH6RxEHCn%2BIQ2zCrjm6JFUhKxQkSyykV8IUndoHYVJuuSuZyT3FmhQZnhffDXLLM2bkMl1dY%2BmOEak2nyXadIdB3k%2F7G9rbIclVg%3D%3D: HTTPSConnectionPool(host='storage.googleapis.com', port=443): Max retries exceeded with url: /wandb-artifacts-prod/wandb_artifacts/120300447/667873143/521e54ab95c254e02c4ef790d5def9ec?Expires=1702744038&GoogleAccessId=gorilla-files-url-signer-man%40wandb-production.iam.gserviceaccount.com&Signature=s3vot08iBEXAP00FH%2B6dl9WPoOvaPb25xr0rrLYQdha1xoBTRzpFQErDALKDiaGTY99S8N5eUtpqJVC%2BHxjOxJ%2BqBJBvDD09ET7WGrAgvVP6UftMpj2kVNFaKQTUGEjyw6LntStF2ur%2F8Z2gBujTIsJa%2BdgyyvGLv5R%2BdQzBVerY4mDEcWSbY9cALcB9K2A6GsKgTqXOi13FgsqWC4uNdnLsLEqBLpUmwUrDQmQlKwgGz82nnWsH6RxEHCn%2BIQ2zCrjm6JFUhKxQkSyykV8IUndoHYVJuuSuZyT3FmhQZnhffDXLLM2bkMl1dY%2BmOEak2nyXadIdB3k%2F7G9rbIclVg%3D%3D (Caused by NewConnectionError('<urllib3.connection.HTTPSConnection object at 0x2b0886876580>: Failed to establish a new connection: [Errno 101] Network is unreachable'))
2023-12-15 17:27:18,342 ERROR   wandb-upload_1:10647 [internal_api.py:upload_file():2558] upload_file request headers: {'User-Agent': 'python-requests/2.28.1', 'Accept-Encoding': 'gzip, deflate, br', 'Accept': '*/*', 'Connection': 'keep-alive', 'Content-MD5': 'Uh5Uq5XCVOAsTveQ1d757A==', 'Content-Type': 'text/plain; charset=utf-8', 'Content-Length': '1820'}
2023-12-15 17:27:18,342 ERROR   wandb-upload_1:10647 [internal_api.py:upload_file():2560] upload_file response body: 
2023-12-15 17:27:18,342 ERROR   wandb-upload_2:10647 [internal_api.py:upload_file():2556] upload_file exception https://storage.googleapis.com/wandb-artifacts-prod/wandb_artifacts/120300447/667873143/90d3d941acdc730294f7988a60e22317?Expires=1702744038&GoogleAccessId=gorilla-files-url-signer-man%40wandb-production.iam.gserviceaccount.com&Signature=rePB%2B712fkIhge3qBC0mcj%2B4bzYu9zU8hOfzDKBHQ9KEwuYypx2TogOJJa3cctFkj0Wy18glZFlSqcG9SngIKaDUD1%2F0ZqUO3UJZVadFQdm1GnumQ5XY3r%2FFMfDTNyotlYhwdoVKBGx12lRElt89PuxYofUT%2BcfaKKBnBkb57xuQKiP0PC08ufDrIW67qu1MbzLK69SCEVp4lWR%2B89sGCUvabBcAjnTslH9VKun7PQV1VEYjHTey2OK1FuSLR2SEy0k%2FLg6C42r61CVKl5TW3uJ%2BGY3h63CzOxCumsmz2vCDC3GSJmDYWIopEyZQIxn%2FUGF3wk1m%2FR7hRQTFCzYSNw%3D%3D: HTTPSConnectionPool(host='storage.googleapis.com', port=443): Max retries exceeded with url: /wandb-artifacts-prod/wandb_artifacts/120300447/667873143/90d3d941acdc730294f7988a60e22317?Expires=1702744038&GoogleAccessId=gorilla-files-url-signer-man%40wandb-production.iam.gserviceaccount.com&Signature=rePB%2B712fkIhge3qBC0mcj%2B4bzYu9zU8hOfzDKBHQ9KEwuYypx2TogOJJa3cctFkj0Wy18glZFlSqcG9SngIKaDUD1%2F0ZqUO3UJZVadFQdm1GnumQ5XY3r%2FFMfDTNyotlYhwdoVKBGx12lRElt89PuxYofUT%2BcfaKKBnBkb57xuQKiP0PC08ufDrIW67qu1MbzLK69SCEVp4lWR%2B89sGCUvabBcAjnTslH9VKun7PQV1VEYjHTey2OK1FuSLR2SEy0k%2FLg6C42r61CVKl5TW3uJ%2BGY3h63CzOxCumsmz2vCDC3GSJmDYWIopEyZQIxn%2FUGF3wk1m%2FR7hRQTFCzYSNw%3D%3D (Caused by NewConnectionError('<urllib3.connection.HTTPSConnection object at 0x2b0886876730>: Failed to establish a new connection: [Errno 101] Network is unreachable'))
2023-12-15 17:27:18,343 ERROR   wandb-upload_2:10647 [internal_api.py:upload_file():2558] upload_file request headers: {'User-Agent': 'python-requests/2.28.1', 'Accept-Encoding': 'gzip, deflate, br', 'Accept': '*/*', 'Connection': 'keep-alive', 'Content-MD5': 'kNPZQazccwKU95iKYOIjFw==', 'Content-Type': 'application/json', 'Content-Length': '648'}
2023-12-15 17:27:18,343 ERROR   wandb-upload_2:10647 [internal_api.py:upload_file():2560] upload_file response body: 
2023-12-15 17:27:19,052 DEBUG   HandlerThread:10647 [handler.py:handle_request():146] handle_request: keepalive
2023-12-15 17:27:19,366 ERROR   wandb-upload_2:10647 [internal_api.py:upload_file():2556] upload_file exception https://storage.googleapis.com/wandb-artifacts-prod/wandb_artifacts/120300447/667873143/90d3d941acdc730294f7988a60e22317?Expires=1702744038&GoogleAccessId=gorilla-files-url-signer-man%40wandb-production.iam.gserviceaccount.com&Signature=rePB%2B712fkIhge3qBC0mcj%2B4bzYu9zU8hOfzDKBHQ9KEwuYypx2TogOJJa3cctFkj0Wy18glZFlSqcG9SngIKaDUD1%2F0ZqUO3UJZVadFQdm1GnumQ5XY3r%2FFMfDTNyotlYhwdoVKBGx12lRElt89PuxYofUT%2BcfaKKBnBkb57xuQKiP0PC08ufDrIW67qu1MbzLK69SCEVp4lWR%2B89sGCUvabBcAjnTslH9VKun7PQV1VEYjHTey2OK1FuSLR2SEy0k%2FLg6C42r61CVKl5TW3uJ%2BGY3h63CzOxCumsmz2vCDC3GSJmDYWIopEyZQIxn%2FUGF3wk1m%2FR7hRQTFCzYSNw%3D%3D: HTTPSConnectionPool(host='storage.googleapis.com', port=443): Max retries exceeded with url: /wandb-artifacts-prod/wandb_artifacts/120300447/667873143/90d3d941acdc730294f7988a60e22317?Expires=1702744038&GoogleAccessId=gorilla-files-url-signer-man%40wandb-production.iam.gserviceaccount.com&Signature=rePB%2B712fkIhge3qBC0mcj%2B4bzYu9zU8hOfzDKBHQ9KEwuYypx2TogOJJa3cctFkj0Wy18glZFlSqcG9SngIKaDUD1%2F0ZqUO3UJZVadFQdm1GnumQ5XY3r%2FFMfDTNyotlYhwdoVKBGx12lRElt89PuxYofUT%2BcfaKKBnBkb57xuQKiP0PC08ufDrIW67qu1MbzLK69SCEVp4lWR%2B89sGCUvabBcAjnTslH9VKun7PQV1VEYjHTey2OK1FuSLR2SEy0k%2FLg6C42r61CVKl5TW3uJ%2BGY3h63CzOxCumsmz2vCDC3GSJmDYWIopEyZQIxn%2FUGF3wk1m%2FR7hRQTFCzYSNw%3D%3D (Caused by NewConnectionError('<urllib3.connection.HTTPSConnection object at 0x2b0853f48280>: Failed to establish a new connection: [Errno 101] Network is unreachable'))
2023-12-15 17:27:19,366 ERROR   wandb-upload_2:10647 [internal_api.py:upload_file():2558] upload_file request headers: {'User-Agent': 'python-requests/2.28.1', 'Accept-Encoding': 'gzip, deflate, br', 'Accept': '*/*', 'Connection': 'keep-alive', 'Content-MD5': 'kNPZQazccwKU95iKYOIjFw==', 'Content-Type': 'application/json', 'Content-Length': '648'}
2023-12-15 17:27:19,366 ERROR   wandb-upload_2:10647 [internal_api.py:upload_file():2560] upload_file response body: 
2023-12-15 17:27:19,610 ERROR   wandb-upload_1:10647 [internal_api.py:upload_file():2556] upload_file exception https://storage.googleapis.com/wandb-artifacts-prod/wandb_artifacts/120300447/667873143/521e54ab95c254e02c4ef790d5def9ec?Expires=1702744038&GoogleAccessId=gorilla-files-url-signer-man%40wandb-production.iam.gserviceaccount.com&Signature=s3vot08iBEXAP00FH%2B6dl9WPoOvaPb25xr0rrLYQdha1xoBTRzpFQErDALKDiaGTY99S8N5eUtpqJVC%2BHxjOxJ%2BqBJBvDD09ET7WGrAgvVP6UftMpj2kVNFaKQTUGEjyw6LntStF2ur%2F8Z2gBujTIsJa%2BdgyyvGLv5R%2BdQzBVerY4mDEcWSbY9cALcB9K2A6GsKgTqXOi13FgsqWC4uNdnLsLEqBLpUmwUrDQmQlKwgGz82nnWsH6RxEHCn%2BIQ2zCrjm6JFUhKxQkSyykV8IUndoHYVJuuSuZyT3FmhQZnhffDXLLM2bkMl1dY%2BmOEak2nyXadIdB3k%2F7G9rbIclVg%3D%3D: HTTPSConnectionPool(host='storage.googleapis.com', port=443): Max retries exceeded with url: /wandb-artifacts-prod/wandb_artifacts/120300447/667873143/521e54ab95c254e02c4ef790d5def9ec?Expires=1702744038&GoogleAccessId=gorilla-files-url-signer-man%40wandb-production.iam.gserviceaccount.com&Signature=s3vot08iBEXAP00FH%2B6dl9WPoOvaPb25xr0rrLYQdha1xoBTRzpFQErDALKDiaGTY99S8N5eUtpqJVC%2BHxjOxJ%2BqBJBvDD09ET7WGrAgvVP6UftMpj2kVNFaKQTUGEjyw6LntStF2ur%2F8Z2gBujTIsJa%2BdgyyvGLv5R%2BdQzBVerY4mDEcWSbY9cALcB9K2A6GsKgTqXOi13FgsqWC4uNdnLsLEqBLpUmwUrDQmQlKwgGz82nnWsH6RxEHCn%2BIQ2zCrjm6JFUhKxQkSyykV8IUndoHYVJuuSuZyT3FmhQZnhffDXLLM2bkMl1dY%2BmOEak2nyXadIdB3k%2F7G9rbIclVg%3D%3D (Caused by NewConnectionError('<urllib3.connection.HTTPSConnection object at 0x2b0886880460>: Failed to establish a new connection: [Errno 101] Network is unreachable'))
2023-12-15 17:27:19,610 ERROR   wandb-upload_1:10647 [internal_api.py:upload_file():2558] upload_file request headers: {'User-Agent': 'python-requests/2.28.1', 'Accept-Encoding': 'gzip, deflate, br', 'Accept': '*/*', 'Connection': 'keep-alive', 'Content-MD5': 'Uh5Uq5XCVOAsTveQ1d757A==', 'Content-Type': 'text/plain; charset=utf-8', 'Content-Length': '1820'}
2023-12-15 17:27:19,610 ERROR   wandb-upload_1:10647 [internal_api.py:upload_file():2560] upload_file response body: 
2023-12-15 17:27:20,907 ERROR   wandb-upload_0:10647 [internal_api.py:upload_file():2556] upload_file exception https://storage.googleapis.com/wandb-production.appspot.com/bryant-tang-ethz/DKT-trial%201/9eekgqhp/wandb-metadata.json?Expires=1702744033&GoogleAccessId=gorilla-files-url-signer-man%40wandb-production.iam.gserviceaccount.com&Signature=fegoYMfhWi%2BTDz1a3zzHD%2BIbpiF53bhEtxIb5YVugk308fWYTH%2F%2BhSserivSmCe7AQn3fJqp%2FRbigYGriOxJpUOZrCILoVCr4kBJ8%2FGvSIB9rqRZMh1OzJMPmYweNifG9ftvLeh2M6I8IyURJr5AmrXijbGIt%2FwmyGuNU2a%2F1idrbqxSqI49rNpcoiLkHz8GFGR4IVSarZwWRBBjICqH2BKdjsmQ33%2Bm2r1264r8ewh%2FDbwZn3V2wuDOFdj1UoKaXBOt1JCStB1ksp9yPnORFJ10JgbR5oavFEdnfE7qO33B4MMgqwPjhQRq65jOuU0oPRfInKK3%2B9AmtoO%2BHksEEQ%3D%3D: HTTPSConnectionPool(host='storage.googleapis.com', port=443): Max retries exceeded with url: /wandb-production.appspot.com/bryant-tang-ethz/DKT-trial%201/9eekgqhp/wandb-metadata.json?Expires=1702744033&GoogleAccessId=gorilla-files-url-signer-man%40wandb-production.iam.gserviceaccount.com&Signature=fegoYMfhWi%2BTDz1a3zzHD%2BIbpiF53bhEtxIb5YVugk308fWYTH%2F%2BhSserivSmCe7AQn3fJqp%2FRbigYGriOxJpUOZrCILoVCr4kBJ8%2FGvSIB9rqRZMh1OzJMPmYweNifG9ftvLeh2M6I8IyURJr5AmrXijbGIt%2FwmyGuNU2a%2F1idrbqxSqI49rNpcoiLkHz8GFGR4IVSarZwWRBBjICqH2BKdjsmQ33%2Bm2r1264r8ewh%2FDbwZn3V2wuDOFdj1UoKaXBOt1JCStB1ksp9yPnORFJ10JgbR5oavFEdnfE7qO33B4MMgqwPjhQRq65jOuU0oPRfInKK3%2B9AmtoO%2BHksEEQ%3D%3D (Caused by NewConnectionError('<urllib3.connection.HTTPSConnection object at 0x2b0886880910>: Failed to establish a new connection: [Errno 101] Network is unreachable'))
2023-12-15 17:27:20,907 ERROR   wandb-upload_0:10647 [internal_api.py:upload_file():2558] upload_file request headers: {'User-Agent': 'python-requests/2.28.1', 'Accept-Encoding': 'gzip, deflate, br', 'Accept': '*/*', 'Connection': 'keep-alive', 'Content-Length': '14827'}
2023-12-15 17:27:20,907 ERROR   wandb-upload_0:10647 [internal_api.py:upload_file():2560] upload_file response body: 
2023-12-15 17:27:21,701 ERROR   wandb-upload_1:10647 [internal_api.py:upload_file():2556] upload_file exception https://storage.googleapis.com/wandb-artifacts-prod/wandb_artifacts/120300447/667873143/521e54ab95c254e02c4ef790d5def9ec?Expires=1702744038&GoogleAccessId=gorilla-files-url-signer-man%40wandb-production.iam.gserviceaccount.com&Signature=s3vot08iBEXAP00FH%2B6dl9WPoOvaPb25xr0rrLYQdha1xoBTRzpFQErDALKDiaGTY99S8N5eUtpqJVC%2BHxjOxJ%2BqBJBvDD09ET7WGrAgvVP6UftMpj2kVNFaKQTUGEjyw6LntStF2ur%2F8Z2gBujTIsJa%2BdgyyvGLv5R%2BdQzBVerY4mDEcWSbY9cALcB9K2A6GsKgTqXOi13FgsqWC4uNdnLsLEqBLpUmwUrDQmQlKwgGz82nnWsH6RxEHCn%2BIQ2zCrjm6JFUhKxQkSyykV8IUndoHYVJuuSuZyT3FmhQZnhffDXLLM2bkMl1dY%2BmOEak2nyXadIdB3k%2F7G9rbIclVg%3D%3D: HTTPSConnectionPool(host='storage.googleapis.com', port=443): Max retries exceeded with url: /wandb-artifacts-prod/wandb_artifacts/120300447/667873143/521e54ab95c254e02c4ef790d5def9ec?Expires=1702744038&GoogleAccessId=gorilla-files-url-signer-man%40wandb-production.iam.gserviceaccount.com&Signature=s3vot08iBEXAP00FH%2B6dl9WPoOvaPb25xr0rrLYQdha1xoBTRzpFQErDALKDiaGTY99S8N5eUtpqJVC%2BHxjOxJ%2BqBJBvDD09ET7WGrAgvVP6UftMpj2kVNFaKQTUGEjyw6LntStF2ur%2F8Z2gBujTIsJa%2BdgyyvGLv5R%2BdQzBVerY4mDEcWSbY9cALcB9K2A6GsKgTqXOi13FgsqWC4uNdnLsLEqBLpUmwUrDQmQlKwgGz82nnWsH6RxEHCn%2BIQ2zCrjm6JFUhKxQkSyykV8IUndoHYVJuuSuZyT3FmhQZnhffDXLLM2bkMl1dY%2BmOEak2nyXadIdB3k%2F7G9rbIclVg%3D%3D (Caused by NewConnectionError('<urllib3.connection.HTTPSConnection object at 0x2b0886885100>: Failed to establish a new connection: [Errno 101] Network is unreachable'))
2023-12-15 17:27:21,701 ERROR   wandb-upload_1:10647 [internal_api.py:upload_file():2558] upload_file request headers: {'User-Agent': 'python-requests/2.28.1', 'Accept-Encoding': 'gzip, deflate, br', 'Accept': '*/*', 'Connection': 'keep-alive', 'Content-MD5': 'Uh5Uq5XCVOAsTveQ1d757A==', 'Content-Type': 'text/plain; charset=utf-8', 'Content-Length': '1820'}
2023-12-15 17:27:21,701 ERROR   wandb-upload_1:10647 [internal_api.py:upload_file():2560] upload_file response body: 
2023-12-15 17:27:21,701 INFO    wandb-upload_1:10647 [retry.py:__call__():172] Retry attempt failed:
Traceback (most recent call last):
  File "/cluster/home/yutang/miniconda3/lib/python3.9/site-packages/urllib3/connection.py", line 174, in _new_conn
    conn = connection.create_connection(
  File "/cluster/home/yutang/miniconda3/lib/python3.9/site-packages/urllib3/util/connection.py", line 95, in create_connection
    raise err
  File "/cluster/home/yutang/miniconda3/lib/python3.9/site-packages/urllib3/util/connection.py", line 85, in create_connection
    sock.connect(sa)
OSError: [Errno 101] Network is unreachable

During handling of the above exception, another exception occurred:

Traceback (most recent call last):
  File "/cluster/home/yutang/miniconda3/lib/python3.9/site-packages/urllib3/connectionpool.py", line 703, in urlopen
    httplib_response = self._make_request(
  File "/cluster/home/yutang/miniconda3/lib/python3.9/site-packages/urllib3/connectionpool.py", line 386, in _make_request
    self._validate_conn(conn)
  File "/cluster/home/yutang/miniconda3/lib/python3.9/site-packages/urllib3/connectionpool.py", line 1042, in _validate_conn
    conn.connect()
  File "/cluster/home/yutang/miniconda3/lib/python3.9/site-packages/urllib3/connection.py", line 358, in connect
    self.sock = conn = self._new_conn()
  File "/cluster/home/yutang/miniconda3/lib/python3.9/site-packages/urllib3/connection.py", line 186, in _new_conn
    raise NewConnectionError(
urllib3.exceptions.NewConnectionError: <urllib3.connection.HTTPSConnection object at 0x2b0886885100>: Failed to establish a new connection: [Errno 101] Network is unreachable

During handling of the above exception, another exception occurred:

Traceback (most recent call last):
  File "/cluster/home/yutang/miniconda3/lib/python3.9/site-packages/requests/adapters.py", line 489, in send
    resp = conn.urlopen(
  File "/cluster/home/yutang/miniconda3/lib/python3.9/site-packages/urllib3/connectionpool.py", line 787, in urlopen
    retries = retries.increment(
  File "/cluster/home/yutang/miniconda3/lib/python3.9/site-packages/urllib3/util/retry.py", line 592, in increment
    raise MaxRetryError(_pool, url, error or ResponseError(cause))
urllib3.exceptions.MaxRetryError: HTTPSConnectionPool(host='storage.googleapis.com', port=443): Max retries exceeded with url: /wandb-artifacts-prod/wandb_artifacts/120300447/667873143/521e54ab95c254e02c4ef790d5def9ec?Expires=1702744038&GoogleAccessId=gorilla-files-url-signer-man%40wandb-production.iam.gserviceaccount.com&Signature=s3vot08iBEXAP00FH%2B6dl9WPoOvaPb25xr0rrLYQdha1xoBTRzpFQErDALKDiaGTY99S8N5eUtpqJVC%2BHxjOxJ%2BqBJBvDD09ET7WGrAgvVP6UftMpj2kVNFaKQTUGEjyw6LntStF2ur%2F8Z2gBujTIsJa%2BdgyyvGLv5R%2BdQzBVerY4mDEcWSbY9cALcB9K2A6GsKgTqXOi13FgsqWC4uNdnLsLEqBLpUmwUrDQmQlKwgGz82nnWsH6RxEHCn%2BIQ2zCrjm6JFUhKxQkSyykV8IUndoHYVJuuSuZyT3FmhQZnhffDXLLM2bkMl1dY%2BmOEak2nyXadIdB3k%2F7G9rbIclVg%3D%3D (Caused by NewConnectionError('<urllib3.connection.HTTPSConnection object at 0x2b0886885100>: Failed to establish a new connection: [Errno 101] Network is unreachable'))

During handling of the above exception, another exception occurred:

Traceback (most recent call last):
  File "/cluster/home/yutang/miniconda3/lib/python3.9/site-packages/wandb/sdk/internal/internal_api.py", line 2549, in upload_file
    response = self._upload_file_session.put(
  File "/cluster/home/yutang/miniconda3/lib/python3.9/site-packages/requests/sessions.py", line 647, in put
    return self.request("PUT", url, data=data, **kwargs)
  File "/cluster/home/yutang/miniconda3/lib/python3.9/site-packages/requests/sessions.py", line 587, in request
    resp = self.send(prep, **send_kwargs)
  File "/cluster/home/yutang/miniconda3/lib/python3.9/site-packages/requests/sessions.py", line 701, in send
    r = adapter.send(request, **kwargs)
  File "/cluster/home/yutang/miniconda3/lib/python3.9/site-packages/requests/adapters.py", line 565, in send
    raise ConnectionError(e, request=request)
requests.exceptions.ConnectionError: HTTPSConnectionPool(host='storage.googleapis.com', port=443): Max retries exceeded with url: /wandb-artifacts-prod/wandb_artifacts/120300447/667873143/521e54ab95c254e02c4ef790d5def9ec?Expires=1702744038&GoogleAccessId=gorilla-files-url-signer-man%40wandb-production.iam.gserviceaccount.com&Signature=s3vot08iBEXAP00FH%2B6dl9WPoOvaPb25xr0rrLYQdha1xoBTRzpFQErDALKDiaGTY99S8N5eUtpqJVC%2BHxjOxJ%2BqBJBvDD09ET7WGrAgvVP6UftMpj2kVNFaKQTUGEjyw6LntStF2ur%2F8Z2gBujTIsJa%2BdgyyvGLv5R%2BdQzBVerY4mDEcWSbY9cALcB9K2A6GsKgTqXOi13FgsqWC4uNdnLsLEqBLpUmwUrDQmQlKwgGz82nnWsH6RxEHCn%2BIQ2zCrjm6JFUhKxQkSyykV8IUndoHYVJuuSuZyT3FmhQZnhffDXLLM2bkMl1dY%2BmOEak2nyXadIdB3k%2F7G9rbIclVg%3D%3D (Caused by NewConnectionError('<urllib3.connection.HTTPSConnection object at 0x2b0886885100>: Failed to establish a new connection: [Errno 101] Network is unreachable'))

During handling of the above exception, another exception occurred:

Traceback (most recent call last):
  File "/cluster/home/yutang/miniconda3/lib/python3.9/site-packages/wandb/sdk/lib/retry.py", line 131, in __call__
    result = self._call_fn(*args, **kwargs)
  File "/cluster/home/yutang/miniconda3/lib/python3.9/site-packages/wandb/sdk/internal/internal_api.py", line 2580, in upload_file
    raise _e.with_traceback(sys.exc_info()[2])
  File "/cluster/home/yutang/miniconda3/lib/python3.9/site-packages/wandb/sdk/internal/internal_api.py", line 2549, in upload_file
    response = self._upload_file_session.put(
  File "/cluster/home/yutang/miniconda3/lib/python3.9/site-packages/requests/sessions.py", line 647, in put
    return self.request("PUT", url, data=data, **kwargs)
  File "/cluster/home/yutang/miniconda3/lib/python3.9/site-packages/requests/sessions.py", line 587, in request
    resp = self.send(prep, **send_kwargs)
  File "/cluster/home/yutang/miniconda3/lib/python3.9/site-packages/requests/sessions.py", line 701, in send
    r = adapter.send(request, **kwargs)
  File "/cluster/home/yutang/miniconda3/lib/python3.9/site-packages/requests/adapters.py", line 565, in send
    raise ConnectionError(e, request=request)
wandb.sdk.lib.retry.TransientError: None
2023-12-15 17:27:21,709 ERROR   wandb-upload_2:10647 [internal_api.py:upload_file():2556] upload_file exception https://storage.googleapis.com/wandb-artifacts-prod/wandb_artifacts/120300447/667873143/90d3d941acdc730294f7988a60e22317?Expires=1702744038&GoogleAccessId=gorilla-files-url-signer-man%40wandb-production.iam.gserviceaccount.com&Signature=rePB%2B712fkIhge3qBC0mcj%2B4bzYu9zU8hOfzDKBHQ9KEwuYypx2TogOJJa3cctFkj0Wy18glZFlSqcG9SngIKaDUD1%2F0ZqUO3UJZVadFQdm1GnumQ5XY3r%2FFMfDTNyotlYhwdoVKBGx12lRElt89PuxYofUT%2BcfaKKBnBkb57xuQKiP0PC08ufDrIW67qu1MbzLK69SCEVp4lWR%2B89sGCUvabBcAjnTslH9VKun7PQV1VEYjHTey2OK1FuSLR2SEy0k%2FLg6C42r61CVKl5TW3uJ%2BGY3h63CzOxCumsmz2vCDC3GSJmDYWIopEyZQIxn%2FUGF3wk1m%2FR7hRQTFCzYSNw%3D%3D: HTTPSConnectionPool(host='storage.googleapis.com', port=443): Max retries exceeded with url: /wandb-artifacts-prod/wandb_artifacts/120300447/667873143/90d3d941acdc730294f7988a60e22317?Expires=1702744038&GoogleAccessId=gorilla-files-url-signer-man%40wandb-production.iam.gserviceaccount.com&Signature=rePB%2B712fkIhge3qBC0mcj%2B4bzYu9zU8hOfzDKBHQ9KEwuYypx2TogOJJa3cctFkj0Wy18glZFlSqcG9SngIKaDUD1%2F0ZqUO3UJZVadFQdm1GnumQ5XY3r%2FFMfDTNyotlYhwdoVKBGx12lRElt89PuxYofUT%2BcfaKKBnBkb57xuQKiP0PC08ufDrIW67qu1MbzLK69SCEVp4lWR%2B89sGCUvabBcAjnTslH9VKun7PQV1VEYjHTey2OK1FuSLR2SEy0k%2FLg6C42r61CVKl5TW3uJ%2BGY3h63CzOxCumsmz2vCDC3GSJmDYWIopEyZQIxn%2FUGF3wk1m%2FR7hRQTFCzYSNw%3D%3D (Caused by NewConnectionError('<urllib3.connection.HTTPSConnection object at 0x2b08868855e0>: Failed to establish a new connection: [Errno 101] Network is unreachable'))
2023-12-15 17:27:21,709 ERROR   wandb-upload_2:10647 [internal_api.py:upload_file():2558] upload_file request headers: {'User-Agent': 'python-requests/2.28.1', 'Accept-Encoding': 'gzip, deflate, br', 'Accept': '*/*', 'Connection': 'keep-alive', 'Content-MD5': 'kNPZQazccwKU95iKYOIjFw==', 'Content-Type': 'application/json', 'Content-Length': '648'}
2023-12-15 17:27:21,709 ERROR   wandb-upload_2:10647 [internal_api.py:upload_file():2560] upload_file response body: 
2023-12-15 17:27:21,709 INFO    wandb-upload_2:10647 [retry.py:__call__():172] Retry attempt failed:
Traceback (most recent call last):
  File "/cluster/home/yutang/miniconda3/lib/python3.9/site-packages/urllib3/connection.py", line 174, in _new_conn
    conn = connection.create_connection(
  File "/cluster/home/yutang/miniconda3/lib/python3.9/site-packages/urllib3/util/connection.py", line 95, in create_connection
    raise err
  File "/cluster/home/yutang/miniconda3/lib/python3.9/site-packages/urllib3/util/connection.py", line 85, in create_connection
    sock.connect(sa)
OSError: [Errno 101] Network is unreachable

During handling of the above exception, another exception occurred:

Traceback (most recent call last):
  File "/cluster/home/yutang/miniconda3/lib/python3.9/site-packages/urllib3/connectionpool.py", line 703, in urlopen
    httplib_response = self._make_request(
  File "/cluster/home/yutang/miniconda3/lib/python3.9/site-packages/urllib3/connectionpool.py", line 386, in _make_request
    self._validate_conn(conn)
  File "/cluster/home/yutang/miniconda3/lib/python3.9/site-packages/urllib3/connectionpool.py", line 1042, in _validate_conn
    conn.connect()
  File "/cluster/home/yutang/miniconda3/lib/python3.9/site-packages/urllib3/connection.py", line 358, in connect
    self.sock = conn = self._new_conn()
  File "/cluster/home/yutang/miniconda3/lib/python3.9/site-packages/urllib3/connection.py", line 186, in _new_conn
    raise NewConnectionError(
urllib3.exceptions.NewConnectionError: <urllib3.connection.HTTPSConnection object at 0x2b08868855e0>: Failed to establish a new connection: [Errno 101] Network is unreachable

During handling of the above exception, another exception occurred:

Traceback (most recent call last):
  File "/cluster/home/yutang/miniconda3/lib/python3.9/site-packages/requests/adapters.py", line 489, in send
    resp = conn.urlopen(
  File "/cluster/home/yutang/miniconda3/lib/python3.9/site-packages/urllib3/connectionpool.py", line 787, in urlopen
    retries = retries.increment(
  File "/cluster/home/yutang/miniconda3/lib/python3.9/site-packages/urllib3/util/retry.py", line 592, in increment
    raise MaxRetryError(_pool, url, error or ResponseError(cause))
urllib3.exceptions.MaxRetryError: HTTPSConnectionPool(host='storage.googleapis.com', port=443): Max retries exceeded with url: /wandb-artifacts-prod/wandb_artifacts/120300447/667873143/90d3d941acdc730294f7988a60e22317?Expires=1702744038&GoogleAccessId=gorilla-files-url-signer-man%40wandb-production.iam.gserviceaccount.com&Signature=rePB%2B712fkIhge3qBC0mcj%2B4bzYu9zU8hOfzDKBHQ9KEwuYypx2TogOJJa3cctFkj0Wy18glZFlSqcG9SngIKaDUD1%2F0ZqUO3UJZVadFQdm1GnumQ5XY3r%2FFMfDTNyotlYhwdoVKBGx12lRElt89PuxYofUT%2BcfaKKBnBkb57xuQKiP0PC08ufDrIW67qu1MbzLK69SCEVp4lWR%2B89sGCUvabBcAjnTslH9VKun7PQV1VEYjHTey2OK1FuSLR2SEy0k%2FLg6C42r61CVKl5TW3uJ%2BGY3h63CzOxCumsmz2vCDC3GSJmDYWIopEyZQIxn%2FUGF3wk1m%2FR7hRQTFCzYSNw%3D%3D (Caused by NewConnectionError('<urllib3.connection.HTTPSConnection object at 0x2b08868855e0>: Failed to establish a new connection: [Errno 101] Network is unreachable'))

During handling of the above exception, another exception occurred:

Traceback (most recent call last):
  File "/cluster/home/yutang/miniconda3/lib/python3.9/site-packages/wandb/sdk/internal/internal_api.py", line 2549, in upload_file
    response = self._upload_file_session.put(
  File "/cluster/home/yutang/miniconda3/lib/python3.9/site-packages/requests/sessions.py", line 647, in put
    return self.request("PUT", url, data=data, **kwargs)
  File "/cluster/home/yutang/miniconda3/lib/python3.9/site-packages/requests/sessions.py", line 587, in request
    resp = self.send(prep, **send_kwargs)
  File "/cluster/home/yutang/miniconda3/lib/python3.9/site-packages/requests/sessions.py", line 701, in send
    r = adapter.send(request, **kwargs)
  File "/cluster/home/yutang/miniconda3/lib/python3.9/site-packages/requests/adapters.py", line 565, in send
    raise ConnectionError(e, request=request)
requests.exceptions.ConnectionError: HTTPSConnectionPool(host='storage.googleapis.com', port=443): Max retries exceeded with url: /wandb-artifacts-prod/wandb_artifacts/120300447/667873143/90d3d941acdc730294f7988a60e22317?Expires=1702744038&GoogleAccessId=gorilla-files-url-signer-man%40wandb-production.iam.gserviceaccount.com&Signature=rePB%2B712fkIhge3qBC0mcj%2B4bzYu9zU8hOfzDKBHQ9KEwuYypx2TogOJJa3cctFkj0Wy18glZFlSqcG9SngIKaDUD1%2F0ZqUO3UJZVadFQdm1GnumQ5XY3r%2FFMfDTNyotlYhwdoVKBGx12lRElt89PuxYofUT%2BcfaKKBnBkb57xuQKiP0PC08ufDrIW67qu1MbzLK69SCEVp4lWR%2B89sGCUvabBcAjnTslH9VKun7PQV1VEYjHTey2OK1FuSLR2SEy0k%2FLg6C42r61CVKl5TW3uJ%2BGY3h63CzOxCumsmz2vCDC3GSJmDYWIopEyZQIxn%2FUGF3wk1m%2FR7hRQTFCzYSNw%3D%3D (Caused by NewConnectionError('<urllib3.connection.HTTPSConnection object at 0x2b08868855e0>: Failed to establish a new connection: [Errno 101] Network is unreachable'))

During handling of the above exception, another exception occurred:

Traceback (most recent call last):
  File "/cluster/home/yutang/miniconda3/lib/python3.9/site-packages/wandb/sdk/lib/retry.py", line 131, in __call__
    result = self._call_fn(*args, **kwargs)
  File "/cluster/home/yutang/miniconda3/lib/python3.9/site-packages/wandb/sdk/internal/internal_api.py", line 2580, in upload_file
    raise _e.with_traceback(sys.exc_info()[2])
  File "/cluster/home/yutang/miniconda3/lib/python3.9/site-packages/wandb/sdk/internal/internal_api.py", line 2549, in upload_file
    response = self._upload_file_session.put(
  File "/cluster/home/yutang/miniconda3/lib/python3.9/site-packages/requests/sessions.py", line 647, in put
    return self.request("PUT", url, data=data, **kwargs)
  File "/cluster/home/yutang/miniconda3/lib/python3.9/site-packages/requests/sessions.py", line 587, in request
    resp = self.send(prep, **send_kwargs)
  File "/cluster/home/yutang/miniconda3/lib/python3.9/site-packages/requests/sessions.py", line 701, in send
    r = adapter.send(request, **kwargs)
  File "/cluster/home/yutang/miniconda3/lib/python3.9/site-packages/requests/adapters.py", line 565, in send
    raise ConnectionError(e, request=request)
wandb.sdk.lib.retry.TransientError: None
2023-12-15 17:27:24,053 DEBUG   HandlerThread:10647 [handler.py:handle_request():146] handle_request: keepalive
2023-12-15 17:27:25,774 ERROR   wandb-upload_1:10647 [internal_api.py:upload_file():2556] upload_file exception https://storage.googleapis.com/wandb-artifacts-prod/wandb_artifacts/120300447/667873143/521e54ab95c254e02c4ef790d5def9ec?Expires=1702744038&GoogleAccessId=gorilla-files-url-signer-man%40wandb-production.iam.gserviceaccount.com&Signature=s3vot08iBEXAP00FH%2B6dl9WPoOvaPb25xr0rrLYQdha1xoBTRzpFQErDALKDiaGTY99S8N5eUtpqJVC%2BHxjOxJ%2BqBJBvDD09ET7WGrAgvVP6UftMpj2kVNFaKQTUGEjyw6LntStF2ur%2F8Z2gBujTIsJa%2BdgyyvGLv5R%2BdQzBVerY4mDEcWSbY9cALcB9K2A6GsKgTqXOi13FgsqWC4uNdnLsLEqBLpUmwUrDQmQlKwgGz82nnWsH6RxEHCn%2BIQ2zCrjm6JFUhKxQkSyykV8IUndoHYVJuuSuZyT3FmhQZnhffDXLLM2bkMl1dY%2BmOEak2nyXadIdB3k%2F7G9rbIclVg%3D%3D: HTTPSConnectionPool(host='storage.googleapis.com', port=443): Max retries exceeded with url: /wandb-artifacts-prod/wandb_artifacts/120300447/667873143/521e54ab95c254e02c4ef790d5def9ec?Expires=1702744038&GoogleAccessId=gorilla-files-url-signer-man%40wandb-production.iam.gserviceaccount.com&Signature=s3vot08iBEXAP00FH%2B6dl9WPoOvaPb25xr0rrLYQdha1xoBTRzpFQErDALKDiaGTY99S8N5eUtpqJVC%2BHxjOxJ%2BqBJBvDD09ET7WGrAgvVP6UftMpj2kVNFaKQTUGEjyw6LntStF2ur%2F8Z2gBujTIsJa%2BdgyyvGLv5R%2BdQzBVerY4mDEcWSbY9cALcB9K2A6GsKgTqXOi13FgsqWC4uNdnLsLEqBLpUmwUrDQmQlKwgGz82nnWsH6RxEHCn%2BIQ2zCrjm6JFUhKxQkSyykV8IUndoHYVJuuSuZyT3FmhQZnhffDXLLM2bkMl1dY%2BmOEak2nyXadIdB3k%2F7G9rbIclVg%3D%3D (Caused by NewConnectionError('<urllib3.connection.HTTPSConnection object at 0x2b0886880370>: Failed to establish a new connection: [Errno 101] Network is unreachable'))
2023-12-15 17:27:25,774 ERROR   wandb-upload_1:10647 [internal_api.py:upload_file():2558] upload_file request headers: {'User-Agent': 'python-requests/2.28.1', 'Accept-Encoding': 'gzip, deflate, br', 'Accept': '*/*', 'Connection': 'keep-alive', 'Content-MD5': 'Uh5Uq5XCVOAsTveQ1d757A==', 'Content-Type': 'text/plain; charset=utf-8', 'Content-Length': '1820'}
2023-12-15 17:27:25,774 ERROR   wandb-upload_1:10647 [internal_api.py:upload_file():2560] upload_file response body: 
2023-12-15 17:27:26,474 ERROR   wandb-upload_2:10647 [internal_api.py:upload_file():2556] upload_file exception https://storage.googleapis.com/wandb-artifacts-prod/wandb_artifacts/120300447/667873143/90d3d941acdc730294f7988a60e22317?Expires=1702744038&GoogleAccessId=gorilla-files-url-signer-man%40wandb-production.iam.gserviceaccount.com&Signature=rePB%2B712fkIhge3qBC0mcj%2B4bzYu9zU8hOfzDKBHQ9KEwuYypx2TogOJJa3cctFkj0Wy18glZFlSqcG9SngIKaDUD1%2F0ZqUO3UJZVadFQdm1GnumQ5XY3r%2FFMfDTNyotlYhwdoVKBGx12lRElt89PuxYofUT%2BcfaKKBnBkb57xuQKiP0PC08ufDrIW67qu1MbzLK69SCEVp4lWR%2B89sGCUvabBcAjnTslH9VKun7PQV1VEYjHTey2OK1FuSLR2SEy0k%2FLg6C42r61CVKl5TW3uJ%2BGY3h63CzOxCumsmz2vCDC3GSJmDYWIopEyZQIxn%2FUGF3wk1m%2FR7hRQTFCzYSNw%3D%3D: HTTPSConnectionPool(host='storage.googleapis.com', port=443): Max retries exceeded with url: /wandb-artifacts-prod/wandb_artifacts/120300447/667873143/90d3d941acdc730294f7988a60e22317?Expires=1702744038&GoogleAccessId=gorilla-files-url-signer-man%40wandb-production.iam.gserviceaccount.com&Signature=rePB%2B712fkIhge3qBC0mcj%2B4bzYu9zU8hOfzDKBHQ9KEwuYypx2TogOJJa3cctFkj0Wy18glZFlSqcG9SngIKaDUD1%2F0ZqUO3UJZVadFQdm1GnumQ5XY3r%2FFMfDTNyotlYhwdoVKBGx12lRElt89PuxYofUT%2BcfaKKBnBkb57xuQKiP0PC08ufDrIW67qu1MbzLK69SCEVp4lWR%2B89sGCUvabBcAjnTslH9VKun7PQV1VEYjHTey2OK1FuSLR2SEy0k%2FLg6C42r61CVKl5TW3uJ%2BGY3h63CzOxCumsmz2vCDC3GSJmDYWIopEyZQIxn%2FUGF3wk1m%2FR7hRQTFCzYSNw%3D%3D (Caused by NewConnectionError('<urllib3.connection.HTTPSConnection object at 0x2b08868803d0>: Failed to establish a new connection: [Errno 101] Network is unreachable'))
2023-12-15 17:27:26,474 ERROR   wandb-upload_2:10647 [internal_api.py:upload_file():2558] upload_file request headers: {'User-Agent': 'python-requests/2.28.1', 'Accept-Encoding': 'gzip, deflate, br', 'Accept': '*/*', 'Connection': 'keep-alive', 'Content-MD5': 'kNPZQazccwKU95iKYOIjFw==', 'Content-Type': 'application/json', 'Content-Length': '648'}
2023-12-15 17:27:26,474 ERROR   wandb-upload_2:10647 [internal_api.py:upload_file():2560] upload_file response body: 
2023-12-15 17:27:29,055 DEBUG   HandlerThread:10647 [handler.py:handle_request():146] handle_request: keepalive
2023-12-15 17:27:30,572 ERROR   wandb-upload_0:10647 [internal_api.py:upload_file():2556] upload_file exception https://storage.googleapis.com/wandb-production.appspot.com/bryant-tang-ethz/DKT-trial%201/9eekgqhp/wandb-metadata.json?Expires=1702744033&GoogleAccessId=gorilla-files-url-signer-man%40wandb-production.iam.gserviceaccount.com&Signature=fegoYMfhWi%2BTDz1a3zzHD%2BIbpiF53bhEtxIb5YVugk308fWYTH%2F%2BhSserivSmCe7AQn3fJqp%2FRbigYGriOxJpUOZrCILoVCr4kBJ8%2FGvSIB9rqRZMh1OzJMPmYweNifG9ftvLeh2M6I8IyURJr5AmrXijbGIt%2FwmyGuNU2a%2F1idrbqxSqI49rNpcoiLkHz8GFGR4IVSarZwWRBBjICqH2BKdjsmQ33%2Bm2r1264r8ewh%2FDbwZn3V2wuDOFdj1UoKaXBOt1JCStB1ksp9yPnORFJ10JgbR5oavFEdnfE7qO33B4MMgqwPjhQRq65jOuU0oPRfInKK3%2B9AmtoO%2BHksEEQ%3D%3D: HTTPSConnectionPool(host='storage.googleapis.com', port=443): Max retries exceeded with url: /wandb-production.appspot.com/bryant-tang-ethz/DKT-trial%201/9eekgqhp/wandb-metadata.json?Expires=1702744033&GoogleAccessId=gorilla-files-url-signer-man%40wandb-production.iam.gserviceaccount.com&Signature=fegoYMfhWi%2BTDz1a3zzHD%2BIbpiF53bhEtxIb5YVugk308fWYTH%2F%2BhSserivSmCe7AQn3fJqp%2FRbigYGriOxJpUOZrCILoVCr4kBJ8%2FGvSIB9rqRZMh1OzJMPmYweNifG9ftvLeh2M6I8IyURJr5AmrXijbGIt%2FwmyGuNU2a%2F1idrbqxSqI49rNpcoiLkHz8GFGR4IVSarZwWRBBjICqH2BKdjsmQ33%2Bm2r1264r8ewh%2FDbwZn3V2wuDOFdj1UoKaXBOt1JCStB1ksp9yPnORFJ10JgbR5oavFEdnfE7qO33B4MMgqwPjhQRq65jOuU0oPRfInKK3%2B9AmtoO%2BHksEEQ%3D%3D (Caused by NewConnectionError('<urllib3.connection.HTTPSConnection object at 0x2b0886876730>: Failed to establish a new connection: [Errno 101] Network is unreachable'))
2023-12-15 17:27:30,572 ERROR   wandb-upload_0:10647 [internal_api.py:upload_file():2558] upload_file request headers: {'User-Agent': 'python-requests/2.28.1', 'Accept-Encoding': 'gzip, deflate, br', 'Accept': '*/*', 'Connection': 'keep-alive', 'Content-Length': '14827'}
2023-12-15 17:27:30,572 ERROR   wandb-upload_0:10647 [internal_api.py:upload_file():2560] upload_file response body: 
2023-12-15 17:27:33,886 ERROR   wandb-upload_1:10647 [internal_api.py:upload_file():2556] upload_file exception https://storage.googleapis.com/wandb-artifacts-prod/wandb_artifacts/120300447/667873143/521e54ab95c254e02c4ef790d5def9ec?Expires=1702744038&GoogleAccessId=gorilla-files-url-signer-man%40wandb-production.iam.gserviceaccount.com&Signature=s3vot08iBEXAP00FH%2B6dl9WPoOvaPb25xr0rrLYQdha1xoBTRzpFQErDALKDiaGTY99S8N5eUtpqJVC%2BHxjOxJ%2BqBJBvDD09ET7WGrAgvVP6UftMpj2kVNFaKQTUGEjyw6LntStF2ur%2F8Z2gBujTIsJa%2BdgyyvGLv5R%2BdQzBVerY4mDEcWSbY9cALcB9K2A6GsKgTqXOi13FgsqWC4uNdnLsLEqBLpUmwUrDQmQlKwgGz82nnWsH6RxEHCn%2BIQ2zCrjm6JFUhKxQkSyykV8IUndoHYVJuuSuZyT3FmhQZnhffDXLLM2bkMl1dY%2BmOEak2nyXadIdB3k%2F7G9rbIclVg%3D%3D: HTTPSConnectionPool(host='storage.googleapis.com', port=443): Max retries exceeded with url: /wandb-artifacts-prod/wandb_artifacts/120300447/667873143/521e54ab95c254e02c4ef790d5def9ec?Expires=1702744038&GoogleAccessId=gorilla-files-url-signer-man%40wandb-production.iam.gserviceaccount.com&Signature=s3vot08iBEXAP00FH%2B6dl9WPoOvaPb25xr0rrLYQdha1xoBTRzpFQErDALKDiaGTY99S8N5eUtpqJVC%2BHxjOxJ%2BqBJBvDD09ET7WGrAgvVP6UftMpj2kVNFaKQTUGEjyw6LntStF2ur%2F8Z2gBujTIsJa%2BdgyyvGLv5R%2BdQzBVerY4mDEcWSbY9cALcB9K2A6GsKgTqXOi13FgsqWC4uNdnLsLEqBLpUmwUrDQmQlKwgGz82nnWsH6RxEHCn%2BIQ2zCrjm6JFUhKxQkSyykV8IUndoHYVJuuSuZyT3FmhQZnhffDXLLM2bkMl1dY%2BmOEak2nyXadIdB3k%2F7G9rbIclVg%3D%3D (Caused by NewConnectionError('<urllib3.connection.HTTPSConnection object at 0x2b08868856a0>: Failed to establish a new connection: [Errno 101] Network is unreachable'))
2023-12-15 17:27:33,886 ERROR   wandb-upload_1:10647 [internal_api.py:upload_file():2558] upload_file request headers: {'User-Agent': 'python-requests/2.28.1', 'Accept-Encoding': 'gzip, deflate, br', 'Accept': '*/*', 'Connection': 'keep-alive', 'Content-MD5': 'Uh5Uq5XCVOAsTveQ1d757A==', 'Content-Type': 'text/plain; charset=utf-8', 'Content-Length': '1820'}
2023-12-15 17:27:33,886 ERROR   wandb-upload_1:10647 [internal_api.py:upload_file():2560] upload_file response body: 
2023-12-15 17:27:34,056 DEBUG   HandlerThread:10647 [handler.py:handle_request():146] handle_request: keepalive
2023-12-15 17:27:35,969 ERROR   wandb-upload_2:10647 [internal_api.py:upload_file():2556] upload_file exception https://storage.googleapis.com/wandb-artifacts-prod/wandb_artifacts/120300447/667873143/90d3d941acdc730294f7988a60e22317?Expires=1702744038&GoogleAccessId=gorilla-files-url-signer-man%40wandb-production.iam.gserviceaccount.com&Signature=rePB%2B712fkIhge3qBC0mcj%2B4bzYu9zU8hOfzDKBHQ9KEwuYypx2TogOJJa3cctFkj0Wy18glZFlSqcG9SngIKaDUD1%2F0ZqUO3UJZVadFQdm1GnumQ5XY3r%2FFMfDTNyotlYhwdoVKBGx12lRElt89PuxYofUT%2BcfaKKBnBkb57xuQKiP0PC08ufDrIW67qu1MbzLK69SCEVp4lWR%2B89sGCUvabBcAjnTslH9VKun7PQV1VEYjHTey2OK1FuSLR2SEy0k%2FLg6C42r61CVKl5TW3uJ%2BGY3h63CzOxCumsmz2vCDC3GSJmDYWIopEyZQIxn%2FUGF3wk1m%2FR7hRQTFCzYSNw%3D%3D: HTTPSConnectionPool(host='storage.googleapis.com', port=443): Max retries exceeded with url: /wandb-artifacts-prod/wandb_artifacts/120300447/667873143/90d3d941acdc730294f7988a60e22317?Expires=1702744038&GoogleAccessId=gorilla-files-url-signer-man%40wandb-production.iam.gserviceaccount.com&Signature=rePB%2B712fkIhge3qBC0mcj%2B4bzYu9zU8hOfzDKBHQ9KEwuYypx2TogOJJa3cctFkj0Wy18glZFlSqcG9SngIKaDUD1%2F0ZqUO3UJZVadFQdm1GnumQ5XY3r%2FFMfDTNyotlYhwdoVKBGx12lRElt89PuxYofUT%2BcfaKKBnBkb57xuQKiP0PC08ufDrIW67qu1MbzLK69SCEVp4lWR%2B89sGCUvabBcAjnTslH9VKun7PQV1VEYjHTey2OK1FuSLR2SEy0k%2FLg6C42r61CVKl5TW3uJ%2BGY3h63CzOxCumsmz2vCDC3GSJmDYWIopEyZQIxn%2FUGF3wk1m%2FR7hRQTFCzYSNw%3D%3D (Caused by NewConnectionError('<urllib3.connection.HTTPSConnection object at 0x2b0886885d30>: Failed to establish a new connection: [Errno 101] Network is unreachable'))
2023-12-15 17:27:35,969 ERROR   wandb-upload_2:10647 [internal_api.py:upload_file():2558] upload_file request headers: {'User-Agent': 'python-requests/2.28.1', 'Accept-Encoding': 'gzip, deflate, br', 'Accept': '*/*', 'Connection': 'keep-alive', 'Content-MD5': 'kNPZQazccwKU95iKYOIjFw==', 'Content-Type': 'application/json', 'Content-Length': '648'}
2023-12-15 17:27:35,969 ERROR   wandb-upload_2:10647 [internal_api.py:upload_file():2560] upload_file response body: 
2023-12-15 17:27:39,058 DEBUG   HandlerThread:10647 [handler.py:handle_request():146] handle_request: keepalive
2023-12-15 17:27:44,060 DEBUG   HandlerThread:10647 [handler.py:handle_request():146] handle_request: keepalive
2023-12-15 17:27:49,061 DEBUG   HandlerThread:10647 [handler.py:handle_request():146] handle_request: keepalive
2023-12-15 17:27:49,466 ERROR   wandb-upload_0:10647 [internal_api.py:upload_file():2556] upload_file exception https://storage.googleapis.com/wandb-production.appspot.com/bryant-tang-ethz/DKT-trial%201/9eekgqhp/wandb-metadata.json?Expires=1702744033&GoogleAccessId=gorilla-files-url-signer-man%40wandb-production.iam.gserviceaccount.com&Signature=fegoYMfhWi%2BTDz1a3zzHD%2BIbpiF53bhEtxIb5YVugk308fWYTH%2F%2BhSserivSmCe7AQn3fJqp%2FRbigYGriOxJpUOZrCILoVCr4kBJ8%2FGvSIB9rqRZMh1OzJMPmYweNifG9ftvLeh2M6I8IyURJr5AmrXijbGIt%2FwmyGuNU2a%2F1idrbqxSqI49rNpcoiLkHz8GFGR4IVSarZwWRBBjICqH2BKdjsmQ33%2Bm2r1264r8ewh%2FDbwZn3V2wuDOFdj1UoKaXBOt1JCStB1ksp9yPnORFJ10JgbR5oavFEdnfE7qO33B4MMgqwPjhQRq65jOuU0oPRfInKK3%2B9AmtoO%2BHksEEQ%3D%3D: HTTPSConnectionPool(host='storage.googleapis.com', port=443): Max retries exceeded with url: /wandb-production.appspot.com/bryant-tang-ethz/DKT-trial%201/9eekgqhp/wandb-metadata.json?Expires=1702744033&GoogleAccessId=gorilla-files-url-signer-man%40wandb-production.iam.gserviceaccount.com&Signature=fegoYMfhWi%2BTDz1a3zzHD%2BIbpiF53bhEtxIb5YVugk308fWYTH%2F%2BhSserivSmCe7AQn3fJqp%2FRbigYGriOxJpUOZrCILoVCr4kBJ8%2FGvSIB9rqRZMh1OzJMPmYweNifG9ftvLeh2M6I8IyURJr5AmrXijbGIt%2FwmyGuNU2a%2F1idrbqxSqI49rNpcoiLkHz8GFGR4IVSarZwWRBBjICqH2BKdjsmQ33%2Bm2r1264r8ewh%2FDbwZn3V2wuDOFdj1UoKaXBOt1JCStB1ksp9yPnORFJ10JgbR5oavFEdnfE7qO33B4MMgqwPjhQRq65jOuU0oPRfInKK3%2B9AmtoO%2BHksEEQ%3D%3D (Caused by NewConnectionError('<urllib3.connection.HTTPSConnection object at 0x2b088688ddf0>: Failed to establish a new connection: [Errno 101] Network is unreachable'))
2023-12-15 17:27:49,466 ERROR   wandb-upload_0:10647 [internal_api.py:upload_file():2558] upload_file request headers: {'User-Agent': 'python-requests/2.28.1', 'Accept-Encoding': 'gzip, deflate, br', 'Accept': '*/*', 'Connection': 'keep-alive', 'Content-Length': '14827'}
2023-12-15 17:27:49,466 ERROR   wandb-upload_0:10647 [internal_api.py:upload_file():2560] upload_file response body: 
2023-12-15 17:27:53,487 ERROR   wandb-upload_1:10647 [internal_api.py:upload_file():2556] upload_file exception https://storage.googleapis.com/wandb-artifacts-prod/wandb_artifacts/120300447/667873143/521e54ab95c254e02c4ef790d5def9ec?Expires=1702744038&GoogleAccessId=gorilla-files-url-signer-man%40wandb-production.iam.gserviceaccount.com&Signature=s3vot08iBEXAP00FH%2B6dl9WPoOvaPb25xr0rrLYQdha1xoBTRzpFQErDALKDiaGTY99S8N5eUtpqJVC%2BHxjOxJ%2BqBJBvDD09ET7WGrAgvVP6UftMpj2kVNFaKQTUGEjyw6LntStF2ur%2F8Z2gBujTIsJa%2BdgyyvGLv5R%2BdQzBVerY4mDEcWSbY9cALcB9K2A6GsKgTqXOi13FgsqWC4uNdnLsLEqBLpUmwUrDQmQlKwgGz82nnWsH6RxEHCn%2BIQ2zCrjm6JFUhKxQkSyykV8IUndoHYVJuuSuZyT3FmhQZnhffDXLLM2bkMl1dY%2BmOEak2nyXadIdB3k%2F7G9rbIclVg%3D%3D: HTTPSConnectionPool(host='storage.googleapis.com', port=443): Max retries exceeded with url: /wandb-artifacts-prod/wandb_artifacts/120300447/667873143/521e54ab95c254e02c4ef790d5def9ec?Expires=1702744038&GoogleAccessId=gorilla-files-url-signer-man%40wandb-production.iam.gserviceaccount.com&Signature=s3vot08iBEXAP00FH%2B6dl9WPoOvaPb25xr0rrLYQdha1xoBTRzpFQErDALKDiaGTY99S8N5eUtpqJVC%2BHxjOxJ%2BqBJBvDD09ET7WGrAgvVP6UftMpj2kVNFaKQTUGEjyw6LntStF2ur%2F8Z2gBujTIsJa%2BdgyyvGLv5R%2BdQzBVerY4mDEcWSbY9cALcB9K2A6GsKgTqXOi13FgsqWC4uNdnLsLEqBLpUmwUrDQmQlKwgGz82nnWsH6RxEHCn%2BIQ2zCrjm6JFUhKxQkSyykV8IUndoHYVJuuSuZyT3FmhQZnhffDXLLM2bkMl1dY%2BmOEak2nyXadIdB3k%2F7G9rbIclVg%3D%3D (Caused by NewConnectionError('<urllib3.connection.HTTPSConnection object at 0x2b088688d4c0>: Failed to establish a new connection: [Errno 101] Network is unreachable'))
2023-12-15 17:27:53,488 ERROR   wandb-upload_1:10647 [internal_api.py:upload_file():2558] upload_file request headers: {'User-Agent': 'python-requests/2.28.1', 'Accept-Encoding': 'gzip, deflate, br', 'Accept': '*/*', 'Connection': 'keep-alive', 'Content-MD5': 'Uh5Uq5XCVOAsTveQ1d757A==', 'Content-Type': 'text/plain; charset=utf-8', 'Content-Length': '1820'}
2023-12-15 17:27:53,488 ERROR   wandb-upload_1:10647 [internal_api.py:upload_file():2560] upload_file response body: 
2023-12-15 17:27:54,063 DEBUG   HandlerThread:10647 [handler.py:handle_request():146] handle_request: keepalive
2023-12-15 17:27:55,949 ERROR   wandb-upload_2:10647 [internal_api.py:upload_file():2556] upload_file exception https://storage.googleapis.com/wandb-artifacts-prod/wandb_artifacts/120300447/667873143/90d3d941acdc730294f7988a60e22317?Expires=1702744038&GoogleAccessId=gorilla-files-url-signer-man%40wandb-production.iam.gserviceaccount.com&Signature=rePB%2B712fkIhge3qBC0mcj%2B4bzYu9zU8hOfzDKBHQ9KEwuYypx2TogOJJa3cctFkj0Wy18glZFlSqcG9SngIKaDUD1%2F0ZqUO3UJZVadFQdm1GnumQ5XY3r%2FFMfDTNyotlYhwdoVKBGx12lRElt89PuxYofUT%2BcfaKKBnBkb57xuQKiP0PC08ufDrIW67qu1MbzLK69SCEVp4lWR%2B89sGCUvabBcAjnTslH9VKun7PQV1VEYjHTey2OK1FuSLR2SEy0k%2FLg6C42r61CVKl5TW3uJ%2BGY3h63CzOxCumsmz2vCDC3GSJmDYWIopEyZQIxn%2FUGF3wk1m%2FR7hRQTFCzYSNw%3D%3D: HTTPSConnectionPool(host='storage.googleapis.com', port=443): Max retries exceeded with url: /wandb-artifacts-prod/wandb_artifacts/120300447/667873143/90d3d941acdc730294f7988a60e22317?Expires=1702744038&GoogleAccessId=gorilla-files-url-signer-man%40wandb-production.iam.gserviceaccount.com&Signature=rePB%2B712fkIhge3qBC0mcj%2B4bzYu9zU8hOfzDKBHQ9KEwuYypx2TogOJJa3cctFkj0Wy18glZFlSqcG9SngIKaDUD1%2F0ZqUO3UJZVadFQdm1GnumQ5XY3r%2FFMfDTNyotlYhwdoVKBGx12lRElt89PuxYofUT%2BcfaKKBnBkb57xuQKiP0PC08ufDrIW67qu1MbzLK69SCEVp4lWR%2B89sGCUvabBcAjnTslH9VKun7PQV1VEYjHTey2OK1FuSLR2SEy0k%2FLg6C42r61CVKl5TW3uJ%2BGY3h63CzOxCumsmz2vCDC3GSJmDYWIopEyZQIxn%2FUGF3wk1m%2FR7hRQTFCzYSNw%3D%3D (Caused by NewConnectionError('<urllib3.connection.HTTPSConnection object at 0x2b088688db20>: Failed to establish a new connection: [Errno 101] Network is unreachable'))
2023-12-15 17:27:55,949 ERROR   wandb-upload_2:10647 [internal_api.py:upload_file():2558] upload_file request headers: {'User-Agent': 'python-requests/2.28.1', 'Accept-Encoding': 'gzip, deflate, br', 'Accept': '*/*', 'Connection': 'keep-alive', 'Content-MD5': 'kNPZQazccwKU95iKYOIjFw==', 'Content-Type': 'application/json', 'Content-Length': '648'}
2023-12-15 17:27:55,949 ERROR   wandb-upload_2:10647 [internal_api.py:upload_file():2560] upload_file response body: 
2023-12-15 17:27:59,065 DEBUG   HandlerThread:10647 [handler.py:handle_request():146] handle_request: keepalive
2023-12-15 17:28:04,066 DEBUG   HandlerThread:10647 [handler.py:handle_request():146] handle_request: keepalive
2023-12-15 17:28:09,068 DEBUG   HandlerThread:10647 [handler.py:handle_request():146] handle_request: keepalive
2023-12-15 17:28:14,070 DEBUG   HandlerThread:10647 [handler.py:handle_request():146] handle_request: keepalive
2023-12-15 17:28:19,071 DEBUG   HandlerThread:10647 [handler.py:handle_request():146] handle_request: keepalive
2023-12-15 17:28:22,301 ERROR   wandb-upload_0:10647 [internal_api.py:upload_file():2556] upload_file exception https://storage.googleapis.com/wandb-production.appspot.com/bryant-tang-ethz/DKT-trial%201/9eekgqhp/wandb-metadata.json?Expires=1702744033&GoogleAccessId=gorilla-files-url-signer-man%40wandb-production.iam.gserviceaccount.com&Signature=fegoYMfhWi%2BTDz1a3zzHD%2BIbpiF53bhEtxIb5YVugk308fWYTH%2F%2BhSserivSmCe7AQn3fJqp%2FRbigYGriOxJpUOZrCILoVCr4kBJ8%2FGvSIB9rqRZMh1OzJMPmYweNifG9ftvLeh2M6I8IyURJr5AmrXijbGIt%2FwmyGuNU2a%2F1idrbqxSqI49rNpcoiLkHz8GFGR4IVSarZwWRBBjICqH2BKdjsmQ33%2Bm2r1264r8ewh%2FDbwZn3V2wuDOFdj1UoKaXBOt1JCStB1ksp9yPnORFJ10JgbR5oavFEdnfE7qO33B4MMgqwPjhQRq65jOuU0oPRfInKK3%2B9AmtoO%2BHksEEQ%3D%3D: HTTPSConnectionPool(host='storage.googleapis.com', port=443): Max retries exceeded with url: /wandb-production.appspot.com/bryant-tang-ethz/DKT-trial%201/9eekgqhp/wandb-metadata.json?Expires=1702744033&GoogleAccessId=gorilla-files-url-signer-man%40wandb-production.iam.gserviceaccount.com&Signature=fegoYMfhWi%2BTDz1a3zzHD%2BIbpiF53bhEtxIb5YVugk308fWYTH%2F%2BhSserivSmCe7AQn3fJqp%2FRbigYGriOxJpUOZrCILoVCr4kBJ8%2FGvSIB9rqRZMh1OzJMPmYweNifG9ftvLeh2M6I8IyURJr5AmrXijbGIt%2FwmyGuNU2a%2F1idrbqxSqI49rNpcoiLkHz8GFGR4IVSarZwWRBBjICqH2BKdjsmQ33%2Bm2r1264r8ewh%2FDbwZn3V2wuDOFdj1UoKaXBOt1JCStB1ksp9yPnORFJ10JgbR5oavFEdnfE7qO33B4MMgqwPjhQRq65jOuU0oPRfInKK3%2B9AmtoO%2BHksEEQ%3D%3D (Caused by NewConnectionError('<urllib3.connection.HTTPSConnection object at 0x2b08868801c0>: Failed to establish a new connection: [Errno 101] Network is unreachable'))
2023-12-15 17:28:22,301 ERROR   wandb-upload_0:10647 [internal_api.py:upload_file():2558] upload_file request headers: {'User-Agent': 'python-requests/2.28.1', 'Accept-Encoding': 'gzip, deflate, br', 'Accept': '*/*', 'Connection': 'keep-alive', 'Content-Length': '14827'}
2023-12-15 17:28:22,301 ERROR   wandb-upload_0:10647 [internal_api.py:upload_file():2560] upload_file response body: 
2023-12-15 17:28:24,073 DEBUG   HandlerThread:10647 [handler.py:handle_request():146] handle_request: keepalive
2023-12-15 17:28:26,142 ERROR   wandb-upload_1:10647 [internal_api.py:upload_file():2556] upload_file exception https://storage.googleapis.com/wandb-artifacts-prod/wandb_artifacts/120300447/667873143/521e54ab95c254e02c4ef790d5def9ec?Expires=1702744038&GoogleAccessId=gorilla-files-url-signer-man%40wandb-production.iam.gserviceaccount.com&Signature=s3vot08iBEXAP00FH%2B6dl9WPoOvaPb25xr0rrLYQdha1xoBTRzpFQErDALKDiaGTY99S8N5eUtpqJVC%2BHxjOxJ%2BqBJBvDD09ET7WGrAgvVP6UftMpj2kVNFaKQTUGEjyw6LntStF2ur%2F8Z2gBujTIsJa%2BdgyyvGLv5R%2BdQzBVerY4mDEcWSbY9cALcB9K2A6GsKgTqXOi13FgsqWC4uNdnLsLEqBLpUmwUrDQmQlKwgGz82nnWsH6RxEHCn%2BIQ2zCrjm6JFUhKxQkSyykV8IUndoHYVJuuSuZyT3FmhQZnhffDXLLM2bkMl1dY%2BmOEak2nyXadIdB3k%2F7G9rbIclVg%3D%3D: HTTPSConnectionPool(host='storage.googleapis.com', port=443): Max retries exceeded with url: /wandb-artifacts-prod/wandb_artifacts/120300447/667873143/521e54ab95c254e02c4ef790d5def9ec?Expires=1702744038&GoogleAccessId=gorilla-files-url-signer-man%40wandb-production.iam.gserviceaccount.com&Signature=s3vot08iBEXAP00FH%2B6dl9WPoOvaPb25xr0rrLYQdha1xoBTRzpFQErDALKDiaGTY99S8N5eUtpqJVC%2BHxjOxJ%2BqBJBvDD09ET7WGrAgvVP6UftMpj2kVNFaKQTUGEjyw6LntStF2ur%2F8Z2gBujTIsJa%2BdgyyvGLv5R%2BdQzBVerY4mDEcWSbY9cALcB9K2A6GsKgTqXOi13FgsqWC4uNdnLsLEqBLpUmwUrDQmQlKwgGz82nnWsH6RxEHCn%2BIQ2zCrjm6JFUhKxQkSyykV8IUndoHYVJuuSuZyT3FmhQZnhffDXLLM2bkMl1dY%2BmOEak2nyXadIdB3k%2F7G9rbIclVg%3D%3D (Caused by NewConnectionError('<urllib3.connection.HTTPSConnection object at 0x2b0886885b80>: Failed to establish a new connection: [Errno 101] Network is unreachable'))
2023-12-15 17:28:26,142 ERROR   wandb-upload_1:10647 [internal_api.py:upload_file():2558] upload_file request headers: {'User-Agent': 'python-requests/2.28.1', 'Accept-Encoding': 'gzip, deflate, br', 'Accept': '*/*', 'Connection': 'keep-alive', 'Content-MD5': 'Uh5Uq5XCVOAsTveQ1d757A==', 'Content-Type': 'text/plain; charset=utf-8', 'Content-Length': '1820'}
2023-12-15 17:28:26,142 ERROR   wandb-upload_1:10647 [internal_api.py:upload_file():2560] upload_file response body: 
2023-12-15 17:28:29,075 DEBUG   HandlerThread:10647 [handler.py:handle_request():146] handle_request: keepalive
2023-12-15 17:28:34,076 DEBUG   HandlerThread:10647 [handler.py:handle_request():146] handle_request: keepalive
2023-12-15 17:28:34,227 ERROR   wandb-upload_2:10647 [internal_api.py:upload_file():2556] upload_file exception https://storage.googleapis.com/wandb-artifacts-prod/wandb_artifacts/120300447/667873143/90d3d941acdc730294f7988a60e22317?Expires=1702744038&GoogleAccessId=gorilla-files-url-signer-man%40wandb-production.iam.gserviceaccount.com&Signature=rePB%2B712fkIhge3qBC0mcj%2B4bzYu9zU8hOfzDKBHQ9KEwuYypx2TogOJJa3cctFkj0Wy18glZFlSqcG9SngIKaDUD1%2F0ZqUO3UJZVadFQdm1GnumQ5XY3r%2FFMfDTNyotlYhwdoVKBGx12lRElt89PuxYofUT%2BcfaKKBnBkb57xuQKiP0PC08ufDrIW67qu1MbzLK69SCEVp4lWR%2B89sGCUvabBcAjnTslH9VKun7PQV1VEYjHTey2OK1FuSLR2SEy0k%2FLg6C42r61CVKl5TW3uJ%2BGY3h63CzOxCumsmz2vCDC3GSJmDYWIopEyZQIxn%2FUGF3wk1m%2FR7hRQTFCzYSNw%3D%3D: HTTPSConnectionPool(host='storage.googleapis.com', port=443): Max retries exceeded with url: /wandb-artifacts-prod/wandb_artifacts/120300447/667873143/90d3d941acdc730294f7988a60e22317?Expires=1702744038&GoogleAccessId=gorilla-files-url-signer-man%40wandb-production.iam.gserviceaccount.com&Signature=rePB%2B712fkIhge3qBC0mcj%2B4bzYu9zU8hOfzDKBHQ9KEwuYypx2TogOJJa3cctFkj0Wy18glZFlSqcG9SngIKaDUD1%2F0ZqUO3UJZVadFQdm1GnumQ5XY3r%2FFMfDTNyotlYhwdoVKBGx12lRElt89PuxYofUT%2BcfaKKBnBkb57xuQKiP0PC08ufDrIW67qu1MbzLK69SCEVp4lWR%2B89sGCUvabBcAjnTslH9VKun7PQV1VEYjHTey2OK1FuSLR2SEy0k%2FLg6C42r61CVKl5TW3uJ%2BGY3h63CzOxCumsmz2vCDC3GSJmDYWIopEyZQIxn%2FUGF3wk1m%2FR7hRQTFCzYSNw%3D%3D (Caused by NewConnectionError('<urllib3.connection.HTTPSConnection object at 0x2b0886885b20>: Failed to establish a new connection: [Errno 101] Network is unreachable'))
2023-12-15 17:28:34,227 ERROR   wandb-upload_2:10647 [internal_api.py:upload_file():2558] upload_file request headers: {'User-Agent': 'python-requests/2.28.1', 'Accept-Encoding': 'gzip, deflate, br', 'Accept': '*/*', 'Connection': 'keep-alive', 'Content-MD5': 'kNPZQazccwKU95iKYOIjFw==', 'Content-Type': 'application/json', 'Content-Length': '648'}
2023-12-15 17:28:34,227 ERROR   wandb-upload_2:10647 [internal_api.py:upload_file():2560] upload_file response body: 
2023-12-15 17:28:39,078 DEBUG   HandlerThread:10647 [handler.py:handle_request():146] handle_request: keepalive
2023-12-15 17:28:44,080 DEBUG   HandlerThread:10647 [handler.py:handle_request():146] handle_request: keepalive
2023-12-15 17:28:49,081 DEBUG   HandlerThread:10647 [handler.py:handle_request():146] handle_request: keepalive
2023-12-15 17:28:54,083 DEBUG   HandlerThread:10647 [handler.py:handle_request():146] handle_request: keepalive
2023-12-15 17:28:59,085 DEBUG   HandlerThread:10647 [handler.py:handle_request():146] handle_request: keepalive
2023-12-15 17:29:04,086 DEBUG   HandlerThread:10647 [handler.py:handle_request():146] handle_request: keepalive
2023-12-15 17:29:09,088 DEBUG   HandlerThread:10647 [handler.py:handle_request():146] handle_request: keepalive
2023-12-15 17:29:14,089 DEBUG   HandlerThread:10647 [handler.py:handle_request():146] handle_request: keepalive
2023-12-15 17:29:19,091 DEBUG   HandlerThread:10647 [handler.py:handle_request():146] handle_request: keepalive
2023-12-15 17:29:24,093 DEBUG   HandlerThread:10647 [handler.py:handle_request():146] handle_request: keepalive
2023-12-15 17:29:29,094 DEBUG   HandlerThread:10647 [handler.py:handle_request():146] handle_request: keepalive
2023-12-15 17:29:34,096 DEBUG   HandlerThread:10647 [handler.py:handle_request():146] handle_request: keepalive
2023-12-15 17:29:38,680 ERROR   wandb-upload_0:10647 [internal_api.py:upload_file():2556] upload_file exception https://storage.googleapis.com/wandb-production.appspot.com/bryant-tang-ethz/DKT-trial%201/9eekgqhp/wandb-metadata.json?Expires=1702744033&GoogleAccessId=gorilla-files-url-signer-man%40wandb-production.iam.gserviceaccount.com&Signature=fegoYMfhWi%2BTDz1a3zzHD%2BIbpiF53bhEtxIb5YVugk308fWYTH%2F%2BhSserivSmCe7AQn3fJqp%2FRbigYGriOxJpUOZrCILoVCr4kBJ8%2FGvSIB9rqRZMh1OzJMPmYweNifG9ftvLeh2M6I8IyURJr5AmrXijbGIt%2FwmyGuNU2a%2F1idrbqxSqI49rNpcoiLkHz8GFGR4IVSarZwWRBBjICqH2BKdjsmQ33%2Bm2r1264r8ewh%2FDbwZn3V2wuDOFdj1UoKaXBOt1JCStB1ksp9yPnORFJ10JgbR5oavFEdnfE7qO33B4MMgqwPjhQRq65jOuU0oPRfInKK3%2B9AmtoO%2BHksEEQ%3D%3D: HTTPSConnectionPool(host='storage.googleapis.com', port=443): Max retries exceeded with url: /wandb-production.appspot.com/bryant-tang-ethz/DKT-trial%201/9eekgqhp/wandb-metadata.json?Expires=1702744033&GoogleAccessId=gorilla-files-url-signer-man%40wandb-production.iam.gserviceaccount.com&Signature=fegoYMfhWi%2BTDz1a3zzHD%2BIbpiF53bhEtxIb5YVugk308fWYTH%2F%2BhSserivSmCe7AQn3fJqp%2FRbigYGriOxJpUOZrCILoVCr4kBJ8%2FGvSIB9rqRZMh1OzJMPmYweNifG9ftvLeh2M6I8IyURJr5AmrXijbGIt%2FwmyGuNU2a%2F1idrbqxSqI49rNpcoiLkHz8GFGR4IVSarZwWRBBjICqH2BKdjsmQ33%2Bm2r1264r8ewh%2FDbwZn3V2wuDOFdj1UoKaXBOt1JCStB1ksp9yPnORFJ10JgbR5oavFEdnfE7qO33B4MMgqwPjhQRq65jOuU0oPRfInKK3%2B9AmtoO%2BHksEEQ%3D%3D (Caused by NewConnectionError('<urllib3.connection.HTTPSConnection object at 0x2b0886876d90>: Failed to establish a new connection: [Errno 101] Network is unreachable'))
2023-12-15 17:29:38,681 ERROR   wandb-upload_0:10647 [internal_api.py:upload_file():2558] upload_file request headers: {'User-Agent': 'python-requests/2.28.1', 'Accept-Encoding': 'gzip, deflate, br', 'Accept': '*/*', 'Connection': 'keep-alive', 'Content-Length': '14827'}
2023-12-15 17:29:38,681 ERROR   wandb-upload_0:10647 [internal_api.py:upload_file():2560] upload_file response body: 
2023-12-15 17:29:39,098 DEBUG   HandlerThread:10647 [handler.py:handle_request():146] handle_request: keepalive
2023-12-15 17:29:42,117 ERROR   wandb-upload_1:10647 [internal_api.py:upload_file():2556] upload_file exception https://storage.googleapis.com/wandb-artifacts-prod/wandb_artifacts/120300447/667873143/521e54ab95c254e02c4ef790d5def9ec?Expires=1702744038&GoogleAccessId=gorilla-files-url-signer-man%40wandb-production.iam.gserviceaccount.com&Signature=s3vot08iBEXAP00FH%2B6dl9WPoOvaPb25xr0rrLYQdha1xoBTRzpFQErDALKDiaGTY99S8N5eUtpqJVC%2BHxjOxJ%2BqBJBvDD09ET7WGrAgvVP6UftMpj2kVNFaKQTUGEjyw6LntStF2ur%2F8Z2gBujTIsJa%2BdgyyvGLv5R%2BdQzBVerY4mDEcWSbY9cALcB9K2A6GsKgTqXOi13FgsqWC4uNdnLsLEqBLpUmwUrDQmQlKwgGz82nnWsH6RxEHCn%2BIQ2zCrjm6JFUhKxQkSyykV8IUndoHYVJuuSuZyT3FmhQZnhffDXLLM2bkMl1dY%2BmOEak2nyXadIdB3k%2F7G9rbIclVg%3D%3D: HTTPSConnectionPool(host='storage.googleapis.com', port=443): Max retries exceeded with url: /wandb-artifacts-prod/wandb_artifacts/120300447/667873143/521e54ab95c254e02c4ef790d5def9ec?Expires=1702744038&GoogleAccessId=gorilla-files-url-signer-man%40wandb-production.iam.gserviceaccount.com&Signature=s3vot08iBEXAP00FH%2B6dl9WPoOvaPb25xr0rrLYQdha1xoBTRzpFQErDALKDiaGTY99S8N5eUtpqJVC%2BHxjOxJ%2BqBJBvDD09ET7WGrAgvVP6UftMpj2kVNFaKQTUGEjyw6LntStF2ur%2F8Z2gBujTIsJa%2BdgyyvGLv5R%2BdQzBVerY4mDEcWSbY9cALcB9K2A6GsKgTqXOi13FgsqWC4uNdnLsLEqBLpUmwUrDQmQlKwgGz82nnWsH6RxEHCn%2BIQ2zCrjm6JFUhKxQkSyykV8IUndoHYVJuuSuZyT3FmhQZnhffDXLLM2bkMl1dY%2BmOEak2nyXadIdB3k%2F7G9rbIclVg%3D%3D (Caused by NewConnectionError('<urllib3.connection.HTTPSConnection object at 0x2b08868763d0>: Failed to establish a new connection: [Errno 101] Network is unreachable'))
2023-12-15 17:29:42,117 ERROR   wandb-upload_1:10647 [internal_api.py:upload_file():2558] upload_file request headers: {'User-Agent': 'python-requests/2.28.1', 'Accept-Encoding': 'gzip, deflate, br', 'Accept': '*/*', 'Connection': 'keep-alive', 'Content-MD5': 'Uh5Uq5XCVOAsTveQ1d757A==', 'Content-Type': 'text/plain; charset=utf-8', 'Content-Length': '1820'}
2023-12-15 17:29:42,117 ERROR   wandb-upload_1:10647 [internal_api.py:upload_file():2560] upload_file response body: 
2023-12-15 17:29:44,100 DEBUG   HandlerThread:10647 [handler.py:handle_request():146] handle_request: keepalive
2023-12-15 17:29:45,492 ERROR   wandb-upload_2:10647 [internal_api.py:upload_file():2556] upload_file exception https://storage.googleapis.com/wandb-artifacts-prod/wandb_artifacts/120300447/667873143/90d3d941acdc730294f7988a60e22317?Expires=1702744038&GoogleAccessId=gorilla-files-url-signer-man%40wandb-production.iam.gserviceaccount.com&Signature=rePB%2B712fkIhge3qBC0mcj%2B4bzYu9zU8hOfzDKBHQ9KEwuYypx2TogOJJa3cctFkj0Wy18glZFlSqcG9SngIKaDUD1%2F0ZqUO3UJZVadFQdm1GnumQ5XY3r%2FFMfDTNyotlYhwdoVKBGx12lRElt89PuxYofUT%2BcfaKKBnBkb57xuQKiP0PC08ufDrIW67qu1MbzLK69SCEVp4lWR%2B89sGCUvabBcAjnTslH9VKun7PQV1VEYjHTey2OK1FuSLR2SEy0k%2FLg6C42r61CVKl5TW3uJ%2BGY3h63CzOxCumsmz2vCDC3GSJmDYWIopEyZQIxn%2FUGF3wk1m%2FR7hRQTFCzYSNw%3D%3D: HTTPSConnectionPool(host='storage.googleapis.com', port=443): Max retries exceeded with url: /wandb-artifacts-prod/wandb_artifacts/120300447/667873143/90d3d941acdc730294f7988a60e22317?Expires=1702744038&GoogleAccessId=gorilla-files-url-signer-man%40wandb-production.iam.gserviceaccount.com&Signature=rePB%2B712fkIhge3qBC0mcj%2B4bzYu9zU8hOfzDKBHQ9KEwuYypx2TogOJJa3cctFkj0Wy18glZFlSqcG9SngIKaDUD1%2F0ZqUO3UJZVadFQdm1GnumQ5XY3r%2FFMfDTNyotlYhwdoVKBGx12lRElt89PuxYofUT%2BcfaKKBnBkb57xuQKiP0PC08ufDrIW67qu1MbzLK69SCEVp4lWR%2B89sGCUvabBcAjnTslH9VKun7PQV1VEYjHTey2OK1FuSLR2SEy0k%2FLg6C42r61CVKl5TW3uJ%2BGY3h63CzOxCumsmz2vCDC3GSJmDYWIopEyZQIxn%2FUGF3wk1m%2FR7hRQTFCzYSNw%3D%3D (Caused by NewConnectionError('<urllib3.connection.HTTPSConnection object at 0x2b08868950a0>: Failed to establish a new connection: [Errno 101] Network is unreachable'))
2023-12-15 17:29:45,492 ERROR   wandb-upload_2:10647 [internal_api.py:upload_file():2558] upload_file request headers: {'User-Agent': 'python-requests/2.28.1', 'Accept-Encoding': 'gzip, deflate, br', 'Accept': '*/*', 'Connection': 'keep-alive', 'Content-MD5': 'kNPZQazccwKU95iKYOIjFw==', 'Content-Type': 'application/json', 'Content-Length': '648'}
2023-12-15 17:29:45,493 ERROR   wandb-upload_2:10647 [internal_api.py:upload_file():2560] upload_file response body: 
2023-12-15 17:29:49,102 DEBUG   HandlerThread:10647 [handler.py:handle_request():146] handle_request: keepalive
2023-12-15 17:29:54,103 DEBUG   HandlerThread:10647 [handler.py:handle_request():146] handle_request: keepalive
2023-12-15 17:29:59,105 DEBUG   HandlerThread:10647 [handler.py:handle_request():146] handle_request: keepalive
2023-12-15 17:30:04,106 DEBUG   HandlerThread:10647 [handler.py:handle_request():146] handle_request: keepalive
2023-12-15 17:30:09,108 DEBUG   HandlerThread:10647 [handler.py:handle_request():146] handle_request: keepalive
2023-12-15 17:30:14,110 DEBUG   HandlerThread:10647 [handler.py:handle_request():146] handle_request: keepalive
2023-12-15 17:30:19,111 DEBUG   HandlerThread:10647 [handler.py:handle_request():146] handle_request: keepalive
2023-12-15 17:30:24,113 DEBUG   HandlerThread:10647 [handler.py:handle_request():146] handle_request: keepalive
2023-12-15 17:30:29,114 DEBUG   HandlerThread:10647 [handler.py:handle_request():146] handle_request: keepalive
2023-12-15 17:30:34,116 DEBUG   HandlerThread:10647 [handler.py:handle_request():146] handle_request: keepalive
2023-12-15 17:30:39,118 DEBUG   HandlerThread:10647 [handler.py:handle_request():146] handle_request: keepalive
2023-12-15 17:30:44,120 DEBUG   HandlerThread:10647 [handler.py:handle_request():146] handle_request: keepalive
2023-12-15 17:30:49,121 DEBUG   HandlerThread:10647 [handler.py:handle_request():146] handle_request: keepalive
2023-12-15 17:30:54,123 DEBUG   HandlerThread:10647 [handler.py:handle_request():146] handle_request: keepalive
2023-12-15 17:30:59,125 DEBUG   HandlerThread:10647 [handler.py:handle_request():146] handle_request: keepalive
2023-12-15 17:31:04,127 DEBUG   HandlerThread:10647 [handler.py:handle_request():146] handle_request: keepalive
2023-12-15 17:31:09,129 DEBUG   HandlerThread:10647 [handler.py:handle_request():146] handle_request: keepalive
2023-12-15 17:31:14,130 DEBUG   HandlerThread:10647 [handler.py:handle_request():146] handle_request: keepalive
2023-12-15 17:31:19,132 DEBUG   HandlerThread:10647 [handler.py:handle_request():146] handle_request: keepalive
2023-12-15 17:31:24,134 DEBUG   HandlerThread:10647 [handler.py:handle_request():146] handle_request: keepalive
2023-12-15 17:31:29,135 DEBUG   HandlerThread:10647 [handler.py:handle_request():146] handle_request: keepalive
2023-12-15 17:31:34,137 DEBUG   HandlerThread:10647 [handler.py:handle_request():146] handle_request: keepalive
2023-12-15 17:31:39,139 DEBUG   HandlerThread:10647 [handler.py:handle_request():146] handle_request: keepalive
2023-12-15 17:31:44,140 DEBUG   HandlerThread:10647 [handler.py:handle_request():146] handle_request: keepalive
2023-12-15 17:31:49,142 DEBUG   HandlerThread:10647 [handler.py:handle_request():146] handle_request: keepalive
2023-12-15 17:31:54,143 DEBUG   HandlerThread:10647 [handler.py:handle_request():146] handle_request: keepalive
2023-12-15 17:31:58,920 ERROR   wandb-upload_0:10647 [internal_api.py:upload_file():2556] upload_file exception https://storage.googleapis.com/wandb-production.appspot.com/bryant-tang-ethz/DKT-trial%201/9eekgqhp/wandb-metadata.json?Expires=1702744033&GoogleAccessId=gorilla-files-url-signer-man%40wandb-production.iam.gserviceaccount.com&Signature=fegoYMfhWi%2BTDz1a3zzHD%2BIbpiF53bhEtxIb5YVugk308fWYTH%2F%2BhSserivSmCe7AQn3fJqp%2FRbigYGriOxJpUOZrCILoVCr4kBJ8%2FGvSIB9rqRZMh1OzJMPmYweNifG9ftvLeh2M6I8IyURJr5AmrXijbGIt%2FwmyGuNU2a%2F1idrbqxSqI49rNpcoiLkHz8GFGR4IVSarZwWRBBjICqH2BKdjsmQ33%2Bm2r1264r8ewh%2FDbwZn3V2wuDOFdj1UoKaXBOt1JCStB1ksp9yPnORFJ10JgbR5oavFEdnfE7qO33B4MMgqwPjhQRq65jOuU0oPRfInKK3%2B9AmtoO%2BHksEEQ%3D%3D: HTTPSConnectionPool(host='storage.googleapis.com', port=443): Max retries exceeded with url: /wandb-production.appspot.com/bryant-tang-ethz/DKT-trial%201/9eekgqhp/wandb-metadata.json?Expires=1702744033&GoogleAccessId=gorilla-files-url-signer-man%40wandb-production.iam.gserviceaccount.com&Signature=fegoYMfhWi%2BTDz1a3zzHD%2BIbpiF53bhEtxIb5YVugk308fWYTH%2F%2BhSserivSmCe7AQn3fJqp%2FRbigYGriOxJpUOZrCILoVCr4kBJ8%2FGvSIB9rqRZMh1OzJMPmYweNifG9ftvLeh2M6I8IyURJr5AmrXijbGIt%2FwmyGuNU2a%2F1idrbqxSqI49rNpcoiLkHz8GFGR4IVSarZwWRBBjICqH2BKdjsmQ33%2Bm2r1264r8ewh%2FDbwZn3V2wuDOFdj1UoKaXBOt1JCStB1ksp9yPnORFJ10JgbR5oavFEdnfE7qO33B4MMgqwPjhQRq65jOuU0oPRfInKK3%2B9AmtoO%2BHksEEQ%3D%3D (Caused by NewConnectionError('<urllib3.connection.HTTPSConnection object at 0x2b0886880730>: Failed to establish a new connection: [Errno 101] Network is unreachable'))
2023-12-15 17:31:58,920 ERROR   wandb-upload_0:10647 [internal_api.py:upload_file():2558] upload_file request headers: {'User-Agent': 'python-requests/2.28.1', 'Accept-Encoding': 'gzip, deflate, br', 'Accept': '*/*', 'Connection': 'keep-alive', 'Content-Length': '14827'}
2023-12-15 17:31:58,920 ERROR   wandb-upload_0:10647 [internal_api.py:upload_file():2560] upload_file response body: 
2023-12-15 17:31:59,145 DEBUG   HandlerThread:10647 [handler.py:handle_request():146] handle_request: keepalive
2023-12-15 17:32:04,147 DEBUG   HandlerThread:10647 [handler.py:handle_request():146] handle_request: keepalive
2023-12-15 17:32:09,148 DEBUG   HandlerThread:10647 [handler.py:handle_request():146] handle_request: keepalive
2023-12-15 17:32:13,765 ERROR   wandb-upload_2:10647 [internal_api.py:upload_file():2556] upload_file exception https://storage.googleapis.com/wandb-artifacts-prod/wandb_artifacts/120300447/667873143/90d3d941acdc730294f7988a60e22317?Expires=1702744038&GoogleAccessId=gorilla-files-url-signer-man%40wandb-production.iam.gserviceaccount.com&Signature=rePB%2B712fkIhge3qBC0mcj%2B4bzYu9zU8hOfzDKBHQ9KEwuYypx2TogOJJa3cctFkj0Wy18glZFlSqcG9SngIKaDUD1%2F0ZqUO3UJZVadFQdm1GnumQ5XY3r%2FFMfDTNyotlYhwdoVKBGx12lRElt89PuxYofUT%2BcfaKKBnBkb57xuQKiP0PC08ufDrIW67qu1MbzLK69SCEVp4lWR%2B89sGCUvabBcAjnTslH9VKun7PQV1VEYjHTey2OK1FuSLR2SEy0k%2FLg6C42r61CVKl5TW3uJ%2BGY3h63CzOxCumsmz2vCDC3GSJmDYWIopEyZQIxn%2FUGF3wk1m%2FR7hRQTFCzYSNw%3D%3D: HTTPSConnectionPool(host='storage.googleapis.com', port=443): Max retries exceeded with url: /wandb-artifacts-prod/wandb_artifacts/120300447/667873143/90d3d941acdc730294f7988a60e22317?Expires=1702744038&GoogleAccessId=gorilla-files-url-signer-man%40wandb-production.iam.gserviceaccount.com&Signature=rePB%2B712fkIhge3qBC0mcj%2B4bzYu9zU8hOfzDKBHQ9KEwuYypx2TogOJJa3cctFkj0Wy18glZFlSqcG9SngIKaDUD1%2F0ZqUO3UJZVadFQdm1GnumQ5XY3r%2FFMfDTNyotlYhwdoVKBGx12lRElt89PuxYofUT%2BcfaKKBnBkb57xuQKiP0PC08ufDrIW67qu1MbzLK69SCEVp4lWR%2B89sGCUvabBcAjnTslH9VKun7PQV1VEYjHTey2OK1FuSLR2SEy0k%2FLg6C42r61CVKl5TW3uJ%2BGY3h63CzOxCumsmz2vCDC3GSJmDYWIopEyZQIxn%2FUGF3wk1m%2FR7hRQTFCzYSNw%3D%3D (Caused by NewConnectionError('<urllib3.connection.HTTPSConnection object at 0x2b08868851c0>: Failed to establish a new connection: [Errno 101] Network is unreachable'))
2023-12-15 17:32:13,766 ERROR   wandb-upload_2:10647 [internal_api.py:upload_file():2558] upload_file request headers: {'User-Agent': 'python-requests/2.28.1', 'Accept-Encoding': 'gzip, deflate, br', 'Accept': '*/*', 'Connection': 'keep-alive', 'Content-MD5': 'kNPZQazccwKU95iKYOIjFw==', 'Content-Type': 'application/json', 'Content-Length': '648'}
2023-12-15 17:32:13,766 ERROR   wandb-upload_2:10647 [internal_api.py:upload_file():2560] upload_file response body: 
2023-12-15 17:32:14,150 DEBUG   HandlerThread:10647 [handler.py:handle_request():146] handle_request: keepalive
2023-12-15 17:32:15,108 ERROR   wandb-upload_1:10647 [internal_api.py:upload_file():2556] upload_file exception https://storage.googleapis.com/wandb-artifacts-prod/wandb_artifacts/120300447/667873143/521e54ab95c254e02c4ef790d5def9ec?Expires=1702744038&GoogleAccessId=gorilla-files-url-signer-man%40wandb-production.iam.gserviceaccount.com&Signature=s3vot08iBEXAP00FH%2B6dl9WPoOvaPb25xr0rrLYQdha1xoBTRzpFQErDALKDiaGTY99S8N5eUtpqJVC%2BHxjOxJ%2BqBJBvDD09ET7WGrAgvVP6UftMpj2kVNFaKQTUGEjyw6LntStF2ur%2F8Z2gBujTIsJa%2BdgyyvGLv5R%2BdQzBVerY4mDEcWSbY9cALcB9K2A6GsKgTqXOi13FgsqWC4uNdnLsLEqBLpUmwUrDQmQlKwgGz82nnWsH6RxEHCn%2BIQ2zCrjm6JFUhKxQkSyykV8IUndoHYVJuuSuZyT3FmhQZnhffDXLLM2bkMl1dY%2BmOEak2nyXadIdB3k%2F7G9rbIclVg%3D%3D: HTTPSConnectionPool(host='storage.googleapis.com', port=443): Max retries exceeded with url: /wandb-artifacts-prod/wandb_artifacts/120300447/667873143/521e54ab95c254e02c4ef790d5def9ec?Expires=1702744038&GoogleAccessId=gorilla-files-url-signer-man%40wandb-production.iam.gserviceaccount.com&Signature=s3vot08iBEXAP00FH%2B6dl9WPoOvaPb25xr0rrLYQdha1xoBTRzpFQErDALKDiaGTY99S8N5eUtpqJVC%2BHxjOxJ%2BqBJBvDD09ET7WGrAgvVP6UftMpj2kVNFaKQTUGEjyw6LntStF2ur%2F8Z2gBujTIsJa%2BdgyyvGLv5R%2BdQzBVerY4mDEcWSbY9cALcB9K2A6GsKgTqXOi13FgsqWC4uNdnLsLEqBLpUmwUrDQmQlKwgGz82nnWsH6RxEHCn%2BIQ2zCrjm6JFUhKxQkSyykV8IUndoHYVJuuSuZyT3FmhQZnhffDXLLM2bkMl1dY%2BmOEak2nyXadIdB3k%2F7G9rbIclVg%3D%3D (Caused by NewConnectionError('<urllib3.connection.HTTPSConnection object at 0x2b0886898400>: Failed to establish a new connection: [Errno 101] Network is unreachable'))
2023-12-15 17:32:15,108 ERROR   wandb-upload_1:10647 [internal_api.py:upload_file():2558] upload_file request headers: {'User-Agent': 'python-requests/2.28.1', 'Accept-Encoding': 'gzip, deflate, br', 'Accept': '*/*', 'Connection': 'keep-alive', 'Content-MD5': 'Uh5Uq5XCVOAsTveQ1d757A==', 'Content-Type': 'text/plain; charset=utf-8', 'Content-Length': '1820'}
2023-12-15 17:32:15,109 ERROR   wandb-upload_1:10647 [internal_api.py:upload_file():2560] upload_file response body: 
2023-12-15 17:32:19,152 DEBUG   HandlerThread:10647 [handler.py:handle_request():146] handle_request: keepalive
2023-12-15 17:32:24,153 DEBUG   HandlerThread:10647 [handler.py:handle_request():146] handle_request: keepalive
2023-12-15 17:32:29,155 DEBUG   HandlerThread:10647 [handler.py:handle_request():146] handle_request: keepalive
2023-12-15 17:32:34,156 DEBUG   HandlerThread:10647 [handler.py:handle_request():146] handle_request: keepalive
2023-12-15 17:32:39,158 DEBUG   HandlerThread:10647 [handler.py:handle_request():146] handle_request: keepalive
2023-12-15 17:32:44,159 DEBUG   HandlerThread:10647 [handler.py:handle_request():146] handle_request: keepalive
2023-12-15 17:32:49,161 DEBUG   HandlerThread:10647 [handler.py:handle_request():146] handle_request: keepalive
2023-12-15 17:32:54,163 DEBUG   HandlerThread:10647 [handler.py:handle_request():146] handle_request: keepalive
2023-12-15 17:32:59,164 DEBUG   HandlerThread:10647 [handler.py:handle_request():146] handle_request: keepalive
2023-12-15 17:33:04,166 DEBUG   HandlerThread:10647 [handler.py:handle_request():146] handle_request: keepalive
2023-12-15 17:33:09,168 DEBUG   HandlerThread:10647 [handler.py:handle_request():146] handle_request: keepalive
2023-12-15 17:33:14,169 DEBUG   HandlerThread:10647 [handler.py:handle_request():146] handle_request: keepalive
2023-12-15 17:33:19,171 DEBUG   HandlerThread:10647 [handler.py:handle_request():146] handle_request: keepalive
2023-12-15 17:33:24,172 DEBUG   HandlerThread:10647 [handler.py:handle_request():146] handle_request: keepalive
2023-12-15 17:33:29,174 DEBUG   HandlerThread:10647 [handler.py:handle_request():146] handle_request: keepalive
2023-12-15 17:33:34,175 DEBUG   HandlerThread:10647 [handler.py:handle_request():146] handle_request: keepalive
2023-12-15 17:33:39,177 DEBUG   HandlerThread:10647 [handler.py:handle_request():146] handle_request: keepalive
2023-12-15 17:33:44,178 DEBUG   HandlerThread:10647 [handler.py:handle_request():146] handle_request: keepalive
2023-12-15 17:33:49,180 DEBUG   HandlerThread:10647 [handler.py:handle_request():146] handle_request: keepalive
2023-12-15 17:33:54,181 DEBUG   HandlerThread:10647 [handler.py:handle_request():146] handle_request: keepalive
2023-12-15 17:33:59,183 DEBUG   HandlerThread:10647 [handler.py:handle_request():146] handle_request: keepalive
2023-12-15 17:34:04,184 DEBUG   HandlerThread:10647 [handler.py:handle_request():146] handle_request: keepalive
2023-12-15 17:34:09,186 DEBUG   HandlerThread:10647 [handler.py:handle_request():146] handle_request: keepalive
2023-12-15 17:34:14,188 DEBUG   HandlerThread:10647 [handler.py:handle_request():146] handle_request: keepalive
2023-12-15 17:34:19,189 DEBUG   HandlerThread:10647 [handler.py:handle_request():146] handle_request: keepalive
2023-12-15 17:34:24,191 DEBUG   HandlerThread:10647 [handler.py:handle_request():146] handle_request: keepalive
2023-12-15 17:34:29,193 DEBUG   HandlerThread:10647 [handler.py:handle_request():146] handle_request: keepalive
2023-12-15 17:34:34,194 DEBUG   HandlerThread:10647 [handler.py:handle_request():146] handle_request: keepalive
2023-12-15 17:34:39,196 DEBUG   HandlerThread:10647 [handler.py:handle_request():146] handle_request: keepalive
2023-12-15 17:34:44,197 DEBUG   HandlerThread:10647 [handler.py:handle_request():146] handle_request: keepalive
2023-12-15 17:34:49,199 DEBUG   HandlerThread:10647 [handler.py:handle_request():146] handle_request: keepalive
2023-12-15 17:34:54,200 DEBUG   HandlerThread:10647 [handler.py:handle_request():146] handle_request: keepalive
2023-12-15 17:34:59,202 DEBUG   HandlerThread:10647 [handler.py:handle_request():146] handle_request: keepalive
2023-12-15 17:35:04,203 DEBUG   HandlerThread:10647 [handler.py:handle_request():146] handle_request: keepalive
2023-12-15 17:35:09,205 DEBUG   HandlerThread:10647 [handler.py:handle_request():146] handle_request: keepalive
2023-12-15 17:35:14,206 DEBUG   HandlerThread:10647 [handler.py:handle_request():146] handle_request: keepalive
2023-12-15 17:35:19,208 DEBUG   HandlerThread:10647 [handler.py:handle_request():146] handle_request: keepalive
2023-12-15 17:35:24,210 DEBUG   HandlerThread:10647 [handler.py:handle_request():146] handle_request: keepalive
2023-12-15 17:35:29,211 DEBUG   HandlerThread:10647 [handler.py:handle_request():146] handle_request: keepalive
2023-12-15 17:35:34,213 DEBUG   HandlerThread:10647 [handler.py:handle_request():146] handle_request: keepalive
2023-12-15 17:35:39,214 DEBUG   HandlerThread:10647 [handler.py:handle_request():146] handle_request: keepalive
2023-12-15 17:35:44,216 DEBUG   HandlerThread:10647 [handler.py:handle_request():146] handle_request: keepalive
2023-12-15 17:35:49,217 DEBUG   HandlerThread:10647 [handler.py:handle_request():146] handle_request: keepalive
2023-12-15 17:35:54,219 DEBUG   HandlerThread:10647 [handler.py:handle_request():146] handle_request: keepalive
2023-12-15 17:35:59,221 DEBUG   HandlerThread:10647 [handler.py:handle_request():146] handle_request: keepalive
2023-12-15 17:36:04,222 DEBUG   HandlerThread:10647 [handler.py:handle_request():146] handle_request: keepalive
2023-12-15 17:36:09,224 DEBUG   HandlerThread:10647 [handler.py:handle_request():146] handle_request: keepalive
2023-12-15 17:36:14,225 DEBUG   HandlerThread:10647 [handler.py:handle_request():146] handle_request: keepalive
2023-12-15 17:36:19,227 DEBUG   HandlerThread:10647 [handler.py:handle_request():146] handle_request: keepalive
2023-12-15 17:36:20,046 ERROR   wandb-upload_0:10647 [internal_api.py:upload_file():2556] upload_file exception https://storage.googleapis.com/wandb-production.appspot.com/bryant-tang-ethz/DKT-trial%201/9eekgqhp/wandb-metadata.json?Expires=1702744033&GoogleAccessId=gorilla-files-url-signer-man%40wandb-production.iam.gserviceaccount.com&Signature=fegoYMfhWi%2BTDz1a3zzHD%2BIbpiF53bhEtxIb5YVugk308fWYTH%2F%2BhSserivSmCe7AQn3fJqp%2FRbigYGriOxJpUOZrCILoVCr4kBJ8%2FGvSIB9rqRZMh1OzJMPmYweNifG9ftvLeh2M6I8IyURJr5AmrXijbGIt%2FwmyGuNU2a%2F1idrbqxSqI49rNpcoiLkHz8GFGR4IVSarZwWRBBjICqH2BKdjsmQ33%2Bm2r1264r8ewh%2FDbwZn3V2wuDOFdj1UoKaXBOt1JCStB1ksp9yPnORFJ10JgbR5oavFEdnfE7qO33B4MMgqwPjhQRq65jOuU0oPRfInKK3%2B9AmtoO%2BHksEEQ%3D%3D: HTTPSConnectionPool(host='storage.googleapis.com', port=443): Max retries exceeded with url: /wandb-production.appspot.com/bryant-tang-ethz/DKT-trial%201/9eekgqhp/wandb-metadata.json?Expires=1702744033&GoogleAccessId=gorilla-files-url-signer-man%40wandb-production.iam.gserviceaccount.com&Signature=fegoYMfhWi%2BTDz1a3zzHD%2BIbpiF53bhEtxIb5YVugk308fWYTH%2F%2BhSserivSmCe7AQn3fJqp%2FRbigYGriOxJpUOZrCILoVCr4kBJ8%2FGvSIB9rqRZMh1OzJMPmYweNifG9ftvLeh2M6I8IyURJr5AmrXijbGIt%2FwmyGuNU2a%2F1idrbqxSqI49rNpcoiLkHz8GFGR4IVSarZwWRBBjICqH2BKdjsmQ33%2Bm2r1264r8ewh%2FDbwZn3V2wuDOFdj1UoKaXBOt1JCStB1ksp9yPnORFJ10JgbR5oavFEdnfE7qO33B4MMgqwPjhQRq65jOuU0oPRfInKK3%2B9AmtoO%2BHksEEQ%3D%3D (Caused by NewConnectionError('<urllib3.connection.HTTPSConnection object at 0x2b088688d6d0>: Failed to establish a new connection: [Errno 101] Network is unreachable'))
2023-12-15 17:36:20,046 ERROR   wandb-upload_0:10647 [internal_api.py:upload_file():2558] upload_file request headers: {'User-Agent': 'python-requests/2.28.1', 'Accept-Encoding': 'gzip, deflate, br', 'Accept': '*/*', 'Connection': 'keep-alive', 'Content-Length': '14827'}
2023-12-15 17:36:20,046 ERROR   wandb-upload_0:10647 [internal_api.py:upload_file():2560] upload_file response body: 
2023-12-15 17:36:24,229 DEBUG   HandlerThread:10647 [handler.py:handle_request():146] handle_request: keepalive
2023-12-15 17:36:29,231 DEBUG   HandlerThread:10647 [handler.py:handle_request():146] handle_request: keepalive
2023-12-15 17:36:34,232 DEBUG   HandlerThread:10647 [handler.py:handle_request():146] handle_request: keepalive
2023-12-15 17:36:39,234 DEBUG   HandlerThread:10647 [handler.py:handle_request():146] handle_request: keepalive
2023-12-15 17:36:44,235 DEBUG   HandlerThread:10647 [handler.py:handle_request():146] handle_request: keepalive
