2023-11-07 16:42:39,101 INFO    StreamThr :85669 [internal.py:wandb_internal():86] W&B internal server running at pid: 85669, started at: 2023-11-07 16:42:39.100368
2023-11-07 16:42:39,103 DEBUG   HandlerThread:85669 [handler.py:handle_request():146] handle_request: status
2023-11-07 16:42:39,106 INFO    WriterThread:85669 [datastore.py:open_for_write():85] open: /cluster/home/yutang/Deep-Knowledge-Tracing/DKT/KnowledgeTracing/evaluation/wandb/run-20231107_164239-ofzmp069/run-ofzmp069.wandb
2023-11-07 16:42:39,108 DEBUG   SenderThread:85669 [sender.py:send():380] send: header
2023-11-07 16:42:39,133 DEBUG   SenderThread:85669 [sender.py:send():380] send: run
2023-11-07 16:42:39,615 INFO    SenderThread:85669 [dir_watcher.py:__init__():211] watching files in: /cluster/home/yutang/Deep-Knowledge-Tracing/DKT/KnowledgeTracing/evaluation/wandb/run-20231107_164239-ofzmp069/files
2023-11-07 16:42:39,616 INFO    SenderThread:85669 [sender.py:_start_run_threads():1122] run started: ofzmp069 with start time 1699371759.102655
2023-11-07 16:42:39,629 DEBUG   HandlerThread:85669 [handler.py:handle_request():146] handle_request: check_version
2023-11-07 16:42:39,630 DEBUG   SenderThread:85669 [sender.py:send_request():407] send_request: check_version
2023-11-07 16:42:39,698 DEBUG   HandlerThread:85669 [handler.py:handle_request():146] handle_request: run_start
2023-11-07 16:42:39,708 DEBUG   HandlerThread:85669 [system_info.py:__init__():32] System info init
2023-11-07 16:42:39,708 DEBUG   HandlerThread:85669 [system_info.py:__init__():47] System info init done
2023-11-07 16:42:39,708 INFO    HandlerThread:85669 [system_monitor.py:start():194] Starting system monitor
2023-11-07 16:42:39,708 INFO    SystemMonitor:85669 [system_monitor.py:_start():158] Starting system asset monitoring threads
2023-11-07 16:42:39,708 INFO    HandlerThread:85669 [system_monitor.py:probe():214] Collecting system info
2023-11-07 16:42:39,711 INFO    SystemMonitor:85669 [interfaces.py:start():190] Started cpu monitoring
2023-11-07 16:42:39,712 INFO    SystemMonitor:85669 [interfaces.py:start():190] Started disk monitoring
2023-11-07 16:42:39,712 INFO    SystemMonitor:85669 [interfaces.py:start():190] Started gpu monitoring
2023-11-07 16:42:39,714 INFO    SystemMonitor:85669 [interfaces.py:start():190] Started memory monitoring
2023-11-07 16:42:39,716 INFO    SystemMonitor:85669 [interfaces.py:start():190] Started network monitoring
2023-11-07 16:42:39,760 DEBUG   HandlerThread:85669 [system_info.py:probe():196] Probing system
2023-11-07 16:42:39,765 DEBUG   HandlerThread:85669 [system_info.py:_probe_git():181] Probing git
2023-11-07 16:42:39,786 DEBUG   HandlerThread:85669 [system_info.py:_probe_git():189] Probing git done
2023-11-07 16:42:39,787 DEBUG   HandlerThread:85669 [system_info.py:probe():244] Probing system done
2023-11-07 16:42:39,787 DEBUG   HandlerThread:85669 [system_monitor.py:probe():223] {'os': 'Linux-3.10.0-1160.95.1.el7.x86_64-x86_64-with-glibc2.17', 'python': '3.9.16', 'heartbeatAt': '2023-11-07T15:42:39.760420', 'startedAt': '2023-11-07T15:42:39.086436', 'docker': None, 'cuda': None, 'args': (), 'state': 'running', 'program': '/cluster/home/yutang/Deep-Knowledge-Tracing/DKT/KnowledgeTracing/evaluation/./run.py', 'codePathLocal': 'run.py', 'codePath': 'DKT/KnowledgeTracing/evaluation/run.py', 'git': {'remote': 'https://github.com/Bryanttt-tang/Deep-Knowledge-Tracing.git', 'commit': '49ccc1577031aa273a60c479c5cd4149ebda2bb5'}, 'email': None, 'root': '/cluster/home/yutang/Deep-Knowledge-Tracing', 'host': 'eu-g4-006', 'username': 'yutang', 'executable': '/cluster/home/yutang/miniconda3/bin/python', 'cpu_count': 128, 'cpu_count_logical': 128, 'cpu_freq': {'current': 1617.1875, 'min': 1500.0, 'max': 2250.0}, 'cpu_freq_per_core': [{'current': 2250.0, 'min': 1500.0, 'max': 2250.0}, {'current': 2250.0, 'min': 1500.0, 'max': 2250.0}, {'current': 2250.0, 'min': 1500.0, 'max': 2250.0}, {'current': 2250.0, 'min': 1500.0, 'max': 2250.0}, {'current': 1500.0, 'min': 1500.0, 'max': 2250.0}, {'current': 1500.0, 'min': 1500.0, 'max': 2250.0}, {'current': 1500.0, 'min': 1500.0, 'max': 2250.0}, {'current': 1500.0, 'min': 1500.0, 'max': 2250.0}, {'current': 2250.0, 'min': 1500.0, 'max': 2250.0}, {'current': 1500.0, 'min': 1500.0, 'max': 2250.0}, {'current': 1500.0, 'min': 1500.0, 'max': 2250.0}, {'current': 1500.0, 'min': 1500.0, 'max': 2250.0}, {'current': 1500.0, 'min': 1500.0, 'max': 2250.0}, {'current': 1500.0, 'min': 1500.0, 'max': 2250.0}, {'current': 1500.0, 'min': 1500.0, 'max': 2250.0}, {'current': 1500.0, 'min': 1500.0, 'max': 2250.0}, {'current': 2000.0, 'min': 1500.0, 'max': 2250.0}, {'current': 1500.0, 'min': 1500.0, 'max': 2250.0}, {'current': 1500.0, 'min': 1500.0, 'max': 2250.0}, {'current': 2250.0, 'min': 1500.0, 'max': 2250.0}, {'current': 2250.0, 'min': 1500.0, 'max': 2250.0}, {'current': 1500.0, 'min': 1500.0, 'max': 2250.0}, {'current': 1500.0, 'min': 1500.0, 'max': 2250.0}, {'current': 1500.0, 'min': 1500.0, 'max': 2250.0}, {'current': 1500.0, 'min': 1500.0, 'max': 2250.0}, {'current': 1500.0, 'min': 1500.0, 'max': 2250.0}, {'current': 1500.0, 'min': 1500.0, 'max': 2250.0}, {'current': 1500.0, 'min': 1500.0, 'max': 2250.0}, {'current': 1500.0, 'min': 1500.0, 'max': 2250.0}, {'current': 1500.0, 'min': 1500.0, 'max': 2250.0}, {'current': 1500.0, 'min': 1500.0, 'max': 2250.0}, {'current': 1500.0, 'min': 1500.0, 'max': 2250.0}, {'current': 2250.0, 'min': 1500.0, 'max': 2250.0}, {'current': 2250.0, 'min': 1500.0, 'max': 2250.0}, {'current': 1500.0, 'min': 1500.0, 'max': 2250.0}, {'current': 1500.0, 'min': 1500.0, 'max': 2250.0}, {'current': 1500.0, 'min': 1500.0, 'max': 2250.0}, {'current': 1500.0, 'min': 1500.0, 'max': 2250.0}, {'current': 1500.0, 'min': 1500.0, 'max': 2250.0}, {'current': 1500.0, 'min': 1500.0, 'max': 2250.0}, {'current': 1500.0, 'min': 1500.0, 'max': 2250.0}, {'current': 1500.0, 'min': 1500.0, 'max': 2250.0}, {'current': 1500.0, 'min': 1500.0, 'max': 2250.0}, {'current': 1500.0, 'min': 1500.0, 'max': 2250.0}, {'current': 1500.0, 'min': 1500.0, 'max': 2250.0}, {'current': 1500.0, 'min': 1500.0, 'max': 2250.0}, {'current': 1500.0, 'min': 1500.0, 'max': 2250.0}, {'current': 1500.0, 'min': 1500.0, 'max': 2250.0}, {'current': 1500.0, 'min': 1500.0, 'max': 2250.0}, {'current': 1500.0, 'min': 1500.0, 'max': 2250.0}, {'current': 1500.0, 'min': 1500.0, 'max': 2250.0}, {'current': 1500.0, 'min': 1500.0, 'max': 2250.0}, {'current': 1500.0, 'min': 1500.0, 'max': 2250.0}, {'current': 1500.0, 'min': 1500.0, 'max': 2250.0}, {'current': 1500.0, 'min': 1500.0, 'max': 2250.0}, {'current': 1500.0, 'min': 1500.0, 'max': 2250.0}, {'current': 1500.0, 'min': 1500.0, 'max': 2250.0}, {'current': 1500.0, 'min': 1500.0, 'max': 2250.0}, {'current': 1500.0, 'min': 1500.0, 'max': 2250.0}, {'current': 1500.0, 'min': 1500.0, 'max': 2250.0}, {'current': 1500.0, 'min': 1500.0, 'max': 2250.0}, {'current': 1500.0, 'min': 1500.0, 'max': 2250.0}, {'current': 1500.0, 'min': 1500.0, 'max': 2250.0}, {'current': 1500.0, 'min': 1500.0, 'max': 2250.0}, {'current': 2250.0, 'min': 1500.0, 'max': 2250.0}, {'current': 1500.0, 'min': 1500.0, 'max': 2250.0}, {'current': 1500.0, 'min': 1500.0, 'max': 2250.0}, {'current': 1500.0, 'min': 1500.0, 'max': 2250.0}, {'current': 1500.0, 'min': 1500.0, 'max': 2250.0}, {'current': 1500.0, 'min': 1500.0, 'max': 2250.0}, {'current': 2250.0, 'min': 1500.0, 'max': 2250.0}, {'current': 2250.0, 'min': 1500.0, 'max': 2250.0}, {'current': 1500.0, 'min': 1500.0, 'max': 2250.0}, {'current': 1500.0, 'min': 1500.0, 'max': 2250.0}, {'current': 1500.0, 'min': 1500.0, 'max': 2250.0}, {'current': 1500.0, 'min': 1500.0, 'max': 2250.0}, {'current': 1500.0, 'min': 1500.0, 'max': 2250.0}, {'current': 1500.0, 'min': 1500.0, 'max': 2250.0}, {'current': 1500.0, 'min': 1500.0, 'max': 2250.0}, {'current': 2000.0, 'min': 1500.0, 'max': 2250.0}, {'current': 2250.0, 'min': 1500.0, 'max': 2250.0}, {'current': 2000.0, 'min': 1500.0, 'max': 2250.0}, {'current': 2000.0, 'min': 1500.0, 'max': 2250.0}, {'current': 2250.0, 'min': 1500.0, 'max': 2250.0}, {'current': 1500.0, 'min': 1500.0, 'max': 2250.0}, {'current': 2250.0, 'min': 1500.0, 'max': 2250.0}, {'current': 1500.0, 'min': 1500.0, 'max': 2250.0}, {'current': 1500.0, 'min': 1500.0, 'max': 2250.0}, {'current': 1500.0, 'min': 1500.0, 'max': 2250.0}, {'current': 1500.0, 'min': 1500.0, 'max': 2250.0}, {'current': 1500.0, 'min': 1500.0, 'max': 2250.0}, {'current': 1500.0, 'min': 1500.0, 'max': 2250.0}, {'current': 1500.0, 'min': 1500.0, 'max': 2250.0}, {'current': 1500.0, 'min': 1500.0, 'max': 2250.0}, {'current': 1500.0, 'min': 1500.0, 'max': 2250.0}, {'current': 1500.0, 'min': 1500.0, 'max': 2250.0}, {'current': 1500.0, 'min': 1500.0, 'max': 2250.0}, {'current': 1500.0, 'min': 1500.0, 'max': 2250.0}, {'current': 1500.0, 'min': 1500.0, 'max': 2250.0}, {'current': 1500.0, 'min': 1500.0, 'max': 2250.0}, {'current': 1500.0, 'min': 1500.0, 'max': 2250.0}, {'current': 1500.0, 'min': 1500.0, 'max': 2250.0}, {'current': 1500.0, 'min': 1500.0, 'max': 2250.0}, {'current': 1500.0, 'min': 1500.0, 'max': 2250.0}, {'current': 1500.0, 'min': 1500.0, 'max': 2250.0}, {'current': 1500.0, 'min': 1500.0, 'max': 2250.0}, {'current': 1500.0, 'min': 1500.0, 'max': 2250.0}, {'current': 1500.0, 'min': 1500.0, 'max': 2250.0}, {'current': 1500.0, 'min': 1500.0, 'max': 2250.0}, {'current': 1500.0, 'min': 1500.0, 'max': 2250.0}, {'current': 2000.0, 'min': 1500.0, 'max': 2250.0}, {'current': 1500.0, 'min': 1500.0, 'max': 2250.0}, {'current': 1500.0, 'min': 1500.0, 'max': 2250.0}, {'current': 1500.0, 'min': 1500.0, 'max': 2250.0}, {'current': 1500.0, 'min': 1500.0, 'max': 2250.0}, {'current': 1500.0, 'min': 1500.0, 'max': 2250.0}, {'current': 1500.0, 'min': 1500.0, 'max': 2250.0}, {'current': 1500.0, 'min': 1500.0, 'max': 2250.0}, {'current': 1500.0, 'min': 1500.0, 'max': 2250.0}, {'current': 2250.0, 'min': 1500.0, 'max': 2250.0}, {'current': 1500.0, 'min': 1500.0, 'max': 2250.0}, {'current': 1500.0, 'min': 1500.0, 'max': 2250.0}, {'current': 1500.0, 'min': 1500.0, 'max': 2250.0}, {'current': 1500.0, 'min': 1500.0, 'max': 2250.0}, {'current': 1500.0, 'min': 1500.0, 'max': 2250.0}, {'current': 1500.0, 'min': 1500.0, 'max': 2250.0}, {'current': 1500.0, 'min': 1500.0, 'max': 2250.0}, {'current': 1500.0, 'min': 1500.0, 'max': 2250.0}], 'disk': {'/': {'total': 10.0, 'used': 4.599216461181641}}, 'gpu': 'NVIDIA GeForce RTX 3090', 'gpu_count': 2, 'gpu_devices': [{'name': 'NVIDIA GeForce RTX 3090', 'memory_total': 25769803776}, {'name': 'NVIDIA GeForce RTX 3090', 'memory_total': 25769803776}], 'memory': {'total': 501.5154609680176}}
2023-11-07 16:42:39,787 INFO    HandlerThread:85669 [system_monitor.py:probe():224] Finished collecting system info
2023-11-07 16:42:39,787 INFO    HandlerThread:85669 [system_monitor.py:probe():227] Publishing system info
2023-11-07 16:42:39,787 DEBUG   HandlerThread:85669 [system_info.py:_save_pip():52] Saving list of pip packages installed into the current environment
2023-11-07 16:42:39,788 DEBUG   HandlerThread:85669 [system_info.py:_save_pip():68] Saving pip packages done
2023-11-07 16:42:39,789 DEBUG   HandlerThread:85669 [system_info.py:_save_conda():75] Saving list of conda packages installed into the current environment
2023-11-07 16:42:40,620 INFO    Thread-12 :85669 [dir_watcher.py:_on_file_created():271] file/dir created: /cluster/home/yutang/Deep-Knowledge-Tracing/DKT/KnowledgeTracing/evaluation/wandb/run-20231107_164239-ofzmp069/files/conda-environment.yaml
2023-11-07 16:42:40,620 INFO    Thread-12 :85669 [dir_watcher.py:_on_file_created():271] file/dir created: /cluster/home/yutang/Deep-Knowledge-Tracing/DKT/KnowledgeTracing/evaluation/wandb/run-20231107_164239-ofzmp069/files/requirements.txt
2023-11-07 16:42:43,024 DEBUG   HandlerThread:85669 [system_info.py:_save_conda():87] Saving conda packages done
2023-11-07 16:42:43,026 INFO    HandlerThread:85669 [system_monitor.py:probe():229] Finished publishing system info
2023-11-07 16:42:43,033 DEBUG   SenderThread:85669 [sender.py:send():380] send: files
2023-11-07 16:42:43,033 INFO    SenderThread:85669 [sender.py:_save_file():1378] saving file wandb-metadata.json with policy now
2023-11-07 16:42:43,042 DEBUG   HandlerThread:85669 [handler.py:handle_request():146] handle_request: internal_messages
2023-11-07 16:42:43,042 DEBUG   HandlerThread:85669 [handler.py:handle_request():146] handle_request: stop_status
2023-11-07 16:42:43,043 DEBUG   SenderThread:85669 [sender.py:send_request():407] send_request: stop_status
2023-11-07 16:42:43,290 DEBUG   SenderThread:85669 [sender.py:send():380] send: telemetry
2023-11-07 16:42:43,353 ERROR   wandb-upload_0:85669 [internal_api.py:upload_file():2556] upload_file exception https://storage.googleapis.com/wandb-production.appspot.com/bryant-ty/DKT-trial%201/ofzmp069/wandb-metadata.json?Expires=1699458163&GoogleAccessId=gorilla-files-url-signer-man%40wandb-production.iam.gserviceaccount.com&Signature=PrD2kR8PtL%2FLzZA7Dz9HSfpSKY6s5qJheJDJ3LLgC7wpTumvfWK%2Bza154EKHCfHeC3HbkL86CuSox54Ixvzisx8gF4LJjTto%2FCMkTfsG1Njmaxk8KigZQGLx3wxMWCyKhANaToP1QiGJHpHA6R8TtxOByNBtK2f0d24LN8%2BuK6oDgqeo1FvByEVXakT1Le80JAkFQtqG9erYfhmYtOH2E32reh6MWLA6qzqGyyqGUw6EaswRqunF%2FGqFW%2BpHPQSwHjDb9VFJbLuNF4J2E3TDmTGL5JNu3ZmkgB%2BazmazbFE0jn1XlUhI8RztoqOywXDP8kSmaQXRL644Vi28iAJWnQ%3D%3D: HTTPSConnectionPool(host='storage.googleapis.com', port=443): Max retries exceeded with url: /wandb-production.appspot.com/bryant-ty/DKT-trial%201/ofzmp069/wandb-metadata.json?Expires=1699458163&GoogleAccessId=gorilla-files-url-signer-man%40wandb-production.iam.gserviceaccount.com&Signature=PrD2kR8PtL%2FLzZA7Dz9HSfpSKY6s5qJheJDJ3LLgC7wpTumvfWK%2Bza154EKHCfHeC3HbkL86CuSox54Ixvzisx8gF4LJjTto%2FCMkTfsG1Njmaxk8KigZQGLx3wxMWCyKhANaToP1QiGJHpHA6R8TtxOByNBtK2f0d24LN8%2BuK6oDgqeo1FvByEVXakT1Le80JAkFQtqG9erYfhmYtOH2E32reh6MWLA6qzqGyyqGUw6EaswRqunF%2FGqFW%2BpHPQSwHjDb9VFJbLuNF4J2E3TDmTGL5JNu3ZmkgB%2BazmazbFE0jn1XlUhI8RztoqOywXDP8kSmaQXRL644Vi28iAJWnQ%3D%3D (Caused by NewConnectionError('<urllib3.connection.HTTPSConnection object at 0x2afd27f52f10>: Failed to establish a new connection: [Errno 101] Network is unreachable'))
2023-11-07 16:42:43,354 ERROR   wandb-upload_0:85669 [internal_api.py:upload_file():2558] upload_file request headers: {'User-Agent': 'python-requests/2.28.1', 'Accept-Encoding': 'gzip, deflate, br', 'Accept': '*/*', 'Connection': 'keep-alive', 'Content-Length': '14912'}
2023-11-07 16:42:43,354 ERROR   wandb-upload_0:85669 [internal_api.py:upload_file():2560] upload_file response body: 
2023-11-07 16:42:43,619 INFO    Thread-12 :85669 [dir_watcher.py:_on_file_modified():288] file/dir modified: /cluster/home/yutang/Deep-Knowledge-Tracing/DKT/KnowledgeTracing/evaluation/wandb/run-20231107_164239-ofzmp069/files/conda-environment.yaml
2023-11-07 16:42:43,619 INFO    Thread-12 :85669 [dir_watcher.py:_on_file_created():271] file/dir created: /cluster/home/yutang/Deep-Knowledge-Tracing/DKT/KnowledgeTracing/evaluation/wandb/run-20231107_164239-ofzmp069/files/wandb-metadata.json
2023-11-07 16:42:43,619 INFO    Thread-12 :85669 [dir_watcher.py:_on_file_created():271] file/dir created: /cluster/home/yutang/Deep-Knowledge-Tracing/DKT/KnowledgeTracing/evaluation/wandb/run-20231107_164239-ofzmp069/files/output.log
2023-11-07 16:42:44,292 DEBUG   HandlerThread:85669 [handler.py:handle_request():146] handle_request: status_report
2023-11-07 16:42:44,606 ERROR   wandb-upload_0:85669 [internal_api.py:upload_file():2556] upload_file exception https://storage.googleapis.com/wandb-production.appspot.com/bryant-ty/DKT-trial%201/ofzmp069/wandb-metadata.json?Expires=1699458163&GoogleAccessId=gorilla-files-url-signer-man%40wandb-production.iam.gserviceaccount.com&Signature=PrD2kR8PtL%2FLzZA7Dz9HSfpSKY6s5qJheJDJ3LLgC7wpTumvfWK%2Bza154EKHCfHeC3HbkL86CuSox54Ixvzisx8gF4LJjTto%2FCMkTfsG1Njmaxk8KigZQGLx3wxMWCyKhANaToP1QiGJHpHA6R8TtxOByNBtK2f0d24LN8%2BuK6oDgqeo1FvByEVXakT1Le80JAkFQtqG9erYfhmYtOH2E32reh6MWLA6qzqGyyqGUw6EaswRqunF%2FGqFW%2BpHPQSwHjDb9VFJbLuNF4J2E3TDmTGL5JNu3ZmkgB%2BazmazbFE0jn1XlUhI8RztoqOywXDP8kSmaQXRL644Vi28iAJWnQ%3D%3D: HTTPSConnectionPool(host='storage.googleapis.com', port=443): Max retries exceeded with url: /wandb-production.appspot.com/bryant-ty/DKT-trial%201/ofzmp069/wandb-metadata.json?Expires=1699458163&GoogleAccessId=gorilla-files-url-signer-man%40wandb-production.iam.gserviceaccount.com&Signature=PrD2kR8PtL%2FLzZA7Dz9HSfpSKY6s5qJheJDJ3LLgC7wpTumvfWK%2Bza154EKHCfHeC3HbkL86CuSox54Ixvzisx8gF4LJjTto%2FCMkTfsG1Njmaxk8KigZQGLx3wxMWCyKhANaToP1QiGJHpHA6R8TtxOByNBtK2f0d24LN8%2BuK6oDgqeo1FvByEVXakT1Le80JAkFQtqG9erYfhmYtOH2E32reh6MWLA6qzqGyyqGUw6EaswRqunF%2FGqFW%2BpHPQSwHjDb9VFJbLuNF4J2E3TDmTGL5JNu3ZmkgB%2BazmazbFE0jn1XlUhI8RztoqOywXDP8kSmaQXRL644Vi28iAJWnQ%3D%3D (Caused by NewConnectionError('<urllib3.connection.HTTPSConnection object at 0x2afd27f5e2e0>: Failed to establish a new connection: [Errno 101] Network is unreachable'))
2023-11-07 16:42:44,606 ERROR   wandb-upload_0:85669 [internal_api.py:upload_file():2558] upload_file request headers: {'User-Agent': 'python-requests/2.28.1', 'Accept-Encoding': 'gzip, deflate, br', 'Accept': '*/*', 'Connection': 'keep-alive', 'Content-Length': '14912'}
2023-11-07 16:42:44,606 ERROR   wandb-upload_0:85669 [internal_api.py:upload_file():2560] upload_file response body: 
2023-11-07 16:42:45,620 INFO    Thread-12 :85669 [dir_watcher.py:_on_file_modified():288] file/dir modified: /cluster/home/yutang/Deep-Knowledge-Tracing/DKT/KnowledgeTracing/evaluation/wandb/run-20231107_164239-ofzmp069/files/output.log
2023-11-07 16:42:46,824 ERROR   wandb-upload_0:85669 [internal_api.py:upload_file():2556] upload_file exception https://storage.googleapis.com/wandb-production.appspot.com/bryant-ty/DKT-trial%201/ofzmp069/wandb-metadata.json?Expires=1699458163&GoogleAccessId=gorilla-files-url-signer-man%40wandb-production.iam.gserviceaccount.com&Signature=PrD2kR8PtL%2FLzZA7Dz9HSfpSKY6s5qJheJDJ3LLgC7wpTumvfWK%2Bza154EKHCfHeC3HbkL86CuSox54Ixvzisx8gF4LJjTto%2FCMkTfsG1Njmaxk8KigZQGLx3wxMWCyKhANaToP1QiGJHpHA6R8TtxOByNBtK2f0d24LN8%2BuK6oDgqeo1FvByEVXakT1Le80JAkFQtqG9erYfhmYtOH2E32reh6MWLA6qzqGyyqGUw6EaswRqunF%2FGqFW%2BpHPQSwHjDb9VFJbLuNF4J2E3TDmTGL5JNu3ZmkgB%2BazmazbFE0jn1XlUhI8RztoqOywXDP8kSmaQXRL644Vi28iAJWnQ%3D%3D: HTTPSConnectionPool(host='storage.googleapis.com', port=443): Max retries exceeded with url: /wandb-production.appspot.com/bryant-ty/DKT-trial%201/ofzmp069/wandb-metadata.json?Expires=1699458163&GoogleAccessId=gorilla-files-url-signer-man%40wandb-production.iam.gserviceaccount.com&Signature=PrD2kR8PtL%2FLzZA7Dz9HSfpSKY6s5qJheJDJ3LLgC7wpTumvfWK%2Bza154EKHCfHeC3HbkL86CuSox54Ixvzisx8gF4LJjTto%2FCMkTfsG1Njmaxk8KigZQGLx3wxMWCyKhANaToP1QiGJHpHA6R8TtxOByNBtK2f0d24LN8%2BuK6oDgqeo1FvByEVXakT1Le80JAkFQtqG9erYfhmYtOH2E32reh6MWLA6qzqGyyqGUw6EaswRqunF%2FGqFW%2BpHPQSwHjDb9VFJbLuNF4J2E3TDmTGL5JNu3ZmkgB%2BazmazbFE0jn1XlUhI8RztoqOywXDP8kSmaQXRL644Vi28iAJWnQ%3D%3D (Caused by NewConnectionError('<urllib3.connection.HTTPSConnection object at 0x2afd27f5e160>: Failed to establish a new connection: [Errno 101] Network is unreachable'))
2023-11-07 16:42:46,824 ERROR   wandb-upload_0:85669 [internal_api.py:upload_file():2558] upload_file request headers: {'User-Agent': 'python-requests/2.28.1', 'Accept-Encoding': 'gzip, deflate, br', 'Accept': '*/*', 'Connection': 'keep-alive', 'Content-Length': '14912'}
2023-11-07 16:42:46,825 ERROR   wandb-upload_0:85669 [internal_api.py:upload_file():2560] upload_file response body: 
2023-11-07 16:42:46,825 INFO    wandb-upload_0:85669 [retry.py:__call__():172] Retry attempt failed:
Traceback (most recent call last):
  File "/cluster/home/yutang/miniconda3/lib/python3.9/site-packages/urllib3/connection.py", line 174, in _new_conn
    conn = connection.create_connection(
  File "/cluster/home/yutang/miniconda3/lib/python3.9/site-packages/urllib3/util/connection.py", line 95, in create_connection
    raise err
  File "/cluster/home/yutang/miniconda3/lib/python3.9/site-packages/urllib3/util/connection.py", line 85, in create_connection
    sock.connect(sa)
OSError: [Errno 101] Network is unreachable

During handling of the above exception, another exception occurred:

Traceback (most recent call last):
  File "/cluster/home/yutang/miniconda3/lib/python3.9/site-packages/urllib3/connectionpool.py", line 703, in urlopen
    httplib_response = self._make_request(
  File "/cluster/home/yutang/miniconda3/lib/python3.9/site-packages/urllib3/connectionpool.py", line 386, in _make_request
    self._validate_conn(conn)
  File "/cluster/home/yutang/miniconda3/lib/python3.9/site-packages/urllib3/connectionpool.py", line 1042, in _validate_conn
    conn.connect()
  File "/cluster/home/yutang/miniconda3/lib/python3.9/site-packages/urllib3/connection.py", line 358, in connect
    self.sock = conn = self._new_conn()
  File "/cluster/home/yutang/miniconda3/lib/python3.9/site-packages/urllib3/connection.py", line 186, in _new_conn
    raise NewConnectionError(
urllib3.exceptions.NewConnectionError: <urllib3.connection.HTTPSConnection object at 0x2afd27f5e160>: Failed to establish a new connection: [Errno 101] Network is unreachable

During handling of the above exception, another exception occurred:

Traceback (most recent call last):
  File "/cluster/home/yutang/miniconda3/lib/python3.9/site-packages/requests/adapters.py", line 489, in send
    resp = conn.urlopen(
  File "/cluster/home/yutang/miniconda3/lib/python3.9/site-packages/urllib3/connectionpool.py", line 787, in urlopen
    retries = retries.increment(
  File "/cluster/home/yutang/miniconda3/lib/python3.9/site-packages/urllib3/util/retry.py", line 592, in increment
    raise MaxRetryError(_pool, url, error or ResponseError(cause))
urllib3.exceptions.MaxRetryError: HTTPSConnectionPool(host='storage.googleapis.com', port=443): Max retries exceeded with url: /wandb-production.appspot.com/bryant-ty/DKT-trial%201/ofzmp069/wandb-metadata.json?Expires=1699458163&GoogleAccessId=gorilla-files-url-signer-man%40wandb-production.iam.gserviceaccount.com&Signature=PrD2kR8PtL%2FLzZA7Dz9HSfpSKY6s5qJheJDJ3LLgC7wpTumvfWK%2Bza154EKHCfHeC3HbkL86CuSox54Ixvzisx8gF4LJjTto%2FCMkTfsG1Njmaxk8KigZQGLx3wxMWCyKhANaToP1QiGJHpHA6R8TtxOByNBtK2f0d24LN8%2BuK6oDgqeo1FvByEVXakT1Le80JAkFQtqG9erYfhmYtOH2E32reh6MWLA6qzqGyyqGUw6EaswRqunF%2FGqFW%2BpHPQSwHjDb9VFJbLuNF4J2E3TDmTGL5JNu3ZmkgB%2BazmazbFE0jn1XlUhI8RztoqOywXDP8kSmaQXRL644Vi28iAJWnQ%3D%3D (Caused by NewConnectionError('<urllib3.connection.HTTPSConnection object at 0x2afd27f5e160>: Failed to establish a new connection: [Errno 101] Network is unreachable'))

During handling of the above exception, another exception occurred:

Traceback (most recent call last):
  File "/cluster/home/yutang/miniconda3/lib/python3.9/site-packages/wandb/sdk/internal/internal_api.py", line 2549, in upload_file
    response = self._upload_file_session.put(
  File "/cluster/home/yutang/miniconda3/lib/python3.9/site-packages/requests/sessions.py", line 647, in put
    return self.request("PUT", url, data=data, **kwargs)
  File "/cluster/home/yutang/miniconda3/lib/python3.9/site-packages/requests/sessions.py", line 587, in request
    resp = self.send(prep, **send_kwargs)
  File "/cluster/home/yutang/miniconda3/lib/python3.9/site-packages/requests/sessions.py", line 701, in send
    r = adapter.send(request, **kwargs)
  File "/cluster/home/yutang/miniconda3/lib/python3.9/site-packages/requests/adapters.py", line 565, in send
    raise ConnectionError(e, request=request)
requests.exceptions.ConnectionError: HTTPSConnectionPool(host='storage.googleapis.com', port=443): Max retries exceeded with url: /wandb-production.appspot.com/bryant-ty/DKT-trial%201/ofzmp069/wandb-metadata.json?Expires=1699458163&GoogleAccessId=gorilla-files-url-signer-man%40wandb-production.iam.gserviceaccount.com&Signature=PrD2kR8PtL%2FLzZA7Dz9HSfpSKY6s5qJheJDJ3LLgC7wpTumvfWK%2Bza154EKHCfHeC3HbkL86CuSox54Ixvzisx8gF4LJjTto%2FCMkTfsG1Njmaxk8KigZQGLx3wxMWCyKhANaToP1QiGJHpHA6R8TtxOByNBtK2f0d24LN8%2BuK6oDgqeo1FvByEVXakT1Le80JAkFQtqG9erYfhmYtOH2E32reh6MWLA6qzqGyyqGUw6EaswRqunF%2FGqFW%2BpHPQSwHjDb9VFJbLuNF4J2E3TDmTGL5JNu3ZmkgB%2BazmazbFE0jn1XlUhI8RztoqOywXDP8kSmaQXRL644Vi28iAJWnQ%3D%3D (Caused by NewConnectionError('<urllib3.connection.HTTPSConnection object at 0x2afd27f5e160>: Failed to establish a new connection: [Errno 101] Network is unreachable'))

During handling of the above exception, another exception occurred:

Traceback (most recent call last):
  File "/cluster/home/yutang/miniconda3/lib/python3.9/site-packages/wandb/sdk/lib/retry.py", line 131, in __call__
    result = self._call_fn(*args, **kwargs)
  File "/cluster/home/yutang/miniconda3/lib/python3.9/site-packages/wandb/sdk/internal/internal_api.py", line 2580, in upload_file
    raise _e.with_traceback(sys.exc_info()[2])
  File "/cluster/home/yutang/miniconda3/lib/python3.9/site-packages/wandb/sdk/internal/internal_api.py", line 2549, in upload_file
    response = self._upload_file_session.put(
  File "/cluster/home/yutang/miniconda3/lib/python3.9/site-packages/requests/sessions.py", line 647, in put
    return self.request("PUT", url, data=data, **kwargs)
  File "/cluster/home/yutang/miniconda3/lib/python3.9/site-packages/requests/sessions.py", line 587, in request
    resp = self.send(prep, **send_kwargs)
  File "/cluster/home/yutang/miniconda3/lib/python3.9/site-packages/requests/sessions.py", line 701, in send
    r = adapter.send(request, **kwargs)
  File "/cluster/home/yutang/miniconda3/lib/python3.9/site-packages/requests/adapters.py", line 565, in send
    raise ConnectionError(e, request=request)
wandb.sdk.lib.retry.TransientError: None
2023-11-07 16:42:48,626 DEBUG   SenderThread:85669 [sender.py:send():380] send: exit
2023-11-07 16:42:48,626 INFO    SenderThread:85669 [sender.py:send_exit():585] handling exit code: 1
2023-11-07 16:42:48,626 INFO    SenderThread:85669 [sender.py:send_exit():587] handling runtime: 8
2023-11-07 16:42:48,628 INFO    SenderThread:85669 [sender.py:_save_file():1378] saving file wandb-summary.json with policy end
2023-11-07 16:42:48,628 INFO    SenderThread:85669 [sender.py:send_exit():593] send defer
2023-11-07 16:42:48,629 DEBUG   HandlerThread:85669 [handler.py:handle_request():146] handle_request: defer
2023-11-07 16:42:48,629 INFO    HandlerThread:85669 [handler.py:handle_request_defer():172] handle defer: 0
2023-11-07 16:42:48,629 DEBUG   SenderThread:85669 [sender.py:send_request():407] send_request: defer
2023-11-07 16:42:48,629 INFO    SenderThread:85669 [sender.py:send_request_defer():609] handle sender defer: 0
2023-11-07 16:42:48,629 INFO    SenderThread:85669 [sender.py:transition_state():613] send defer: 1
2023-11-07 16:42:48,629 DEBUG   HandlerThread:85669 [handler.py:handle_request():146] handle_request: defer
2023-11-07 16:42:48,629 INFO    HandlerThread:85669 [handler.py:handle_request_defer():172] handle defer: 1
2023-11-07 16:42:48,629 DEBUG   SenderThread:85669 [sender.py:send_request():407] send_request: defer
2023-11-07 16:42:48,629 INFO    SenderThread:85669 [sender.py:send_request_defer():609] handle sender defer: 1
2023-11-07 16:42:48,629 INFO    SenderThread:85669 [sender.py:transition_state():613] send defer: 2
2023-11-07 16:42:48,629 DEBUG   HandlerThread:85669 [handler.py:handle_request():146] handle_request: defer
2023-11-07 16:42:48,629 INFO    HandlerThread:85669 [handler.py:handle_request_defer():172] handle defer: 2
2023-11-07 16:42:48,629 INFO    HandlerThread:85669 [system_monitor.py:finish():203] Stopping system monitor
2023-11-07 16:42:48,630 DEBUG   SystemMonitor:85669 [system_monitor.py:_start():172] Starting system metrics aggregation loop
2023-11-07 16:42:48,634 DEBUG   SystemMonitor:85669 [system_monitor.py:_start():179] Finished system metrics aggregation loop
2023-11-07 16:42:48,638 DEBUG   SystemMonitor:85669 [system_monitor.py:_start():183] Publishing last batch of metrics
2023-11-07 16:42:48,630 INFO    HandlerThread:85669 [interfaces.py:finish():202] Joined cpu monitor
2023-11-07 16:42:48,640 INFO    HandlerThread:85669 [interfaces.py:finish():202] Joined disk monitor
2023-11-07 16:42:48,913 INFO    HandlerThread:85669 [interfaces.py:finish():202] Joined gpu monitor
2023-11-07 16:42:48,914 INFO    HandlerThread:85669 [interfaces.py:finish():202] Joined memory monitor
2023-11-07 16:42:48,914 INFO    HandlerThread:85669 [interfaces.py:finish():202] Joined network monitor
2023-11-07 16:42:48,914 DEBUG   SenderThread:85669 [sender.py:send_request():407] send_request: defer
2023-11-07 16:42:48,914 INFO    SenderThread:85669 [sender.py:send_request_defer():609] handle sender defer: 2
2023-11-07 16:42:48,914 INFO    SenderThread:85669 [sender.py:transition_state():613] send defer: 3
2023-11-07 16:42:48,915 DEBUG   SenderThread:85669 [sender.py:send():380] send: stats
2023-11-07 16:42:48,915 DEBUG   HandlerThread:85669 [handler.py:handle_request():146] handle_request: defer
2023-11-07 16:42:48,916 INFO    HandlerThread:85669 [handler.py:handle_request_defer():172] handle defer: 3
2023-11-07 16:42:48,916 DEBUG   SenderThread:85669 [sender.py:send_request():407] send_request: defer
2023-11-07 16:42:48,916 INFO    SenderThread:85669 [sender.py:send_request_defer():609] handle sender defer: 3
2023-11-07 16:42:48,916 INFO    SenderThread:85669 [sender.py:transition_state():613] send defer: 4
2023-11-07 16:42:48,916 DEBUG   HandlerThread:85669 [handler.py:handle_request():146] handle_request: defer
2023-11-07 16:42:48,916 INFO    HandlerThread:85669 [handler.py:handle_request_defer():172] handle defer: 4
2023-11-07 16:42:48,916 DEBUG   SenderThread:85669 [sender.py:send_request():407] send_request: defer
2023-11-07 16:42:48,916 INFO    SenderThread:85669 [sender.py:send_request_defer():609] handle sender defer: 4
2023-11-07 16:42:48,916 INFO    SenderThread:85669 [sender.py:transition_state():613] send defer: 5
2023-11-07 16:42:48,916 DEBUG   HandlerThread:85669 [handler.py:handle_request():146] handle_request: defer
2023-11-07 16:42:48,917 INFO    HandlerThread:85669 [handler.py:handle_request_defer():172] handle defer: 5
2023-11-07 16:42:48,917 DEBUG   SenderThread:85669 [sender.py:send():380] send: summary
2023-11-07 16:42:48,918 INFO    SenderThread:85669 [sender.py:_save_file():1378] saving file wandb-summary.json with policy end
2023-11-07 16:42:48,918 DEBUG   SenderThread:85669 [sender.py:send_request():407] send_request: defer
2023-11-07 16:42:48,918 INFO    SenderThread:85669 [sender.py:send_request_defer():609] handle sender defer: 5
2023-11-07 16:42:48,918 INFO    SenderThread:85669 [sender.py:transition_state():613] send defer: 6
2023-11-07 16:42:48,918 DEBUG   HandlerThread:85669 [handler.py:handle_request():146] handle_request: defer
2023-11-07 16:42:48,919 INFO    HandlerThread:85669 [handler.py:handle_request_defer():172] handle defer: 6
2023-11-07 16:42:48,919 DEBUG   SenderThread:85669 [sender.py:send_request():407] send_request: defer
2023-11-07 16:42:48,919 INFO    SenderThread:85669 [sender.py:send_request_defer():609] handle sender defer: 6
2023-11-07 16:42:48,924 DEBUG   HandlerThread:85669 [handler.py:handle_request():146] handle_request: status_report
2023-11-07 16:42:49,128 INFO    SenderThread:85669 [sender.py:transition_state():613] send defer: 7
2023-11-07 16:42:49,128 DEBUG   HandlerThread:85669 [handler.py:handle_request():146] handle_request: defer
2023-11-07 16:42:49,128 INFO    HandlerThread:85669 [handler.py:handle_request_defer():172] handle defer: 7
2023-11-07 16:42:49,128 DEBUG   SenderThread:85669 [sender.py:send_request():407] send_request: defer
2023-11-07 16:42:49,128 INFO    SenderThread:85669 [sender.py:send_request_defer():609] handle sender defer: 7
2023-11-07 16:42:49,626 DEBUG   HandlerThread:85669 [handler.py:handle_request():146] handle_request: poll_exit
2023-11-07 16:42:49,627 INFO    Thread-12 :85669 [dir_watcher.py:_on_file_modified():288] file/dir modified: /cluster/home/yutang/Deep-Knowledge-Tracing/DKT/KnowledgeTracing/evaluation/wandb/run-20231107_164239-ofzmp069/files/config.yaml
2023-11-07 16:42:49,628 INFO    Thread-12 :85669 [dir_watcher.py:_on_file_modified():288] file/dir modified: /cluster/home/yutang/Deep-Knowledge-Tracing/DKT/KnowledgeTracing/evaluation/wandb/run-20231107_164239-ofzmp069/files/output.log
2023-11-07 16:42:49,628 INFO    Thread-12 :85669 [dir_watcher.py:_on_file_created():271] file/dir created: /cluster/home/yutang/Deep-Knowledge-Tracing/DKT/KnowledgeTracing/evaluation/wandb/run-20231107_164239-ofzmp069/files/wandb-summary.json
2023-11-07 16:42:49,960 INFO    SenderThread:85669 [sender.py:transition_state():613] send defer: 8
2023-11-07 16:42:49,960 DEBUG   SenderThread:85669 [sender.py:send_request():407] send_request: poll_exit
2023-11-07 16:42:49,960 DEBUG   HandlerThread:85669 [handler.py:handle_request():146] handle_request: defer
2023-11-07 16:42:49,960 INFO    HandlerThread:85669 [handler.py:handle_request_defer():172] handle defer: 8
2023-11-07 16:42:49,960 DEBUG   SenderThread:85669 [sender.py:send_request():407] send_request: defer
2023-11-07 16:42:49,960 INFO    SenderThread:85669 [sender.py:send_request_defer():609] handle sender defer: 8
2023-11-07 16:42:49,961 INFO    SenderThread:85669 [job_builder.py:build():281] Attempting to build job artifact
2023-11-07 16:42:49,961 INFO    SenderThread:85669 [job_builder.py:_get_source_type():393] is repo sourced job
2023-11-07 16:42:49,965 INFO    SenderThread:85669 [job_builder.py:build():369] adding wandb-job metadata file
2023-11-07 16:42:49,982 INFO    SenderThread:85669 [sender.py:transition_state():613] send defer: 9
2023-11-07 16:42:49,983 DEBUG   HandlerThread:85669 [handler.py:handle_request():146] handle_request: defer
2023-11-07 16:42:49,983 DEBUG   SenderThread:85669 [sender.py:send():380] send: artifact
2023-11-07 16:42:49,983 INFO    HandlerThread:85669 [handler.py:handle_request_defer():172] handle defer: 9
2023-11-07 16:42:50,627 DEBUG   HandlerThread:85669 [handler.py:handle_request():146] handle_request: poll_exit
2023-11-07 16:42:50,628 INFO    Thread-12 :85669 [dir_watcher.py:_on_file_modified():288] file/dir modified: /cluster/home/yutang/Deep-Knowledge-Tracing/DKT/KnowledgeTracing/evaluation/wandb/run-20231107_164239-ofzmp069/files/output.log
2023-11-07 16:42:51,203 ERROR   wandb-upload_2:85669 [internal_api.py:upload_file():2556] upload_file exception https://storage.googleapis.com/wandb-artifacts-prod/wandb_artifacts/109310165/630888432/a657693071af5cdb84a1279b99aca986?Expires=1699458171&GoogleAccessId=gorilla-files-url-signer-man%40wandb-production.iam.gserviceaccount.com&Signature=Ji2kxLgR5J%2BZuXlRYMK%2BzBM81dDrV%2BUgPCPTgZpRyJ5l8Yel8GnV6K8bQxdOrWuS2pMiudiCdAYSHVVvOO8RboabgN6IuXF74YK%2BylvkkG4FmU9dJzJdycBSLa%2B%2FQqrChTxRoMa5MdqDZEqxhILMy1vk4kIzkj64eX3q%2B9gIEZg8h7UiQHlJOlrifWIewN0Cpfl0QSb%2F%2Ba0%2B9QrV9f20TdVkFMRhBTjXN6Jb2rSDckoUJvfyHRTdSqXLBcQhrRSyC2gSjZVntail1a5rMR0SvgBh%2Fmx3PExwnEUvB83rTgxfnWjOFPGwleIiDpCcpKaft4XpedUtEAy5cO1OIp%2BOIg%3D%3D: HTTPSConnectionPool(host='storage.googleapis.com', port=443): Max retries exceeded with url: /wandb-artifacts-prod/wandb_artifacts/109310165/630888432/a657693071af5cdb84a1279b99aca986?Expires=1699458171&GoogleAccessId=gorilla-files-url-signer-man%40wandb-production.iam.gserviceaccount.com&Signature=Ji2kxLgR5J%2BZuXlRYMK%2BzBM81dDrV%2BUgPCPTgZpRyJ5l8Yel8GnV6K8bQxdOrWuS2pMiudiCdAYSHVVvOO8RboabgN6IuXF74YK%2BylvkkG4FmU9dJzJdycBSLa%2B%2FQqrChTxRoMa5MdqDZEqxhILMy1vk4kIzkj64eX3q%2B9gIEZg8h7UiQHlJOlrifWIewN0Cpfl0QSb%2F%2Ba0%2B9QrV9f20TdVkFMRhBTjXN6Jb2rSDckoUJvfyHRTdSqXLBcQhrRSyC2gSjZVntail1a5rMR0SvgBh%2Fmx3PExwnEUvB83rTgxfnWjOFPGwleIiDpCcpKaft4XpedUtEAy5cO1OIp%2BOIg%3D%3D (Caused by NewConnectionError('<urllib3.connection.HTTPSConnection object at 0x2afd4ea227f0>: Failed to establish a new connection: [Errno 101] Network is unreachable'))
2023-11-07 16:42:51,203 ERROR   wandb-upload_2:85669 [internal_api.py:upload_file():2558] upload_file request headers: {'User-Agent': 'python-requests/2.28.1', 'Accept-Encoding': 'gzip, deflate, br', 'Accept': '*/*', 'Connection': 'keep-alive', 'Content-MD5': 'pldpMHGvXNuEoSebmayphg==', 'Content-Type': 'application/json', 'Content-Length': '648'}
2023-11-07 16:42:51,203 ERROR   wandb-upload_2:85669 [internal_api.py:upload_file():2560] upload_file response body: 
2023-11-07 16:42:51,205 ERROR   wandb-upload_1:85669 [internal_api.py:upload_file():2556] upload_file exception https://storage.googleapis.com/wandb-artifacts-prod/wandb_artifacts/109310165/630888432/102cc8ee8286496275f91b42827e86ae?Expires=1699458171&GoogleAccessId=gorilla-files-url-signer-man%40wandb-production.iam.gserviceaccount.com&Signature=fzksvVNy6SANM1NUw4KhUe%2BIw%2F5AG1qy4VnC9cKlMxAOIqKTLVI5LO5u1MNcr%2FXXICxkYlUfGykO5z%2FevoLb1Xu%2FvRisNroDl9SSw6EzzqdnS7wX8xXEbxD1zyWH1aPdlCMlgUG61X2WPnW%2Bfex1NVW0XhVkNaC3svXAHG%2BrPbIkip%2FyxM%2Fx%2BnBFf5yFxFLRjVM4roHPJuoBdtMnndFVW%2FXn2%2BjlzJjPw2NoviPUUSIQX6xHzyURESMIniErWd7FIw5mRbdvMQkpSmpRE8SihbOdZ1REgjM4Kyw1mHKc5WVzI6ne1defDwC%2F7VNWUpTpMxwCJYAhtiRly2VAPv0W2A%3D%3D: HTTPSConnectionPool(host='storage.googleapis.com', port=443): Max retries exceeded with url: /wandb-artifacts-prod/wandb_artifacts/109310165/630888432/102cc8ee8286496275f91b42827e86ae?Expires=1699458171&GoogleAccessId=gorilla-files-url-signer-man%40wandb-production.iam.gserviceaccount.com&Signature=fzksvVNy6SANM1NUw4KhUe%2BIw%2F5AG1qy4VnC9cKlMxAOIqKTLVI5LO5u1MNcr%2FXXICxkYlUfGykO5z%2FevoLb1Xu%2FvRisNroDl9SSw6EzzqdnS7wX8xXEbxD1zyWH1aPdlCMlgUG61X2WPnW%2Bfex1NVW0XhVkNaC3svXAHG%2BrPbIkip%2FyxM%2Fx%2BnBFf5yFxFLRjVM4roHPJuoBdtMnndFVW%2FXn2%2BjlzJjPw2NoviPUUSIQX6xHzyURESMIniErWd7FIw5mRbdvMQkpSmpRE8SihbOdZ1REgjM4Kyw1mHKc5WVzI6ne1defDwC%2F7VNWUpTpMxwCJYAhtiRly2VAPv0W2A%3D%3D (Caused by NewConnectionError('<urllib3.connection.HTTPSConnection object at 0x2afd4ea22640>: Failed to establish a new connection: [Errno 101] Network is unreachable'))
2023-11-07 16:42:51,205 ERROR   wandb-upload_1:85669 [internal_api.py:upload_file():2558] upload_file request headers: {'User-Agent': 'python-requests/2.28.1', 'Accept-Encoding': 'gzip, deflate, br', 'Accept': '*/*', 'Connection': 'keep-alive', 'Content-MD5': 'ECzI7oKGSWJ1+RtCgn6Grg==', 'Content-Type': 'text/plain; charset=utf-8', 'Content-Length': '1756'}
2023-11-07 16:42:51,205 ERROR   wandb-upload_1:85669 [internal_api.py:upload_file():2560] upload_file response body: 
2023-11-07 16:42:51,440 ERROR   wandb-upload_0:85669 [internal_api.py:upload_file():2556] upload_file exception https://storage.googleapis.com/wandb-production.appspot.com/bryant-ty/DKT-trial%201/ofzmp069/wandb-metadata.json?Expires=1699458163&GoogleAccessId=gorilla-files-url-signer-man%40wandb-production.iam.gserviceaccount.com&Signature=PrD2kR8PtL%2FLzZA7Dz9HSfpSKY6s5qJheJDJ3LLgC7wpTumvfWK%2Bza154EKHCfHeC3HbkL86CuSox54Ixvzisx8gF4LJjTto%2FCMkTfsG1Njmaxk8KigZQGLx3wxMWCyKhANaToP1QiGJHpHA6R8TtxOByNBtK2f0d24LN8%2BuK6oDgqeo1FvByEVXakT1Le80JAkFQtqG9erYfhmYtOH2E32reh6MWLA6qzqGyyqGUw6EaswRqunF%2FGqFW%2BpHPQSwHjDb9VFJbLuNF4J2E3TDmTGL5JNu3ZmkgB%2BazmazbFE0jn1XlUhI8RztoqOywXDP8kSmaQXRL644Vi28iAJWnQ%3D%3D: HTTPSConnectionPool(host='storage.googleapis.com', port=443): Max retries exceeded with url: /wandb-production.appspot.com/bryant-ty/DKT-trial%201/ofzmp069/wandb-metadata.json?Expires=1699458163&GoogleAccessId=gorilla-files-url-signer-man%40wandb-production.iam.gserviceaccount.com&Signature=PrD2kR8PtL%2FLzZA7Dz9HSfpSKY6s5qJheJDJ3LLgC7wpTumvfWK%2Bza154EKHCfHeC3HbkL86CuSox54Ixvzisx8gF4LJjTto%2FCMkTfsG1Njmaxk8KigZQGLx3wxMWCyKhANaToP1QiGJHpHA6R8TtxOByNBtK2f0d24LN8%2BuK6oDgqeo1FvByEVXakT1Le80JAkFQtqG9erYfhmYtOH2E32reh6MWLA6qzqGyyqGUw6EaswRqunF%2FGqFW%2BpHPQSwHjDb9VFJbLuNF4J2E3TDmTGL5JNu3ZmkgB%2BazmazbFE0jn1XlUhI8RztoqOywXDP8kSmaQXRL644Vi28iAJWnQ%3D%3D (Caused by NewConnectionError('<urllib3.connection.HTTPSConnection object at 0x2afd4ea2d580>: Failed to establish a new connection: [Errno 101] Network is unreachable'))
2023-11-07 16:42:51,440 ERROR   wandb-upload_0:85669 [internal_api.py:upload_file():2558] upload_file request headers: {'User-Agent': 'python-requests/2.28.1', 'Accept-Encoding': 'gzip, deflate, br', 'Accept': '*/*', 'Connection': 'keep-alive', 'Content-Length': '14912'}
2023-11-07 16:42:51,440 ERROR   wandb-upload_0:85669 [internal_api.py:upload_file():2560] upload_file response body: 
2023-11-07 16:42:52,428 ERROR   wandb-upload_1:85669 [internal_api.py:upload_file():2556] upload_file exception https://storage.googleapis.com/wandb-artifacts-prod/wandb_artifacts/109310165/630888432/102cc8ee8286496275f91b42827e86ae?Expires=1699458171&GoogleAccessId=gorilla-files-url-signer-man%40wandb-production.iam.gserviceaccount.com&Signature=fzksvVNy6SANM1NUw4KhUe%2BIw%2F5AG1qy4VnC9cKlMxAOIqKTLVI5LO5u1MNcr%2FXXICxkYlUfGykO5z%2FevoLb1Xu%2FvRisNroDl9SSw6EzzqdnS7wX8xXEbxD1zyWH1aPdlCMlgUG61X2WPnW%2Bfex1NVW0XhVkNaC3svXAHG%2BrPbIkip%2FyxM%2Fx%2BnBFf5yFxFLRjVM4roHPJuoBdtMnndFVW%2FXn2%2BjlzJjPw2NoviPUUSIQX6xHzyURESMIniErWd7FIw5mRbdvMQkpSmpRE8SihbOdZ1REgjM4Kyw1mHKc5WVzI6ne1defDwC%2F7VNWUpTpMxwCJYAhtiRly2VAPv0W2A%3D%3D: HTTPSConnectionPool(host='storage.googleapis.com', port=443): Max retries exceeded with url: /wandb-artifacts-prod/wandb_artifacts/109310165/630888432/102cc8ee8286496275f91b42827e86ae?Expires=1699458171&GoogleAccessId=gorilla-files-url-signer-man%40wandb-production.iam.gserviceaccount.com&Signature=fzksvVNy6SANM1NUw4KhUe%2BIw%2F5AG1qy4VnC9cKlMxAOIqKTLVI5LO5u1MNcr%2FXXICxkYlUfGykO5z%2FevoLb1Xu%2FvRisNroDl9SSw6EzzqdnS7wX8xXEbxD1zyWH1aPdlCMlgUG61X2WPnW%2Bfex1NVW0XhVkNaC3svXAHG%2BrPbIkip%2FyxM%2Fx%2BnBFf5yFxFLRjVM4roHPJuoBdtMnndFVW%2FXn2%2BjlzJjPw2NoviPUUSIQX6xHzyURESMIniErWd7FIw5mRbdvMQkpSmpRE8SihbOdZ1REgjM4Kyw1mHKc5WVzI6ne1defDwC%2F7VNWUpTpMxwCJYAhtiRly2VAPv0W2A%3D%3D (Caused by NewConnectionError('<urllib3.connection.HTTPSConnection object at 0x2afd27f72e50>: Failed to establish a new connection: [Errno 101] Network is unreachable'))
2023-11-07 16:42:52,428 ERROR   wandb-upload_1:85669 [internal_api.py:upload_file():2558] upload_file request headers: {'User-Agent': 'python-requests/2.28.1', 'Accept-Encoding': 'gzip, deflate, br', 'Accept': '*/*', 'Connection': 'keep-alive', 'Content-MD5': 'ECzI7oKGSWJ1+RtCgn6Grg==', 'Content-Type': 'text/plain; charset=utf-8', 'Content-Length': '1756'}
2023-11-07 16:42:52,428 ERROR   wandb-upload_1:85669 [internal_api.py:upload_file():2560] upload_file response body: 
2023-11-07 16:42:52,457 ERROR   wandb-upload_2:85669 [internal_api.py:upload_file():2556] upload_file exception https://storage.googleapis.com/wandb-artifacts-prod/wandb_artifacts/109310165/630888432/a657693071af5cdb84a1279b99aca986?Expires=1699458171&GoogleAccessId=gorilla-files-url-signer-man%40wandb-production.iam.gserviceaccount.com&Signature=Ji2kxLgR5J%2BZuXlRYMK%2BzBM81dDrV%2BUgPCPTgZpRyJ5l8Yel8GnV6K8bQxdOrWuS2pMiudiCdAYSHVVvOO8RboabgN6IuXF74YK%2BylvkkG4FmU9dJzJdycBSLa%2B%2FQqrChTxRoMa5MdqDZEqxhILMy1vk4kIzkj64eX3q%2B9gIEZg8h7UiQHlJOlrifWIewN0Cpfl0QSb%2F%2Ba0%2B9QrV9f20TdVkFMRhBTjXN6Jb2rSDckoUJvfyHRTdSqXLBcQhrRSyC2gSjZVntail1a5rMR0SvgBh%2Fmx3PExwnEUvB83rTgxfnWjOFPGwleIiDpCcpKaft4XpedUtEAy5cO1OIp%2BOIg%3D%3D: HTTPSConnectionPool(host='storage.googleapis.com', port=443): Max retries exceeded with url: /wandb-artifacts-prod/wandb_artifacts/109310165/630888432/a657693071af5cdb84a1279b99aca986?Expires=1699458171&GoogleAccessId=gorilla-files-url-signer-man%40wandb-production.iam.gserviceaccount.com&Signature=Ji2kxLgR5J%2BZuXlRYMK%2BzBM81dDrV%2BUgPCPTgZpRyJ5l8Yel8GnV6K8bQxdOrWuS2pMiudiCdAYSHVVvOO8RboabgN6IuXF74YK%2BylvkkG4FmU9dJzJdycBSLa%2B%2FQqrChTxRoMa5MdqDZEqxhILMy1vk4kIzkj64eX3q%2B9gIEZg8h7UiQHlJOlrifWIewN0Cpfl0QSb%2F%2Ba0%2B9QrV9f20TdVkFMRhBTjXN6Jb2rSDckoUJvfyHRTdSqXLBcQhrRSyC2gSjZVntail1a5rMR0SvgBh%2Fmx3PExwnEUvB83rTgxfnWjOFPGwleIiDpCcpKaft4XpedUtEAy5cO1OIp%2BOIg%3D%3D (Caused by NewConnectionError('<urllib3.connection.HTTPSConnection object at 0x2afd4ea22f10>: Failed to establish a new connection: [Errno 101] Network is unreachable'))
2023-11-07 16:42:52,457 ERROR   wandb-upload_2:85669 [internal_api.py:upload_file():2558] upload_file request headers: {'User-Agent': 'python-requests/2.28.1', 'Accept-Encoding': 'gzip, deflate, br', 'Accept': '*/*', 'Connection': 'keep-alive', 'Content-MD5': 'pldpMHGvXNuEoSebmayphg==', 'Content-Type': 'application/json', 'Content-Length': '648'}
2023-11-07 16:42:52,457 ERROR   wandb-upload_2:85669 [internal_api.py:upload_file():2560] upload_file response body: 
2023-11-07 16:42:54,740 ERROR   wandb-upload_2:85669 [internal_api.py:upload_file():2556] upload_file exception https://storage.googleapis.com/wandb-artifacts-prod/wandb_artifacts/109310165/630888432/a657693071af5cdb84a1279b99aca986?Expires=1699458171&GoogleAccessId=gorilla-files-url-signer-man%40wandb-production.iam.gserviceaccount.com&Signature=Ji2kxLgR5J%2BZuXlRYMK%2BzBM81dDrV%2BUgPCPTgZpRyJ5l8Yel8GnV6K8bQxdOrWuS2pMiudiCdAYSHVVvOO8RboabgN6IuXF74YK%2BylvkkG4FmU9dJzJdycBSLa%2B%2FQqrChTxRoMa5MdqDZEqxhILMy1vk4kIzkj64eX3q%2B9gIEZg8h7UiQHlJOlrifWIewN0Cpfl0QSb%2F%2Ba0%2B9QrV9f20TdVkFMRhBTjXN6Jb2rSDckoUJvfyHRTdSqXLBcQhrRSyC2gSjZVntail1a5rMR0SvgBh%2Fmx3PExwnEUvB83rTgxfnWjOFPGwleIiDpCcpKaft4XpedUtEAy5cO1OIp%2BOIg%3D%3D: HTTPSConnectionPool(host='storage.googleapis.com', port=443): Max retries exceeded with url: /wandb-artifacts-prod/wandb_artifacts/109310165/630888432/a657693071af5cdb84a1279b99aca986?Expires=1699458171&GoogleAccessId=gorilla-files-url-signer-man%40wandb-production.iam.gserviceaccount.com&Signature=Ji2kxLgR5J%2BZuXlRYMK%2BzBM81dDrV%2BUgPCPTgZpRyJ5l8Yel8GnV6K8bQxdOrWuS2pMiudiCdAYSHVVvOO8RboabgN6IuXF74YK%2BylvkkG4FmU9dJzJdycBSLa%2B%2FQqrChTxRoMa5MdqDZEqxhILMy1vk4kIzkj64eX3q%2B9gIEZg8h7UiQHlJOlrifWIewN0Cpfl0QSb%2F%2Ba0%2B9QrV9f20TdVkFMRhBTjXN6Jb2rSDckoUJvfyHRTdSqXLBcQhrRSyC2gSjZVntail1a5rMR0SvgBh%2Fmx3PExwnEUvB83rTgxfnWjOFPGwleIiDpCcpKaft4XpedUtEAy5cO1OIp%2BOIg%3D%3D (Caused by NewConnectionError('<urllib3.connection.HTTPSConnection object at 0x2afd4ee476d0>: Failed to establish a new connection: [Errno 101] Network is unreachable'))
2023-11-07 16:42:54,740 ERROR   wandb-upload_2:85669 [internal_api.py:upload_file():2558] upload_file request headers: {'User-Agent': 'python-requests/2.28.1', 'Accept-Encoding': 'gzip, deflate, br', 'Accept': '*/*', 'Connection': 'keep-alive', 'Content-MD5': 'pldpMHGvXNuEoSebmayphg==', 'Content-Type': 'application/json', 'Content-Length': '648'}
2023-11-07 16:42:54,740 ERROR   wandb-upload_2:85669 [internal_api.py:upload_file():2560] upload_file response body: 
2023-11-07 16:42:54,740 INFO    wandb-upload_2:85669 [retry.py:__call__():172] Retry attempt failed:
Traceback (most recent call last):
  File "/cluster/home/yutang/miniconda3/lib/python3.9/site-packages/urllib3/connection.py", line 174, in _new_conn
    conn = connection.create_connection(
  File "/cluster/home/yutang/miniconda3/lib/python3.9/site-packages/urllib3/util/connection.py", line 95, in create_connection
    raise err
  File "/cluster/home/yutang/miniconda3/lib/python3.9/site-packages/urllib3/util/connection.py", line 85, in create_connection
    sock.connect(sa)
OSError: [Errno 101] Network is unreachable

During handling of the above exception, another exception occurred:

Traceback (most recent call last):
  File "/cluster/home/yutang/miniconda3/lib/python3.9/site-packages/urllib3/connectionpool.py", line 703, in urlopen
    httplib_response = self._make_request(
  File "/cluster/home/yutang/miniconda3/lib/python3.9/site-packages/urllib3/connectionpool.py", line 386, in _make_request
    self._validate_conn(conn)
  File "/cluster/home/yutang/miniconda3/lib/python3.9/site-packages/urllib3/connectionpool.py", line 1042, in _validate_conn
    conn.connect()
  File "/cluster/home/yutang/miniconda3/lib/python3.9/site-packages/urllib3/connection.py", line 358, in connect
    self.sock = conn = self._new_conn()
  File "/cluster/home/yutang/miniconda3/lib/python3.9/site-packages/urllib3/connection.py", line 186, in _new_conn
    raise NewConnectionError(
urllib3.exceptions.NewConnectionError: <urllib3.connection.HTTPSConnection object at 0x2afd4ee476d0>: Failed to establish a new connection: [Errno 101] Network is unreachable

During handling of the above exception, another exception occurred:

Traceback (most recent call last):
  File "/cluster/home/yutang/miniconda3/lib/python3.9/site-packages/requests/adapters.py", line 489, in send
    resp = conn.urlopen(
  File "/cluster/home/yutang/miniconda3/lib/python3.9/site-packages/urllib3/connectionpool.py", line 787, in urlopen
    retries = retries.increment(
  File "/cluster/home/yutang/miniconda3/lib/python3.9/site-packages/urllib3/util/retry.py", line 592, in increment
    raise MaxRetryError(_pool, url, error or ResponseError(cause))
urllib3.exceptions.MaxRetryError: HTTPSConnectionPool(host='storage.googleapis.com', port=443): Max retries exceeded with url: /wandb-artifacts-prod/wandb_artifacts/109310165/630888432/a657693071af5cdb84a1279b99aca986?Expires=1699458171&GoogleAccessId=gorilla-files-url-signer-man%40wandb-production.iam.gserviceaccount.com&Signature=Ji2kxLgR5J%2BZuXlRYMK%2BzBM81dDrV%2BUgPCPTgZpRyJ5l8Yel8GnV6K8bQxdOrWuS2pMiudiCdAYSHVVvOO8RboabgN6IuXF74YK%2BylvkkG4FmU9dJzJdycBSLa%2B%2FQqrChTxRoMa5MdqDZEqxhILMy1vk4kIzkj64eX3q%2B9gIEZg8h7UiQHlJOlrifWIewN0Cpfl0QSb%2F%2Ba0%2B9QrV9f20TdVkFMRhBTjXN6Jb2rSDckoUJvfyHRTdSqXLBcQhrRSyC2gSjZVntail1a5rMR0SvgBh%2Fmx3PExwnEUvB83rTgxfnWjOFPGwleIiDpCcpKaft4XpedUtEAy5cO1OIp%2BOIg%3D%3D (Caused by NewConnectionError('<urllib3.connection.HTTPSConnection object at 0x2afd4ee476d0>: Failed to establish a new connection: [Errno 101] Network is unreachable'))

During handling of the above exception, another exception occurred:

Traceback (most recent call last):
  File "/cluster/home/yutang/miniconda3/lib/python3.9/site-packages/wandb/sdk/internal/internal_api.py", line 2549, in upload_file
    response = self._upload_file_session.put(
  File "/cluster/home/yutang/miniconda3/lib/python3.9/site-packages/requests/sessions.py", line 647, in put
    return self.request("PUT", url, data=data, **kwargs)
  File "/cluster/home/yutang/miniconda3/lib/python3.9/site-packages/requests/sessions.py", line 587, in request
    resp = self.send(prep, **send_kwargs)
  File "/cluster/home/yutang/miniconda3/lib/python3.9/site-packages/requests/sessions.py", line 701, in send
    r = adapter.send(request, **kwargs)
  File "/cluster/home/yutang/miniconda3/lib/python3.9/site-packages/requests/adapters.py", line 565, in send
    raise ConnectionError(e, request=request)
requests.exceptions.ConnectionError: HTTPSConnectionPool(host='storage.googleapis.com', port=443): Max retries exceeded with url: /wandb-artifacts-prod/wandb_artifacts/109310165/630888432/a657693071af5cdb84a1279b99aca986?Expires=1699458171&GoogleAccessId=gorilla-files-url-signer-man%40wandb-production.iam.gserviceaccount.com&Signature=Ji2kxLgR5J%2BZuXlRYMK%2BzBM81dDrV%2BUgPCPTgZpRyJ5l8Yel8GnV6K8bQxdOrWuS2pMiudiCdAYSHVVvOO8RboabgN6IuXF74YK%2BylvkkG4FmU9dJzJdycBSLa%2B%2FQqrChTxRoMa5MdqDZEqxhILMy1vk4kIzkj64eX3q%2B9gIEZg8h7UiQHlJOlrifWIewN0Cpfl0QSb%2F%2Ba0%2B9QrV9f20TdVkFMRhBTjXN6Jb2rSDckoUJvfyHRTdSqXLBcQhrRSyC2gSjZVntail1a5rMR0SvgBh%2Fmx3PExwnEUvB83rTgxfnWjOFPGwleIiDpCcpKaft4XpedUtEAy5cO1OIp%2BOIg%3D%3D (Caused by NewConnectionError('<urllib3.connection.HTTPSConnection object at 0x2afd4ee476d0>: Failed to establish a new connection: [Errno 101] Network is unreachable'))

During handling of the above exception, another exception occurred:

Traceback (most recent call last):
  File "/cluster/home/yutang/miniconda3/lib/python3.9/site-packages/wandb/sdk/lib/retry.py", line 131, in __call__
    result = self._call_fn(*args, **kwargs)
  File "/cluster/home/yutang/miniconda3/lib/python3.9/site-packages/wandb/sdk/internal/internal_api.py", line 2580, in upload_file
    raise _e.with_traceback(sys.exc_info()[2])
  File "/cluster/home/yutang/miniconda3/lib/python3.9/site-packages/wandb/sdk/internal/internal_api.py", line 2549, in upload_file
    response = self._upload_file_session.put(
  File "/cluster/home/yutang/miniconda3/lib/python3.9/site-packages/requests/sessions.py", line 647, in put
    return self.request("PUT", url, data=data, **kwargs)
  File "/cluster/home/yutang/miniconda3/lib/python3.9/site-packages/requests/sessions.py", line 587, in request
    resp = self.send(prep, **send_kwargs)
  File "/cluster/home/yutang/miniconda3/lib/python3.9/site-packages/requests/sessions.py", line 701, in send
    r = adapter.send(request, **kwargs)
  File "/cluster/home/yutang/miniconda3/lib/python3.9/site-packages/requests/adapters.py", line 565, in send
    raise ConnectionError(e, request=request)
wandb.sdk.lib.retry.TransientError: None
2023-11-07 16:42:54,761 ERROR   wandb-upload_1:85669 [internal_api.py:upload_file():2556] upload_file exception https://storage.googleapis.com/wandb-artifacts-prod/wandb_artifacts/109310165/630888432/102cc8ee8286496275f91b42827e86ae?Expires=1699458171&GoogleAccessId=gorilla-files-url-signer-man%40wandb-production.iam.gserviceaccount.com&Signature=fzksvVNy6SANM1NUw4KhUe%2BIw%2F5AG1qy4VnC9cKlMxAOIqKTLVI5LO5u1MNcr%2FXXICxkYlUfGykO5z%2FevoLb1Xu%2FvRisNroDl9SSw6EzzqdnS7wX8xXEbxD1zyWH1aPdlCMlgUG61X2WPnW%2Bfex1NVW0XhVkNaC3svXAHG%2BrPbIkip%2FyxM%2Fx%2BnBFf5yFxFLRjVM4roHPJuoBdtMnndFVW%2FXn2%2BjlzJjPw2NoviPUUSIQX6xHzyURESMIniErWd7FIw5mRbdvMQkpSmpRE8SihbOdZ1REgjM4Kyw1mHKc5WVzI6ne1defDwC%2F7VNWUpTpMxwCJYAhtiRly2VAPv0W2A%3D%3D: HTTPSConnectionPool(host='storage.googleapis.com', port=443): Max retries exceeded with url: /wandb-artifacts-prod/wandb_artifacts/109310165/630888432/102cc8ee8286496275f91b42827e86ae?Expires=1699458171&GoogleAccessId=gorilla-files-url-signer-man%40wandb-production.iam.gserviceaccount.com&Signature=fzksvVNy6SANM1NUw4KhUe%2BIw%2F5AG1qy4VnC9cKlMxAOIqKTLVI5LO5u1MNcr%2FXXICxkYlUfGykO5z%2FevoLb1Xu%2FvRisNroDl9SSw6EzzqdnS7wX8xXEbxD1zyWH1aPdlCMlgUG61X2WPnW%2Bfex1NVW0XhVkNaC3svXAHG%2BrPbIkip%2FyxM%2Fx%2BnBFf5yFxFLRjVM4roHPJuoBdtMnndFVW%2FXn2%2BjlzJjPw2NoviPUUSIQX6xHzyURESMIniErWd7FIw5mRbdvMQkpSmpRE8SihbOdZ1REgjM4Kyw1mHKc5WVzI6ne1defDwC%2F7VNWUpTpMxwCJYAhtiRly2VAPv0W2A%3D%3D (Caused by NewConnectionError('<urllib3.connection.HTTPSConnection object at 0x2afd4ee47c40>: Failed to establish a new connection: [Errno 101] Network is unreachable'))
2023-11-07 16:42:54,761 ERROR   wandb-upload_1:85669 [internal_api.py:upload_file():2558] upload_file request headers: {'User-Agent': 'python-requests/2.28.1', 'Accept-Encoding': 'gzip, deflate, br', 'Accept': '*/*', 'Connection': 'keep-alive', 'Content-MD5': 'ECzI7oKGSWJ1+RtCgn6Grg==', 'Content-Type': 'text/plain; charset=utf-8', 'Content-Length': '1756'}
2023-11-07 16:42:54,761 ERROR   wandb-upload_1:85669 [internal_api.py:upload_file():2560] upload_file response body: 
2023-11-07 16:42:54,761 INFO    wandb-upload_1:85669 [retry.py:__call__():172] Retry attempt failed:
Traceback (most recent call last):
  File "/cluster/home/yutang/miniconda3/lib/python3.9/site-packages/urllib3/connection.py", line 174, in _new_conn
    conn = connection.create_connection(
  File "/cluster/home/yutang/miniconda3/lib/python3.9/site-packages/urllib3/util/connection.py", line 95, in create_connection
    raise err
  File "/cluster/home/yutang/miniconda3/lib/python3.9/site-packages/urllib3/util/connection.py", line 85, in create_connection
    sock.connect(sa)
OSError: [Errno 101] Network is unreachable

During handling of the above exception, another exception occurred:

Traceback (most recent call last):
  File "/cluster/home/yutang/miniconda3/lib/python3.9/site-packages/urllib3/connectionpool.py", line 703, in urlopen
    httplib_response = self._make_request(
  File "/cluster/home/yutang/miniconda3/lib/python3.9/site-packages/urllib3/connectionpool.py", line 386, in _make_request
    self._validate_conn(conn)
  File "/cluster/home/yutang/miniconda3/lib/python3.9/site-packages/urllib3/connectionpool.py", line 1042, in _validate_conn
    conn.connect()
  File "/cluster/home/yutang/miniconda3/lib/python3.9/site-packages/urllib3/connection.py", line 358, in connect
    self.sock = conn = self._new_conn()
  File "/cluster/home/yutang/miniconda3/lib/python3.9/site-packages/urllib3/connection.py", line 186, in _new_conn
    raise NewConnectionError(
urllib3.exceptions.NewConnectionError: <urllib3.connection.HTTPSConnection object at 0x2afd4ee47c40>: Failed to establish a new connection: [Errno 101] Network is unreachable

During handling of the above exception, another exception occurred:

Traceback (most recent call last):
  File "/cluster/home/yutang/miniconda3/lib/python3.9/site-packages/requests/adapters.py", line 489, in send
    resp = conn.urlopen(
  File "/cluster/home/yutang/miniconda3/lib/python3.9/site-packages/urllib3/connectionpool.py", line 787, in urlopen
    retries = retries.increment(
  File "/cluster/home/yutang/miniconda3/lib/python3.9/site-packages/urllib3/util/retry.py", line 592, in increment
    raise MaxRetryError(_pool, url, error or ResponseError(cause))
urllib3.exceptions.MaxRetryError: HTTPSConnectionPool(host='storage.googleapis.com', port=443): Max retries exceeded with url: /wandb-artifacts-prod/wandb_artifacts/109310165/630888432/102cc8ee8286496275f91b42827e86ae?Expires=1699458171&GoogleAccessId=gorilla-files-url-signer-man%40wandb-production.iam.gserviceaccount.com&Signature=fzksvVNy6SANM1NUw4KhUe%2BIw%2F5AG1qy4VnC9cKlMxAOIqKTLVI5LO5u1MNcr%2FXXICxkYlUfGykO5z%2FevoLb1Xu%2FvRisNroDl9SSw6EzzqdnS7wX8xXEbxD1zyWH1aPdlCMlgUG61X2WPnW%2Bfex1NVW0XhVkNaC3svXAHG%2BrPbIkip%2FyxM%2Fx%2BnBFf5yFxFLRjVM4roHPJuoBdtMnndFVW%2FXn2%2BjlzJjPw2NoviPUUSIQX6xHzyURESMIniErWd7FIw5mRbdvMQkpSmpRE8SihbOdZ1REgjM4Kyw1mHKc5WVzI6ne1defDwC%2F7VNWUpTpMxwCJYAhtiRly2VAPv0W2A%3D%3D (Caused by NewConnectionError('<urllib3.connection.HTTPSConnection object at 0x2afd4ee47c40>: Failed to establish a new connection: [Errno 101] Network is unreachable'))

During handling of the above exception, another exception occurred:

Traceback (most recent call last):
  File "/cluster/home/yutang/miniconda3/lib/python3.9/site-packages/wandb/sdk/internal/internal_api.py", line 2549, in upload_file
    response = self._upload_file_session.put(
  File "/cluster/home/yutang/miniconda3/lib/python3.9/site-packages/requests/sessions.py", line 647, in put
    return self.request("PUT", url, data=data, **kwargs)
  File "/cluster/home/yutang/miniconda3/lib/python3.9/site-packages/requests/sessions.py", line 587, in request
    resp = self.send(prep, **send_kwargs)
  File "/cluster/home/yutang/miniconda3/lib/python3.9/site-packages/requests/sessions.py", line 701, in send
    r = adapter.send(request, **kwargs)
  File "/cluster/home/yutang/miniconda3/lib/python3.9/site-packages/requests/adapters.py", line 565, in send
    raise ConnectionError(e, request=request)
requests.exceptions.ConnectionError: HTTPSConnectionPool(host='storage.googleapis.com', port=443): Max retries exceeded with url: /wandb-artifacts-prod/wandb_artifacts/109310165/630888432/102cc8ee8286496275f91b42827e86ae?Expires=1699458171&GoogleAccessId=gorilla-files-url-signer-man%40wandb-production.iam.gserviceaccount.com&Signature=fzksvVNy6SANM1NUw4KhUe%2BIw%2F5AG1qy4VnC9cKlMxAOIqKTLVI5LO5u1MNcr%2FXXICxkYlUfGykO5z%2FevoLb1Xu%2FvRisNroDl9SSw6EzzqdnS7wX8xXEbxD1zyWH1aPdlCMlgUG61X2WPnW%2Bfex1NVW0XhVkNaC3svXAHG%2BrPbIkip%2FyxM%2Fx%2BnBFf5yFxFLRjVM4roHPJuoBdtMnndFVW%2FXn2%2BjlzJjPw2NoviPUUSIQX6xHzyURESMIniErWd7FIw5mRbdvMQkpSmpRE8SihbOdZ1REgjM4Kyw1mHKc5WVzI6ne1defDwC%2F7VNWUpTpMxwCJYAhtiRly2VAPv0W2A%3D%3D (Caused by NewConnectionError('<urllib3.connection.HTTPSConnection object at 0x2afd4ee47c40>: Failed to establish a new connection: [Errno 101] Network is unreachable'))

During handling of the above exception, another exception occurred:

Traceback (most recent call last):
  File "/cluster/home/yutang/miniconda3/lib/python3.9/site-packages/wandb/sdk/lib/retry.py", line 131, in __call__
    result = self._call_fn(*args, **kwargs)
  File "/cluster/home/yutang/miniconda3/lib/python3.9/site-packages/wandb/sdk/internal/internal_api.py", line 2580, in upload_file
    raise _e.with_traceback(sys.exc_info()[2])
  File "/cluster/home/yutang/miniconda3/lib/python3.9/site-packages/wandb/sdk/internal/internal_api.py", line 2549, in upload_file
    response = self._upload_file_session.put(
  File "/cluster/home/yutang/miniconda3/lib/python3.9/site-packages/requests/sessions.py", line 647, in put
    return self.request("PUT", url, data=data, **kwargs)
  File "/cluster/home/yutang/miniconda3/lib/python3.9/site-packages/requests/sessions.py", line 587, in request
    resp = self.send(prep, **send_kwargs)
  File "/cluster/home/yutang/miniconda3/lib/python3.9/site-packages/requests/sessions.py", line 701, in send
    r = adapter.send(request, **kwargs)
  File "/cluster/home/yutang/miniconda3/lib/python3.9/site-packages/requests/adapters.py", line 565, in send
    raise ConnectionError(e, request=request)
wandb.sdk.lib.retry.TransientError: None
2023-11-07 16:42:55,629 DEBUG   HandlerThread:85669 [handler.py:handle_request():146] handle_request: keepalive
2023-11-07 16:42:59,282 ERROR   wandb-upload_2:85669 [internal_api.py:upload_file():2556] upload_file exception https://storage.googleapis.com/wandb-artifacts-prod/wandb_artifacts/109310165/630888432/a657693071af5cdb84a1279b99aca986?Expires=1699458171&GoogleAccessId=gorilla-files-url-signer-man%40wandb-production.iam.gserviceaccount.com&Signature=Ji2kxLgR5J%2BZuXlRYMK%2BzBM81dDrV%2BUgPCPTgZpRyJ5l8Yel8GnV6K8bQxdOrWuS2pMiudiCdAYSHVVvOO8RboabgN6IuXF74YK%2BylvkkG4FmU9dJzJdycBSLa%2B%2FQqrChTxRoMa5MdqDZEqxhILMy1vk4kIzkj64eX3q%2B9gIEZg8h7UiQHlJOlrifWIewN0Cpfl0QSb%2F%2Ba0%2B9QrV9f20TdVkFMRhBTjXN6Jb2rSDckoUJvfyHRTdSqXLBcQhrRSyC2gSjZVntail1a5rMR0SvgBh%2Fmx3PExwnEUvB83rTgxfnWjOFPGwleIiDpCcpKaft4XpedUtEAy5cO1OIp%2BOIg%3D%3D: HTTPSConnectionPool(host='storage.googleapis.com', port=443): Max retries exceeded with url: /wandb-artifacts-prod/wandb_artifacts/109310165/630888432/a657693071af5cdb84a1279b99aca986?Expires=1699458171&GoogleAccessId=gorilla-files-url-signer-man%40wandb-production.iam.gserviceaccount.com&Signature=Ji2kxLgR5J%2BZuXlRYMK%2BzBM81dDrV%2BUgPCPTgZpRyJ5l8Yel8GnV6K8bQxdOrWuS2pMiudiCdAYSHVVvOO8RboabgN6IuXF74YK%2BylvkkG4FmU9dJzJdycBSLa%2B%2FQqrChTxRoMa5MdqDZEqxhILMy1vk4kIzkj64eX3q%2B9gIEZg8h7UiQHlJOlrifWIewN0Cpfl0QSb%2F%2Ba0%2B9QrV9f20TdVkFMRhBTjXN6Jb2rSDckoUJvfyHRTdSqXLBcQhrRSyC2gSjZVntail1a5rMR0SvgBh%2Fmx3PExwnEUvB83rTgxfnWjOFPGwleIiDpCcpKaft4XpedUtEAy5cO1OIp%2BOIg%3D%3D (Caused by NewConnectionError('<urllib3.connection.HTTPSConnection object at 0x2afd4ee52250>: Failed to establish a new connection: [Errno 101] Network is unreachable'))
2023-11-07 16:42:59,283 ERROR   wandb-upload_2:85669 [internal_api.py:upload_file():2558] upload_file request headers: {'User-Agent': 'python-requests/2.28.1', 'Accept-Encoding': 'gzip, deflate, br', 'Accept': '*/*', 'Connection': 'keep-alive', 'Content-MD5': 'pldpMHGvXNuEoSebmayphg==', 'Content-Type': 'application/json', 'Content-Length': '648'}
2023-11-07 16:42:59,283 ERROR   wandb-upload_2:85669 [internal_api.py:upload_file():2560] upload_file response body: 
2023-11-07 16:42:59,633 ERROR   wandb-upload_1:85669 [internal_api.py:upload_file():2556] upload_file exception https://storage.googleapis.com/wandb-artifacts-prod/wandb_artifacts/109310165/630888432/102cc8ee8286496275f91b42827e86ae?Expires=1699458171&GoogleAccessId=gorilla-files-url-signer-man%40wandb-production.iam.gserviceaccount.com&Signature=fzksvVNy6SANM1NUw4KhUe%2BIw%2F5AG1qy4VnC9cKlMxAOIqKTLVI5LO5u1MNcr%2FXXICxkYlUfGykO5z%2FevoLb1Xu%2FvRisNroDl9SSw6EzzqdnS7wX8xXEbxD1zyWH1aPdlCMlgUG61X2WPnW%2Bfex1NVW0XhVkNaC3svXAHG%2BrPbIkip%2FyxM%2Fx%2BnBFf5yFxFLRjVM4roHPJuoBdtMnndFVW%2FXn2%2BjlzJjPw2NoviPUUSIQX6xHzyURESMIniErWd7FIw5mRbdvMQkpSmpRE8SihbOdZ1REgjM4Kyw1mHKc5WVzI6ne1defDwC%2F7VNWUpTpMxwCJYAhtiRly2VAPv0W2A%3D%3D: HTTPSConnectionPool(host='storage.googleapis.com', port=443): Max retries exceeded with url: /wandb-artifacts-prod/wandb_artifacts/109310165/630888432/102cc8ee8286496275f91b42827e86ae?Expires=1699458171&GoogleAccessId=gorilla-files-url-signer-man%40wandb-production.iam.gserviceaccount.com&Signature=fzksvVNy6SANM1NUw4KhUe%2BIw%2F5AG1qy4VnC9cKlMxAOIqKTLVI5LO5u1MNcr%2FXXICxkYlUfGykO5z%2FevoLb1Xu%2FvRisNroDl9SSw6EzzqdnS7wX8xXEbxD1zyWH1aPdlCMlgUG61X2WPnW%2Bfex1NVW0XhVkNaC3svXAHG%2BrPbIkip%2FyxM%2Fx%2BnBFf5yFxFLRjVM4roHPJuoBdtMnndFVW%2FXn2%2BjlzJjPw2NoviPUUSIQX6xHzyURESMIniErWd7FIw5mRbdvMQkpSmpRE8SihbOdZ1REgjM4Kyw1mHKc5WVzI6ne1defDwC%2F7VNWUpTpMxwCJYAhtiRly2VAPv0W2A%3D%3D (Caused by NewConnectionError('<urllib3.connection.HTTPSConnection object at 0x2afd4ee52a60>: Failed to establish a new connection: [Errno 101] Network is unreachable'))
2023-11-07 16:42:59,633 ERROR   wandb-upload_1:85669 [internal_api.py:upload_file():2558] upload_file request headers: {'User-Agent': 'python-requests/2.28.1', 'Accept-Encoding': 'gzip, deflate, br', 'Accept': '*/*', 'Connection': 'keep-alive', 'Content-MD5': 'ECzI7oKGSWJ1+RtCgn6Grg==', 'Content-Type': 'text/plain; charset=utf-8', 'Content-Length': '1756'}
2023-11-07 16:42:59,633 ERROR   wandb-upload_1:85669 [internal_api.py:upload_file():2560] upload_file response body: 
2023-11-07 16:43:00,631 DEBUG   HandlerThread:85669 [handler.py:handle_request():146] handle_request: keepalive
2023-11-07 16:43:00,803 ERROR   wandb-upload_0:85669 [internal_api.py:upload_file():2556] upload_file exception https://storage.googleapis.com/wandb-production.appspot.com/bryant-ty/DKT-trial%201/ofzmp069/wandb-metadata.json?Expires=1699458163&GoogleAccessId=gorilla-files-url-signer-man%40wandb-production.iam.gserviceaccount.com&Signature=PrD2kR8PtL%2FLzZA7Dz9HSfpSKY6s5qJheJDJ3LLgC7wpTumvfWK%2Bza154EKHCfHeC3HbkL86CuSox54Ixvzisx8gF4LJjTto%2FCMkTfsG1Njmaxk8KigZQGLx3wxMWCyKhANaToP1QiGJHpHA6R8TtxOByNBtK2f0d24LN8%2BuK6oDgqeo1FvByEVXakT1Le80JAkFQtqG9erYfhmYtOH2E32reh6MWLA6qzqGyyqGUw6EaswRqunF%2FGqFW%2BpHPQSwHjDb9VFJbLuNF4J2E3TDmTGL5JNu3ZmkgB%2BazmazbFE0jn1XlUhI8RztoqOywXDP8kSmaQXRL644Vi28iAJWnQ%3D%3D: HTTPSConnectionPool(host='storage.googleapis.com', port=443): Max retries exceeded with url: /wandb-production.appspot.com/bryant-ty/DKT-trial%201/ofzmp069/wandb-metadata.json?Expires=1699458163&GoogleAccessId=gorilla-files-url-signer-man%40wandb-production.iam.gserviceaccount.com&Signature=PrD2kR8PtL%2FLzZA7Dz9HSfpSKY6s5qJheJDJ3LLgC7wpTumvfWK%2Bza154EKHCfHeC3HbkL86CuSox54Ixvzisx8gF4LJjTto%2FCMkTfsG1Njmaxk8KigZQGLx3wxMWCyKhANaToP1QiGJHpHA6R8TtxOByNBtK2f0d24LN8%2BuK6oDgqeo1FvByEVXakT1Le80JAkFQtqG9erYfhmYtOH2E32reh6MWLA6qzqGyyqGUw6EaswRqunF%2FGqFW%2BpHPQSwHjDb9VFJbLuNF4J2E3TDmTGL5JNu3ZmkgB%2BazmazbFE0jn1XlUhI8RztoqOywXDP8kSmaQXRL644Vi28iAJWnQ%3D%3D (Caused by NewConnectionError('<urllib3.connection.HTTPSConnection object at 0x2afd4ee58160>: Failed to establish a new connection: [Errno 101] Network is unreachable'))
2023-11-07 16:43:00,804 ERROR   wandb-upload_0:85669 [internal_api.py:upload_file():2558] upload_file request headers: {'User-Agent': 'python-requests/2.28.1', 'Accept-Encoding': 'gzip, deflate, br', 'Accept': '*/*', 'Connection': 'keep-alive', 'Content-Length': '14912'}
2023-11-07 16:43:00,804 ERROR   wandb-upload_0:85669 [internal_api.py:upload_file():2560] upload_file response body: 
2023-11-07 16:43:05,633 DEBUG   HandlerThread:85669 [handler.py:handle_request():146] handle_request: keepalive
2023-11-07 16:43:07,403 ERROR   wandb-upload_2:85669 [internal_api.py:upload_file():2556] upload_file exception https://storage.googleapis.com/wandb-artifacts-prod/wandb_artifacts/109310165/630888432/a657693071af5cdb84a1279b99aca986?Expires=1699458171&GoogleAccessId=gorilla-files-url-signer-man%40wandb-production.iam.gserviceaccount.com&Signature=Ji2kxLgR5J%2BZuXlRYMK%2BzBM81dDrV%2BUgPCPTgZpRyJ5l8Yel8GnV6K8bQxdOrWuS2pMiudiCdAYSHVVvOO8RboabgN6IuXF74YK%2BylvkkG4FmU9dJzJdycBSLa%2B%2FQqrChTxRoMa5MdqDZEqxhILMy1vk4kIzkj64eX3q%2B9gIEZg8h7UiQHlJOlrifWIewN0Cpfl0QSb%2F%2Ba0%2B9QrV9f20TdVkFMRhBTjXN6Jb2rSDckoUJvfyHRTdSqXLBcQhrRSyC2gSjZVntail1a5rMR0SvgBh%2Fmx3PExwnEUvB83rTgxfnWjOFPGwleIiDpCcpKaft4XpedUtEAy5cO1OIp%2BOIg%3D%3D: HTTPSConnectionPool(host='storage.googleapis.com', port=443): Max retries exceeded with url: /wandb-artifacts-prod/wandb_artifacts/109310165/630888432/a657693071af5cdb84a1279b99aca986?Expires=1699458171&GoogleAccessId=gorilla-files-url-signer-man%40wandb-production.iam.gserviceaccount.com&Signature=Ji2kxLgR5J%2BZuXlRYMK%2BzBM81dDrV%2BUgPCPTgZpRyJ5l8Yel8GnV6K8bQxdOrWuS2pMiudiCdAYSHVVvOO8RboabgN6IuXF74YK%2BylvkkG4FmU9dJzJdycBSLa%2B%2FQqrChTxRoMa5MdqDZEqxhILMy1vk4kIzkj64eX3q%2B9gIEZg8h7UiQHlJOlrifWIewN0Cpfl0QSb%2F%2Ba0%2B9QrV9f20TdVkFMRhBTjXN6Jb2rSDckoUJvfyHRTdSqXLBcQhrRSyC2gSjZVntail1a5rMR0SvgBh%2Fmx3PExwnEUvB83rTgxfnWjOFPGwleIiDpCcpKaft4XpedUtEAy5cO1OIp%2BOIg%3D%3D (Caused by NewConnectionError('<urllib3.connection.HTTPSConnection object at 0x2afd4ee52340>: Failed to establish a new connection: [Errno 101] Network is unreachable'))
2023-11-07 16:43:07,404 ERROR   wandb-upload_2:85669 [internal_api.py:upload_file():2558] upload_file request headers: {'User-Agent': 'python-requests/2.28.1', 'Accept-Encoding': 'gzip, deflate, br', 'Accept': '*/*', 'Connection': 'keep-alive', 'Content-MD5': 'pldpMHGvXNuEoSebmayphg==', 'Content-Type': 'application/json', 'Content-Length': '648'}
2023-11-07 16:43:07,404 ERROR   wandb-upload_2:85669 [internal_api.py:upload_file():2560] upload_file response body: 
2023-11-07 16:43:09,275 ERROR   wandb-upload_1:85669 [internal_api.py:upload_file():2556] upload_file exception https://storage.googleapis.com/wandb-artifacts-prod/wandb_artifacts/109310165/630888432/102cc8ee8286496275f91b42827e86ae?Expires=1699458171&GoogleAccessId=gorilla-files-url-signer-man%40wandb-production.iam.gserviceaccount.com&Signature=fzksvVNy6SANM1NUw4KhUe%2BIw%2F5AG1qy4VnC9cKlMxAOIqKTLVI5LO5u1MNcr%2FXXICxkYlUfGykO5z%2FevoLb1Xu%2FvRisNroDl9SSw6EzzqdnS7wX8xXEbxD1zyWH1aPdlCMlgUG61X2WPnW%2Bfex1NVW0XhVkNaC3svXAHG%2BrPbIkip%2FyxM%2Fx%2BnBFf5yFxFLRjVM4roHPJuoBdtMnndFVW%2FXn2%2BjlzJjPw2NoviPUUSIQX6xHzyURESMIniErWd7FIw5mRbdvMQkpSmpRE8SihbOdZ1REgjM4Kyw1mHKc5WVzI6ne1defDwC%2F7VNWUpTpMxwCJYAhtiRly2VAPv0W2A%3D%3D: HTTPSConnectionPool(host='storage.googleapis.com', port=443): Max retries exceeded with url: /wandb-artifacts-prod/wandb_artifacts/109310165/630888432/102cc8ee8286496275f91b42827e86ae?Expires=1699458171&GoogleAccessId=gorilla-files-url-signer-man%40wandb-production.iam.gserviceaccount.com&Signature=fzksvVNy6SANM1NUw4KhUe%2BIw%2F5AG1qy4VnC9cKlMxAOIqKTLVI5LO5u1MNcr%2FXXICxkYlUfGykO5z%2FevoLb1Xu%2FvRisNroDl9SSw6EzzqdnS7wX8xXEbxD1zyWH1aPdlCMlgUG61X2WPnW%2Bfex1NVW0XhVkNaC3svXAHG%2BrPbIkip%2FyxM%2Fx%2BnBFf5yFxFLRjVM4roHPJuoBdtMnndFVW%2FXn2%2BjlzJjPw2NoviPUUSIQX6xHzyURESMIniErWd7FIw5mRbdvMQkpSmpRE8SihbOdZ1REgjM4Kyw1mHKc5WVzI6ne1defDwC%2F7VNWUpTpMxwCJYAhtiRly2VAPv0W2A%3D%3D (Caused by NewConnectionError('<urllib3.connection.HTTPSConnection object at 0x2afd4ee47b50>: Failed to establish a new connection: [Errno 101] Network is unreachable'))
2023-11-07 16:43:09,276 ERROR   wandb-upload_1:85669 [internal_api.py:upload_file():2558] upload_file request headers: {'User-Agent': 'python-requests/2.28.1', 'Accept-Encoding': 'gzip, deflate, br', 'Accept': '*/*', 'Connection': 'keep-alive', 'Content-MD5': 'ECzI7oKGSWJ1+RtCgn6Grg==', 'Content-Type': 'text/plain; charset=utf-8', 'Content-Length': '1756'}
2023-11-07 16:43:09,276 ERROR   wandb-upload_1:85669 [internal_api.py:upload_file():2560] upload_file response body: 
2023-11-07 16:43:10,635 DEBUG   HandlerThread:85669 [handler.py:handle_request():146] handle_request: keepalive
2023-11-07 16:43:15,636 DEBUG   HandlerThread:85669 [handler.py:handle_request():146] handle_request: keepalive
2023-11-07 16:43:17,436 ERROR   wandb-upload_0:85669 [internal_api.py:upload_file():2556] upload_file exception https://storage.googleapis.com/wandb-production.appspot.com/bryant-ty/DKT-trial%201/ofzmp069/wandb-metadata.json?Expires=1699458163&GoogleAccessId=gorilla-files-url-signer-man%40wandb-production.iam.gserviceaccount.com&Signature=PrD2kR8PtL%2FLzZA7Dz9HSfpSKY6s5qJheJDJ3LLgC7wpTumvfWK%2Bza154EKHCfHeC3HbkL86CuSox54Ixvzisx8gF4LJjTto%2FCMkTfsG1Njmaxk8KigZQGLx3wxMWCyKhANaToP1QiGJHpHA6R8TtxOByNBtK2f0d24LN8%2BuK6oDgqeo1FvByEVXakT1Le80JAkFQtqG9erYfhmYtOH2E32reh6MWLA6qzqGyyqGUw6EaswRqunF%2FGqFW%2BpHPQSwHjDb9VFJbLuNF4J2E3TDmTGL5JNu3ZmkgB%2BazmazbFE0jn1XlUhI8RztoqOywXDP8kSmaQXRL644Vi28iAJWnQ%3D%3D: HTTPSConnectionPool(host='storage.googleapis.com', port=443): Max retries exceeded with url: /wandb-production.appspot.com/bryant-ty/DKT-trial%201/ofzmp069/wandb-metadata.json?Expires=1699458163&GoogleAccessId=gorilla-files-url-signer-man%40wandb-production.iam.gserviceaccount.com&Signature=PrD2kR8PtL%2FLzZA7Dz9HSfpSKY6s5qJheJDJ3LLgC7wpTumvfWK%2Bza154EKHCfHeC3HbkL86CuSox54Ixvzisx8gF4LJjTto%2FCMkTfsG1Njmaxk8KigZQGLx3wxMWCyKhANaToP1QiGJHpHA6R8TtxOByNBtK2f0d24LN8%2BuK6oDgqeo1FvByEVXakT1Le80JAkFQtqG9erYfhmYtOH2E32reh6MWLA6qzqGyyqGUw6EaswRqunF%2FGqFW%2BpHPQSwHjDb9VFJbLuNF4J2E3TDmTGL5JNu3ZmkgB%2BazmazbFE0jn1XlUhI8RztoqOywXDP8kSmaQXRL644Vi28iAJWnQ%3D%3D (Caused by NewConnectionError('<urllib3.connection.HTTPSConnection object at 0x2afd4ee47760>: Failed to establish a new connection: [Errno 101] Network is unreachable'))
2023-11-07 16:43:17,436 ERROR   wandb-upload_0:85669 [internal_api.py:upload_file():2558] upload_file request headers: {'User-Agent': 'python-requests/2.28.1', 'Accept-Encoding': 'gzip, deflate, br', 'Accept': '*/*', 'Connection': 'keep-alive', 'Content-Length': '14912'}
2023-11-07 16:43:17,436 ERROR   wandb-upload_0:85669 [internal_api.py:upload_file():2560] upload_file response body: 
2023-11-07 16:43:20,639 DEBUG   HandlerThread:85669 [handler.py:handle_request():146] handle_request: keepalive
2023-11-07 16:43:24,577 ERROR   wandb-upload_2:85669 [internal_api.py:upload_file():2556] upload_file exception https://storage.googleapis.com/wandb-artifacts-prod/wandb_artifacts/109310165/630888432/a657693071af5cdb84a1279b99aca986?Expires=1699458171&GoogleAccessId=gorilla-files-url-signer-man%40wandb-production.iam.gserviceaccount.com&Signature=Ji2kxLgR5J%2BZuXlRYMK%2BzBM81dDrV%2BUgPCPTgZpRyJ5l8Yel8GnV6K8bQxdOrWuS2pMiudiCdAYSHVVvOO8RboabgN6IuXF74YK%2BylvkkG4FmU9dJzJdycBSLa%2B%2FQqrChTxRoMa5MdqDZEqxhILMy1vk4kIzkj64eX3q%2B9gIEZg8h7UiQHlJOlrifWIewN0Cpfl0QSb%2F%2Ba0%2B9QrV9f20TdVkFMRhBTjXN6Jb2rSDckoUJvfyHRTdSqXLBcQhrRSyC2gSjZVntail1a5rMR0SvgBh%2Fmx3PExwnEUvB83rTgxfnWjOFPGwleIiDpCcpKaft4XpedUtEAy5cO1OIp%2BOIg%3D%3D: HTTPSConnectionPool(host='storage.googleapis.com', port=443): Max retries exceeded with url: /wandb-artifacts-prod/wandb_artifacts/109310165/630888432/a657693071af5cdb84a1279b99aca986?Expires=1699458171&GoogleAccessId=gorilla-files-url-signer-man%40wandb-production.iam.gserviceaccount.com&Signature=Ji2kxLgR5J%2BZuXlRYMK%2BzBM81dDrV%2BUgPCPTgZpRyJ5l8Yel8GnV6K8bQxdOrWuS2pMiudiCdAYSHVVvOO8RboabgN6IuXF74YK%2BylvkkG4FmU9dJzJdycBSLa%2B%2FQqrChTxRoMa5MdqDZEqxhILMy1vk4kIzkj64eX3q%2B9gIEZg8h7UiQHlJOlrifWIewN0Cpfl0QSb%2F%2Ba0%2B9QrV9f20TdVkFMRhBTjXN6Jb2rSDckoUJvfyHRTdSqXLBcQhrRSyC2gSjZVntail1a5rMR0SvgBh%2Fmx3PExwnEUvB83rTgxfnWjOFPGwleIiDpCcpKaft4XpedUtEAy5cO1OIp%2BOIg%3D%3D (Caused by NewConnectionError('<urllib3.connection.HTTPSConnection object at 0x2afd4ea22fd0>: Failed to establish a new connection: [Errno 101] Network is unreachable'))
2023-11-07 16:43:24,577 ERROR   wandb-upload_2:85669 [internal_api.py:upload_file():2558] upload_file request headers: {'User-Agent': 'python-requests/2.28.1', 'Accept-Encoding': 'gzip, deflate, br', 'Accept': '*/*', 'Connection': 'keep-alive', 'Content-MD5': 'pldpMHGvXNuEoSebmayphg==', 'Content-Type': 'application/json', 'Content-Length': '648'}
2023-11-07 16:43:24,577 ERROR   wandb-upload_2:85669 [internal_api.py:upload_file():2560] upload_file response body: 
2023-11-07 16:43:25,640 DEBUG   HandlerThread:85669 [handler.py:handle_request():146] handle_request: keepalive
2023-11-07 16:43:27,951 ERROR   wandb-upload_1:85669 [internal_api.py:upload_file():2556] upload_file exception https://storage.googleapis.com/wandb-artifacts-prod/wandb_artifacts/109310165/630888432/102cc8ee8286496275f91b42827e86ae?Expires=1699458171&GoogleAccessId=gorilla-files-url-signer-man%40wandb-production.iam.gserviceaccount.com&Signature=fzksvVNy6SANM1NUw4KhUe%2BIw%2F5AG1qy4VnC9cKlMxAOIqKTLVI5LO5u1MNcr%2FXXICxkYlUfGykO5z%2FevoLb1Xu%2FvRisNroDl9SSw6EzzqdnS7wX8xXEbxD1zyWH1aPdlCMlgUG61X2WPnW%2Bfex1NVW0XhVkNaC3svXAHG%2BrPbIkip%2FyxM%2Fx%2BnBFf5yFxFLRjVM4roHPJuoBdtMnndFVW%2FXn2%2BjlzJjPw2NoviPUUSIQX6xHzyURESMIniErWd7FIw5mRbdvMQkpSmpRE8SihbOdZ1REgjM4Kyw1mHKc5WVzI6ne1defDwC%2F7VNWUpTpMxwCJYAhtiRly2VAPv0W2A%3D%3D: HTTPSConnectionPool(host='storage.googleapis.com', port=443): Max retries exceeded with url: /wandb-artifacts-prod/wandb_artifacts/109310165/630888432/102cc8ee8286496275f91b42827e86ae?Expires=1699458171&GoogleAccessId=gorilla-files-url-signer-man%40wandb-production.iam.gserviceaccount.com&Signature=fzksvVNy6SANM1NUw4KhUe%2BIw%2F5AG1qy4VnC9cKlMxAOIqKTLVI5LO5u1MNcr%2FXXICxkYlUfGykO5z%2FevoLb1Xu%2FvRisNroDl9SSw6EzzqdnS7wX8xXEbxD1zyWH1aPdlCMlgUG61X2WPnW%2Bfex1NVW0XhVkNaC3svXAHG%2BrPbIkip%2FyxM%2Fx%2BnBFf5yFxFLRjVM4roHPJuoBdtMnndFVW%2FXn2%2BjlzJjPw2NoviPUUSIQX6xHzyURESMIniErWd7FIw5mRbdvMQkpSmpRE8SihbOdZ1REgjM4Kyw1mHKc5WVzI6ne1defDwC%2F7VNWUpTpMxwCJYAhtiRly2VAPv0W2A%3D%3D (Caused by NewConnectionError('<urllib3.connection.HTTPSConnection object at 0x2afd4ee580a0>: Failed to establish a new connection: [Errno 101] Network is unreachable'))
2023-11-07 16:43:27,951 ERROR   wandb-upload_1:85669 [internal_api.py:upload_file():2558] upload_file request headers: {'User-Agent': 'python-requests/2.28.1', 'Accept-Encoding': 'gzip, deflate, br', 'Accept': '*/*', 'Connection': 'keep-alive', 'Content-MD5': 'ECzI7oKGSWJ1+RtCgn6Grg==', 'Content-Type': 'text/plain; charset=utf-8', 'Content-Length': '1756'}
2023-11-07 16:43:27,951 ERROR   wandb-upload_1:85669 [internal_api.py:upload_file():2560] upload_file response body: 
2023-11-07 16:43:30,642 DEBUG   HandlerThread:85669 [handler.py:handle_request():146] handle_request: keepalive
2023-11-07 16:43:35,644 DEBUG   HandlerThread:85669 [handler.py:handle_request():146] handle_request: keepalive
2023-11-07 16:43:40,646 DEBUG   HandlerThread:85669 [handler.py:handle_request():146] handle_request: keepalive
2023-11-07 16:43:45,647 DEBUG   HandlerThread:85669 [handler.py:handle_request():146] handle_request: keepalive
2023-11-07 16:43:50,649 DEBUG   HandlerThread:85669 [handler.py:handle_request():146] handle_request: keepalive
2023-11-07 16:43:55,651 DEBUG   HandlerThread:85669 [handler.py:handle_request():146] handle_request: keepalive
2023-11-07 16:43:56,399 ERROR   wandb-upload_0:85669 [internal_api.py:upload_file():2556] upload_file exception https://storage.googleapis.com/wandb-production.appspot.com/bryant-ty/DKT-trial%201/ofzmp069/wandb-metadata.json?Expires=1699458163&GoogleAccessId=gorilla-files-url-signer-man%40wandb-production.iam.gserviceaccount.com&Signature=PrD2kR8PtL%2FLzZA7Dz9HSfpSKY6s5qJheJDJ3LLgC7wpTumvfWK%2Bza154EKHCfHeC3HbkL86CuSox54Ixvzisx8gF4LJjTto%2FCMkTfsG1Njmaxk8KigZQGLx3wxMWCyKhANaToP1QiGJHpHA6R8TtxOByNBtK2f0d24LN8%2BuK6oDgqeo1FvByEVXakT1Le80JAkFQtqG9erYfhmYtOH2E32reh6MWLA6qzqGyyqGUw6EaswRqunF%2FGqFW%2BpHPQSwHjDb9VFJbLuNF4J2E3TDmTGL5JNu3ZmkgB%2BazmazbFE0jn1XlUhI8RztoqOywXDP8kSmaQXRL644Vi28iAJWnQ%3D%3D: HTTPSConnectionPool(host='storage.googleapis.com', port=443): Max retries exceeded with url: /wandb-production.appspot.com/bryant-ty/DKT-trial%201/ofzmp069/wandb-metadata.json?Expires=1699458163&GoogleAccessId=gorilla-files-url-signer-man%40wandb-production.iam.gserviceaccount.com&Signature=PrD2kR8PtL%2FLzZA7Dz9HSfpSKY6s5qJheJDJ3LLgC7wpTumvfWK%2Bza154EKHCfHeC3HbkL86CuSox54Ixvzisx8gF4LJjTto%2FCMkTfsG1Njmaxk8KigZQGLx3wxMWCyKhANaToP1QiGJHpHA6R8TtxOByNBtK2f0d24LN8%2BuK6oDgqeo1FvByEVXakT1Le80JAkFQtqG9erYfhmYtOH2E32reh6MWLA6qzqGyyqGUw6EaswRqunF%2FGqFW%2BpHPQSwHjDb9VFJbLuNF4J2E3TDmTGL5JNu3ZmkgB%2BazmazbFE0jn1XlUhI8RztoqOywXDP8kSmaQXRL644Vi28iAJWnQ%3D%3D (Caused by NewConnectionError('<urllib3.connection.HTTPSConnection object at 0x2afd4ee5f070>: Failed to establish a new connection: [Errno 101] Network is unreachable'))
2023-11-07 16:43:56,399 ERROR   wandb-upload_0:85669 [internal_api.py:upload_file():2558] upload_file request headers: {'User-Agent': 'python-requests/2.28.1', 'Accept-Encoding': 'gzip, deflate, br', 'Accept': '*/*', 'Connection': 'keep-alive', 'Content-Length': '14912'}
2023-11-07 16:43:56,399 ERROR   wandb-upload_0:85669 [internal_api.py:upload_file():2560] upload_file response body: 
2023-11-07 16:43:58,684 ERROR   wandb-upload_2:85669 [internal_api.py:upload_file():2556] upload_file exception https://storage.googleapis.com/wandb-artifacts-prod/wandb_artifacts/109310165/630888432/a657693071af5cdb84a1279b99aca986?Expires=1699458171&GoogleAccessId=gorilla-files-url-signer-man%40wandb-production.iam.gserviceaccount.com&Signature=Ji2kxLgR5J%2BZuXlRYMK%2BzBM81dDrV%2BUgPCPTgZpRyJ5l8Yel8GnV6K8bQxdOrWuS2pMiudiCdAYSHVVvOO8RboabgN6IuXF74YK%2BylvkkG4FmU9dJzJdycBSLa%2B%2FQqrChTxRoMa5MdqDZEqxhILMy1vk4kIzkj64eX3q%2B9gIEZg8h7UiQHlJOlrifWIewN0Cpfl0QSb%2F%2Ba0%2B9QrV9f20TdVkFMRhBTjXN6Jb2rSDckoUJvfyHRTdSqXLBcQhrRSyC2gSjZVntail1a5rMR0SvgBh%2Fmx3PExwnEUvB83rTgxfnWjOFPGwleIiDpCcpKaft4XpedUtEAy5cO1OIp%2BOIg%3D%3D: HTTPSConnectionPool(host='storage.googleapis.com', port=443): Max retries exceeded with url: /wandb-artifacts-prod/wandb_artifacts/109310165/630888432/a657693071af5cdb84a1279b99aca986?Expires=1699458171&GoogleAccessId=gorilla-files-url-signer-man%40wandb-production.iam.gserviceaccount.com&Signature=Ji2kxLgR5J%2BZuXlRYMK%2BzBM81dDrV%2BUgPCPTgZpRyJ5l8Yel8GnV6K8bQxdOrWuS2pMiudiCdAYSHVVvOO8RboabgN6IuXF74YK%2BylvkkG4FmU9dJzJdycBSLa%2B%2FQqrChTxRoMa5MdqDZEqxhILMy1vk4kIzkj64eX3q%2B9gIEZg8h7UiQHlJOlrifWIewN0Cpfl0QSb%2F%2Ba0%2B9QrV9f20TdVkFMRhBTjXN6Jb2rSDckoUJvfyHRTdSqXLBcQhrRSyC2gSjZVntail1a5rMR0SvgBh%2Fmx3PExwnEUvB83rTgxfnWjOFPGwleIiDpCcpKaft4XpedUtEAy5cO1OIp%2BOIg%3D%3D (Caused by NewConnectionError('<urllib3.connection.HTTPSConnection object at 0x2afd4ea22d00>: Failed to establish a new connection: [Errno 101] Network is unreachable'))
2023-11-07 16:43:58,684 ERROR   wandb-upload_2:85669 [internal_api.py:upload_file():2558] upload_file request headers: {'User-Agent': 'python-requests/2.28.1', 'Accept-Encoding': 'gzip, deflate, br', 'Accept': '*/*', 'Connection': 'keep-alive', 'Content-MD5': 'pldpMHGvXNuEoSebmayphg==', 'Content-Type': 'application/json', 'Content-Length': '648'}
2023-11-07 16:43:58,684 ERROR   wandb-upload_2:85669 [internal_api.py:upload_file():2560] upload_file response body: 
2023-11-07 16:44:00,653 DEBUG   HandlerThread:85669 [handler.py:handle_request():146] handle_request: keepalive
2023-11-07 16:44:04,781 ERROR   wandb-upload_1:85669 [internal_api.py:upload_file():2556] upload_file exception https://storage.googleapis.com/wandb-artifacts-prod/wandb_artifacts/109310165/630888432/102cc8ee8286496275f91b42827e86ae?Expires=1699458171&GoogleAccessId=gorilla-files-url-signer-man%40wandb-production.iam.gserviceaccount.com&Signature=fzksvVNy6SANM1NUw4KhUe%2BIw%2F5AG1qy4VnC9cKlMxAOIqKTLVI5LO5u1MNcr%2FXXICxkYlUfGykO5z%2FevoLb1Xu%2FvRisNroDl9SSw6EzzqdnS7wX8xXEbxD1zyWH1aPdlCMlgUG61X2WPnW%2Bfex1NVW0XhVkNaC3svXAHG%2BrPbIkip%2FyxM%2Fx%2BnBFf5yFxFLRjVM4roHPJuoBdtMnndFVW%2FXn2%2BjlzJjPw2NoviPUUSIQX6xHzyURESMIniErWd7FIw5mRbdvMQkpSmpRE8SihbOdZ1REgjM4Kyw1mHKc5WVzI6ne1defDwC%2F7VNWUpTpMxwCJYAhtiRly2VAPv0W2A%3D%3D: HTTPSConnectionPool(host='storage.googleapis.com', port=443): Max retries exceeded with url: /wandb-artifacts-prod/wandb_artifacts/109310165/630888432/102cc8ee8286496275f91b42827e86ae?Expires=1699458171&GoogleAccessId=gorilla-files-url-signer-man%40wandb-production.iam.gserviceaccount.com&Signature=fzksvVNy6SANM1NUw4KhUe%2BIw%2F5AG1qy4VnC9cKlMxAOIqKTLVI5LO5u1MNcr%2FXXICxkYlUfGykO5z%2FevoLb1Xu%2FvRisNroDl9SSw6EzzqdnS7wX8xXEbxD1zyWH1aPdlCMlgUG61X2WPnW%2Bfex1NVW0XhVkNaC3svXAHG%2BrPbIkip%2FyxM%2Fx%2BnBFf5yFxFLRjVM4roHPJuoBdtMnndFVW%2FXn2%2BjlzJjPw2NoviPUUSIQX6xHzyURESMIniErWd7FIw5mRbdvMQkpSmpRE8SihbOdZ1REgjM4Kyw1mHKc5WVzI6ne1defDwC%2F7VNWUpTpMxwCJYAhtiRly2VAPv0W2A%3D%3D (Caused by NewConnectionError('<urllib3.connection.HTTPSConnection object at 0x2afd27f72fa0>: Failed to establish a new connection: [Errno 101] Network is unreachable'))
2023-11-07 16:44:04,781 ERROR   wandb-upload_1:85669 [internal_api.py:upload_file():2558] upload_file request headers: {'User-Agent': 'python-requests/2.28.1', 'Accept-Encoding': 'gzip, deflate, br', 'Accept': '*/*', 'Connection': 'keep-alive', 'Content-MD5': 'ECzI7oKGSWJ1+RtCgn6Grg==', 'Content-Type': 'text/plain; charset=utf-8', 'Content-Length': '1756'}
2023-11-07 16:44:04,781 ERROR   wandb-upload_1:85669 [internal_api.py:upload_file():2560] upload_file response body: 
2023-11-07 16:44:05,654 DEBUG   HandlerThread:85669 [handler.py:handle_request():146] handle_request: keepalive
2023-11-07 16:44:10,657 DEBUG   HandlerThread:85669 [handler.py:handle_request():146] handle_request: keepalive
2023-11-07 16:44:15,658 DEBUG   HandlerThread:85669 [handler.py:handle_request():146] handle_request: keepalive
2023-11-07 16:44:20,660 DEBUG   HandlerThread:85669 [handler.py:handle_request():146] handle_request: keepalive
2023-11-07 16:44:25,662 DEBUG   HandlerThread:85669 [handler.py:handle_request():146] handle_request: keepalive
2023-11-07 16:44:30,664 DEBUG   HandlerThread:85669 [handler.py:handle_request():146] handle_request: keepalive
2023-11-07 16:44:35,666 DEBUG   HandlerThread:85669 [handler.py:handle_request():146] handle_request: keepalive
2023-11-07 16:44:40,668 DEBUG   HandlerThread:85669 [handler.py:handle_request():146] handle_request: keepalive
2023-11-07 16:44:45,669 DEBUG   HandlerThread:85669 [handler.py:handle_request():146] handle_request: keepalive
2023-11-07 16:44:50,671 DEBUG   HandlerThread:85669 [handler.py:handle_request():146] handle_request: keepalive
2023-11-07 16:44:55,672 DEBUG   HandlerThread:85669 [handler.py:handle_request():146] handle_request: keepalive
2023-11-07 16:45:00,676 DEBUG   HandlerThread:85669 [handler.py:handle_request():146] handle_request: keepalive
2023-11-07 16:45:05,677 DEBUG   HandlerThread:85669 [handler.py:handle_request():146] handle_request: keepalive
2023-11-07 16:45:08,039 ERROR   wandb-upload_2:85669 [internal_api.py:upload_file():2556] upload_file exception https://storage.googleapis.com/wandb-artifacts-prod/wandb_artifacts/109310165/630888432/a657693071af5cdb84a1279b99aca986?Expires=1699458171&GoogleAccessId=gorilla-files-url-signer-man%40wandb-production.iam.gserviceaccount.com&Signature=Ji2kxLgR5J%2BZuXlRYMK%2BzBM81dDrV%2BUgPCPTgZpRyJ5l8Yel8GnV6K8bQxdOrWuS2pMiudiCdAYSHVVvOO8RboabgN6IuXF74YK%2BylvkkG4FmU9dJzJdycBSLa%2B%2FQqrChTxRoMa5MdqDZEqxhILMy1vk4kIzkj64eX3q%2B9gIEZg8h7UiQHlJOlrifWIewN0Cpfl0QSb%2F%2Ba0%2B9QrV9f20TdVkFMRhBTjXN6Jb2rSDckoUJvfyHRTdSqXLBcQhrRSyC2gSjZVntail1a5rMR0SvgBh%2Fmx3PExwnEUvB83rTgxfnWjOFPGwleIiDpCcpKaft4XpedUtEAy5cO1OIp%2BOIg%3D%3D: HTTPSConnectionPool(host='storage.googleapis.com', port=443): Max retries exceeded with url: /wandb-artifacts-prod/wandb_artifacts/109310165/630888432/a657693071af5cdb84a1279b99aca986?Expires=1699458171&GoogleAccessId=gorilla-files-url-signer-man%40wandb-production.iam.gserviceaccount.com&Signature=Ji2kxLgR5J%2BZuXlRYMK%2BzBM81dDrV%2BUgPCPTgZpRyJ5l8Yel8GnV6K8bQxdOrWuS2pMiudiCdAYSHVVvOO8RboabgN6IuXF74YK%2BylvkkG4FmU9dJzJdycBSLa%2B%2FQqrChTxRoMa5MdqDZEqxhILMy1vk4kIzkj64eX3q%2B9gIEZg8h7UiQHlJOlrifWIewN0Cpfl0QSb%2F%2Ba0%2B9QrV9f20TdVkFMRhBTjXN6Jb2rSDckoUJvfyHRTdSqXLBcQhrRSyC2gSjZVntail1a5rMR0SvgBh%2Fmx3PExwnEUvB83rTgxfnWjOFPGwleIiDpCcpKaft4XpedUtEAy5cO1OIp%2BOIg%3D%3D (Caused by NewConnectionError('<urllib3.connection.HTTPSConnection object at 0x2afd4ee5fa30>: Failed to establish a new connection: [Errno 101] Network is unreachable'))
2023-11-07 16:45:08,039 ERROR   wandb-upload_2:85669 [internal_api.py:upload_file():2558] upload_file request headers: {'User-Agent': 'python-requests/2.28.1', 'Accept-Encoding': 'gzip, deflate, br', 'Accept': '*/*', 'Connection': 'keep-alive', 'Content-MD5': 'pldpMHGvXNuEoSebmayphg==', 'Content-Type': 'application/json', 'Content-Length': '648'}
2023-11-07 16:45:08,039 ERROR   wandb-upload_2:85669 [internal_api.py:upload_file():2560] upload_file response body: 
2023-11-07 16:45:08,996 ERROR   wandb-upload_1:85669 [internal_api.py:upload_file():2556] upload_file exception https://storage.googleapis.com/wandb-artifacts-prod/wandb_artifacts/109310165/630888432/102cc8ee8286496275f91b42827e86ae?Expires=1699458171&GoogleAccessId=gorilla-files-url-signer-man%40wandb-production.iam.gserviceaccount.com&Signature=fzksvVNy6SANM1NUw4KhUe%2BIw%2F5AG1qy4VnC9cKlMxAOIqKTLVI5LO5u1MNcr%2FXXICxkYlUfGykO5z%2FevoLb1Xu%2FvRisNroDl9SSw6EzzqdnS7wX8xXEbxD1zyWH1aPdlCMlgUG61X2WPnW%2Bfex1NVW0XhVkNaC3svXAHG%2BrPbIkip%2FyxM%2Fx%2BnBFf5yFxFLRjVM4roHPJuoBdtMnndFVW%2FXn2%2BjlzJjPw2NoviPUUSIQX6xHzyURESMIniErWd7FIw5mRbdvMQkpSmpRE8SihbOdZ1REgjM4Kyw1mHKc5WVzI6ne1defDwC%2F7VNWUpTpMxwCJYAhtiRly2VAPv0W2A%3D%3D: HTTPSConnectionPool(host='storage.googleapis.com', port=443): Max retries exceeded with url: /wandb-artifacts-prod/wandb_artifacts/109310165/630888432/102cc8ee8286496275f91b42827e86ae?Expires=1699458171&GoogleAccessId=gorilla-files-url-signer-man%40wandb-production.iam.gserviceaccount.com&Signature=fzksvVNy6SANM1NUw4KhUe%2BIw%2F5AG1qy4VnC9cKlMxAOIqKTLVI5LO5u1MNcr%2FXXICxkYlUfGykO5z%2FevoLb1Xu%2FvRisNroDl9SSw6EzzqdnS7wX8xXEbxD1zyWH1aPdlCMlgUG61X2WPnW%2Bfex1NVW0XhVkNaC3svXAHG%2BrPbIkip%2FyxM%2Fx%2BnBFf5yFxFLRjVM4roHPJuoBdtMnndFVW%2FXn2%2BjlzJjPw2NoviPUUSIQX6xHzyURESMIniErWd7FIw5mRbdvMQkpSmpRE8SihbOdZ1REgjM4Kyw1mHKc5WVzI6ne1defDwC%2F7VNWUpTpMxwCJYAhtiRly2VAPv0W2A%3D%3D (Caused by NewConnectionError('<urllib3.connection.HTTPSConnection object at 0x2afd4ee5fc70>: Failed to establish a new connection: [Errno 101] Network is unreachable'))
2023-11-07 16:45:08,996 ERROR   wandb-upload_1:85669 [internal_api.py:upload_file():2558] upload_file request headers: {'User-Agent': 'python-requests/2.28.1', 'Accept-Encoding': 'gzip, deflate, br', 'Accept': '*/*', 'Connection': 'keep-alive', 'Content-MD5': 'ECzI7oKGSWJ1+RtCgn6Grg==', 'Content-Type': 'text/plain; charset=utf-8', 'Content-Length': '1756'}
2023-11-07 16:45:08,996 ERROR   wandb-upload_1:85669 [internal_api.py:upload_file():2560] upload_file response body: 
2023-11-07 16:45:10,679 DEBUG   HandlerThread:85669 [handler.py:handle_request():146] handle_request: keepalive
2023-11-07 16:45:11,815 ERROR   wandb-upload_0:85669 [internal_api.py:upload_file():2556] upload_file exception https://storage.googleapis.com/wandb-production.appspot.com/bryant-ty/DKT-trial%201/ofzmp069/wandb-metadata.json?Expires=1699458163&GoogleAccessId=gorilla-files-url-signer-man%40wandb-production.iam.gserviceaccount.com&Signature=PrD2kR8PtL%2FLzZA7Dz9HSfpSKY6s5qJheJDJ3LLgC7wpTumvfWK%2Bza154EKHCfHeC3HbkL86CuSox54Ixvzisx8gF4LJjTto%2FCMkTfsG1Njmaxk8KigZQGLx3wxMWCyKhANaToP1QiGJHpHA6R8TtxOByNBtK2f0d24LN8%2BuK6oDgqeo1FvByEVXakT1Le80JAkFQtqG9erYfhmYtOH2E32reh6MWLA6qzqGyyqGUw6EaswRqunF%2FGqFW%2BpHPQSwHjDb9VFJbLuNF4J2E3TDmTGL5JNu3ZmkgB%2BazmazbFE0jn1XlUhI8RztoqOywXDP8kSmaQXRL644Vi28iAJWnQ%3D%3D: HTTPSConnectionPool(host='storage.googleapis.com', port=443): Max retries exceeded with url: /wandb-production.appspot.com/bryant-ty/DKT-trial%201/ofzmp069/wandb-metadata.json?Expires=1699458163&GoogleAccessId=gorilla-files-url-signer-man%40wandb-production.iam.gserviceaccount.com&Signature=PrD2kR8PtL%2FLzZA7Dz9HSfpSKY6s5qJheJDJ3LLgC7wpTumvfWK%2Bza154EKHCfHeC3HbkL86CuSox54Ixvzisx8gF4LJjTto%2FCMkTfsG1Njmaxk8KigZQGLx3wxMWCyKhANaToP1QiGJHpHA6R8TtxOByNBtK2f0d24LN8%2BuK6oDgqeo1FvByEVXakT1Le80JAkFQtqG9erYfhmYtOH2E32reh6MWLA6qzqGyyqGUw6EaswRqunF%2FGqFW%2BpHPQSwHjDb9VFJbLuNF4J2E3TDmTGL5JNu3ZmkgB%2BazmazbFE0jn1XlUhI8RztoqOywXDP8kSmaQXRL644Vi28iAJWnQ%3D%3D (Caused by NewConnectionError('<urllib3.connection.HTTPSConnection object at 0x2afd4ee52520>: Failed to establish a new connection: [Errno 101] Network is unreachable'))
2023-11-07 16:45:11,815 ERROR   wandb-upload_0:85669 [internal_api.py:upload_file():2558] upload_file request headers: {'User-Agent': 'python-requests/2.28.1', 'Accept-Encoding': 'gzip, deflate, br', 'Accept': '*/*', 'Connection': 'keep-alive', 'Content-Length': '14912'}
2023-11-07 16:45:11,815 ERROR   wandb-upload_0:85669 [internal_api.py:upload_file():2560] upload_file response body: 
2023-11-07 16:45:15,681 DEBUG   HandlerThread:85669 [handler.py:handle_request():146] handle_request: keepalive
2023-11-07 16:45:20,683 DEBUG   HandlerThread:85669 [handler.py:handle_request():146] handle_request: keepalive
2023-11-07 16:45:25,685 DEBUG   HandlerThread:85669 [handler.py:handle_request():146] handle_request: keepalive
2023-11-07 16:45:30,687 DEBUG   HandlerThread:85669 [handler.py:handle_request():146] handle_request: keepalive
2023-11-07 16:45:35,688 DEBUG   HandlerThread:85669 [handler.py:handle_request():146] handle_request: keepalive
2023-11-07 16:45:40,690 DEBUG   HandlerThread:85669 [handler.py:handle_request():146] handle_request: keepalive
2023-11-07 16:45:45,692 DEBUG   HandlerThread:85669 [handler.py:handle_request():146] handle_request: keepalive
2023-11-07 16:45:50,694 DEBUG   HandlerThread:85669 [handler.py:handle_request():146] handle_request: keepalive
2023-11-07 16:45:55,696 DEBUG   HandlerThread:85669 [handler.py:handle_request():146] handle_request: keepalive
2023-11-07 16:46:00,698 DEBUG   HandlerThread:85669 [handler.py:handle_request():146] handle_request: keepalive
2023-11-07 16:46:05,699 DEBUG   HandlerThread:85669 [handler.py:handle_request():146] handle_request: keepalive
2023-11-07 16:46:10,702 DEBUG   HandlerThread:85669 [handler.py:handle_request():146] handle_request: keepalive
2023-11-07 16:46:15,704 DEBUG   HandlerThread:85669 [handler.py:handle_request():146] handle_request: keepalive
2023-11-07 16:46:20,706 DEBUG   HandlerThread:85669 [handler.py:handle_request():146] handle_request: keepalive
2023-11-07 16:46:25,707 DEBUG   HandlerThread:85669 [handler.py:handle_request():146] handle_request: keepalive
2023-11-07 16:46:30,709 DEBUG   HandlerThread:85669 [handler.py:handle_request():146] handle_request: keepalive
2023-11-07 16:46:35,711 DEBUG   HandlerThread:85669 [handler.py:handle_request():146] handle_request: keepalive
2023-11-07 16:46:40,713 DEBUG   HandlerThread:85669 [handler.py:handle_request():146] handle_request: keepalive
2023-11-07 16:46:45,715 DEBUG   HandlerThread:85669 [handler.py:handle_request():146] handle_request: keepalive
2023-11-07 16:46:50,717 DEBUG   HandlerThread:85669 [handler.py:handle_request():146] handle_request: keepalive
2023-11-07 16:46:55,718 DEBUG   HandlerThread:85669 [handler.py:handle_request():146] handle_request: keepalive
2023-11-07 16:47:00,720 DEBUG   HandlerThread:85669 [handler.py:handle_request():146] handle_request: keepalive
2023-11-07 16:47:05,721 DEBUG   HandlerThread:85669 [handler.py:handle_request():146] handle_request: keepalive
2023-11-07 16:47:10,723 DEBUG   HandlerThread:85669 [handler.py:handle_request():146] handle_request: keepalive
2023-11-07 16:47:15,725 DEBUG   HandlerThread:85669 [handler.py:handle_request():146] handle_request: keepalive
