2023-10-04 19:34:38,577 INFO    MainThread:25516 [wandb_setup.py:_flush():76] Current SDK version is 0.15.11
2023-10-04 19:34:38,577 INFO    MainThread:25516 [wandb_setup.py:_flush():76] Configure stats pid to 25516
2023-10-04 19:34:38,577 INFO    MainThread:25516 [wandb_setup.py:_flush():76] Loading settings from C:\Users\tyu06\.config\wandb\settings
2023-10-04 19:34:38,578 INFO    MainThread:25516 [wandb_setup.py:_flush():76] Loading settings from D:\ETHz\Internship\adaptive-e-learning-for-educational-recommendation-system\DeepKnowledgeTracing-DKT-Pytorch\DKT\KnowledgeTracing\evaluation\wandb\settings
2023-10-04 19:34:38,578 INFO    MainThread:25516 [wandb_setup.py:_flush():76] Loading settings from environment variables: {}
2023-10-04 19:34:38,584 INFO    MainThread:25516 [wandb_setup.py:_flush():76] Applying setup settings: {'_disable_service': False}
2023-10-04 19:34:38,584 INFO    MainThread:25516 [wandb_setup.py:_flush():76] Inferring run settings from compute environment: {'program_relpath': 'DKT\\KnowledgeTracing\\evaluation\\run.py', 'program_abspath': 'D:\\ETHz\\Internship\\adaptive-e-learning-for-educational-recommendation-system\\DeepKnowledgeTracing-DKT-Pytorch\\DKT\\KnowledgeTracing\\evaluation\\run.py', 'program': 'D:\\ETHz\\Internship\\adaptive-e-learning-for-educational-recommendation-system\\DeepKnowledgeTracing-DKT-Pytorch\\DKT\\KnowledgeTracing\\evaluation\\run.py'}
2023-10-04 19:34:38,584 INFO    MainThread:25516 [wandb_init.py:_log_setup():528] Logging user logs to D:\ETHz\Internship\adaptive-e-learning-for-educational-recommendation-system\DeepKnowledgeTracing-DKT-Pytorch\DKT\KnowledgeTracing\evaluation\wandb\run-20231004_193438-fv2cs0ai\logs\debug.log
2023-10-04 19:34:38,584 INFO    MainThread:25516 [wandb_init.py:_log_setup():529] Logging internal logs to D:\ETHz\Internship\adaptive-e-learning-for-educational-recommendation-system\DeepKnowledgeTracing-DKT-Pytorch\DKT\KnowledgeTracing\evaluation\wandb\run-20231004_193438-fv2cs0ai\logs\debug-internal.log
2023-10-04 19:34:38,584 INFO    MainThread:25516 [wandb_init.py:init():568] calling init triggers
2023-10-04 19:34:38,584 INFO    MainThread:25516 [wandb_init.py:init():575] wandb.init called with sweep_config: {}
config: {}
2023-10-04 19:34:38,584 INFO    MainThread:25516 [wandb_init.py:init():618] starting backend
2023-10-04 19:34:38,584 INFO    MainThread:25516 [wandb_init.py:init():622] setting up manager
2023-10-04 19:34:38,589 INFO    MainThread:25516 [backend.py:_multiprocessing_setup():105] multiprocessing start_methods=spawn, using: spawn
2023-10-04 19:34:38,591 INFO    MainThread:25516 [wandb_init.py:init():628] backend started and connected
2023-10-04 19:34:38,595 INFO    MainThread:25516 [wandb_init.py:init():720] updated telemetry
2023-10-04 19:34:38,663 INFO    MainThread:25516 [wandb_init.py:init():753] communicating run to backend with 90.0 second timeout
2023-10-04 19:35:20,956 INFO    Thread-9  :25516 [retry.py:__call__():172] Retry attempt failed:
Traceback (most recent call last):
  File "C:\Users\tyu06\anaconda3\lib\site-packages\urllib3\connection.py", line 174, in _new_conn
    conn = connection.create_connection(
  File "C:\Users\tyu06\anaconda3\lib\site-packages\urllib3\util\connection.py", line 72, in create_connection
    for res in socket.getaddrinfo(host, port, family, socket.SOCK_STREAM):
  File "C:\Users\tyu06\anaconda3\lib\socket.py", line 918, in getaddrinfo
    for res in _socket.getaddrinfo(host, port, family, type, proto, flags):
socket.gaierror: [Errno 11001] getaddrinfo failed

During handling of the above exception, another exception occurred:

Traceback (most recent call last):
  File "C:\Users\tyu06\anaconda3\lib\site-packages\urllib3\connectionpool.py", line 714, in urlopen
    httplib_response = self._make_request(
  File "C:\Users\tyu06\anaconda3\lib\site-packages\urllib3\connectionpool.py", line 403, in _make_request
    self._validate_conn(conn)
  File "C:\Users\tyu06\anaconda3\lib\site-packages\urllib3\connectionpool.py", line 1053, in _validate_conn
    conn.connect()
  File "C:\Users\tyu06\anaconda3\lib\site-packages\urllib3\connection.py", line 363, in connect
    self.sock = conn = self._new_conn()
  File "C:\Users\tyu06\anaconda3\lib\site-packages\urllib3\connection.py", line 186, in _new_conn
    raise NewConnectionError(
urllib3.exceptions.NewConnectionError: <urllib3.connection.HTTPSConnection object at 0x000001ABDCAC61C0>: Failed to establish a new connection: [Errno 11001] getaddrinfo failed

During handling of the above exception, another exception occurred:

Traceback (most recent call last):
  File "C:\Users\tyu06\anaconda3\lib\site-packages\requests\adapters.py", line 439, in send
    resp = conn.urlopen(
  File "C:\Users\tyu06\anaconda3\lib\site-packages\urllib3\connectionpool.py", line 798, in urlopen
    retries = retries.increment(
  File "C:\Users\tyu06\anaconda3\lib\site-packages\urllib3\util\retry.py", line 592, in increment
    raise MaxRetryError(_pool, url, error or ResponseError(cause))
urllib3.exceptions.MaxRetryError: HTTPSConnectionPool(host='api.wandb.ai', port=443): Max retries exceeded with url: /graphql (Caused by NewConnectionError('<urllib3.connection.HTTPSConnection object at 0x000001ABDCAC61C0>: Failed to establish a new connection: [Errno 11001] getaddrinfo failed'))

During handling of the above exception, another exception occurred:

Traceback (most recent call last):
  File "C:\Users\tyu06\anaconda3\lib\site-packages\wandb\sdk\lib\retry.py", line 131, in __call__
    result = self._call_fn(*args, **kwargs)
  File "C:\Users\tyu06\anaconda3\lib\site-packages\wandb\sdk\internal\internal_api.py", line 366, in execute
    return self.client.execute(*args, **kwargs)  # type: ignore
  File "C:\Users\tyu06\anaconda3\lib\site-packages\wandb\vendor\gql-0.2.0\wandb_gql\client.py", line 52, in execute
    result = self._get_result(document, *args, **kwargs)
  File "C:\Users\tyu06\anaconda3\lib\site-packages\wandb\vendor\gql-0.2.0\wandb_gql\client.py", line 60, in _get_result
    return self.transport.execute(document, *args, **kwargs)
  File "C:\Users\tyu06\anaconda3\lib\site-packages\wandb\sdk\lib\gql_request.py", line 58, in execute
    request = self.session.post(self.url, **post_args)
  File "C:\Users\tyu06\anaconda3\lib\site-packages\requests\sessions.py", line 590, in post
    return self.request('POST', url, data=data, json=json, **kwargs)
  File "C:\Users\tyu06\anaconda3\lib\site-packages\requests\sessions.py", line 542, in request
    resp = self.send(prep, **send_kwargs)
  File "C:\Users\tyu06\anaconda3\lib\site-packages\requests\sessions.py", line 655, in send
    r = adapter.send(request, **kwargs)
  File "C:\Users\tyu06\anaconda3\lib\site-packages\requests\adapters.py", line 516, in send
    raise ConnectionError(e, request=request)
requests.exceptions.ConnectionError: HTTPSConnectionPool(host='api.wandb.ai', port=443): Max retries exceeded with url: /graphql (Caused by NewConnectionError('<urllib3.connection.HTTPSConnection object at 0x000001ABDCAC61C0>: Failed to establish a new connection: [Errno 11001] getaddrinfo failed'))
