2023-10-04 19:34:38,593 INFO    StreamThr :23824 [internal.py:wandb_internal():86] W&B internal server running at pid: 23824, started at: 2023-10-04 19:34:38.592264
2023-10-04 19:34:38,594 DEBUG   HandlerThread:23824 [handler.py:handle_request():144] handle_request: status
2023-10-04 19:34:38,596 INFO    WriterThread:23824 [datastore.py:open_for_write():85] open: D:\ETHz\Internship\adaptive-e-learning-for-educational-recommendation-system\DeepKnowledgeTracing-DKT-Pytorch\DKT\KnowledgeTracing\evaluation\wandb\run-20231004_193438-fv2cs0ai\run-fv2cs0ai.wandb
2023-10-04 19:34:38,598 DEBUG   SenderThread:23824 [sender.py:send():380] send: header
2023-10-04 19:34:38,668 DEBUG   SenderThread:23824 [sender.py:send():380] send: run
2023-10-04 19:34:43,706 DEBUG   HandlerThread:23824 [handler.py:handle_request():144] handle_request: keepalive
2023-10-04 19:34:48,742 DEBUG   HandlerThread:23824 [handler.py:handle_request():144] handle_request: keepalive
2023-10-04 19:34:53,768 DEBUG   HandlerThread:23824 [handler.py:handle_request():144] handle_request: keepalive
2023-10-04 19:34:58,831 DEBUG   HandlerThread:23824 [handler.py:handle_request():144] handle_request: keepalive
2023-10-04 19:35:03,874 DEBUG   HandlerThread:23824 [handler.py:handle_request():144] handle_request: keepalive
2023-10-04 19:35:08,923 DEBUG   HandlerThread:23824 [handler.py:handle_request():144] handle_request: keepalive
2023-10-04 19:35:13,964 DEBUG   HandlerThread:23824 [handler.py:handle_request():144] handle_request: keepalive
2023-10-04 19:35:18,988 DEBUG   HandlerThread:23824 [handler.py:handle_request():144] handle_request: keepalive
2023-10-04 19:35:23,306 INFO    SenderThread:23824 [retry.py:__call__():172] Retry attempt failed:
Traceback (most recent call last):
  File "C:\Users\tyu06\anaconda3\lib\site-packages\urllib3\connection.py", line 174, in _new_conn
    conn = connection.create_connection(
  File "C:\Users\tyu06\anaconda3\lib\site-packages\urllib3\util\connection.py", line 72, in create_connection
    for res in socket.getaddrinfo(host, port, family, socket.SOCK_STREAM):
  File "C:\Users\tyu06\anaconda3\lib\socket.py", line 918, in getaddrinfo
    for res in _socket.getaddrinfo(host, port, family, type, proto, flags):
socket.gaierror: [Errno 11001] getaddrinfo failed

During handling of the above exception, another exception occurred:

Traceback (most recent call last):
  File "C:\Users\tyu06\anaconda3\lib\site-packages\urllib3\connectionpool.py", line 714, in urlopen
    httplib_response = self._make_request(
  File "C:\Users\tyu06\anaconda3\lib\site-packages\urllib3\connectionpool.py", line 403, in _make_request
    self._validate_conn(conn)
  File "C:\Users\tyu06\anaconda3\lib\site-packages\urllib3\connectionpool.py", line 1053, in _validate_conn
    conn.connect()
  File "C:\Users\tyu06\anaconda3\lib\site-packages\urllib3\connection.py", line 363, in connect
    self.sock = conn = self._new_conn()
  File "C:\Users\tyu06\anaconda3\lib\site-packages\urllib3\connection.py", line 186, in _new_conn
    raise NewConnectionError(
urllib3.exceptions.NewConnectionError: <urllib3.connection.HTTPSConnection object at 0x000002784BDCD0A0>: Failed to establish a new connection: [Errno 11001] getaddrinfo failed

During handling of the above exception, another exception occurred:

Traceback (most recent call last):
  File "C:\Users\tyu06\anaconda3\lib\site-packages\requests\adapters.py", line 439, in send
    resp = conn.urlopen(
  File "C:\Users\tyu06\anaconda3\lib\site-packages\urllib3\connectionpool.py", line 798, in urlopen
    retries = retries.increment(
  File "C:\Users\tyu06\anaconda3\lib\site-packages\urllib3\util\retry.py", line 592, in increment
    raise MaxRetryError(_pool, url, error or ResponseError(cause))
urllib3.exceptions.MaxRetryError: HTTPSConnectionPool(host='api.wandb.ai', port=443): Max retries exceeded with url: /graphql (Caused by NewConnectionError('<urllib3.connection.HTTPSConnection object at 0x000002784BDCD0A0>: Failed to establish a new connection: [Errno 11001] getaddrinfo failed'))

During handling of the above exception, another exception occurred:

Traceback (most recent call last):
  File "C:\Users\tyu06\anaconda3\lib\site-packages\wandb\sdk\lib\retry.py", line 131, in __call__
    result = self._call_fn(*args, **kwargs)
  File "C:\Users\tyu06\anaconda3\lib\site-packages\wandb\sdk\internal\internal_api.py", line 366, in execute
    return self.client.execute(*args, **kwargs)  # type: ignore
  File "C:\Users\tyu06\anaconda3\lib\site-packages\wandb\vendor\gql-0.2.0\wandb_gql\client.py", line 52, in execute
    result = self._get_result(document, *args, **kwargs)
  File "C:\Users\tyu06\anaconda3\lib\site-packages\wandb\vendor\gql-0.2.0\wandb_gql\client.py", line 60, in _get_result
    return self.transport.execute(document, *args, **kwargs)
  File "C:\Users\tyu06\anaconda3\lib\site-packages\wandb\sdk\lib\gql_request.py", line 58, in execute
    request = self.session.post(self.url, **post_args)
  File "C:\Users\tyu06\anaconda3\lib\site-packages\requests\sessions.py", line 590, in post
    return self.request('POST', url, data=data, json=json, **kwargs)
  File "C:\Users\tyu06\anaconda3\lib\site-packages\requests\sessions.py", line 542, in request
    resp = self.send(prep, **send_kwargs)
  File "C:\Users\tyu06\anaconda3\lib\site-packages\requests\sessions.py", line 655, in send
    r = adapter.send(request, **kwargs)
  File "C:\Users\tyu06\anaconda3\lib\site-packages\requests\adapters.py", line 516, in send
    raise ConnectionError(e, request=request)
requests.exceptions.ConnectionError: HTTPSConnectionPool(host='api.wandb.ai', port=443): Max retries exceeded with url: /graphql (Caused by NewConnectionError('<urllib3.connection.HTTPSConnection object at 0x000002784BDCD0A0>: Failed to establish a new connection: [Errno 11001] getaddrinfo failed'))
2023-10-04 19:35:24,035 DEBUG   HandlerThread:23824 [handler.py:handle_request():144] handle_request: keepalive
2023-10-04 19:35:29,101 DEBUG   HandlerThread:23824 [handler.py:handle_request():144] handle_request: keepalive
2023-10-04 19:35:34,146 DEBUG   HandlerThread:23824 [handler.py:handle_request():144] handle_request: keepalive
2023-10-04 19:35:39,192 DEBUG   HandlerThread:23824 [handler.py:handle_request():144] handle_request: keepalive
2023-10-04 19:35:44,216 DEBUG   HandlerThread:23824 [handler.py:handle_request():144] handle_request: keepalive
2023-10-04 19:35:49,262 DEBUG   HandlerThread:23824 [handler.py:handle_request():144] handle_request: keepalive
2023-10-04 19:35:54,305 DEBUG   HandlerThread:23824 [handler.py:handle_request():144] handle_request: keepalive
2023-10-04 19:35:59,458 DEBUG   HandlerThread:23824 [handler.py:handle_request():144] handle_request: keepalive
2023-10-04 19:36:04,510 DEBUG   HandlerThread:23824 [handler.py:handle_request():144] handle_request: keepalive
2023-10-04 19:36:08,550 WARNING StreamThr :23824 [internal.py:is_dead():414] Internal process exiting, parent pid 25516 disappeared
2023-10-04 19:36:08,557 ERROR   StreamThr :23824 [internal.py:wandb_internal():152] Internal process shutdown.
2023-10-04 19:36:09,532 INFO    WriterThread:23824 [datastore.py:close():294] close: D:\ETHz\Internship\adaptive-e-learning-for-educational-recommendation-system\DeepKnowledgeTracing-DKT-Pytorch\DKT\KnowledgeTracing\evaluation\wandb\run-20231004_193438-fv2cs0ai\run-fv2cs0ai.wandb
2023-10-04 19:36:09,564 INFO    HandlerThread:23824 [handler.py:finish():844] shutting down handler
2023-10-04 19:36:09,564 INFO    MainThread:23824 [internal.py:handle_exit():76] Internal process exited
