2023-12-29 21:59:52,163 INFO    StreamThr :35328 [internal.py:wandb_internal():86] W&B internal server running at pid: 35328, started at: 2023-12-29 21:59:52.154333
2023-12-29 21:59:52,166 DEBUG   HandlerThread:35328 [handler.py:handle_request():146] handle_request: status
2023-12-29 21:59:52,206 INFO    WriterThread:35328 [datastore.py:open_for_write():85] open: /cluster/home/yutang/Deep-Knowledge-Tracing/DKT/KnowledgeTracing/evaluation/wandb/run-20231229_215952-r45hitom/run-r45hitom.wandb
2023-12-29 21:59:52,216 DEBUG   SenderThread:35328 [sender.py:send():382] send: header
2023-12-29 21:59:52,537 DEBUG   SenderThread:35328 [sender.py:send():382] send: run
2023-12-29 21:59:53,038 INFO    SenderThread:35328 [dir_watcher.py:__init__():211] watching files in: /cluster/home/yutang/Deep-Knowledge-Tracing/DKT/KnowledgeTracing/evaluation/wandb/run-20231229_215952-r45hitom/files
2023-12-29 21:59:53,038 INFO    SenderThread:35328 [sender.py:_start_run_threads():1136] run started: r45hitom with start time 1703883592.198983
2023-12-29 21:59:53,114 DEBUG   HandlerThread:35328 [handler.py:handle_request():146] handle_request: check_version
2023-12-29 21:59:53,115 DEBUG   SenderThread:35328 [sender.py:send_request():409] send_request: check_version
2023-12-29 21:59:53,215 DEBUG   HandlerThread:35328 [handler.py:handle_request():146] handle_request: run_start
2023-12-29 21:59:53,244 DEBUG   HandlerThread:35328 [system_info.py:__init__():32] System info init
2023-12-29 21:59:53,244 DEBUG   HandlerThread:35328 [system_info.py:__init__():47] System info init done
2023-12-29 21:59:53,244 INFO    HandlerThread:35328 [system_monitor.py:start():194] Starting system monitor
2023-12-29 21:59:53,244 INFO    SystemMonitor:35328 [system_monitor.py:_start():158] Starting system asset monitoring threads
2023-12-29 21:59:53,245 INFO    HandlerThread:35328 [system_monitor.py:probe():214] Collecting system info
2023-12-29 21:59:53,246 INFO    SystemMonitor:35328 [interfaces.py:start():190] Started cpu monitoring
2023-12-29 21:59:53,247 INFO    SystemMonitor:35328 [interfaces.py:start():190] Started disk monitoring
2023-12-29 21:59:53,249 INFO    SystemMonitor:35328 [interfaces.py:start():190] Started gpu monitoring
2023-12-29 21:59:53,250 INFO    SystemMonitor:35328 [interfaces.py:start():190] Started memory monitoring
2023-12-29 21:59:53,254 INFO    SystemMonitor:35328 [interfaces.py:start():190] Started network monitoring
2023-12-29 21:59:53,301 DEBUG   HandlerThread:35328 [system_info.py:probe():196] Probing system
2023-12-29 21:59:53,325 DEBUG   HandlerThread:35328 [system_info.py:_probe_git():181] Probing git
2023-12-29 21:59:53,575 DEBUG   HandlerThread:35328 [system_info.py:_probe_git():189] Probing git done
2023-12-29 21:59:53,575 DEBUG   HandlerThread:35328 [system_info.py:probe():244] Probing system done
2023-12-29 21:59:53,576 DEBUG   HandlerThread:35328 [system_monitor.py:probe():223] {'os': 'Linux-3.10.0-1160.102.1.el7.x86_64-x86_64-with-glibc2.17', 'python': '3.9.16', 'heartbeatAt': '2023-12-29T20:59:53.301543', 'startedAt': '2023-12-29T20:59:52.011477', 'docker': None, 'cuda': None, 'args': (), 'state': 'running', 'program': '/cluster/home/yutang/Deep-Knowledge-Tracing/DKT/KnowledgeTracing/evaluation/./run.py', 'codePathLocal': 'run.py', 'codePath': 'DKT/KnowledgeTracing/evaluation/run.py', 'git': {'remote': 'https://github.com/Bryanttt-tang/Deep-Knowledge-Tracing.git', 'commit': '594fcd40aa603001758372768dc575be2a483edd'}, 'email': 'tangyu990628@gmail.com', 'root': '/cluster/home/yutang/Deep-Knowledge-Tracing', 'host': 'eu-lo-dgx1-001', 'username': 'yutang', 'executable': '/cluster/home/yutang/miniconda3/bin/python', 'cpu_count': 40, 'cpu_count_logical': 80, 'cpu_freq': {'current': 1298.775, 'min': 1200.0, 'max': 2201.0}, 'cpu_freq_per_core': [{'current': 1200.0, 'min': 1200.0, 'max': 2201.0}, {'current': 2201.0, 'min': 1200.0, 'max': 2201.0}, {'current': 1200.0, 'min': 1200.0, 'max': 2201.0}, {'current': 1200.0, 'min': 1200.0, 'max': 2201.0}, {'current': 1200.0, 'min': 1200.0, 'max': 2201.0}, {'current': 1200.0, 'min': 1200.0, 'max': 2201.0}, {'current': 1200.0, 'min': 1200.0, 'max': 2201.0}, {'current': 1200.0, 'min': 1200.0, 'max': 2201.0}, {'current': 1200.0, 'min': 1200.0, 'max': 2201.0}, {'current': 1200.0, 'min': 1200.0, 'max': 2201.0}, {'current': 1200.0, 'min': 1200.0, 'max': 2201.0}, {'current': 1200.0, 'min': 1200.0, 'max': 2201.0}, {'current': 1200.0, 'min': 1200.0, 'max': 2201.0}, {'current': 1200.0, 'min': 1200.0, 'max': 2201.0}, {'current': 1200.0, 'min': 1200.0, 'max': 2201.0}, {'current': 1200.0, 'min': 1200.0, 'max': 2201.0}, {'current': 1200.0, 'min': 1200.0, 'max': 2201.0}, {'current': 1200.0, 'min': 1200.0, 'max': 2201.0}, {'current': 1200.0, 'min': 1200.0, 'max': 2201.0}, {'current': 1200.0, 'min': 1200.0, 'max': 2201.0}, {'current': 1200.0, 'min': 1200.0, 'max': 2201.0}, {'current': 1200.0, 'min': 1200.0, 'max': 2201.0}, {'current': 1200.0, 'min': 1200.0, 'max': 2201.0}, {'current': 1200.0, 'min': 1200.0, 'max': 2201.0}, {'current': 1200.0, 'min': 1200.0, 'max': 2201.0}, {'current': 1200.0, 'min': 1200.0, 'max': 2201.0}, {'current': 1200.0, 'min': 1200.0, 'max': 2201.0}, {'current': 1200.0, 'min': 1200.0, 'max': 2201.0}, {'current': 1200.0, 'min': 1200.0, 'max': 2201.0}, {'current': 1200.0, 'min': 1200.0, 'max': 2201.0}, {'current': 1200.0, 'min': 1200.0, 'max': 2201.0}, {'current': 1200.0, 'min': 1200.0, 'max': 2201.0}, {'current': 1200.0, 'min': 1200.0, 'max': 2201.0}, {'current': 1200.0, 'min': 1200.0, 'max': 2201.0}, {'current': 1200.0, 'min': 1200.0, 'max': 2201.0}, {'current': 1200.0, 'min': 1200.0, 'max': 2201.0}, {'current': 1200.0, 'min': 1200.0, 'max': 2201.0}, {'current': 1200.0, 'min': 1200.0, 'max': 2201.0}, {'current': 1200.0, 'min': 1200.0, 'max': 2201.0}, {'current': 1200.0, 'min': 1200.0, 'max': 2201.0}, {'current': 1400.0, 'min': 1200.0, 'max': 2201.0}, {'current': 1200.0, 'min': 1200.0, 'max': 2201.0}, {'current': 1200.0, 'min': 1200.0, 'max': 2201.0}, {'current': 1200.0, 'min': 1200.0, 'max': 2201.0}, {'current': 1200.0, 'min': 1200.0, 'max': 2201.0}, {'current': 1200.0, 'min': 1200.0, 'max': 2201.0}, {'current': 1200.0, 'min': 1200.0, 'max': 2201.0}, {'current': 1200.0, 'min': 1200.0, 'max': 2201.0}, {'current': 1200.0, 'min': 1200.0, 'max': 2201.0}, {'current': 1200.0, 'min': 1200.0, 'max': 2201.0}, {'current': 1200.0, 'min': 1200.0, 'max': 2201.0}, {'current': 1300.0, 'min': 1200.0, 'max': 2201.0}, {'current': 1200.0, 'min': 1200.0, 'max': 2201.0}, {'current': 1200.0, 'min': 1200.0, 'max': 2201.0}, {'current': 1900.0, 'min': 1200.0, 'max': 2201.0}, {'current': 1800.0, 'min': 1200.0, 'max': 2201.0}, {'current': 1200.0, 'min': 1200.0, 'max': 2201.0}, {'current': 1200.0, 'min': 1200.0, 'max': 2201.0}, {'current': 1500.0, 'min': 1200.0, 'max': 2201.0}, {'current': 1500.0, 'min': 1200.0, 'max': 2201.0}, {'current': 1200.0, 'min': 1200.0, 'max': 2201.0}, {'current': 1200.0, 'min': 1200.0, 'max': 2201.0}, {'current': 1200.0, 'min': 1200.0, 'max': 2201.0}, {'current': 1800.0, 'min': 1200.0, 'max': 2201.0}, {'current': 1500.0, 'min': 1200.0, 'max': 2201.0}, {'current': 1200.0, 'min': 1200.0, 'max': 2201.0}, {'current': 2201.0, 'min': 1200.0, 'max': 2201.0}, {'current': 1200.0, 'min': 1200.0, 'max': 2201.0}, {'current': 1200.0, 'min': 1200.0, 'max': 2201.0}, {'current': 1200.0, 'min': 1200.0, 'max': 2201.0}, {'current': 1200.0, 'min': 1200.0, 'max': 2201.0}, {'current': 1700.0, 'min': 1200.0, 'max': 2201.0}, {'current': 2201.0, 'min': 1200.0, 'max': 2201.0}, {'current': 1200.0, 'min': 1200.0, 'max': 2201.0}, {'current': 1200.0, 'min': 1200.0, 'max': 2201.0}, {'current': 1800.0, 'min': 1200.0, 'max': 2201.0}, {'current': 1200.0, 'min': 1200.0, 'max': 2201.0}, {'current': 1200.0, 'min': 1200.0, 'max': 2201.0}, {'current': 1200.0, 'min': 1200.0, 'max': 2201.0}, {'current': 1200.0, 'min': 1200.0, 'max': 2201.0}], 'disk': {'/': {'total': 10.0, 'used': 4.6128997802734375}}, 'gpu': 'Tesla V100-SXM2-32GB', 'gpu_count': 1, 'gpu_devices': [{'name': 'Tesla V100-SXM2-32GB', 'memory_total': 34359738368}], 'memory': {'total': 501.5517120361328}}
2023-12-29 21:59:53,576 INFO    HandlerThread:35328 [system_monitor.py:probe():224] Finished collecting system info
2023-12-29 21:59:53,576 INFO    HandlerThread:35328 [system_monitor.py:probe():227] Publishing system info
2023-12-29 21:59:53,576 DEBUG   HandlerThread:35328 [system_info.py:_save_pip():52] Saving list of pip packages installed into the current environment
2023-12-29 21:59:53,591 DEBUG   HandlerThread:35328 [system_info.py:_save_pip():68] Saving pip packages done
2023-12-29 21:59:53,595 DEBUG   HandlerThread:35328 [system_info.py:_save_conda():75] Saving list of conda packages installed into the current environment
2023-12-29 21:59:54,065 INFO    Thread-12 :35328 [dir_watcher.py:_on_file_created():271] file/dir created: /cluster/home/yutang/Deep-Knowledge-Tracing/DKT/KnowledgeTracing/evaluation/wandb/run-20231229_215952-r45hitom/files/requirements.txt
2023-12-29 21:59:54,065 INFO    Thread-12 :35328 [dir_watcher.py:_on_file_created():271] file/dir created: /cluster/home/yutang/Deep-Knowledge-Tracing/DKT/KnowledgeTracing/evaluation/wandb/run-20231229_215952-r45hitom/files/conda-environment.yaml
2023-12-29 22:00:21,524 DEBUG   HandlerThread:35328 [system_info.py:_save_conda():87] Saving conda packages done
2023-12-29 22:00:21,543 INFO    HandlerThread:35328 [system_monitor.py:probe():229] Finished publishing system info
2023-12-29 22:00:21,637 DEBUG   HandlerThread:35328 [handler.py:handle_request():146] handle_request: status_report
2023-12-29 22:00:21,637 DEBUG   HandlerThread:35328 [handler.py:handle_request():146] handle_request: keepalive
2023-12-29 22:00:21,637 DEBUG   HandlerThread:35328 [handler.py:handle_request():146] handle_request: status_report
2023-12-29 22:00:21,638 DEBUG   HandlerThread:35328 [handler.py:handle_request():146] handle_request: keepalive
2023-12-29 22:00:21,638 DEBUG   HandlerThread:35328 [handler.py:handle_request():146] handle_request: status_report
2023-12-29 22:00:21,638 DEBUG   HandlerThread:35328 [handler.py:handle_request():146] handle_request: keepalive
2023-12-29 22:00:21,638 DEBUG   HandlerThread:35328 [handler.py:handle_request():146] handle_request: status_report
2023-12-29 22:00:21,638 DEBUG   HandlerThread:35328 [handler.py:handle_request():146] handle_request: keepalive
2023-12-29 22:00:21,638 DEBUG   HandlerThread:35328 [handler.py:handle_request():146] handle_request: status_report
2023-12-29 22:00:21,638 DEBUG   HandlerThread:35328 [handler.py:handle_request():146] handle_request: keepalive
2023-12-29 22:00:21,640 DEBUG   SenderThread:35328 [sender.py:send():382] send: files
2023-12-29 22:00:21,640 INFO    SenderThread:35328 [sender.py:_save_file():1392] saving file wandb-metadata.json with policy now
2023-12-29 22:00:21,728 DEBUG   HandlerThread:35328 [handler.py:handle_request():146] handle_request: internal_messages
2023-12-29 22:00:21,728 DEBUG   HandlerThread:35328 [handler.py:handle_request():146] handle_request: stop_status
2023-12-29 22:00:21,729 DEBUG   SenderThread:35328 [sender.py:send_request():409] send_request: stop_status
2023-12-29 22:00:21,975 DEBUG   SenderThread:35328 [sender.py:send():382] send: telemetry
2023-12-29 22:00:21,977 ERROR   wandb-upload_0:35328 [internal_api.py:upload_file():2761] upload_file exception https://storage.googleapis.com/wandb-production.appspot.com/bryant-tang-ethz/DKT-trial%201/r45hitom/wandb-metadata.json?Expires=1703970021&GoogleAccessId=gorilla-files-url-signer-man%40wandb-production.iam.gserviceaccount.com&Signature=GREXo93rsWu5tN2Do3BDTqyp78EkUGEPCnZZNCIZAZ77an0YL3JPHTzO0RXwk63EhRgGfFuBpVTE4r8GHbjBRqfJYdZleab7PUI6tTZN%2FAjATBGZyfDad5VxyCODLozo0xjHtpf1sbmjPQL0YvAHY3q26YszJZCFlrxi1jukBukKouGBOCfy6EoXIfuZnLDw%2FVUIanr3gZZB8%2BDYz7w5lGr2uP%2FCN9L%2FBWx3d5ubscAUDhUWr2y36%2FkNVR7Izw9fGQOz1aH6GfPx%2F79QQzc8XFTG%2FqUBfFdi38hEyAEjzbn7BPfkMT0JgfktqnXriD%2Fetwj5KmN%2F9ZvW38e%2BlYQ%2Bfg%3D%3D: HTTPSConnectionPool(host='storage.googleapis.com', port=443): Max retries exceeded with url: /wandb-production.appspot.com/bryant-tang-ethz/DKT-trial%201/r45hitom/wandb-metadata.json?Expires=1703970021&GoogleAccessId=gorilla-files-url-signer-man%40wandb-production.iam.gserviceaccount.com&Signature=GREXo93rsWu5tN2Do3BDTqyp78EkUGEPCnZZNCIZAZ77an0YL3JPHTzO0RXwk63EhRgGfFuBpVTE4r8GHbjBRqfJYdZleab7PUI6tTZN%2FAjATBGZyfDad5VxyCODLozo0xjHtpf1sbmjPQL0YvAHY3q26YszJZCFlrxi1jukBukKouGBOCfy6EoXIfuZnLDw%2FVUIanr3gZZB8%2BDYz7w5lGr2uP%2FCN9L%2FBWx3d5ubscAUDhUWr2y36%2FkNVR7Izw9fGQOz1aH6GfPx%2F79QQzc8XFTG%2FqUBfFdi38hEyAEjzbn7BPfkMT0JgfktqnXriD%2Fetwj5KmN%2F9ZvW38e%2BlYQ%2Bfg%3D%3D (Caused by NewConnectionError('<urllib3.connection.HTTPSConnection object at 0x2b0d67e72df0>: Failed to establish a new connection: [Errno 101] Network is unreachable'))
2023-12-29 22:00:21,977 ERROR   wandb-upload_0:35328 [internal_api.py:upload_file():2763] upload_file request headers: {'User-Agent': 'python-requests/2.28.1', 'Accept-Encoding': 'gzip, deflate, br', 'Accept': '*/*', 'Connection': 'keep-alive', 'Content-Length': '9782'}
2023-12-29 22:00:21,977 ERROR   wandb-upload_0:35328 [internal_api.py:upload_file():2765] upload_file response body: 
2023-12-29 22:00:22,252 INFO    Thread-12 :35328 [dir_watcher.py:_on_file_modified():288] file/dir modified: /cluster/home/yutang/Deep-Knowledge-Tracing/DKT/KnowledgeTracing/evaluation/wandb/run-20231229_215952-r45hitom/files/conda-environment.yaml
2023-12-29 22:00:22,252 INFO    Thread-12 :35328 [dir_watcher.py:_on_file_created():271] file/dir created: /cluster/home/yutang/Deep-Knowledge-Tracing/DKT/KnowledgeTracing/evaluation/wandb/run-20231229_215952-r45hitom/files/output.log
2023-12-29 22:00:22,252 INFO    Thread-12 :35328 [dir_watcher.py:_on_file_created():271] file/dir created: /cluster/home/yutang/Deep-Knowledge-Tracing/DKT/KnowledgeTracing/evaluation/wandb/run-20231229_215952-r45hitom/files/wandb-metadata.json
2023-12-29 22:00:23,059 ERROR   wandb-upload_0:35328 [internal_api.py:upload_file():2761] upload_file exception https://storage.googleapis.com/wandb-production.appspot.com/bryant-tang-ethz/DKT-trial%201/r45hitom/wandb-metadata.json?Expires=1703970021&GoogleAccessId=gorilla-files-url-signer-man%40wandb-production.iam.gserviceaccount.com&Signature=GREXo93rsWu5tN2Do3BDTqyp78EkUGEPCnZZNCIZAZ77an0YL3JPHTzO0RXwk63EhRgGfFuBpVTE4r8GHbjBRqfJYdZleab7PUI6tTZN%2FAjATBGZyfDad5VxyCODLozo0xjHtpf1sbmjPQL0YvAHY3q26YszJZCFlrxi1jukBukKouGBOCfy6EoXIfuZnLDw%2FVUIanr3gZZB8%2BDYz7w5lGr2uP%2FCN9L%2FBWx3d5ubscAUDhUWr2y36%2FkNVR7Izw9fGQOz1aH6GfPx%2F79QQzc8XFTG%2FqUBfFdi38hEyAEjzbn7BPfkMT0JgfktqnXriD%2Fetwj5KmN%2F9ZvW38e%2BlYQ%2Bfg%3D%3D: HTTPSConnectionPool(host='storage.googleapis.com', port=443): Max retries exceeded with url: /wandb-production.appspot.com/bryant-tang-ethz/DKT-trial%201/r45hitom/wandb-metadata.json?Expires=1703970021&GoogleAccessId=gorilla-files-url-signer-man%40wandb-production.iam.gserviceaccount.com&Signature=GREXo93rsWu5tN2Do3BDTqyp78EkUGEPCnZZNCIZAZ77an0YL3JPHTzO0RXwk63EhRgGfFuBpVTE4r8GHbjBRqfJYdZleab7PUI6tTZN%2FAjATBGZyfDad5VxyCODLozo0xjHtpf1sbmjPQL0YvAHY3q26YszJZCFlrxi1jukBukKouGBOCfy6EoXIfuZnLDw%2FVUIanr3gZZB8%2BDYz7w5lGr2uP%2FCN9L%2FBWx3d5ubscAUDhUWr2y36%2FkNVR7Izw9fGQOz1aH6GfPx%2F79QQzc8XFTG%2FqUBfFdi38hEyAEjzbn7BPfkMT0JgfktqnXriD%2Fetwj5KmN%2F9ZvW38e%2BlYQ%2Bfg%3D%3D (Caused by NewConnectionError('<urllib3.connection.HTTPSConnection object at 0x2b0d67ea01c0>: Failed to establish a new connection: [Errno 101] Network is unreachable'))
2023-12-29 22:00:23,059 ERROR   wandb-upload_0:35328 [internal_api.py:upload_file():2763] upload_file request headers: {'User-Agent': 'python-requests/2.28.1', 'Accept-Encoding': 'gzip, deflate, br', 'Accept': '*/*', 'Connection': 'keep-alive', 'Content-Length': '9782'}
2023-12-29 22:00:23,059 ERROR   wandb-upload_0:35328 [internal_api.py:upload_file():2765] upload_file response body: 
2023-12-29 22:00:23,991 DEBUG   HandlerThread:35328 [handler.py:handle_request():146] handle_request: status_report
2023-12-29 22:00:24,386 INFO    Thread-12 :35328 [dir_watcher.py:_on_file_modified():288] file/dir modified: /cluster/home/yutang/Deep-Knowledge-Tracing/DKT/KnowledgeTracing/evaluation/wandb/run-20231229_215952-r45hitom/files/output.log
2023-12-29 22:00:24,387 INFO    Thread-12 :35328 [dir_watcher.py:_on_file_modified():288] file/dir modified: /cluster/home/yutang/Deep-Knowledge-Tracing/DKT/KnowledgeTracing/evaluation/wandb/run-20231229_215952-r45hitom/files/config.yaml
2023-12-29 22:00:25,267 ERROR   wandb-upload_0:35328 [internal_api.py:upload_file():2761] upload_file exception https://storage.googleapis.com/wandb-production.appspot.com/bryant-tang-ethz/DKT-trial%201/r45hitom/wandb-metadata.json?Expires=1703970021&GoogleAccessId=gorilla-files-url-signer-man%40wandb-production.iam.gserviceaccount.com&Signature=GREXo93rsWu5tN2Do3BDTqyp78EkUGEPCnZZNCIZAZ77an0YL3JPHTzO0RXwk63EhRgGfFuBpVTE4r8GHbjBRqfJYdZleab7PUI6tTZN%2FAjATBGZyfDad5VxyCODLozo0xjHtpf1sbmjPQL0YvAHY3q26YszJZCFlrxi1jukBukKouGBOCfy6EoXIfuZnLDw%2FVUIanr3gZZB8%2BDYz7w5lGr2uP%2FCN9L%2FBWx3d5ubscAUDhUWr2y36%2FkNVR7Izw9fGQOz1aH6GfPx%2F79QQzc8XFTG%2FqUBfFdi38hEyAEjzbn7BPfkMT0JgfktqnXriD%2Fetwj5KmN%2F9ZvW38e%2BlYQ%2Bfg%3D%3D: HTTPSConnectionPool(host='storage.googleapis.com', port=443): Max retries exceeded with url: /wandb-production.appspot.com/bryant-tang-ethz/DKT-trial%201/r45hitom/wandb-metadata.json?Expires=1703970021&GoogleAccessId=gorilla-files-url-signer-man%40wandb-production.iam.gserviceaccount.com&Signature=GREXo93rsWu5tN2Do3BDTqyp78EkUGEPCnZZNCIZAZ77an0YL3JPHTzO0RXwk63EhRgGfFuBpVTE4r8GHbjBRqfJYdZleab7PUI6tTZN%2FAjATBGZyfDad5VxyCODLozo0xjHtpf1sbmjPQL0YvAHY3q26YszJZCFlrxi1jukBukKouGBOCfy6EoXIfuZnLDw%2FVUIanr3gZZB8%2BDYz7w5lGr2uP%2FCN9L%2FBWx3d5ubscAUDhUWr2y36%2FkNVR7Izw9fGQOz1aH6GfPx%2F79QQzc8XFTG%2FqUBfFdi38hEyAEjzbn7BPfkMT0JgfktqnXriD%2Fetwj5KmN%2F9ZvW38e%2BlYQ%2Bfg%3D%3D (Caused by NewConnectionError('<urllib3.connection.HTTPSConnection object at 0x2b0d67a25c10>: Failed to establish a new connection: [Errno 101] Network is unreachable'))
2023-12-29 22:00:25,267 ERROR   wandb-upload_0:35328 [internal_api.py:upload_file():2763] upload_file request headers: {'User-Agent': 'python-requests/2.28.1', 'Accept-Encoding': 'gzip, deflate, br', 'Accept': '*/*', 'Connection': 'keep-alive', 'Content-Length': '9782'}
2023-12-29 22:00:25,267 ERROR   wandb-upload_0:35328 [internal_api.py:upload_file():2765] upload_file response body: 
2023-12-29 22:00:25,267 INFO    wandb-upload_0:35328 [retry.py:__call__():172] Retry attempt failed:
Traceback (most recent call last):
  File "/cluster/home/yutang/miniconda3/lib/python3.9/site-packages/urllib3/connection.py", line 174, in _new_conn
    conn = connection.create_connection(
  File "/cluster/home/yutang/miniconda3/lib/python3.9/site-packages/urllib3/util/connection.py", line 95, in create_connection
    raise err
  File "/cluster/home/yutang/miniconda3/lib/python3.9/site-packages/urllib3/util/connection.py", line 85, in create_connection
    sock.connect(sa)
OSError: [Errno 101] Network is unreachable

During handling of the above exception, another exception occurred:

Traceback (most recent call last):
  File "/cluster/home/yutang/miniconda3/lib/python3.9/site-packages/urllib3/connectionpool.py", line 703, in urlopen
    httplib_response = self._make_request(
  File "/cluster/home/yutang/miniconda3/lib/python3.9/site-packages/urllib3/connectionpool.py", line 386, in _make_request
    self._validate_conn(conn)
  File "/cluster/home/yutang/miniconda3/lib/python3.9/site-packages/urllib3/connectionpool.py", line 1042, in _validate_conn
    conn.connect()
  File "/cluster/home/yutang/miniconda3/lib/python3.9/site-packages/urllib3/connection.py", line 358, in connect
    self.sock = conn = self._new_conn()
  File "/cluster/home/yutang/miniconda3/lib/python3.9/site-packages/urllib3/connection.py", line 186, in _new_conn
    raise NewConnectionError(
urllib3.exceptions.NewConnectionError: <urllib3.connection.HTTPSConnection object at 0x2b0d67a25c10>: Failed to establish a new connection: [Errno 101] Network is unreachable

During handling of the above exception, another exception occurred:

Traceback (most recent call last):
  File "/cluster/home/yutang/miniconda3/lib/python3.9/site-packages/requests/adapters.py", line 489, in send
    resp = conn.urlopen(
  File "/cluster/home/yutang/miniconda3/lib/python3.9/site-packages/urllib3/connectionpool.py", line 787, in urlopen
    retries = retries.increment(
  File "/cluster/home/yutang/miniconda3/lib/python3.9/site-packages/urllib3/util/retry.py", line 592, in increment
    raise MaxRetryError(_pool, url, error or ResponseError(cause))
urllib3.exceptions.MaxRetryError: HTTPSConnectionPool(host='storage.googleapis.com', port=443): Max retries exceeded with url: /wandb-production.appspot.com/bryant-tang-ethz/DKT-trial%201/r45hitom/wandb-metadata.json?Expires=1703970021&GoogleAccessId=gorilla-files-url-signer-man%40wandb-production.iam.gserviceaccount.com&Signature=GREXo93rsWu5tN2Do3BDTqyp78EkUGEPCnZZNCIZAZ77an0YL3JPHTzO0RXwk63EhRgGfFuBpVTE4r8GHbjBRqfJYdZleab7PUI6tTZN%2FAjATBGZyfDad5VxyCODLozo0xjHtpf1sbmjPQL0YvAHY3q26YszJZCFlrxi1jukBukKouGBOCfy6EoXIfuZnLDw%2FVUIanr3gZZB8%2BDYz7w5lGr2uP%2FCN9L%2FBWx3d5ubscAUDhUWr2y36%2FkNVR7Izw9fGQOz1aH6GfPx%2F79QQzc8XFTG%2FqUBfFdi38hEyAEjzbn7BPfkMT0JgfktqnXriD%2Fetwj5KmN%2F9ZvW38e%2BlYQ%2Bfg%3D%3D (Caused by NewConnectionError('<urllib3.connection.HTTPSConnection object at 0x2b0d67a25c10>: Failed to establish a new connection: [Errno 101] Network is unreachable'))

During handling of the above exception, another exception occurred:

Traceback (most recent call last):
  File "/cluster/home/yutang/miniconda3/lib/python3.9/site-packages/wandb/sdk/internal/internal_api.py", line 2754, in upload_file
    response = self._upload_file_session.put(
  File "/cluster/home/yutang/miniconda3/lib/python3.9/site-packages/requests/sessions.py", line 647, in put
    return self.request("PUT", url, data=data, **kwargs)
  File "/cluster/home/yutang/miniconda3/lib/python3.9/site-packages/requests/sessions.py", line 587, in request
    resp = self.send(prep, **send_kwargs)
  File "/cluster/home/yutang/miniconda3/lib/python3.9/site-packages/requests/sessions.py", line 701, in send
    r = adapter.send(request, **kwargs)
  File "/cluster/home/yutang/miniconda3/lib/python3.9/site-packages/requests/adapters.py", line 565, in send
    raise ConnectionError(e, request=request)
requests.exceptions.ConnectionError: HTTPSConnectionPool(host='storage.googleapis.com', port=443): Max retries exceeded with url: /wandb-production.appspot.com/bryant-tang-ethz/DKT-trial%201/r45hitom/wandb-metadata.json?Expires=1703970021&GoogleAccessId=gorilla-files-url-signer-man%40wandb-production.iam.gserviceaccount.com&Signature=GREXo93rsWu5tN2Do3BDTqyp78EkUGEPCnZZNCIZAZ77an0YL3JPHTzO0RXwk63EhRgGfFuBpVTE4r8GHbjBRqfJYdZleab7PUI6tTZN%2FAjATBGZyfDad5VxyCODLozo0xjHtpf1sbmjPQL0YvAHY3q26YszJZCFlrxi1jukBukKouGBOCfy6EoXIfuZnLDw%2FVUIanr3gZZB8%2BDYz7w5lGr2uP%2FCN9L%2FBWx3d5ubscAUDhUWr2y36%2FkNVR7Izw9fGQOz1aH6GfPx%2F79QQzc8XFTG%2FqUBfFdi38hEyAEjzbn7BPfkMT0JgfktqnXriD%2Fetwj5KmN%2F9ZvW38e%2BlYQ%2Bfg%3D%3D (Caused by NewConnectionError('<urllib3.connection.HTTPSConnection object at 0x2b0d67a25c10>: Failed to establish a new connection: [Errno 101] Network is unreachable'))

During handling of the above exception, another exception occurred:

Traceback (most recent call last):
  File "/cluster/home/yutang/miniconda3/lib/python3.9/site-packages/wandb/sdk/lib/retry.py", line 131, in __call__
    result = self._call_fn(*args, **kwargs)
  File "/cluster/home/yutang/miniconda3/lib/python3.9/site-packages/wandb/sdk/internal/internal_api.py", line 2785, in upload_file
    raise _e.with_traceback(sys.exc_info()[2])
  File "/cluster/home/yutang/miniconda3/lib/python3.9/site-packages/wandb/sdk/internal/internal_api.py", line 2754, in upload_file
    response = self._upload_file_session.put(
  File "/cluster/home/yutang/miniconda3/lib/python3.9/site-packages/requests/sessions.py", line 647, in put
    return self.request("PUT", url, data=data, **kwargs)
  File "/cluster/home/yutang/miniconda3/lib/python3.9/site-packages/requests/sessions.py", line 587, in request
    resp = self.send(prep, **send_kwargs)
  File "/cluster/home/yutang/miniconda3/lib/python3.9/site-packages/requests/sessions.py", line 701, in send
    r = adapter.send(request, **kwargs)
  File "/cluster/home/yutang/miniconda3/lib/python3.9/site-packages/requests/adapters.py", line 565, in send
    raise ConnectionError(e, request=request)
wandb.sdk.lib.retry.TransientError: None
2023-12-29 22:00:25,400 INFO    Thread-12 :35328 [dir_watcher.py:_on_file_modified():288] file/dir modified: /cluster/home/yutang/Deep-Knowledge-Tracing/DKT/KnowledgeTracing/evaluation/wandb/run-20231229_215952-r45hitom/files/config.yaml
2023-12-29 22:00:29,387 DEBUG   HandlerThread:35328 [handler.py:handle_request():146] handle_request: status_report
2023-12-29 22:00:30,028 ERROR   wandb-upload_0:35328 [internal_api.py:upload_file():2761] upload_file exception https://storage.googleapis.com/wandb-production.appspot.com/bryant-tang-ethz/DKT-trial%201/r45hitom/wandb-metadata.json?Expires=1703970021&GoogleAccessId=gorilla-files-url-signer-man%40wandb-production.iam.gserviceaccount.com&Signature=GREXo93rsWu5tN2Do3BDTqyp78EkUGEPCnZZNCIZAZ77an0YL3JPHTzO0RXwk63EhRgGfFuBpVTE4r8GHbjBRqfJYdZleab7PUI6tTZN%2FAjATBGZyfDad5VxyCODLozo0xjHtpf1sbmjPQL0YvAHY3q26YszJZCFlrxi1jukBukKouGBOCfy6EoXIfuZnLDw%2FVUIanr3gZZB8%2BDYz7w5lGr2uP%2FCN9L%2FBWx3d5ubscAUDhUWr2y36%2FkNVR7Izw9fGQOz1aH6GfPx%2F79QQzc8XFTG%2FqUBfFdi38hEyAEjzbn7BPfkMT0JgfktqnXriD%2Fetwj5KmN%2F9ZvW38e%2BlYQ%2Bfg%3D%3D: HTTPSConnectionPool(host='storage.googleapis.com', port=443): Max retries exceeded with url: /wandb-production.appspot.com/bryant-tang-ethz/DKT-trial%201/r45hitom/wandb-metadata.json?Expires=1703970021&GoogleAccessId=gorilla-files-url-signer-man%40wandb-production.iam.gserviceaccount.com&Signature=GREXo93rsWu5tN2Do3BDTqyp78EkUGEPCnZZNCIZAZ77an0YL3JPHTzO0RXwk63EhRgGfFuBpVTE4r8GHbjBRqfJYdZleab7PUI6tTZN%2FAjATBGZyfDad5VxyCODLozo0xjHtpf1sbmjPQL0YvAHY3q26YszJZCFlrxi1jukBukKouGBOCfy6EoXIfuZnLDw%2FVUIanr3gZZB8%2BDYz7w5lGr2uP%2FCN9L%2FBWx3d5ubscAUDhUWr2y36%2FkNVR7Izw9fGQOz1aH6GfPx%2F79QQzc8XFTG%2FqUBfFdi38hEyAEjzbn7BPfkMT0JgfktqnXriD%2Fetwj5KmN%2F9ZvW38e%2BlYQ%2Bfg%3D%3D (Caused by NewConnectionError('<urllib3.connection.HTTPSConnection object at 0x2b0d67ea0730>: Failed to establish a new connection: [Errno 101] Network is unreachable'))
2023-12-29 22:00:30,029 ERROR   wandb-upload_0:35328 [internal_api.py:upload_file():2763] upload_file request headers: {'User-Agent': 'python-requests/2.28.1', 'Accept-Encoding': 'gzip, deflate, br', 'Accept': '*/*', 'Connection': 'keep-alive', 'Content-Length': '9782'}
2023-12-29 22:00:30,029 ERROR   wandb-upload_0:35328 [internal_api.py:upload_file():2765] upload_file response body: 
2023-12-29 22:00:34,388 DEBUG   HandlerThread:35328 [handler.py:handle_request():146] handle_request: status_report
2023-12-29 22:00:36,727 DEBUG   HandlerThread:35328 [handler.py:handle_request():146] handle_request: internal_messages
2023-12-29 22:00:36,729 DEBUG   HandlerThread:35328 [handler.py:handle_request():146] handle_request: stop_status
2023-12-29 22:00:36,729 DEBUG   SenderThread:35328 [sender.py:send_request():409] send_request: stop_status
2023-12-29 22:00:37,521 INFO    Thread-12 :35328 [dir_watcher.py:_on_file_modified():288] file/dir modified: /cluster/home/yutang/Deep-Knowledge-Tracing/DKT/KnowledgeTracing/evaluation/wandb/run-20231229_215952-r45hitom/files/output.log
2023-12-29 22:00:39,000 ERROR   wandb-upload_0:35328 [internal_api.py:upload_file():2761] upload_file exception https://storage.googleapis.com/wandb-production.appspot.com/bryant-tang-ethz/DKT-trial%201/r45hitom/wandb-metadata.json?Expires=1703970021&GoogleAccessId=gorilla-files-url-signer-man%40wandb-production.iam.gserviceaccount.com&Signature=GREXo93rsWu5tN2Do3BDTqyp78EkUGEPCnZZNCIZAZ77an0YL3JPHTzO0RXwk63EhRgGfFuBpVTE4r8GHbjBRqfJYdZleab7PUI6tTZN%2FAjATBGZyfDad5VxyCODLozo0xjHtpf1sbmjPQL0YvAHY3q26YszJZCFlrxi1jukBukKouGBOCfy6EoXIfuZnLDw%2FVUIanr3gZZB8%2BDYz7w5lGr2uP%2FCN9L%2FBWx3d5ubscAUDhUWr2y36%2FkNVR7Izw9fGQOz1aH6GfPx%2F79QQzc8XFTG%2FqUBfFdi38hEyAEjzbn7BPfkMT0JgfktqnXriD%2Fetwj5KmN%2F9ZvW38e%2BlYQ%2Bfg%3D%3D: HTTPSConnectionPool(host='storage.googleapis.com', port=443): Max retries exceeded with url: /wandb-production.appspot.com/bryant-tang-ethz/DKT-trial%201/r45hitom/wandb-metadata.json?Expires=1703970021&GoogleAccessId=gorilla-files-url-signer-man%40wandb-production.iam.gserviceaccount.com&Signature=GREXo93rsWu5tN2Do3BDTqyp78EkUGEPCnZZNCIZAZ77an0YL3JPHTzO0RXwk63EhRgGfFuBpVTE4r8GHbjBRqfJYdZleab7PUI6tTZN%2FAjATBGZyfDad5VxyCODLozo0xjHtpf1sbmjPQL0YvAHY3q26YszJZCFlrxi1jukBukKouGBOCfy6EoXIfuZnLDw%2FVUIanr3gZZB8%2BDYz7w5lGr2uP%2FCN9L%2FBWx3d5ubscAUDhUWr2y36%2FkNVR7Izw9fGQOz1aH6GfPx%2F79QQzc8XFTG%2FqUBfFdi38hEyAEjzbn7BPfkMT0JgfktqnXriD%2Fetwj5KmN%2F9ZvW38e%2BlYQ%2Bfg%3D%3D (Caused by NewConnectionError('<urllib3.connection.HTTPSConnection object at 0x2b0d67e5f3a0>: Failed to establish a new connection: [Errno 101] Network is unreachable'))
2023-12-29 22:00:39,000 ERROR   wandb-upload_0:35328 [internal_api.py:upload_file():2763] upload_file request headers: {'User-Agent': 'python-requests/2.28.1', 'Accept-Encoding': 'gzip, deflate, br', 'Accept': '*/*', 'Connection': 'keep-alive', 'Content-Length': '9782'}
2023-12-29 22:00:39,000 ERROR   wandb-upload_0:35328 [internal_api.py:upload_file():2765] upload_file response body: 
2023-12-29 22:00:39,481 DEBUG   HandlerThread:35328 [handler.py:handle_request():146] handle_request: status_report
2023-12-29 22:00:39,535 INFO    Thread-12 :35328 [dir_watcher.py:_on_file_modified():288] file/dir modified: /cluster/home/yutang/Deep-Knowledge-Tracing/DKT/KnowledgeTracing/evaluation/wandb/run-20231229_215952-r45hitom/files/output.log
2023-12-29 22:00:43,572 INFO    Thread-12 :35328 [dir_watcher.py:_on_file_modified():288] file/dir modified: /cluster/home/yutang/Deep-Knowledge-Tracing/DKT/KnowledgeTracing/evaluation/wandb/run-20231229_215952-r45hitom/files/output.log
2023-12-29 22:00:44,581 INFO    Thread-12 :35328 [dir_watcher.py:_on_file_modified():288] file/dir modified: /cluster/home/yutang/Deep-Knowledge-Tracing/DKT/KnowledgeTracing/evaluation/wandb/run-20231229_215952-r45hitom/files/output.log
2023-12-29 22:00:45,093 DEBUG   HandlerThread:35328 [handler.py:handle_request():146] handle_request: status_report
2023-12-29 22:00:50,094 DEBUG   HandlerThread:35328 [handler.py:handle_request():146] handle_request: status_report
2023-12-29 22:00:51,728 DEBUG   HandlerThread:35328 [handler.py:handle_request():146] handle_request: internal_messages
2023-12-29 22:00:51,728 DEBUG   HandlerThread:35328 [handler.py:handle_request():146] handle_request: stop_status
2023-12-29 22:00:51,729 DEBUG   SenderThread:35328 [sender.py:send_request():409] send_request: stop_status
2023-12-29 22:00:53,254 DEBUG   SystemMonitor:35328 [system_monitor.py:_start():172] Starting system metrics aggregation loop
2023-12-29 22:00:53,257 DEBUG   SenderThread:35328 [sender.py:send():382] send: stats
2023-12-29 22:00:55,161 DEBUG   HandlerThread:35328 [handler.py:handle_request():146] handle_request: status_report
2023-12-29 22:00:55,682 INFO    Thread-12 :35328 [dir_watcher.py:_on_file_modified():288] file/dir modified: /cluster/home/yutang/Deep-Knowledge-Tracing/DKT/KnowledgeTracing/evaluation/wandb/run-20231229_215952-r45hitom/files/output.log
2023-12-29 22:00:58,193 ERROR   wandb-upload_0:35328 [internal_api.py:upload_file():2761] upload_file exception https://storage.googleapis.com/wandb-production.appspot.com/bryant-tang-ethz/DKT-trial%201/r45hitom/wandb-metadata.json?Expires=1703970021&GoogleAccessId=gorilla-files-url-signer-man%40wandb-production.iam.gserviceaccount.com&Signature=GREXo93rsWu5tN2Do3BDTqyp78EkUGEPCnZZNCIZAZ77an0YL3JPHTzO0RXwk63EhRgGfFuBpVTE4r8GHbjBRqfJYdZleab7PUI6tTZN%2FAjATBGZyfDad5VxyCODLozo0xjHtpf1sbmjPQL0YvAHY3q26YszJZCFlrxi1jukBukKouGBOCfy6EoXIfuZnLDw%2FVUIanr3gZZB8%2BDYz7w5lGr2uP%2FCN9L%2FBWx3d5ubscAUDhUWr2y36%2FkNVR7Izw9fGQOz1aH6GfPx%2F79QQzc8XFTG%2FqUBfFdi38hEyAEjzbn7BPfkMT0JgfktqnXriD%2Fetwj5KmN%2F9ZvW38e%2BlYQ%2Bfg%3D%3D: HTTPSConnectionPool(host='storage.googleapis.com', port=443): Max retries exceeded with url: /wandb-production.appspot.com/bryant-tang-ethz/DKT-trial%201/r45hitom/wandb-metadata.json?Expires=1703970021&GoogleAccessId=gorilla-files-url-signer-man%40wandb-production.iam.gserviceaccount.com&Signature=GREXo93rsWu5tN2Do3BDTqyp78EkUGEPCnZZNCIZAZ77an0YL3JPHTzO0RXwk63EhRgGfFuBpVTE4r8GHbjBRqfJYdZleab7PUI6tTZN%2FAjATBGZyfDad5VxyCODLozo0xjHtpf1sbmjPQL0YvAHY3q26YszJZCFlrxi1jukBukKouGBOCfy6EoXIfuZnLDw%2FVUIanr3gZZB8%2BDYz7w5lGr2uP%2FCN9L%2FBWx3d5ubscAUDhUWr2y36%2FkNVR7Izw9fGQOz1aH6GfPx%2F79QQzc8XFTG%2FqUBfFdi38hEyAEjzbn7BPfkMT0JgfktqnXriD%2Fetwj5KmN%2F9ZvW38e%2BlYQ%2Bfg%3D%3D (Caused by NewConnectionError('<urllib3.connection.HTTPSConnection object at 0x2b0d67e72be0>: Failed to establish a new connection: [Errno 101] Network is unreachable'))
2023-12-29 22:00:58,193 ERROR   wandb-upload_0:35328 [internal_api.py:upload_file():2763] upload_file request headers: {'User-Agent': 'python-requests/2.28.1', 'Accept-Encoding': 'gzip, deflate, br', 'Accept': '*/*', 'Connection': 'keep-alive', 'Content-Length': '9782'}
2023-12-29 22:00:58,193 ERROR   wandb-upload_0:35328 [internal_api.py:upload_file():2765] upload_file response body: 
2023-12-29 22:01:00,161 DEBUG   HandlerThread:35328 [handler.py:handle_request():146] handle_request: status_report
