2023-10-09 19:54:21,285 INFO    StreamThr :15120 [internal.py:wandb_internal():86] W&B internal server running at pid: 15120, started at: 2023-10-09 19:54:21.284817
2023-10-09 19:54:21,287 DEBUG   HandlerThread:15120 [handler.py:handle_request():144] handle_request: status
2023-10-09 19:54:21,293 INFO    WriterThread:15120 [datastore.py:open_for_write():85] open: D:\ETHz\Internship\adaptive-e-learning-for-educational-recommendation-system\DeepKnowledgeTracing-DKT-Pytorch\DKT\KnowledgeTracing\evaluation\wandb\run-20231009_195421-5bpask06\run-5bpask06.wandb
2023-10-09 19:54:21,295 DEBUG   SenderThread:15120 [sender.py:send():380] send: header
2023-10-09 19:54:21,377 DEBUG   SenderThread:15120 [sender.py:send():380] send: run
2023-10-09 19:54:22,298 INFO    SenderThread:15120 [dir_watcher.py:__init__():211] watching files in: D:\ETHz\Internship\adaptive-e-learning-for-educational-recommendation-system\DeepKnowledgeTracing-DKT-Pytorch\DKT\KnowledgeTracing\evaluation\wandb\run-20231009_195421-5bpask06\files
2023-10-09 19:54:22,298 INFO    SenderThread:15120 [sender.py:_start_run_threads():1122] run started: 5bpask06 with start time 1696874061.285816
2023-10-09 19:54:22,320 DEBUG   HandlerThread:15120 [handler.py:handle_request():144] handle_request: check_version
2023-10-09 19:54:22,320 DEBUG   SenderThread:15120 [sender.py:send_request():407] send_request: check_version
2023-10-09 19:54:22,437 DEBUG   HandlerThread:15120 [handler.py:handle_request():144] handle_request: run_start
2023-10-09 19:54:23,064 DEBUG   HandlerThread:15120 [system_info.py:__init__():32] System info init
2023-10-09 19:54:23,064 DEBUG   HandlerThread:15120 [system_info.py:__init__():47] System info init done
2023-10-09 19:54:23,064 INFO    HandlerThread:15120 [system_monitor.py:start():181] Starting system monitor
2023-10-09 19:54:23,065 INFO    SystemMonitor:15120 [system_monitor.py:_start():145] Starting system asset monitoring threads
2023-10-09 19:54:23,065 INFO    HandlerThread:15120 [system_monitor.py:probe():201] Collecting system info
2023-10-09 19:54:23,071 INFO    SystemMonitor:15120 [interfaces.py:start():190] Started cpu monitoring
2023-10-09 19:54:23,072 INFO    SystemMonitor:15120 [interfaces.py:start():190] Started disk monitoring
2023-10-09 19:54:23,073 INFO    SystemMonitor:15120 [interfaces.py:start():190] Started gpu monitoring
2023-10-09 19:54:23,074 INFO    SystemMonitor:15120 [interfaces.py:start():190] Started memory monitoring
2023-10-09 19:54:23,087 INFO    SystemMonitor:15120 [interfaces.py:start():190] Started network monitoring
2023-10-09 19:54:23,119 DEBUG   HandlerThread:15120 [system_info.py:probe():196] Probing system
2023-10-09 19:54:23,124 DEBUG   HandlerThread:15120 [system_info.py:_probe_git():181] Probing git
2023-10-09 19:54:23,137 ERROR   gpu       :15120 [interfaces.py:monitor():144] Failed to sample metric: Not Supported
2023-10-09 19:54:23,138 ERROR   gpu       :15120 [interfaces.py:monitor():144] Failed to sample metric: Not Supported
2023-10-09 19:54:23,318 DEBUG   HandlerThread:15120 [system_info.py:_probe_git():189] Probing git done
2023-10-09 19:54:23,319 DEBUG   HandlerThread:15120 [system_info.py:probe():244] Probing system done
2023-10-09 19:54:23,319 DEBUG   HandlerThread:15120 [system_monitor.py:probe():210] {'os': 'Windows-10-10.0.19041-SP0', 'python': '3.8.8', 'heartbeatAt': '2023-10-09T17:54:23.119360', 'startedAt': '2023-10-09T17:54:21.266860', 'docker': None, 'cuda': None, 'args': (), 'state': 'running', 'program': 'D:\\ETHz\\Internship\\adaptive-e-learning-for-educational-recommendation-system\\DeepKnowledgeTracing-DKT-Pytorch\\DKT\\KnowledgeTracing\\evaluation\\run.py', 'codePathLocal': 'run.py', 'codePath': 'DKT\\KnowledgeTracing\\evaluation\\run.py', 'git': {'remote': 'https://github.com/pydaxing/DeepKnowledgeTracing-DKT-Pytorch.git', 'commit': '49418a2a50164318844b32e6f41b69032501ee9b'}, 'email': 'tangyu990628@gmail.com', 'root': 'D:/ETHz/Internship/adaptive-e-learning-for-educational-recommendation-system/DeepKnowledgeTracing-DKT-Pytorch', 'host': 'LAPTOP-HVTN1FK1', 'username': 'tyu06', 'executable': 'C:\\Users\\tyu06\\anaconda3\\python.exe', 'cpu_count': 4, 'cpu_count_logical': 8, 'cpu_freq': {'current': 2301.0, 'min': 0.0, 'max': 2301.0}, 'cpu_freq_per_core': [{'current': 2301.0, 'min': 0.0, 'max': 2301.0}], 'disk': {'/': {'total': 433.9125785827637, 'used': 295.64342880249023}}, 'gpu': 'GeForce MX350', 'gpu_count': 1, 'gpu_devices': [{'name': 'GeForce MX350', 'memory_total': 2147483648}], 'memory': {'total': 15.870410919189453}}
2023-10-09 19:54:23,319 INFO    HandlerThread:15120 [system_monitor.py:probe():211] Finished collecting system info
2023-10-09 19:54:23,319 INFO    HandlerThread:15120 [system_monitor.py:probe():214] Publishing system info
2023-10-09 19:54:23,319 DEBUG   HandlerThread:15120 [system_info.py:_save_pip():52] Saving list of pip packages installed into the current environment
2023-10-09 19:54:23,321 DEBUG   HandlerThread:15120 [system_info.py:_save_pip():68] Saving pip packages done
2023-10-09 19:54:23,322 DEBUG   HandlerThread:15120 [system_info.py:_save_conda():75] Saving list of conda packages installed into the current environment
2023-10-09 19:54:24,323 INFO    Thread-16 :15120 [dir_watcher.py:_on_file_created():271] file/dir created: D:\ETHz\Internship\adaptive-e-learning-for-educational-recommendation-system\DeepKnowledgeTracing-DKT-Pytorch\DKT\KnowledgeTracing\evaluation\wandb\run-20231009_195421-5bpask06\files\requirements.txt
2023-10-09 19:54:24,324 INFO    Thread-16 :15120 [dir_watcher.py:_on_file_created():271] file/dir created: D:\ETHz\Internship\adaptive-e-learning-for-educational-recommendation-system\DeepKnowledgeTracing-DKT-Pytorch\DKT\KnowledgeTracing\evaluation\wandb\run-20231009_195421-5bpask06\files\conda-environment.yaml
2023-10-09 19:54:25,437 ERROR   gpu       :15120 [interfaces.py:monitor():144] Failed to sample metric: Not Supported
2023-10-09 19:54:25,438 ERROR   gpu       :15120 [interfaces.py:monitor():144] Failed to sample metric: Not Supported
2023-10-09 19:54:27,737 ERROR   gpu       :15120 [interfaces.py:monitor():144] Failed to sample metric: Not Supported
2023-10-09 19:54:27,738 ERROR   gpu       :15120 [interfaces.py:monitor():144] Failed to sample metric: Not Supported
2023-10-09 19:54:30,026 ERROR   gpu       :15120 [interfaces.py:monitor():144] Failed to sample metric: Not Supported
2023-10-09 19:54:30,027 ERROR   gpu       :15120 [interfaces.py:monitor():144] Failed to sample metric: Not Supported
2023-10-09 19:54:32,420 ERROR   gpu       :15120 [interfaces.py:monitor():144] Failed to sample metric: Not Supported
2023-10-09 19:54:32,421 ERROR   gpu       :15120 [interfaces.py:monitor():144] Failed to sample metric: Not Supported
2023-10-09 19:54:34,850 ERROR   gpu       :15120 [interfaces.py:monitor():144] Failed to sample metric: Not Supported
2023-10-09 19:54:34,850 ERROR   gpu       :15120 [interfaces.py:monitor():144] Failed to sample metric: Not Supported
2023-10-09 19:54:37,219 ERROR   gpu       :15120 [interfaces.py:monitor():144] Failed to sample metric: Not Supported
2023-10-09 19:54:37,220 ERROR   gpu       :15120 [interfaces.py:monitor():144] Failed to sample metric: Not Supported
2023-10-09 19:54:39,507 ERROR   gpu       :15120 [interfaces.py:monitor():144] Failed to sample metric: Not Supported
2023-10-09 19:54:39,508 ERROR   gpu       :15120 [interfaces.py:monitor():144] Failed to sample metric: Not Supported
2023-10-09 19:54:41,827 ERROR   gpu       :15120 [interfaces.py:monitor():144] Failed to sample metric: Not Supported
2023-10-09 19:54:41,828 ERROR   gpu       :15120 [interfaces.py:monitor():144] Failed to sample metric: Not Supported
2023-10-09 19:54:44,160 ERROR   gpu       :15120 [interfaces.py:monitor():144] Failed to sample metric: Not Supported
2023-10-09 19:54:44,160 ERROR   gpu       :15120 [interfaces.py:monitor():144] Failed to sample metric: Not Supported
2023-10-09 19:54:46,554 ERROR   gpu       :15120 [interfaces.py:monitor():144] Failed to sample metric: Not Supported
2023-10-09 19:54:46,555 ERROR   gpu       :15120 [interfaces.py:monitor():144] Failed to sample metric: Not Supported
2023-10-09 19:54:48,166 DEBUG   HandlerThread:15120 [system_info.py:_save_conda():87] Saving conda packages done
2023-10-09 19:54:48,180 INFO    HandlerThread:15120 [system_monitor.py:probe():216] Finished publishing system info
2023-10-09 19:54:48,210 DEBUG   HandlerThread:15120 [handler.py:handle_request():144] handle_request: status_report
2023-10-09 19:54:48,210 DEBUG   HandlerThread:15120 [handler.py:handle_request():144] handle_request: keepalive
2023-10-09 19:54:48,210 DEBUG   HandlerThread:15120 [handler.py:handle_request():144] handle_request: status_report
2023-10-09 19:54:48,211 DEBUG   HandlerThread:15120 [handler.py:handle_request():144] handle_request: keepalive
2023-10-09 19:54:48,211 DEBUG   HandlerThread:15120 [handler.py:handle_request():144] handle_request: status_report
2023-10-09 19:54:48,211 DEBUG   HandlerThread:15120 [handler.py:handle_request():144] handle_request: keepalive
2023-10-09 19:54:48,212 DEBUG   HandlerThread:15120 [handler.py:handle_request():144] handle_request: status_report
2023-10-09 19:54:48,212 DEBUG   HandlerThread:15120 [handler.py:handle_request():144] handle_request: keepalive
2023-10-09 19:54:48,212 DEBUG   HandlerThread:15120 [handler.py:handle_request():144] handle_request: status_report
2023-10-09 19:54:48,212 DEBUG   HandlerThread:15120 [handler.py:handle_request():144] handle_request: keepalive
2023-10-09 19:54:48,213 DEBUG   SenderThread:15120 [sender.py:send():380] send: files
2023-10-09 19:54:48,213 INFO    SenderThread:15120 [sender.py:_save_file():1378] saving file wandb-metadata.json with policy now
2023-10-09 19:54:48,228 DEBUG   HandlerThread:15120 [handler.py:handle_request():144] handle_request: stop_status
2023-10-09 19:54:48,228 DEBUG   SenderThread:15120 [sender.py:send_request():407] send_request: stop_status
2023-10-09 19:54:48,231 DEBUG   HandlerThread:15120 [handler.py:handle_request():144] handle_request: internal_messages
2023-10-09 19:54:48,252 INFO    Thread-16 :15120 [dir_watcher.py:_on_file_modified():288] file/dir modified: D:\ETHz\Internship\adaptive-e-learning-for-educational-recommendation-system\DeepKnowledgeTracing-DKT-Pytorch\DKT\KnowledgeTracing\evaluation\wandb\run-20231009_195421-5bpask06\files\conda-environment.yaml
2023-10-09 19:54:48,292 INFO    Thread-16 :15120 [dir_watcher.py:_on_file_created():271] file/dir created: D:\ETHz\Internship\adaptive-e-learning-for-educational-recommendation-system\DeepKnowledgeTracing-DKT-Pytorch\DKT\KnowledgeTracing\evaluation\wandb\run-20231009_195421-5bpask06\files\wandb-metadata.json
2023-10-09 19:54:48,500 ERROR   wandb-upload_0:15120 [internal_api.py:execute():369] 404 response executing GraphQL.
2023-10-09 19:54:48,500 ERROR   wandb-upload_0:15120 [internal_api.py:execute():370] {"errors":[{"message":"run DKT-trial 1/5bpask06 not found during createRunFiles","path":["createRunFiles"]}],"data":{"createRunFiles":null}}
2023-10-09 19:54:48,502 ERROR   Thread-15 :15120 [step_upload.py:_handle_event():200] Failed to upload file: C:\Users\tyu06\AppData\Local\Temp\tmp1a8bbc4ewandb\gwcacy56-wandb-metadata.json
Traceback (most recent call last):
  File "C:\Users\tyu06\anaconda3\lib\site-packages\wandb\sdk\lib\retry.py", line 131, in __call__
    result = self._call_fn(*args, **kwargs)
  File "C:\Users\tyu06\anaconda3\lib\site-packages\wandb\sdk\internal\internal_api.py", line 366, in execute
    return self.client.execute(*args, **kwargs)  # type: ignore
  File "C:\Users\tyu06\anaconda3\lib\site-packages\wandb\vendor\gql-0.2.0\wandb_gql\client.py", line 52, in execute
    result = self._get_result(document, *args, **kwargs)
  File "C:\Users\tyu06\anaconda3\lib\site-packages\wandb\vendor\gql-0.2.0\wandb_gql\client.py", line 60, in _get_result
    return self.transport.execute(document, *args, **kwargs)
  File "C:\Users\tyu06\anaconda3\lib\site-packages\wandb\sdk\lib\gql_request.py", line 59, in execute
    request.raise_for_status()
  File "C:\Users\tyu06\anaconda3\lib\site-packages\requests\models.py", line 943, in raise_for_status
    raise HTTPError(http_error_msg, response=self)
requests.exceptions.HTTPError: 404 Client Error: Not Found for url: https://api.wandb.ai/graphql

During handling of the above exception, another exception occurred:

Traceback (most recent call last):
  File "C:\Users\tyu06\anaconda3\lib\concurrent\futures\thread.py", line 57, in run
    result = self.fn(*self.args, **self.kwargs)
  File "C:\Users\tyu06\anaconda3\lib\site-packages\wandb\filesync\step_upload.py", line 288, in run_and_notify
    self._do_upload_sync(event)
  File "C:\Users\tyu06\anaconda3\lib\site-packages\wandb\filesync\step_upload.py", line 330, in _do_upload_sync
    job.run()
  File "C:\Users\tyu06\anaconda3\lib\site-packages\wandb\filesync\upload_job.py", line 57, in run
    self.push()
  File "C:\Users\tyu06\anaconda3\lib\site-packages\wandb\filesync\upload_job.py", line 106, in push
    _, upload_headers, result = self._api.upload_urls(project, [self.save_name])
  File "C:\Users\tyu06\anaconda3\lib\site-packages\wandb\apis\normalize.py", line 73, in wrapper
    raise err
  File "C:\Users\tyu06\anaconda3\lib\site-packages\wandb\apis\normalize.py", line 41, in wrapper
    return func(*args, **kwargs)
  File "C:\Users\tyu06\anaconda3\lib\site-packages\wandb\sdk\internal\internal_api.py", line 2175, in upload_urls
    query_result = self.gql(
  File "C:\Users\tyu06\anaconda3\lib\site-packages\wandb\sdk\internal\internal_api.py", line 338, in gql
    ret = self._retry_gql(
  File "C:\Users\tyu06\anaconda3\lib\site-packages\wandb\sdk\lib\retry.py", line 147, in __call__
    retry_timedelta_triggered = check_retry_fn(e)
  File "C:\Users\tyu06\anaconda3\lib\site-packages\wandb\util.py", line 906, in no_retry_auth
    raise CommError(
wandb.errors.CommError: It appears that you do not have permission to access the requested resource. Please reach out to the project owner to grant you access. If you have the correct permissions, verify that there are no issues with your networking setup.(Error 404: Not Found)
2023-10-09 19:54:48,515 DEBUG   SenderThread:15120 [sender.py:send():380] send: telemetry
2023-10-09 19:54:48,842 ERROR   gpu       :15120 [interfaces.py:monitor():144] Failed to sample metric: Not Supported
2023-10-09 19:54:48,842 ERROR   gpu       :15120 [interfaces.py:monitor():144] Failed to sample metric: Not Supported
2023-10-09 19:54:49,260 INFO    Thread-16 :15120 [dir_watcher.py:_on_file_created():271] file/dir created: D:\ETHz\Internship\adaptive-e-learning-for-educational-recommendation-system\DeepKnowledgeTracing-DKT-Pytorch\DKT\KnowledgeTracing\evaluation\wandb\run-20231009_195421-5bpask06\files\output.log
2023-10-09 19:54:50,710 ERROR   FileStreamThread:15120 [file_stream.py:_handle_response():504] dropped chunk 404 Client Error: Not Found for url: https://api.wandb.ai/files/bryant-ty/DKT-trial%201/5bpask06/file_stream
NoneType: None
2023-10-09 19:54:51,113 ERROR   gpu       :15120 [interfaces.py:monitor():144] Failed to sample metric: Not Supported
2023-10-09 19:54:51,113 ERROR   gpu       :15120 [interfaces.py:monitor():144] Failed to sample metric: Not Supported
2023-10-09 19:54:51,303 INFO    Thread-16 :15120 [dir_watcher.py:_on_file_modified():288] file/dir modified: D:\ETHz\Internship\adaptive-e-learning-for-educational-recommendation-system\DeepKnowledgeTracing-DKT-Pytorch\DKT\KnowledgeTracing\evaluation\wandb\run-20231009_195421-5bpask06\files\output.log
2023-10-09 19:54:52,305 DEBUG   HandlerThread:15120 [handler.py:handle_request():144] handle_request: status_report
2023-10-09 19:54:52,465 ERROR   SenderThread:15120 [internal_api.py:execute():369] 409 response executing GraphQL.
2023-10-09 19:54:52,465 ERROR   SenderThread:15120 [internal_api.py:execute():370] {"errors":[{"message":"run bryant-ty/DKT-trial 1/5bpask06 was previously created and deleted; try a new run name","path":["upsertBucket"]}],"data":{"upsertBucket":null}}
2023-10-09 19:54:52,664 ERROR   FileStreamThread:15120 [file_stream.py:_handle_response():504] dropped chunk 404 Client Error: Not Found for url: https://api.wandb.ai/files/bryant-ty/DKT-trial%201/5bpask06/file_stream
NoneType: None
2023-10-09 19:54:53,322 INFO    Thread-16 :15120 [dir_watcher.py:_on_file_modified():288] file/dir modified: D:\ETHz\Internship\adaptive-e-learning-for-educational-recommendation-system\DeepKnowledgeTracing-DKT-Pytorch\DKT\KnowledgeTracing\evaluation\wandb\run-20231009_195421-5bpask06\files\output.log
2023-10-09 19:54:53,385 ERROR   gpu       :15120 [interfaces.py:monitor():144] Failed to sample metric: Not Supported
2023-10-09 19:54:53,385 ERROR   gpu       :15120 [interfaces.py:monitor():144] Failed to sample metric: Not Supported
2023-10-09 19:54:53,704 ERROR   SenderThread:15120 [internal_api.py:execute():369] 409 response executing GraphQL.
2023-10-09 19:54:53,704 ERROR   SenderThread:15120 [internal_api.py:execute():370] {"errors":[{"message":"run bryant-ty/DKT-trial 1/5bpask06 was previously created and deleted; try a new run name","path":["upsertBucket"]}],"data":{"upsertBucket":null}}
2023-10-09 19:54:55,671 ERROR   gpu       :15120 [interfaces.py:monitor():144] Failed to sample metric: Not Supported
2023-10-09 19:54:55,672 ERROR   gpu       :15120 [interfaces.py:monitor():144] Failed to sample metric: Not Supported
2023-10-09 19:54:56,208 ERROR   SenderThread:15120 [internal_api.py:execute():369] 409 response executing GraphQL.
2023-10-09 19:54:56,208 ERROR   SenderThread:15120 [internal_api.py:execute():370] {"errors":[{"message":"run bryant-ty/DKT-trial 1/5bpask06 was previously created and deleted; try a new run name","path":["upsertBucket"]}],"data":{"upsertBucket":null}}
2023-10-09 19:54:56,208 INFO    SenderThread:15120 [retry.py:__call__():172] Retry attempt failed:
Traceback (most recent call last):
  File "C:\Users\tyu06\anaconda3\lib\site-packages\wandb\sdk\lib\retry.py", line 131, in __call__
    result = self._call_fn(*args, **kwargs)
  File "C:\Users\tyu06\anaconda3\lib\site-packages\wandb\sdk\internal\internal_api.py", line 366, in execute
    return self.client.execute(*args, **kwargs)  # type: ignore
  File "C:\Users\tyu06\anaconda3\lib\site-packages\wandb\vendor\gql-0.2.0\wandb_gql\client.py", line 52, in execute
    result = self._get_result(document, *args, **kwargs)
  File "C:\Users\tyu06\anaconda3\lib\site-packages\wandb\vendor\gql-0.2.0\wandb_gql\client.py", line 60, in _get_result
    return self.transport.execute(document, *args, **kwargs)
  File "C:\Users\tyu06\anaconda3\lib\site-packages\wandb\sdk\lib\gql_request.py", line 59, in execute
    request.raise_for_status()
  File "C:\Users\tyu06\anaconda3\lib\site-packages\requests\models.py", line 943, in raise_for_status
    raise HTTPError(http_error_msg, response=self)
requests.exceptions.HTTPError: 409 Client Error: Conflict for url: https://api.wandb.ai/graphql
2023-10-09 19:54:57,992 ERROR   gpu       :15120 [interfaces.py:aggregate():161] Failed to serialize metric: division by zero
2023-10-09 19:54:58,029 ERROR   gpu       :15120 [interfaces.py:monitor():144] Failed to sample metric: Not Supported
2023-10-09 19:54:58,029 ERROR   gpu       :15120 [interfaces.py:monitor():144] Failed to sample metric: Not Supported
2023-10-09 19:55:00,241 ERROR   gpu       :15120 [interfaces.py:monitor():144] Failed to sample metric: Not Supported
2023-10-09 19:55:00,241 ERROR   gpu       :15120 [interfaces.py:monitor():144] Failed to sample metric: Not Supported
2023-10-09 19:55:01,299 ERROR   SenderThread:15120 [internal_api.py:execute():369] 409 response executing GraphQL.
2023-10-09 19:55:01,299 ERROR   SenderThread:15120 [internal_api.py:execute():370] {"errors":[{"message":"run bryant-ty/DKT-trial 1/5bpask06 was previously created and deleted; try a new run name","path":["upsertBucket"]}],"data":{"upsertBucket":null}}
2023-10-09 19:55:02,276 ERROR   gpu       :15120 [interfaces.py:monitor():144] Failed to sample metric: Not Supported
2023-10-09 19:55:02,276 ERROR   gpu       :15120 [interfaces.py:monitor():144] Failed to sample metric: Not Supported
2023-10-09 19:55:03,231 DEBUG   HandlerThread:15120 [handler.py:handle_request():144] handle_request: stop_status
2023-10-09 19:55:03,244 DEBUG   HandlerThread:15120 [handler.py:handle_request():144] handle_request: internal_messages
2023-10-09 19:55:04,316 ERROR   gpu       :15120 [interfaces.py:monitor():144] Failed to sample metric: Not Supported
2023-10-09 19:55:04,316 ERROR   gpu       :15120 [interfaces.py:monitor():144] Failed to sample metric: Not Supported
2023-10-09 19:55:06,359 ERROR   gpu       :15120 [interfaces.py:monitor():144] Failed to sample metric: Not Supported
2023-10-09 19:55:06,359 ERROR   gpu       :15120 [interfaces.py:monitor():144] Failed to sample metric: Not Supported
2023-10-09 19:55:08,280 DEBUG   HandlerThread:15120 [handler.py:handle_request():144] handle_request: keepalive
2023-10-09 19:55:08,397 ERROR   gpu       :15120 [interfaces.py:monitor():144] Failed to sample metric: Not Supported
2023-10-09 19:55:08,397 ERROR   gpu       :15120 [interfaces.py:monitor():144] Failed to sample metric: Not Supported
2023-10-09 19:55:10,425 ERROR   gpu       :15120 [interfaces.py:monitor():144] Failed to sample metric: Not Supported
2023-10-09 19:55:10,426 ERROR   gpu       :15120 [interfaces.py:monitor():144] Failed to sample metric: Not Supported
2023-10-09 19:55:10,928 ERROR   SenderThread:15120 [internal_api.py:execute():369] 409 response executing GraphQL.
2023-10-09 19:55:10,929 ERROR   SenderThread:15120 [internal_api.py:execute():370] {"errors":[{"message":"run bryant-ty/DKT-trial 1/5bpask06 was previously created and deleted; try a new run name","path":["upsertBucket"]}],"data":{"upsertBucket":null}}
2023-10-09 19:55:12,452 ERROR   gpu       :15120 [interfaces.py:monitor():144] Failed to sample metric: Not Supported
2023-10-09 19:55:12,452 ERROR   gpu       :15120 [interfaces.py:monitor():144] Failed to sample metric: Not Supported
2023-10-09 19:55:13,313 DEBUG   HandlerThread:15120 [handler.py:handle_request():144] handle_request: keepalive
2023-10-09 19:55:14,488 ERROR   gpu       :15120 [interfaces.py:monitor():144] Failed to sample metric: Not Supported
2023-10-09 19:55:14,488 ERROR   gpu       :15120 [interfaces.py:monitor():144] Failed to sample metric: Not Supported
2023-10-09 19:55:16,538 ERROR   gpu       :15120 [interfaces.py:monitor():144] Failed to sample metric: Not Supported
2023-10-09 19:55:16,539 ERROR   gpu       :15120 [interfaces.py:monitor():144] Failed to sample metric: Not Supported
2023-10-09 19:55:18,247 DEBUG   HandlerThread:15120 [handler.py:handle_request():144] handle_request: internal_messages
2023-10-09 19:55:18,582 ERROR   gpu       :15120 [interfaces.py:monitor():144] Failed to sample metric: Not Supported
2023-10-09 19:55:18,583 ERROR   gpu       :15120 [interfaces.py:monitor():144] Failed to sample metric: Not Supported
2023-10-09 19:55:20,611 ERROR   gpu       :15120 [interfaces.py:monitor():144] Failed to sample metric: Not Supported
2023-10-09 19:55:20,611 ERROR   gpu       :15120 [interfaces.py:monitor():144] Failed to sample metric: Not Supported
2023-10-09 19:55:22,640 ERROR   gpu       :15120 [interfaces.py:monitor():144] Failed to sample metric: Not Supported
2023-10-09 19:55:22,640 ERROR   gpu       :15120 [interfaces.py:monitor():144] Failed to sample metric: Not Supported
2023-10-09 19:55:23,097 DEBUG   SystemMonitor:15120 [system_monitor.py:_start():159] Starting system metrics aggregation loop
2023-10-09 19:55:23,413 DEBUG   HandlerThread:15120 [handler.py:handle_request():144] handle_request: keepalive
2023-10-09 19:55:24,669 ERROR   gpu       :15120 [interfaces.py:monitor():144] Failed to sample metric: Not Supported
2023-10-09 19:55:24,669 ERROR   gpu       :15120 [interfaces.py:monitor():144] Failed to sample metric: Not Supported
2023-10-09 19:55:26,743 ERROR   gpu       :15120 [interfaces.py:monitor():144] Failed to sample metric: Not Supported
2023-10-09 19:55:26,743 ERROR   gpu       :15120 [interfaces.py:monitor():144] Failed to sample metric: Not Supported
2023-10-09 19:55:28,447 DEBUG   HandlerThread:15120 [handler.py:handle_request():144] handle_request: keepalive
2023-10-09 19:55:28,798 ERROR   gpu       :15120 [interfaces.py:aggregate():161] Failed to serialize metric: division by zero
2023-10-09 19:55:28,823 ERROR   gpu       :15120 [interfaces.py:monitor():144] Failed to sample metric: Not Supported
2023-10-09 19:55:28,823 ERROR   gpu       :15120 [interfaces.py:monitor():144] Failed to sample metric: Not Supported
2023-10-09 19:55:29,864 ERROR   SenderThread:15120 [internal_api.py:execute():369] 409 response executing GraphQL.
2023-10-09 19:55:29,864 ERROR   SenderThread:15120 [internal_api.py:execute():370] {"errors":[{"message":"run bryant-ty/DKT-trial 1/5bpask06 was previously created and deleted; try a new run name","path":["upsertBucket"]}],"data":{"upsertBucket":null}}
2023-10-09 19:55:30,856 ERROR   gpu       :15120 [interfaces.py:monitor():144] Failed to sample metric: Not Supported
2023-10-09 19:55:30,856 ERROR   gpu       :15120 [interfaces.py:monitor():144] Failed to sample metric: Not Supported
2023-10-09 19:55:32,898 ERROR   gpu       :15120 [interfaces.py:monitor():144] Failed to sample metric: Not Supported
2023-10-09 19:55:32,898 ERROR   gpu       :15120 [interfaces.py:monitor():144] Failed to sample metric: Not Supported
2023-10-09 19:55:33,250 DEBUG   HandlerThread:15120 [handler.py:handle_request():144] handle_request: internal_messages
2023-10-09 19:55:34,926 ERROR   gpu       :15120 [interfaces.py:monitor():144] Failed to sample metric: Not Supported
2023-10-09 19:55:34,926 ERROR   gpu       :15120 [interfaces.py:monitor():144] Failed to sample metric: Not Supported
2023-10-09 19:55:36,961 ERROR   gpu       :15120 [interfaces.py:monitor():144] Failed to sample metric: Not Supported
2023-10-09 19:55:36,961 ERROR   gpu       :15120 [interfaces.py:monitor():144] Failed to sample metric: Not Supported
2023-10-09 19:55:38,542 DEBUG   HandlerThread:15120 [handler.py:handle_request():144] handle_request: keepalive
2023-10-09 19:55:38,991 ERROR   gpu       :15120 [interfaces.py:monitor():144] Failed to sample metric: Not Supported
2023-10-09 19:55:38,992 ERROR   gpu       :15120 [interfaces.py:monitor():144] Failed to sample metric: Not Supported
2023-10-09 19:55:41,022 ERROR   gpu       :15120 [interfaces.py:monitor():144] Failed to sample metric: Not Supported
2023-10-09 19:55:41,022 ERROR   gpu       :15120 [interfaces.py:monitor():144] Failed to sample metric: Not Supported
2023-10-09 19:55:43,053 ERROR   gpu       :15120 [interfaces.py:monitor():144] Failed to sample metric: Not Supported
2023-10-09 19:55:43,053 ERROR   gpu       :15120 [interfaces.py:monitor():144] Failed to sample metric: Not Supported
2023-10-09 19:55:43,604 DEBUG   HandlerThread:15120 [handler.py:handle_request():144] handle_request: keepalive
2023-10-09 19:55:45,078 ERROR   gpu       :15120 [interfaces.py:monitor():144] Failed to sample metric: Not Supported
2023-10-09 19:55:45,078 ERROR   gpu       :15120 [interfaces.py:monitor():144] Failed to sample metric: Not Supported
2023-10-09 19:55:47,107 ERROR   gpu       :15120 [interfaces.py:monitor():144] Failed to sample metric: Not Supported
2023-10-09 19:55:47,107 ERROR   gpu       :15120 [interfaces.py:monitor():144] Failed to sample metric: Not Supported
2023-10-09 19:55:48,255 DEBUG   HandlerThread:15120 [handler.py:handle_request():144] handle_request: internal_messages
2023-10-09 19:55:49,151 ERROR   gpu       :15120 [interfaces.py:monitor():144] Failed to sample metric: Not Supported
2023-10-09 19:55:49,151 ERROR   gpu       :15120 [interfaces.py:monitor():144] Failed to sample metric: Not Supported
2023-10-09 19:55:51,180 ERROR   gpu       :15120 [interfaces.py:monitor():144] Failed to sample metric: Not Supported
2023-10-09 19:55:51,180 ERROR   gpu       :15120 [interfaces.py:monitor():144] Failed to sample metric: Not Supported
2023-10-09 19:55:53,216 ERROR   gpu       :15120 [interfaces.py:monitor():144] Failed to sample metric: Not Supported
2023-10-09 19:55:53,216 ERROR   gpu       :15120 [interfaces.py:monitor():144] Failed to sample metric: Not Supported
2023-10-09 19:55:53,707 DEBUG   HandlerThread:15120 [handler.py:handle_request():144] handle_request: keepalive
2023-10-09 19:55:55,250 ERROR   gpu       :15120 [interfaces.py:monitor():144] Failed to sample metric: Not Supported
2023-10-09 19:55:55,251 ERROR   gpu       :15120 [interfaces.py:monitor():144] Failed to sample metric: Not Supported
2023-10-09 19:55:57,295 ERROR   gpu       :15120 [interfaces.py:monitor():144] Failed to sample metric: Not Supported
2023-10-09 19:55:57,295 ERROR   gpu       :15120 [interfaces.py:monitor():144] Failed to sample metric: Not Supported
2023-10-09 19:55:58,770 DEBUG   HandlerThread:15120 [handler.py:handle_request():144] handle_request: keepalive
2023-10-09 19:55:59,351 ERROR   gpu       :15120 [interfaces.py:aggregate():161] Failed to serialize metric: division by zero
2023-10-09 19:55:59,377 ERROR   gpu       :15120 [interfaces.py:monitor():144] Failed to sample metric: Not Supported
2023-10-09 19:55:59,377 ERROR   gpu       :15120 [interfaces.py:monitor():144] Failed to sample metric: Not Supported
2023-10-09 19:56:01,422 ERROR   gpu       :15120 [interfaces.py:monitor():144] Failed to sample metric: Not Supported
2023-10-09 19:56:01,422 ERROR   gpu       :15120 [interfaces.py:monitor():144] Failed to sample metric: Not Supported
2023-10-09 19:56:03,264 DEBUG   HandlerThread:15120 [handler.py:handle_request():144] handle_request: internal_messages
2023-10-09 19:56:03,460 ERROR   gpu       :15120 [interfaces.py:monitor():144] Failed to sample metric: Not Supported
2023-10-09 19:56:03,460 ERROR   gpu       :15120 [interfaces.py:monitor():144] Failed to sample metric: Not Supported
2023-10-09 19:56:05,496 ERROR   gpu       :15120 [interfaces.py:monitor():144] Failed to sample metric: Not Supported
2023-10-09 19:56:05,497 ERROR   gpu       :15120 [interfaces.py:monitor():144] Failed to sample metric: Not Supported
2023-10-09 19:56:07,522 ERROR   SenderThread:15120 [internal_api.py:execute():369] 409 response executing GraphQL.
2023-10-09 19:56:07,522 ERROR   SenderThread:15120 [internal_api.py:execute():370] {"errors":[{"message":"run bryant-ty/DKT-trial 1/5bpask06 was previously created and deleted; try a new run name","path":["upsertBucket"]}],"data":{"upsertBucket":null}}
2023-10-09 19:56:07,548 ERROR   gpu       :15120 [interfaces.py:monitor():144] Failed to sample metric: Not Supported
2023-10-09 19:56:07,548 ERROR   gpu       :15120 [interfaces.py:monitor():144] Failed to sample metric: Not Supported
2023-10-09 19:56:08,855 DEBUG   HandlerThread:15120 [handler.py:handle_request():144] handle_request: keepalive
2023-10-09 19:56:09,615 ERROR   gpu       :15120 [interfaces.py:monitor():144] Failed to sample metric: Not Supported
2023-10-09 19:56:09,615 ERROR   gpu       :15120 [interfaces.py:monitor():144] Failed to sample metric: Not Supported
2023-10-09 19:56:11,653 ERROR   gpu       :15120 [interfaces.py:monitor():144] Failed to sample metric: Not Supported
2023-10-09 19:56:11,653 ERROR   gpu       :15120 [interfaces.py:monitor():144] Failed to sample metric: Not Supported
2023-10-09 19:56:13,685 ERROR   gpu       :15120 [interfaces.py:monitor():144] Failed to sample metric: Not Supported
2023-10-09 19:56:13,685 ERROR   gpu       :15120 [interfaces.py:monitor():144] Failed to sample metric: Not Supported
2023-10-09 19:56:13,927 DEBUG   HandlerThread:15120 [handler.py:handle_request():144] handle_request: keepalive
2023-10-09 19:56:15,721 ERROR   gpu       :15120 [interfaces.py:monitor():144] Failed to sample metric: Not Supported
2023-10-09 19:56:15,722 ERROR   gpu       :15120 [interfaces.py:monitor():144] Failed to sample metric: Not Supported
2023-10-09 19:56:17,749 ERROR   gpu       :15120 [interfaces.py:monitor():144] Failed to sample metric: Not Supported
2023-10-09 19:56:17,749 ERROR   gpu       :15120 [interfaces.py:monitor():144] Failed to sample metric: Not Supported
2023-10-09 19:56:18,272 DEBUG   HandlerThread:15120 [handler.py:handle_request():144] handle_request: internal_messages
2023-10-09 19:56:19,780 ERROR   gpu       :15120 [interfaces.py:monitor():144] Failed to sample metric: Not Supported
2023-10-09 19:56:19,780 ERROR   gpu       :15120 [interfaces.py:monitor():144] Failed to sample metric: Not Supported
2023-10-09 19:56:21,815 ERROR   gpu       :15120 [interfaces.py:monitor():144] Failed to sample metric: Not Supported
2023-10-09 19:56:21,816 ERROR   gpu       :15120 [interfaces.py:monitor():144] Failed to sample metric: Not Supported
2023-10-09 19:56:23,845 ERROR   gpu       :15120 [interfaces.py:monitor():144] Failed to sample metric: Not Supported
2023-10-09 19:56:23,846 ERROR   gpu       :15120 [interfaces.py:monitor():144] Failed to sample metric: Not Supported
2023-10-09 19:56:23,998 DEBUG   HandlerThread:15120 [handler.py:handle_request():144] handle_request: keepalive
2023-10-09 19:56:25,883 ERROR   gpu       :15120 [interfaces.py:monitor():144] Failed to sample metric: Not Supported
2023-10-09 19:56:25,884 ERROR   gpu       :15120 [interfaces.py:monitor():144] Failed to sample metric: Not Supported
2023-10-09 19:56:27,913 ERROR   gpu       :15120 [interfaces.py:monitor():144] Failed to sample metric: Not Supported
2023-10-09 19:56:27,913 ERROR   gpu       :15120 [interfaces.py:monitor():144] Failed to sample metric: Not Supported
2023-10-09 19:56:29,037 DEBUG   HandlerThread:15120 [handler.py:handle_request():144] handle_request: keepalive
2023-10-09 19:56:29,954 ERROR   gpu       :15120 [interfaces.py:aggregate():161] Failed to serialize metric: division by zero
2023-10-09 19:56:29,977 ERROR   gpu       :15120 [interfaces.py:monitor():144] Failed to sample metric: Not Supported
2023-10-09 19:56:29,977 ERROR   gpu       :15120 [interfaces.py:monitor():144] Failed to sample metric: Not Supported
2023-10-09 19:56:32,009 ERROR   gpu       :15120 [interfaces.py:monitor():144] Failed to sample metric: Not Supported
2023-10-09 19:56:32,009 ERROR   gpu       :15120 [interfaces.py:monitor():144] Failed to sample metric: Not Supported
2023-10-09 19:56:33,279 DEBUG   HandlerThread:15120 [handler.py:handle_request():144] handle_request: internal_messages
2023-10-09 19:56:34,030 ERROR   gpu       :15120 [interfaces.py:monitor():144] Failed to sample metric: Not Supported
2023-10-09 19:56:34,030 ERROR   gpu       :15120 [interfaces.py:monitor():144] Failed to sample metric: Not Supported
2023-10-09 19:56:36,055 ERROR   gpu       :15120 [interfaces.py:monitor():144] Failed to sample metric: Not Supported
2023-10-09 19:56:36,055 ERROR   gpu       :15120 [interfaces.py:monitor():144] Failed to sample metric: Not Supported
2023-10-09 19:56:38,087 ERROR   gpu       :15120 [interfaces.py:monitor():144] Failed to sample metric: Not Supported
2023-10-09 19:56:38,088 ERROR   gpu       :15120 [interfaces.py:monitor():144] Failed to sample metric: Not Supported
2023-10-09 19:56:39,125 DEBUG   HandlerThread:15120 [handler.py:handle_request():144] handle_request: keepalive
2023-10-09 19:56:40,110 ERROR   gpu       :15120 [interfaces.py:monitor():144] Failed to sample metric: Not Supported
2023-10-09 19:56:40,110 ERROR   gpu       :15120 [interfaces.py:monitor():144] Failed to sample metric: Not Supported
2023-10-09 19:56:42,132 ERROR   gpu       :15120 [interfaces.py:monitor():144] Failed to sample metric: Not Supported
2023-10-09 19:56:42,133 ERROR   gpu       :15120 [interfaces.py:monitor():144] Failed to sample metric: Not Supported
2023-10-09 19:56:44,162 ERROR   gpu       :15120 [interfaces.py:monitor():144] Failed to sample metric: Not Supported
2023-10-09 19:56:44,162 ERROR   gpu       :15120 [interfaces.py:monitor():144] Failed to sample metric: Not Supported
2023-10-09 19:56:44,168 DEBUG   HandlerThread:15120 [handler.py:handle_request():144] handle_request: keepalive
2023-10-09 19:56:46,193 ERROR   gpu       :15120 [interfaces.py:monitor():144] Failed to sample metric: Not Supported
2023-10-09 19:56:46,194 ERROR   gpu       :15120 [interfaces.py:monitor():144] Failed to sample metric: Not Supported
2023-10-09 19:56:48,217 ERROR   gpu       :15120 [interfaces.py:monitor():144] Failed to sample metric: Not Supported
2023-10-09 19:56:48,218 ERROR   gpu       :15120 [interfaces.py:monitor():144] Failed to sample metric: Not Supported
2023-10-09 19:56:48,292 DEBUG   HandlerThread:15120 [handler.py:handle_request():144] handle_request: internal_messages
2023-10-09 19:56:50,323 ERROR   gpu       :15120 [interfaces.py:monitor():144] Failed to sample metric: Not Supported
2023-10-09 19:56:50,324 ERROR   gpu       :15120 [interfaces.py:monitor():144] Failed to sample metric: Not Supported
2023-10-09 19:56:52,359 ERROR   gpu       :15120 [interfaces.py:monitor():144] Failed to sample metric: Not Supported
2023-10-09 19:56:52,359 ERROR   gpu       :15120 [interfaces.py:monitor():144] Failed to sample metric: Not Supported
2023-10-09 19:56:53,302 DEBUG   HandlerThread:15120 [handler.py:handle_request():144] handle_request: keepalive
2023-10-09 19:56:54,388 ERROR   gpu       :15120 [interfaces.py:monitor():144] Failed to sample metric: Not Supported
2023-10-09 19:56:54,389 ERROR   gpu       :15120 [interfaces.py:monitor():144] Failed to sample metric: Not Supported
2023-10-09 19:56:56,420 ERROR   gpu       :15120 [interfaces.py:monitor():144] Failed to sample metric: Not Supported
2023-10-09 19:56:56,420 ERROR   gpu       :15120 [interfaces.py:monitor():144] Failed to sample metric: Not Supported
2023-10-09 19:56:58,342 DEBUG   HandlerThread:15120 [handler.py:handle_request():144] handle_request: keepalive
2023-10-09 19:56:58,457 ERROR   gpu       :15120 [interfaces.py:monitor():144] Failed to sample metric: Not Supported
2023-10-09 19:56:58,458 ERROR   gpu       :15120 [interfaces.py:monitor():144] Failed to sample metric: Not Supported
2023-10-09 19:57:00,510 ERROR   gpu       :15120 [interfaces.py:aggregate():161] Failed to serialize metric: division by zero
2023-10-09 19:57:00,536 ERROR   gpu       :15120 [interfaces.py:monitor():144] Failed to sample metric: Not Supported
2023-10-09 19:57:00,536 ERROR   gpu       :15120 [interfaces.py:monitor():144] Failed to sample metric: Not Supported
2023-10-09 19:57:00,955 DEBUG   HandlerThread:15120 [handler.py:handle_request():144] handle_request: poll_exit
2023-10-09 19:57:01,844 INFO    memory    :15120 [interfaces.py:monitor():140] Process proc.memory.rssMB has exited.
2023-10-09 19:57:01,844 DEBUG   SystemMonitor:15120 [system_monitor.py:_start():166] Finished system metrics aggregation loop
2023-10-09 19:57:01,845 DEBUG   SystemMonitor:15120 [system_monitor.py:_start():170] Publishing last batch of metrics
2023-10-09 19:57:01,876 ERROR   gpu       :15120 [interfaces.py:aggregate():161] Failed to serialize metric: division by zero
2023-10-09 19:57:04,160 WARNING StreamThr :15120 [internal.py:is_dead():414] Internal process exiting, parent pid 32284 disappeared
2023-10-09 19:57:04,160 ERROR   StreamThr :15120 [internal.py:wandb_internal():152] Internal process shutdown.
2023-10-09 19:57:04,890 INFO    HandlerThread:15120 [handler.py:finish():844] shutting down handler
2023-10-09 19:57:04,890 INFO    WriterThread:15120 [datastore.py:close():294] close: D:\ETHz\Internship\adaptive-e-learning-for-educational-recommendation-system\DeepKnowledgeTracing-DKT-Pytorch\DKT\KnowledgeTracing\evaluation\wandb\run-20231009_195421-5bpask06\run-5bpask06.wandb
2023-10-09 19:57:04,890 INFO    HandlerThread:15120 [system_monitor.py:finish():190] Stopping system monitor
2023-10-09 19:57:04,890 INFO    HandlerThread:15120 [interfaces.py:finish():202] Joined cpu monitor
2023-10-09 19:57:04,891 INFO    HandlerThread:15120 [interfaces.py:finish():202] Joined disk monitor
2023-10-09 19:57:04,891 INFO    HandlerThread:15120 [interfaces.py:finish():202] Joined gpu monitor
2023-10-09 19:57:04,891 INFO    HandlerThread:15120 [interfaces.py:finish():202] Joined memory monitor
2023-10-09 19:57:04,892 INFO    HandlerThread:15120 [interfaces.py:finish():202] Joined network monitor
2023-10-09 19:57:26,621 ERROR   SenderThread:15120 [internal_api.py:execute():369] 409 response executing GraphQL.
2023-10-09 19:57:26,621 ERROR   SenderThread:15120 [internal_api.py:execute():370] {"errors":[{"message":"run bryant-ty/DKT-trial 1/5bpask06 was previously created and deleted; try a new run name","path":["upsertBucket"]}],"data":{"upsertBucket":null}}
2023-10-09 19:57:26,621 ERROR   StreamThr :15120 [internal.py:wandb_internal():174] Thread SenderThread:
Traceback (most recent call last):
  File "C:\Users\tyu06\anaconda3\lib\site-packages\wandb\sdk\internal\internal_api.py", line 366, in execute
    return self.client.execute(*args, **kwargs)  # type: ignore
  File "C:\Users\tyu06\anaconda3\lib\site-packages\wandb\vendor\gql-0.2.0\wandb_gql\client.py", line 52, in execute
    result = self._get_result(document, *args, **kwargs)
  File "C:\Users\tyu06\anaconda3\lib\site-packages\wandb\vendor\gql-0.2.0\wandb_gql\client.py", line 60, in _get_result
    return self.transport.execute(document, *args, **kwargs)
  File "C:\Users\tyu06\anaconda3\lib\site-packages\wandb\sdk\lib\gql_request.py", line 59, in execute
    request.raise_for_status()
  File "C:\Users\tyu06\anaconda3\lib\site-packages\requests\models.py", line 943, in raise_for_status
    raise HTTPError(http_error_msg, response=self)
requests.exceptions.HTTPError: 409 Client Error: Conflict for url: https://api.wandb.ai/graphql

During handling of the above exception, another exception occurred:

Traceback (most recent call last):
  File "C:\Users\tyu06\anaconda3\lib\site-packages\wandb\apis\normalize.py", line 41, in wrapper
    return func(*args, **kwargs)
  File "C:\Users\tyu06\anaconda3\lib\site-packages\wandb\sdk\internal\internal_api.py", line 2007, in upsert_run
    response = self.gql(
  File "C:\Users\tyu06\anaconda3\lib\site-packages\wandb\sdk\internal\internal_api.py", line 338, in gql
    ret = self._retry_gql(
  File "C:\Users\tyu06\anaconda3\lib\site-packages\wandb\sdk\lib\retry.py", line 131, in __call__
    result = self._call_fn(*args, **kwargs)
  File "C:\Users\tyu06\anaconda3\lib\site-packages\wandb\sdk\internal\internal_api.py", line 372, in execute
    wandb.termerror(f"Error while calling W&B API: {error} ({response})")
  File "C:\Users\tyu06\anaconda3\lib\site-packages\wandb\errors\term.py", line 61, in termerror
    _log(
  File "C:\Users\tyu06\anaconda3\lib\site-packages\wandb\errors\term.py", line 95, in _log
    click.echo(line, file=sys.stderr, nl=newline)
  File "C:\Users\tyu06\anaconda3\lib\site-packages\click\utils.py", line 272, in echo
    file.write(message)
OSError: [Errno 22] Invalid argument

During handling of the above exception, another exception occurred:

Traceback (most recent call last):
  File "C:\Users\tyu06\anaconda3\lib\site-packages\wandb\sdk\internal\internal_util.py", line 49, in run
    self._run()
  File "C:\Users\tyu06\anaconda3\lib\site-packages\wandb\sdk\internal\internal_util.py", line 93, in _run
    self._debounce()
  File "C:\Users\tyu06\anaconda3\lib\site-packages\wandb\sdk\internal\internal.py", line 334, in _debounce
    self._sm.debounce()
  File "C:\Users\tyu06\anaconda3\lib\site-packages\wandb\sdk\internal\sender.py", line 538, in debounce
    self._maybe_update_config(always=final)
  File "C:\Users\tyu06\anaconda3\lib\site-packages\wandb\sdk\internal\sender.py", line 515, in _maybe_update_config
    self._debounce_config()
  File "C:\Users\tyu06\anaconda3\lib\site-packages\wandb\sdk\internal\sender.py", line 544, in _debounce_config
    self._api.upsert_run(
  File "C:\Users\tyu06\anaconda3\lib\site-packages\wandb\apis\normalize.py", line 87, in wrapper
    raise CommError(message, err).with_traceback(sys.exc_info()[2])
  File "C:\Users\tyu06\anaconda3\lib\site-packages\wandb\apis\normalize.py", line 41, in wrapper
    return func(*args, **kwargs)
  File "C:\Users\tyu06\anaconda3\lib\site-packages\wandb\sdk\internal\internal_api.py", line 2007, in upsert_run
    response = self.gql(
  File "C:\Users\tyu06\anaconda3\lib\site-packages\wandb\sdk\internal\internal_api.py", line 338, in gql
    ret = self._retry_gql(
  File "C:\Users\tyu06\anaconda3\lib\site-packages\wandb\sdk\lib\retry.py", line 131, in __call__
    result = self._call_fn(*args, **kwargs)
  File "C:\Users\tyu06\anaconda3\lib\site-packages\wandb\sdk\internal\internal_api.py", line 372, in execute
    wandb.termerror(f"Error while calling W&B API: {error} ({response})")
  File "C:\Users\tyu06\anaconda3\lib\site-packages\wandb\errors\term.py", line 61, in termerror
    _log(
  File "C:\Users\tyu06\anaconda3\lib\site-packages\wandb\errors\term.py", line 95, in _log
    click.echo(line, file=sys.stderr, nl=newline)
  File "C:\Users\tyu06\anaconda3\lib\site-packages\click\utils.py", line 272, in echo
    file.write(message)
wandb.errors.CommError: [Errno 22] Invalid argument
2023-10-09 20:24:33,682 WARNING FileStreamThread:15120 [file_stream.py:request_with_retry():668] requests_with_retry encountered retryable exception: HTTPSConnectionPool(host='api.wandb.ai', port=443): Max retries exceeded with url: /files/bryant-ty/DKT-trial%201/5bpask06/file_stream (Caused by NewConnectionError('<urllib3.connection.HTTPSConnection object at 0x00000210FF460070>: Failed to establish a new connection: [Errno 11001] getaddrinfo failed')). func: functools.partial(<bound method Session.post of <requests.sessions.Session object at 0x00000210FBEF7730>>, timeout=180), args: ('https://api.wandb.ai/files/bryant-ty/DKT-trial 1/5bpask06/file_stream',), kwargs: {'json': {'complete': False, 'failed': False, 'dropped': 2, 'uploaded': []}}
2023-10-09 20:24:35,760 WARNING FileStreamThread:15120 [file_stream.py:request_with_retry():668] requests_with_retry encountered retryable exception: HTTPSConnectionPool(host='api.wandb.ai', port=443): Max retries exceeded with url: /files/bryant-ty/DKT-trial%201/5bpask06/file_stream (Caused by NewConnectionError('<urllib3.connection.HTTPSConnection object at 0x00000210FF797B50>: Failed to establish a new connection: [Errno 11001] getaddrinfo failed')). func: functools.partial(<bound method Session.post of <requests.sessions.Session object at 0x00000210FBEF7730>>, timeout=180), args: ('https://api.wandb.ai/files/bryant-ty/DKT-trial 1/5bpask06/file_stream',), kwargs: {'json': {'complete': False, 'failed': False, 'dropped': 2, 'uploaded': []}}
2023-10-09 20:24:40,679 WARNING FileStreamThread:15120 [file_stream.py:request_with_retry():668] requests_with_retry encountered retryable exception: HTTPSConnectionPool(host='api.wandb.ai', port=443): Max retries exceeded with url: /files/bryant-ty/DKT-trial%201/5bpask06/file_stream (Caused by NewConnectionError('<urllib3.connection.HTTPSConnection object at 0x00000210FF783F40>: Failed to establish a new connection: [Errno 11001] getaddrinfo failed')). func: functools.partial(<bound method Session.post of <requests.sessions.Session object at 0x00000210FBEF7730>>, timeout=180), args: ('https://api.wandb.ai/files/bryant-ty/DKT-trial 1/5bpask06/file_stream',), kwargs: {'json': {'complete': False, 'failed': False, 'dropped': 2, 'uploaded': []}}
2023-10-09 20:24:49,940 WARNING FileStreamThread:15120 [file_stream.py:request_with_retry():668] requests_with_retry encountered retryable exception: HTTPSConnectionPool(host='api.wandb.ai', port=443): Max retries exceeded with url: /files/bryant-ty/DKT-trial%201/5bpask06/file_stream (Caused by NewConnectionError('<urllib3.connection.HTTPSConnection object at 0x00000210FF79E640>: Failed to establish a new connection: [Errno 11001] getaddrinfo failed')). func: functools.partial(<bound method Session.post of <requests.sessions.Session object at 0x00000210FBEF7730>>, timeout=180), args: ('https://api.wandb.ai/files/bryant-ty/DKT-trial 1/5bpask06/file_stream',), kwargs: {'json': {'complete': False, 'failed': False, 'dropped': 2, 'uploaded': []}}
2023-10-09 20:25:07,425 WARNING FileStreamThread:15120 [file_stream.py:request_with_retry():668] requests_with_retry encountered retryable exception: HTTPSConnectionPool(host='api.wandb.ai', port=443): Max retries exceeded with url: /files/bryant-ty/DKT-trial%201/5bpask06/file_stream (Caused by NewConnectionError('<urllib3.connection.HTTPSConnection object at 0x00000210FF7B5E80>: Failed to establish a new connection: [Errno 11001] getaddrinfo failed')). func: functools.partial(<bound method Session.post of <requests.sessions.Session object at 0x00000210FBEF7730>>, timeout=180), args: ('https://api.wandb.ai/files/bryant-ty/DKT-trial 1/5bpask06/file_stream',), kwargs: {'json': {'complete': False, 'failed': False, 'dropped': 2, 'uploaded': []}}
