2023-12-08 20:20:57,332 INFO    StreamThr :27837 [internal.py:wandb_internal():86] W&B internal server running at pid: 27837, started at: 2023-12-08 20:20:57.330837
2023-12-08 20:20:57,333 DEBUG   HandlerThread:27837 [handler.py:handle_request():146] handle_request: status
2023-12-08 20:20:57,337 INFO    WriterThread:27837 [datastore.py:open_for_write():85] open: /cluster/home/yutang/Deep-Knowledge-Tracing/DKT/KnowledgeTracing/evaluation/wandb/run-20231208_202057-c30p1g8z/run-c30p1g8z.wandb
2023-12-08 20:20:57,338 DEBUG   SenderThread:27837 [sender.py:send():380] send: header
2023-12-08 20:20:57,364 DEBUG   SenderThread:27837 [sender.py:send():380] send: run
2023-12-08 20:20:57,792 INFO    SenderThread:27837 [dir_watcher.py:__init__():211] watching files in: /cluster/home/yutang/Deep-Knowledge-Tracing/DKT/KnowledgeTracing/evaluation/wandb/run-20231208_202057-c30p1g8z/files
2023-12-08 20:20:57,792 INFO    SenderThread:27837 [sender.py:_start_run_threads():1122] run started: c30p1g8z with start time 1702063257.332266
2023-12-08 20:20:57,796 DEBUG   HandlerThread:27837 [handler.py:handle_request():146] handle_request: check_version
2023-12-08 20:20:57,797 DEBUG   SenderThread:27837 [sender.py:send_request():407] send_request: check_version
2023-12-08 20:20:57,864 DEBUG   HandlerThread:27837 [handler.py:handle_request():146] handle_request: run_start
2023-12-08 20:20:57,875 DEBUG   HandlerThread:27837 [system_info.py:__init__():32] System info init
2023-12-08 20:20:57,875 DEBUG   HandlerThread:27837 [system_info.py:__init__():47] System info init done
2023-12-08 20:20:57,875 INFO    HandlerThread:27837 [system_monitor.py:start():194] Starting system monitor
2023-12-08 20:20:57,875 INFO    SystemMonitor:27837 [system_monitor.py:_start():158] Starting system asset monitoring threads
2023-12-08 20:20:57,875 INFO    HandlerThread:27837 [system_monitor.py:probe():214] Collecting system info
2023-12-08 20:20:57,878 INFO    SystemMonitor:27837 [interfaces.py:start():190] Started cpu monitoring
2023-12-08 20:20:57,878 INFO    SystemMonitor:27837 [interfaces.py:start():190] Started disk monitoring
2023-12-08 20:20:57,879 INFO    SystemMonitor:27837 [interfaces.py:start():190] Started gpu monitoring
2023-12-08 20:20:57,882 INFO    SystemMonitor:27837 [interfaces.py:start():190] Started memory monitoring
2023-12-08 20:20:57,883 INFO    SystemMonitor:27837 [interfaces.py:start():190] Started network monitoring
2023-12-08 20:20:57,920 DEBUG   HandlerThread:27837 [system_info.py:probe():196] Probing system
2023-12-08 20:20:57,926 DEBUG   HandlerThread:27837 [system_info.py:_probe_git():181] Probing git
2023-12-08 20:20:57,946 DEBUG   HandlerThread:27837 [system_info.py:_probe_git():189] Probing git done
2023-12-08 20:20:57,946 DEBUG   HandlerThread:27837 [system_info.py:probe():244] Probing system done
2023-12-08 20:20:57,946 DEBUG   HandlerThread:27837 [system_monitor.py:probe():223] {'os': 'Linux-3.10.0-1160.102.1.el7.x86_64-x86_64-with-glibc2.17', 'python': '3.9.16', 'heartbeatAt': '2023-12-08T19:20:57.920759', 'startedAt': '2023-12-08T19:20:57.317836', 'docker': None, 'cuda': None, 'args': (), 'state': 'running', 'program': '/cluster/home/yutang/Deep-Knowledge-Tracing/DKT/KnowledgeTracing/evaluation/./run.py', 'codePathLocal': 'run.py', 'codePath': 'DKT/KnowledgeTracing/evaluation/run.py', 'git': {'remote': 'https://github.com/Bryanttt-tang/Deep-Knowledge-Tracing.git', 'commit': '124d101f598db85f1193fc0ebb309f96ee5f8b75'}, 'email': 'tangyu990628@gmail.com', 'root': '/cluster/home/yutang/Deep-Knowledge-Tracing', 'host': 'eu-g4-001', 'username': 'yutang', 'executable': '/cluster/home/yutang/miniconda3/bin/python', 'cpu_count': 128, 'cpu_count_logical': 128, 'cpu_freq': {'current': 1617.1875, 'min': 1500.0, 'max': 2250.0}, 'cpu_freq_per_core': [{'current': 2250.0, 'min': 1500.0, 'max': 2250.0}, {'current': 2000.0, 'min': 1500.0, 'max': 2250.0}, {'current': 2000.0, 'min': 1500.0, 'max': 2250.0}, {'current': 2250.0, 'min': 1500.0, 'max': 2250.0}, {'current': 2250.0, 'min': 1500.0, 'max': 2250.0}, {'current': 2250.0, 'min': 1500.0, 'max': 2250.0}, {'current': 2000.0, 'min': 1500.0, 'max': 2250.0}, {'current': 1500.0, 'min': 1500.0, 'max': 2250.0}, {'current': 1500.0, 'min': 1500.0, 'max': 2250.0}, {'current': 2250.0, 'min': 1500.0, 'max': 2250.0}, {'current': 2250.0, 'min': 1500.0, 'max': 2250.0}, {'current': 2250.0, 'min': 1500.0, 'max': 2250.0}, {'current': 1500.0, 'min': 1500.0, 'max': 2250.0}, {'current': 1500.0, 'min': 1500.0, 'max': 2250.0}, {'current': 1500.0, 'min': 1500.0, 'max': 2250.0}, {'current': 2250.0, 'min': 1500.0, 'max': 2250.0}, {'current': 1500.0, 'min': 1500.0, 'max': 2250.0}, {'current': 1500.0, 'min': 1500.0, 'max': 2250.0}, {'current': 1500.0, 'min': 1500.0, 'max': 2250.0}, {'current': 1500.0, 'min': 1500.0, 'max': 2250.0}, {'current': 1500.0, 'min': 1500.0, 'max': 2250.0}, {'current': 1500.0, 'min': 1500.0, 'max': 2250.0}, {'current': 1500.0, 'min': 1500.0, 'max': 2250.0}, {'current': 1500.0, 'min': 1500.0, 'max': 2250.0}, {'current': 1500.0, 'min': 1500.0, 'max': 2250.0}, {'current': 1500.0, 'min': 1500.0, 'max': 2250.0}, {'current': 1500.0, 'min': 1500.0, 'max': 2250.0}, {'current': 1500.0, 'min': 1500.0, 'max': 2250.0}, {'current': 1500.0, 'min': 1500.0, 'max': 2250.0}, {'current': 1500.0, 'min': 1500.0, 'max': 2250.0}, {'current': 1500.0, 'min': 1500.0, 'max': 2250.0}, {'current': 1500.0, 'min': 1500.0, 'max': 2250.0}, {'current': 1500.0, 'min': 1500.0, 'max': 2250.0}, {'current': 1500.0, 'min': 1500.0, 'max': 2250.0}, {'current': 1500.0, 'min': 1500.0, 'max': 2250.0}, {'current': 1500.0, 'min': 1500.0, 'max': 2250.0}, {'current': 1500.0, 'min': 1500.0, 'max': 2250.0}, {'current': 1500.0, 'min': 1500.0, 'max': 2250.0}, {'current': 1500.0, 'min': 1500.0, 'max': 2250.0}, {'current': 1500.0, 'min': 1500.0, 'max': 2250.0}, {'current': 1500.0, 'min': 1500.0, 'max': 2250.0}, {'current': 1500.0, 'min': 1500.0, 'max': 2250.0}, {'current': 1500.0, 'min': 1500.0, 'max': 2250.0}, {'current': 1500.0, 'min': 1500.0, 'max': 2250.0}, {'current': 1500.0, 'min': 1500.0, 'max': 2250.0}, {'current': 1500.0, 'min': 1500.0, 'max': 2250.0}, {'current': 1500.0, 'min': 1500.0, 'max': 2250.0}, {'current': 1500.0, 'min': 1500.0, 'max': 2250.0}, {'current': 1500.0, 'min': 1500.0, 'max': 2250.0}, {'current': 1500.0, 'min': 1500.0, 'max': 2250.0}, {'current': 1500.0, 'min': 1500.0, 'max': 2250.0}, {'current': 1500.0, 'min': 1500.0, 'max': 2250.0}, {'current': 1500.0, 'min': 1500.0, 'max': 2250.0}, {'current': 1500.0, 'min': 1500.0, 'max': 2250.0}, {'current': 1500.0, 'min': 1500.0, 'max': 2250.0}, {'current': 1500.0, 'min': 1500.0, 'max': 2250.0}, {'current': 2250.0, 'min': 1500.0, 'max': 2250.0}, {'current': 1500.0, 'min': 1500.0, 'max': 2250.0}, {'current': 1500.0, 'min': 1500.0, 'max': 2250.0}, {'current': 2000.0, 'min': 1500.0, 'max': 2250.0}, {'current': 1500.0, 'min': 1500.0, 'max': 2250.0}, {'current': 1500.0, 'min': 1500.0, 'max': 2250.0}, {'current': 1500.0, 'min': 1500.0, 'max': 2250.0}, {'current': 1500.0, 'min': 1500.0, 'max': 2250.0}, {'current': 1500.0, 'min': 1500.0, 'max': 2250.0}, {'current': 2250.0, 'min': 1500.0, 'max': 2250.0}, {'current': 1500.0, 'min': 1500.0, 'max': 2250.0}, {'current': 1500.0, 'min': 1500.0, 'max': 2250.0}, {'current': 1500.0, 'min': 1500.0, 'max': 2250.0}, {'current': 1500.0, 'min': 1500.0, 'max': 2250.0}, {'current': 1500.0, 'min': 1500.0, 'max': 2250.0}, {'current': 1500.0, 'min': 1500.0, 'max': 2250.0}, {'current': 1500.0, 'min': 1500.0, 'max': 2250.0}, {'current': 1500.0, 'min': 1500.0, 'max': 2250.0}, {'current': 1500.0, 'min': 1500.0, 'max': 2250.0}, {'current': 1500.0, 'min': 1500.0, 'max': 2250.0}, {'current': 1500.0, 'min': 1500.0, 'max': 2250.0}, {'current': 1500.0, 'min': 1500.0, 'max': 2250.0}, {'current': 1500.0, 'min': 1500.0, 'max': 2250.0}, {'current': 1500.0, 'min': 1500.0, 'max': 2250.0}, {'current': 1500.0, 'min': 1500.0, 'max': 2250.0}, {'current': 1500.0, 'min': 1500.0, 'max': 2250.0}, {'current': 1500.0, 'min': 1500.0, 'max': 2250.0}, {'current': 1500.0, 'min': 1500.0, 'max': 2250.0}, {'current': 2250.0, 'min': 1500.0, 'max': 2250.0}, {'current': 1500.0, 'min': 1500.0, 'max': 2250.0}, {'current': 2250.0, 'min': 1500.0, 'max': 2250.0}, {'current': 2250.0, 'min': 1500.0, 'max': 2250.0}, {'current': 2250.0, 'min': 1500.0, 'max': 2250.0}, {'current': 2250.0, 'min': 1500.0, 'max': 2250.0}, {'current': 1500.0, 'min': 1500.0, 'max': 2250.0}, {'current': 1500.0, 'min': 1500.0, 'max': 2250.0}, {'current': 1500.0, 'min': 1500.0, 'max': 2250.0}, {'current': 1500.0, 'min': 1500.0, 'max': 2250.0}, {'current': 1500.0, 'min': 1500.0, 'max': 2250.0}, {'current': 1500.0, 'min': 1500.0, 'max': 2250.0}, {'current': 2250.0, 'min': 1500.0, 'max': 2250.0}, {'current': 1500.0, 'min': 1500.0, 'max': 2250.0}, {'current': 1500.0, 'min': 1500.0, 'max': 2250.0}, {'current': 1500.0, 'min': 1500.0, 'max': 2250.0}, {'current': 1500.0, 'min': 1500.0, 'max': 2250.0}, {'current': 1500.0, 'min': 1500.0, 'max': 2250.0}, {'current': 1500.0, 'min': 1500.0, 'max': 2250.0}, {'current': 1500.0, 'min': 1500.0, 'max': 2250.0}, {'current': 1500.0, 'min': 1500.0, 'max': 2250.0}, {'current': 1500.0, 'min': 1500.0, 'max': 2250.0}, {'current': 1500.0, 'min': 1500.0, 'max': 2250.0}, {'current': 2250.0, 'min': 1500.0, 'max': 2250.0}, {'current': 1500.0, 'min': 1500.0, 'max': 2250.0}, {'current': 1500.0, 'min': 1500.0, 'max': 2250.0}, {'current': 1500.0, 'min': 1500.0, 'max': 2250.0}, {'current': 1500.0, 'min': 1500.0, 'max': 2250.0}, {'current': 1500.0, 'min': 1500.0, 'max': 2250.0}, {'current': 1500.0, 'min': 1500.0, 'max': 2250.0}, {'current': 1500.0, 'min': 1500.0, 'max': 2250.0}, {'current': 1500.0, 'min': 1500.0, 'max': 2250.0}, {'current': 1500.0, 'min': 1500.0, 'max': 2250.0}, {'current': 1500.0, 'min': 1500.0, 'max': 2250.0}, {'current': 1500.0, 'min': 1500.0, 'max': 2250.0}, {'current': 1500.0, 'min': 1500.0, 'max': 2250.0}, {'current': 1500.0, 'min': 1500.0, 'max': 2250.0}, {'current': 1500.0, 'min': 1500.0, 'max': 2250.0}, {'current': 1500.0, 'min': 1500.0, 'max': 2250.0}, {'current': 1500.0, 'min': 1500.0, 'max': 2250.0}, {'current': 1500.0, 'min': 1500.0, 'max': 2250.0}, {'current': 1500.0, 'min': 1500.0, 'max': 2250.0}, {'current': 1500.0, 'min': 1500.0, 'max': 2250.0}, {'current': 1500.0, 'min': 1500.0, 'max': 2250.0}], 'disk': {'/': {'total': 10.0, 'used': 4.6097869873046875}}, 'gpu': 'NVIDIA GeForce RTX 3090', 'gpu_count': 1, 'gpu_devices': [{'name': 'NVIDIA GeForce RTX 3090', 'memory_total': 25769803776}], 'memory': {'total': 501.51181411743164}}
2023-12-08 20:20:57,947 INFO    HandlerThread:27837 [system_monitor.py:probe():224] Finished collecting system info
2023-12-08 20:20:57,947 INFO    HandlerThread:27837 [system_monitor.py:probe():227] Publishing system info
2023-12-08 20:20:57,947 DEBUG   HandlerThread:27837 [system_info.py:_save_pip():52] Saving list of pip packages installed into the current environment
2023-12-08 20:20:57,948 DEBUG   HandlerThread:27837 [system_info.py:_save_pip():68] Saving pip packages done
2023-12-08 20:20:57,949 DEBUG   HandlerThread:27837 [system_info.py:_save_conda():75] Saving list of conda packages installed into the current environment
2023-12-08 20:20:58,795 INFO    Thread-12 :27837 [dir_watcher.py:_on_file_created():271] file/dir created: /cluster/home/yutang/Deep-Knowledge-Tracing/DKT/KnowledgeTracing/evaluation/wandb/run-20231208_202057-c30p1g8z/files/requirements.txt
2023-12-08 20:20:58,796 INFO    Thread-12 :27837 [dir_watcher.py:_on_file_created():271] file/dir created: /cluster/home/yutang/Deep-Knowledge-Tracing/DKT/KnowledgeTracing/evaluation/wandb/run-20231208_202057-c30p1g8z/files/conda-environment.yaml
2023-12-08 20:21:01,063 DEBUG   HandlerThread:27837 [system_info.py:_save_conda():87] Saving conda packages done
2023-12-08 20:21:01,066 INFO    HandlerThread:27837 [system_monitor.py:probe():229] Finished publishing system info
2023-12-08 20:21:01,071 DEBUG   SenderThread:27837 [sender.py:send():380] send: files
2023-12-08 20:21:01,071 INFO    SenderThread:27837 [sender.py:_save_file():1378] saving file wandb-metadata.json with policy now
2023-12-08 20:21:01,077 DEBUG   HandlerThread:27837 [handler.py:handle_request():146] handle_request: stop_status
2023-12-08 20:21:01,078 DEBUG   SenderThread:27837 [sender.py:send_request():407] send_request: stop_status
2023-12-08 20:21:01,081 DEBUG   HandlerThread:27837 [handler.py:handle_request():146] handle_request: internal_messages
2023-12-08 20:21:01,330 DEBUG   SenderThread:27837 [sender.py:send():380] send: telemetry
2023-12-08 20:21:01,374 ERROR   wandb-upload_0:27837 [internal_api.py:upload_file():2556] upload_file exception https://storage.googleapis.com/wandb-production.appspot.com/bryant-tang-ethz/DKT-trial%201/c30p1g8z/wandb-metadata.json?Expires=1702149661&GoogleAccessId=gorilla-files-url-signer-man%40wandb-production.iam.gserviceaccount.com&Signature=KexFrx2bT1sRpPrCOnyFHTll42CAL7GxpXaMUOibyXhHbJN9T9Y%2FkSS2BhtTRt%2BioM0ny%2BCcaNtgQZe%2FzjvryjM0lcTOFtJCbc1Gxa278S7GHDcQF7PcW2QxQJ3VIijjPFkEf%2Br%2F%2By0fGDwyCbb%2BtkeUCSjgwdPwykXxdGyTgGmZa13eMGWnGiDKtOaji3FpdhOF4OI3LTDBARhwUEsu8yoCFTi9RVUMEVuOt7rquhqaIfYBWN53r2CGofT7pRk%2BM0WftI%2B3m%2F9qIDWDvz9lu6sRo8u2sZuHUspSYiQBAnUKOOy5lRwySufIHuk1SVhkU1Z%2F4pqKPW%2B%2B1SX6i7iqJg%3D%3D: HTTPSConnectionPool(host='storage.googleapis.com', port=443): Max retries exceeded with url: /wandb-production.appspot.com/bryant-tang-ethz/DKT-trial%201/c30p1g8z/wandb-metadata.json?Expires=1702149661&GoogleAccessId=gorilla-files-url-signer-man%40wandb-production.iam.gserviceaccount.com&Signature=KexFrx2bT1sRpPrCOnyFHTll42CAL7GxpXaMUOibyXhHbJN9T9Y%2FkSS2BhtTRt%2BioM0ny%2BCcaNtgQZe%2FzjvryjM0lcTOFtJCbc1Gxa278S7GHDcQF7PcW2QxQJ3VIijjPFkEf%2Br%2F%2By0fGDwyCbb%2BtkeUCSjgwdPwykXxdGyTgGmZa13eMGWnGiDKtOaji3FpdhOF4OI3LTDBARhwUEsu8yoCFTi9RVUMEVuOt7rquhqaIfYBWN53r2CGofT7pRk%2BM0WftI%2B3m%2F9qIDWDvz9lu6sRo8u2sZuHUspSYiQBAnUKOOy5lRwySufIHuk1SVhkU1Z%2F4pqKPW%2B%2B1SX6i7iqJg%3D%3D (Caused by NewConnectionError('<urllib3.connection.HTTPSConnection object at 0x2b9c6af41910>: Failed to establish a new connection: [Errno 101] Network is unreachable'))
2023-12-08 20:21:01,374 ERROR   wandb-upload_0:27837 [internal_api.py:upload_file():2558] upload_file request headers: {'User-Agent': 'python-requests/2.28.1', 'Accept-Encoding': 'gzip, deflate, br', 'Accept': '*/*', 'Connection': 'keep-alive', 'Content-Length': '14827'}
2023-12-08 20:21:01,374 ERROR   wandb-upload_0:27837 [internal_api.py:upload_file():2560] upload_file response body: 
2023-12-08 20:21:01,794 INFO    Thread-12 :27837 [dir_watcher.py:_on_file_modified():288] file/dir modified: /cluster/home/yutang/Deep-Knowledge-Tracing/DKT/KnowledgeTracing/evaluation/wandb/run-20231208_202057-c30p1g8z/files/conda-environment.yaml
2023-12-08 20:21:01,794 INFO    Thread-12 :27837 [dir_watcher.py:_on_file_created():271] file/dir created: /cluster/home/yutang/Deep-Knowledge-Tracing/DKT/KnowledgeTracing/evaluation/wandb/run-20231208_202057-c30p1g8z/files/wandb-metadata.json
2023-12-08 20:21:01,795 INFO    Thread-12 :27837 [dir_watcher.py:_on_file_created():271] file/dir created: /cluster/home/yutang/Deep-Knowledge-Tracing/DKT/KnowledgeTracing/evaluation/wandb/run-20231208_202057-c30p1g8z/files/output.log
2023-12-08 20:21:02,631 ERROR   wandb-upload_0:27837 [internal_api.py:upload_file():2556] upload_file exception https://storage.googleapis.com/wandb-production.appspot.com/bryant-tang-ethz/DKT-trial%201/c30p1g8z/wandb-metadata.json?Expires=1702149661&GoogleAccessId=gorilla-files-url-signer-man%40wandb-production.iam.gserviceaccount.com&Signature=KexFrx2bT1sRpPrCOnyFHTll42CAL7GxpXaMUOibyXhHbJN9T9Y%2FkSS2BhtTRt%2BioM0ny%2BCcaNtgQZe%2FzjvryjM0lcTOFtJCbc1Gxa278S7GHDcQF7PcW2QxQJ3VIijjPFkEf%2Br%2F%2By0fGDwyCbb%2BtkeUCSjgwdPwykXxdGyTgGmZa13eMGWnGiDKtOaji3FpdhOF4OI3LTDBARhwUEsu8yoCFTi9RVUMEVuOt7rquhqaIfYBWN53r2CGofT7pRk%2BM0WftI%2B3m%2F9qIDWDvz9lu6sRo8u2sZuHUspSYiQBAnUKOOy5lRwySufIHuk1SVhkU1Z%2F4pqKPW%2B%2B1SX6i7iqJg%3D%3D: HTTPSConnectionPool(host='storage.googleapis.com', port=443): Max retries exceeded with url: /wandb-production.appspot.com/bryant-tang-ethz/DKT-trial%201/c30p1g8z/wandb-metadata.json?Expires=1702149661&GoogleAccessId=gorilla-files-url-signer-man%40wandb-production.iam.gserviceaccount.com&Signature=KexFrx2bT1sRpPrCOnyFHTll42CAL7GxpXaMUOibyXhHbJN9T9Y%2FkSS2BhtTRt%2BioM0ny%2BCcaNtgQZe%2FzjvryjM0lcTOFtJCbc1Gxa278S7GHDcQF7PcW2QxQJ3VIijjPFkEf%2Br%2F%2By0fGDwyCbb%2BtkeUCSjgwdPwykXxdGyTgGmZa13eMGWnGiDKtOaji3FpdhOF4OI3LTDBARhwUEsu8yoCFTi9RVUMEVuOt7rquhqaIfYBWN53r2CGofT7pRk%2BM0WftI%2B3m%2F9qIDWDvz9lu6sRo8u2sZuHUspSYiQBAnUKOOy5lRwySufIHuk1SVhkU1Z%2F4pqKPW%2B%2B1SX6i7iqJg%3D%3D (Caused by NewConnectionError('<urllib3.connection.HTTPSConnection object at 0x2b9ca1bf20d0>: Failed to establish a new connection: [Errno 101] Network is unreachable'))
2023-12-08 20:21:02,631 ERROR   wandb-upload_0:27837 [internal_api.py:upload_file():2558] upload_file request headers: {'User-Agent': 'python-requests/2.28.1', 'Accept-Encoding': 'gzip, deflate, br', 'Accept': '*/*', 'Connection': 'keep-alive', 'Content-Length': '14827'}
2023-12-08 20:21:02,631 ERROR   wandb-upload_0:27837 [internal_api.py:upload_file():2560] upload_file response body: 
2023-12-08 20:21:03,333 DEBUG   HandlerThread:27837 [handler.py:handle_request():146] handle_request: status_report
2023-12-08 20:21:03,796 INFO    Thread-12 :27837 [dir_watcher.py:_on_file_modified():288] file/dir modified: /cluster/home/yutang/Deep-Knowledge-Tracing/DKT/KnowledgeTracing/evaluation/wandb/run-20231208_202057-c30p1g8z/files/output.log
2023-12-08 20:21:04,926 ERROR   wandb-upload_0:27837 [internal_api.py:upload_file():2556] upload_file exception https://storage.googleapis.com/wandb-production.appspot.com/bryant-tang-ethz/DKT-trial%201/c30p1g8z/wandb-metadata.json?Expires=1702149661&GoogleAccessId=gorilla-files-url-signer-man%40wandb-production.iam.gserviceaccount.com&Signature=KexFrx2bT1sRpPrCOnyFHTll42CAL7GxpXaMUOibyXhHbJN9T9Y%2FkSS2BhtTRt%2BioM0ny%2BCcaNtgQZe%2FzjvryjM0lcTOFtJCbc1Gxa278S7GHDcQF7PcW2QxQJ3VIijjPFkEf%2Br%2F%2By0fGDwyCbb%2BtkeUCSjgwdPwykXxdGyTgGmZa13eMGWnGiDKtOaji3FpdhOF4OI3LTDBARhwUEsu8yoCFTi9RVUMEVuOt7rquhqaIfYBWN53r2CGofT7pRk%2BM0WftI%2B3m%2F9qIDWDvz9lu6sRo8u2sZuHUspSYiQBAnUKOOy5lRwySufIHuk1SVhkU1Z%2F4pqKPW%2B%2B1SX6i7iqJg%3D%3D: HTTPSConnectionPool(host='storage.googleapis.com', port=443): Max retries exceeded with url: /wandb-production.appspot.com/bryant-tang-ethz/DKT-trial%201/c30p1g8z/wandb-metadata.json?Expires=1702149661&GoogleAccessId=gorilla-files-url-signer-man%40wandb-production.iam.gserviceaccount.com&Signature=KexFrx2bT1sRpPrCOnyFHTll42CAL7GxpXaMUOibyXhHbJN9T9Y%2FkSS2BhtTRt%2BioM0ny%2BCcaNtgQZe%2FzjvryjM0lcTOFtJCbc1Gxa278S7GHDcQF7PcW2QxQJ3VIijjPFkEf%2Br%2F%2By0fGDwyCbb%2BtkeUCSjgwdPwykXxdGyTgGmZa13eMGWnGiDKtOaji3FpdhOF4OI3LTDBARhwUEsu8yoCFTi9RVUMEVuOt7rquhqaIfYBWN53r2CGofT7pRk%2BM0WftI%2B3m%2F9qIDWDvz9lu6sRo8u2sZuHUspSYiQBAnUKOOy5lRwySufIHuk1SVhkU1Z%2F4pqKPW%2B%2B1SX6i7iqJg%3D%3D (Caused by NewConnectionError('<urllib3.connection.HTTPSConnection object at 0x2b9ca1bf2190>: Failed to establish a new connection: [Errno 101] Network is unreachable'))
2023-12-08 20:21:04,927 ERROR   wandb-upload_0:27837 [internal_api.py:upload_file():2558] upload_file request headers: {'User-Agent': 'python-requests/2.28.1', 'Accept-Encoding': 'gzip, deflate, br', 'Accept': '*/*', 'Connection': 'keep-alive', 'Content-Length': '14827'}
2023-12-08 20:21:04,927 ERROR   wandb-upload_0:27837 [internal_api.py:upload_file():2560] upload_file response body: 
2023-12-08 20:21:04,927 INFO    wandb-upload_0:27837 [retry.py:__call__():172] Retry attempt failed:
Traceback (most recent call last):
  File "/cluster/home/yutang/miniconda3/lib/python3.9/site-packages/urllib3/connection.py", line 174, in _new_conn
    conn = connection.create_connection(
  File "/cluster/home/yutang/miniconda3/lib/python3.9/site-packages/urllib3/util/connection.py", line 95, in create_connection
    raise err
  File "/cluster/home/yutang/miniconda3/lib/python3.9/site-packages/urllib3/util/connection.py", line 85, in create_connection
    sock.connect(sa)
OSError: [Errno 101] Network is unreachable

During handling of the above exception, another exception occurred:

Traceback (most recent call last):
  File "/cluster/home/yutang/miniconda3/lib/python3.9/site-packages/urllib3/connectionpool.py", line 703, in urlopen
    httplib_response = self._make_request(
  File "/cluster/home/yutang/miniconda3/lib/python3.9/site-packages/urllib3/connectionpool.py", line 386, in _make_request
    self._validate_conn(conn)
  File "/cluster/home/yutang/miniconda3/lib/python3.9/site-packages/urllib3/connectionpool.py", line 1042, in _validate_conn
    conn.connect()
  File "/cluster/home/yutang/miniconda3/lib/python3.9/site-packages/urllib3/connection.py", line 358, in connect
    self.sock = conn = self._new_conn()
  File "/cluster/home/yutang/miniconda3/lib/python3.9/site-packages/urllib3/connection.py", line 186, in _new_conn
    raise NewConnectionError(
urllib3.exceptions.NewConnectionError: <urllib3.connection.HTTPSConnection object at 0x2b9ca1bf2190>: Failed to establish a new connection: [Errno 101] Network is unreachable

During handling of the above exception, another exception occurred:

Traceback (most recent call last):
  File "/cluster/home/yutang/miniconda3/lib/python3.9/site-packages/requests/adapters.py", line 489, in send
    resp = conn.urlopen(
  File "/cluster/home/yutang/miniconda3/lib/python3.9/site-packages/urllib3/connectionpool.py", line 787, in urlopen
    retries = retries.increment(
  File "/cluster/home/yutang/miniconda3/lib/python3.9/site-packages/urllib3/util/retry.py", line 592, in increment
    raise MaxRetryError(_pool, url, error or ResponseError(cause))
urllib3.exceptions.MaxRetryError: HTTPSConnectionPool(host='storage.googleapis.com', port=443): Max retries exceeded with url: /wandb-production.appspot.com/bryant-tang-ethz/DKT-trial%201/c30p1g8z/wandb-metadata.json?Expires=1702149661&GoogleAccessId=gorilla-files-url-signer-man%40wandb-production.iam.gserviceaccount.com&Signature=KexFrx2bT1sRpPrCOnyFHTll42CAL7GxpXaMUOibyXhHbJN9T9Y%2FkSS2BhtTRt%2BioM0ny%2BCcaNtgQZe%2FzjvryjM0lcTOFtJCbc1Gxa278S7GHDcQF7PcW2QxQJ3VIijjPFkEf%2Br%2F%2By0fGDwyCbb%2BtkeUCSjgwdPwykXxdGyTgGmZa13eMGWnGiDKtOaji3FpdhOF4OI3LTDBARhwUEsu8yoCFTi9RVUMEVuOt7rquhqaIfYBWN53r2CGofT7pRk%2BM0WftI%2B3m%2F9qIDWDvz9lu6sRo8u2sZuHUspSYiQBAnUKOOy5lRwySufIHuk1SVhkU1Z%2F4pqKPW%2B%2B1SX6i7iqJg%3D%3D (Caused by NewConnectionError('<urllib3.connection.HTTPSConnection object at 0x2b9ca1bf2190>: Failed to establish a new connection: [Errno 101] Network is unreachable'))

During handling of the above exception, another exception occurred:

Traceback (most recent call last):
  File "/cluster/home/yutang/miniconda3/lib/python3.9/site-packages/wandb/sdk/internal/internal_api.py", line 2549, in upload_file
    response = self._upload_file_session.put(
  File "/cluster/home/yutang/miniconda3/lib/python3.9/site-packages/requests/sessions.py", line 647, in put
    return self.request("PUT", url, data=data, **kwargs)
  File "/cluster/home/yutang/miniconda3/lib/python3.9/site-packages/requests/sessions.py", line 587, in request
    resp = self.send(prep, **send_kwargs)
  File "/cluster/home/yutang/miniconda3/lib/python3.9/site-packages/requests/sessions.py", line 701, in send
    r = adapter.send(request, **kwargs)
  File "/cluster/home/yutang/miniconda3/lib/python3.9/site-packages/requests/adapters.py", line 565, in send
    raise ConnectionError(e, request=request)
requests.exceptions.ConnectionError: HTTPSConnectionPool(host='storage.googleapis.com', port=443): Max retries exceeded with url: /wandb-production.appspot.com/bryant-tang-ethz/DKT-trial%201/c30p1g8z/wandb-metadata.json?Expires=1702149661&GoogleAccessId=gorilla-files-url-signer-man%40wandb-production.iam.gserviceaccount.com&Signature=KexFrx2bT1sRpPrCOnyFHTll42CAL7GxpXaMUOibyXhHbJN9T9Y%2FkSS2BhtTRt%2BioM0ny%2BCcaNtgQZe%2FzjvryjM0lcTOFtJCbc1Gxa278S7GHDcQF7PcW2QxQJ3VIijjPFkEf%2Br%2F%2By0fGDwyCbb%2BtkeUCSjgwdPwykXxdGyTgGmZa13eMGWnGiDKtOaji3FpdhOF4OI3LTDBARhwUEsu8yoCFTi9RVUMEVuOt7rquhqaIfYBWN53r2CGofT7pRk%2BM0WftI%2B3m%2F9qIDWDvz9lu6sRo8u2sZuHUspSYiQBAnUKOOy5lRwySufIHuk1SVhkU1Z%2F4pqKPW%2B%2B1SX6i7iqJg%3D%3D (Caused by NewConnectionError('<urllib3.connection.HTTPSConnection object at 0x2b9ca1bf2190>: Failed to establish a new connection: [Errno 101] Network is unreachable'))

During handling of the above exception, another exception occurred:

Traceback (most recent call last):
  File "/cluster/home/yutang/miniconda3/lib/python3.9/site-packages/wandb/sdk/lib/retry.py", line 131, in __call__
    result = self._call_fn(*args, **kwargs)
  File "/cluster/home/yutang/miniconda3/lib/python3.9/site-packages/wandb/sdk/internal/internal_api.py", line 2580, in upload_file
    raise _e.with_traceback(sys.exc_info()[2])
  File "/cluster/home/yutang/miniconda3/lib/python3.9/site-packages/wandb/sdk/internal/internal_api.py", line 2549, in upload_file
    response = self._upload_file_session.put(
  File "/cluster/home/yutang/miniconda3/lib/python3.9/site-packages/requests/sessions.py", line 647, in put
    return self.request("PUT", url, data=data, **kwargs)
  File "/cluster/home/yutang/miniconda3/lib/python3.9/site-packages/requests/sessions.py", line 587, in request
    resp = self.send(prep, **send_kwargs)
  File "/cluster/home/yutang/miniconda3/lib/python3.9/site-packages/requests/sessions.py", line 701, in send
    r = adapter.send(request, **kwargs)
  File "/cluster/home/yutang/miniconda3/lib/python3.9/site-packages/requests/adapters.py", line 565, in send
    raise ConnectionError(e, request=request)
wandb.sdk.lib.retry.TransientError: None
2023-12-08 20:21:08,800 INFO    Thread-12 :27837 [dir_watcher.py:_on_file_modified():288] file/dir modified: /cluster/home/yutang/Deep-Knowledge-Tracing/DKT/KnowledgeTracing/evaluation/wandb/run-20231208_202057-c30p1g8z/files/output.log
2023-12-08 20:21:08,924 DEBUG   HandlerThread:27837 [handler.py:handle_request():146] handle_request: status_report
2023-12-08 20:21:09,066 DEBUG   SenderThread:27837 [sender.py:send():380] send: exit
2023-12-08 20:21:09,066 INFO    SenderThread:27837 [sender.py:send_exit():585] handling exit code: 1
2023-12-08 20:21:09,066 INFO    SenderThread:27837 [sender.py:send_exit():587] handling runtime: 11
2023-12-08 20:21:09,067 INFO    SenderThread:27837 [sender.py:_save_file():1378] saving file wandb-summary.json with policy end
2023-12-08 20:21:09,067 INFO    SenderThread:27837 [sender.py:send_exit():593] send defer
2023-12-08 20:21:09,067 DEBUG   HandlerThread:27837 [handler.py:handle_request():146] handle_request: defer
2023-12-08 20:21:09,067 INFO    HandlerThread:27837 [handler.py:handle_request_defer():172] handle defer: 0
2023-12-08 20:21:09,067 DEBUG   SenderThread:27837 [sender.py:send_request():407] send_request: defer
2023-12-08 20:21:09,067 INFO    SenderThread:27837 [sender.py:send_request_defer():609] handle sender defer: 0
2023-12-08 20:21:09,067 INFO    SenderThread:27837 [sender.py:transition_state():613] send defer: 1
2023-12-08 20:21:09,067 DEBUG   HandlerThread:27837 [handler.py:handle_request():146] handle_request: defer
2023-12-08 20:21:09,068 INFO    HandlerThread:27837 [handler.py:handle_request_defer():172] handle defer: 1
2023-12-08 20:21:09,068 DEBUG   SenderThread:27837 [sender.py:send_request():407] send_request: defer
2023-12-08 20:21:09,068 INFO    SenderThread:27837 [sender.py:send_request_defer():609] handle sender defer: 1
2023-12-08 20:21:09,068 INFO    SenderThread:27837 [sender.py:transition_state():613] send defer: 2
2023-12-08 20:21:09,068 DEBUG   HandlerThread:27837 [handler.py:handle_request():146] handle_request: defer
2023-12-08 20:21:09,068 INFO    HandlerThread:27837 [handler.py:handle_request_defer():172] handle defer: 2
2023-12-08 20:21:09,068 INFO    HandlerThread:27837 [system_monitor.py:finish():203] Stopping system monitor
2023-12-08 20:21:09,068 DEBUG   SystemMonitor:27837 [system_monitor.py:_start():172] Starting system metrics aggregation loop
2023-12-08 20:21:09,073 DEBUG   SystemMonitor:27837 [system_monitor.py:_start():179] Finished system metrics aggregation loop
2023-12-08 20:21:09,073 DEBUG   SystemMonitor:27837 [system_monitor.py:_start():183] Publishing last batch of metrics
2023-12-08 20:21:09,069 INFO    HandlerThread:27837 [interfaces.py:finish():202] Joined cpu monitor
2023-12-08 20:21:09,076 INFO    HandlerThread:27837 [interfaces.py:finish():202] Joined disk monitor
2023-12-08 20:21:09,221 INFO    HandlerThread:27837 [interfaces.py:finish():202] Joined gpu monitor
2023-12-08 20:21:09,221 INFO    HandlerThread:27837 [interfaces.py:finish():202] Joined memory monitor
2023-12-08 20:21:09,222 INFO    HandlerThread:27837 [interfaces.py:finish():202] Joined network monitor
2023-12-08 20:21:09,222 DEBUG   SenderThread:27837 [sender.py:send_request():407] send_request: defer
2023-12-08 20:21:09,222 INFO    SenderThread:27837 [sender.py:send_request_defer():609] handle sender defer: 2
2023-12-08 20:21:09,222 INFO    SenderThread:27837 [sender.py:transition_state():613] send defer: 3
2023-12-08 20:21:09,222 DEBUG   SenderThread:27837 [sender.py:send():380] send: stats
2023-12-08 20:21:09,222 DEBUG   HandlerThread:27837 [handler.py:handle_request():146] handle_request: defer
2023-12-08 20:21:09,223 INFO    HandlerThread:27837 [handler.py:handle_request_defer():172] handle defer: 3
2023-12-08 20:21:09,224 DEBUG   SenderThread:27837 [sender.py:send_request():407] send_request: defer
2023-12-08 20:21:09,224 INFO    SenderThread:27837 [sender.py:send_request_defer():609] handle sender defer: 3
2023-12-08 20:21:09,224 INFO    SenderThread:27837 [sender.py:transition_state():613] send defer: 4
2023-12-08 20:21:09,224 DEBUG   HandlerThread:27837 [handler.py:handle_request():146] handle_request: defer
2023-12-08 20:21:09,224 INFO    HandlerThread:27837 [handler.py:handle_request_defer():172] handle defer: 4
2023-12-08 20:21:09,224 DEBUG   SenderThread:27837 [sender.py:send_request():407] send_request: defer
2023-12-08 20:21:09,224 INFO    SenderThread:27837 [sender.py:send_request_defer():609] handle sender defer: 4
2023-12-08 20:21:09,224 INFO    SenderThread:27837 [sender.py:transition_state():613] send defer: 5
2023-12-08 20:21:09,224 DEBUG   HandlerThread:27837 [handler.py:handle_request():146] handle_request: defer
2023-12-08 20:21:09,224 INFO    HandlerThread:27837 [handler.py:handle_request_defer():172] handle defer: 5
2023-12-08 20:21:09,224 DEBUG   SenderThread:27837 [sender.py:send():380] send: summary
2023-12-08 20:21:09,226 INFO    SenderThread:27837 [sender.py:_save_file():1378] saving file wandb-summary.json with policy end
2023-12-08 20:21:09,226 DEBUG   SenderThread:27837 [sender.py:send_request():407] send_request: defer
2023-12-08 20:21:09,226 INFO    SenderThread:27837 [sender.py:send_request_defer():609] handle sender defer: 5
2023-12-08 20:21:09,226 INFO    SenderThread:27837 [sender.py:transition_state():613] send defer: 6
2023-12-08 20:21:09,226 DEBUG   HandlerThread:27837 [handler.py:handle_request():146] handle_request: defer
2023-12-08 20:21:09,226 INFO    HandlerThread:27837 [handler.py:handle_request_defer():172] handle defer: 6
2023-12-08 20:21:09,226 DEBUG   SenderThread:27837 [sender.py:send_request():407] send_request: defer
2023-12-08 20:21:09,226 INFO    SenderThread:27837 [sender.py:send_request_defer():609] handle sender defer: 6
2023-12-08 20:21:09,232 DEBUG   HandlerThread:27837 [handler.py:handle_request():146] handle_request: status_report
2023-12-08 20:21:09,416 INFO    SenderThread:27837 [sender.py:transition_state():613] send defer: 7
2023-12-08 20:21:09,416 DEBUG   HandlerThread:27837 [handler.py:handle_request():146] handle_request: defer
2023-12-08 20:21:09,416 INFO    HandlerThread:27837 [handler.py:handle_request_defer():172] handle defer: 7
2023-12-08 20:21:09,417 DEBUG   SenderThread:27837 [sender.py:send_request():407] send_request: defer
2023-12-08 20:21:09,417 INFO    SenderThread:27837 [sender.py:send_request_defer():609] handle sender defer: 7
2023-12-08 20:21:09,690 ERROR   wandb-upload_0:27837 [internal_api.py:upload_file():2556] upload_file exception https://storage.googleapis.com/wandb-production.appspot.com/bryant-tang-ethz/DKT-trial%201/c30p1g8z/wandb-metadata.json?Expires=1702149661&GoogleAccessId=gorilla-files-url-signer-man%40wandb-production.iam.gserviceaccount.com&Signature=KexFrx2bT1sRpPrCOnyFHTll42CAL7GxpXaMUOibyXhHbJN9T9Y%2FkSS2BhtTRt%2BioM0ny%2BCcaNtgQZe%2FzjvryjM0lcTOFtJCbc1Gxa278S7GHDcQF7PcW2QxQJ3VIijjPFkEf%2Br%2F%2By0fGDwyCbb%2BtkeUCSjgwdPwykXxdGyTgGmZa13eMGWnGiDKtOaji3FpdhOF4OI3LTDBARhwUEsu8yoCFTi9RVUMEVuOt7rquhqaIfYBWN53r2CGofT7pRk%2BM0WftI%2B3m%2F9qIDWDvz9lu6sRo8u2sZuHUspSYiQBAnUKOOy5lRwySufIHuk1SVhkU1Z%2F4pqKPW%2B%2B1SX6i7iqJg%3D%3D: HTTPSConnectionPool(host='storage.googleapis.com', port=443): Max retries exceeded with url: /wandb-production.appspot.com/bryant-tang-ethz/DKT-trial%201/c30p1g8z/wandb-metadata.json?Expires=1702149661&GoogleAccessId=gorilla-files-url-signer-man%40wandb-production.iam.gserviceaccount.com&Signature=KexFrx2bT1sRpPrCOnyFHTll42CAL7GxpXaMUOibyXhHbJN9T9Y%2FkSS2BhtTRt%2BioM0ny%2BCcaNtgQZe%2FzjvryjM0lcTOFtJCbc1Gxa278S7GHDcQF7PcW2QxQJ3VIijjPFkEf%2Br%2F%2By0fGDwyCbb%2BtkeUCSjgwdPwykXxdGyTgGmZa13eMGWnGiDKtOaji3FpdhOF4OI3LTDBARhwUEsu8yoCFTi9RVUMEVuOt7rquhqaIfYBWN53r2CGofT7pRk%2BM0WftI%2B3m%2F9qIDWDvz9lu6sRo8u2sZuHUspSYiQBAnUKOOy5lRwySufIHuk1SVhkU1Z%2F4pqKPW%2B%2B1SX6i7iqJg%3D%3D (Caused by NewConnectionError('<urllib3.connection.HTTPSConnection object at 0x2b9c6bfc40a0>: Failed to establish a new connection: [Errno 101] Network is unreachable'))
2023-12-08 20:21:09,690 ERROR   wandb-upload_0:27837 [internal_api.py:upload_file():2558] upload_file request headers: {'User-Agent': 'python-requests/2.28.1', 'Accept-Encoding': 'gzip, deflate, br', 'Accept': '*/*', 'Connection': 'keep-alive', 'Content-Length': '14827'}
2023-12-08 20:21:09,690 ERROR   wandb-upload_0:27837 [internal_api.py:upload_file():2560] upload_file response body: 
2023-12-08 20:21:09,801 INFO    Thread-12 :27837 [dir_watcher.py:_on_file_modified():288] file/dir modified: /cluster/home/yutang/Deep-Knowledge-Tracing/DKT/KnowledgeTracing/evaluation/wandb/run-20231208_202057-c30p1g8z/files/config.yaml
2023-12-08 20:21:09,802 INFO    Thread-12 :27837 [dir_watcher.py:_on_file_created():271] file/dir created: /cluster/home/yutang/Deep-Knowledge-Tracing/DKT/KnowledgeTracing/evaluation/wandb/run-20231208_202057-c30p1g8z/files/wandb-summary.json
2023-12-08 20:21:10,066 DEBUG   HandlerThread:27837 [handler.py:handle_request():146] handle_request: poll_exit
2023-12-08 20:21:10,802 INFO    Thread-12 :27837 [dir_watcher.py:_on_file_modified():288] file/dir modified: /cluster/home/yutang/Deep-Knowledge-Tracing/DKT/KnowledgeTracing/evaluation/wandb/run-20231208_202057-c30p1g8z/files/output.log
2023-12-08 20:21:11,938 INFO    SenderThread:27837 [sender.py:transition_state():613] send defer: 8
2023-12-08 20:21:11,939 DEBUG   SenderThread:27837 [sender.py:send_request():407] send_request: poll_exit
2023-12-08 20:21:11,939 DEBUG   HandlerThread:27837 [handler.py:handle_request():146] handle_request: defer
2023-12-08 20:21:11,939 INFO    HandlerThread:27837 [handler.py:handle_request_defer():172] handle defer: 8
2023-12-08 20:21:11,940 DEBUG   SenderThread:27837 [sender.py:send_request():407] send_request: defer
2023-12-08 20:21:11,940 INFO    SenderThread:27837 [sender.py:send_request_defer():609] handle sender defer: 8
2023-12-08 20:21:11,940 INFO    SenderThread:27837 [job_builder.py:build():281] Attempting to build job artifact
2023-12-08 20:21:11,941 INFO    SenderThread:27837 [job_builder.py:_get_source_type():393] is repo sourced job
2023-12-08 20:21:11,945 INFO    SenderThread:27837 [job_builder.py:build():369] adding wandb-job metadata file
2023-12-08 20:21:11,952 INFO    SenderThread:27837 [sender.py:transition_state():613] send defer: 9
2023-12-08 20:21:11,952 DEBUG   HandlerThread:27837 [handler.py:handle_request():146] handle_request: defer
2023-12-08 20:21:11,953 INFO    HandlerThread:27837 [handler.py:handle_request_defer():172] handle defer: 9
2023-12-08 20:21:11,953 DEBUG   SenderThread:27837 [sender.py:send():380] send: artifact
2023-12-08 20:21:12,804 INFO    Thread-12 :27837 [dir_watcher.py:_on_file_modified():288] file/dir modified: /cluster/home/yutang/Deep-Knowledge-Tracing/DKT/KnowledgeTracing/evaluation/wandb/run-20231208_202057-c30p1g8z/files/output.log
2023-12-08 20:21:13,097 ERROR   wandb-upload_2:27837 [internal_api.py:upload_file():2556] upload_file exception https://storage.googleapis.com/wandb-artifacts-prod/wandb_artifacts/120300447/661768373/7d403960cc78ee51501901f4effaf804?Expires=1702149673&GoogleAccessId=gorilla-files-url-signer-man%40wandb-production.iam.gserviceaccount.com&Signature=L8AQMQPD7qLLhZtGhc3fzIzQX9C9uQJUI2jyh%2BJsrZF63PAECSlMX8H6XhBEPdkG8nFmOHXM9Mozf3qjmGR9by9ZJlrWTSbvVjAM%2BTxcTSmfQrjBFNmR%2BufbstUknoHi52uQ69nCgb4UspHPaBbgrvdhHEGKe%2BZaRx1Kef39N7OBS%2BZykfBnBEutYwt4XJc0w3K2gzWufouZkIeCNbipE7YExQgKHaSaFMAXv2mYoFpV8Vw8ex6J%2Fu5H%2F84erlMNU5hqp2GzsW%2F3FSTKbITK7u5G2qJ1Mfd3ehEW58R6y81PQqkBhMEWqO%2BLsA02hyF8y%2BRWYR6Igiq9oNWsM2j74w%3D%3D: HTTPSConnectionPool(host='storage.googleapis.com', port=443): Max retries exceeded with url: /wandb-artifacts-prod/wandb_artifacts/120300447/661768373/7d403960cc78ee51501901f4effaf804?Expires=1702149673&GoogleAccessId=gorilla-files-url-signer-man%40wandb-production.iam.gserviceaccount.com&Signature=L8AQMQPD7qLLhZtGhc3fzIzQX9C9uQJUI2jyh%2BJsrZF63PAECSlMX8H6XhBEPdkG8nFmOHXM9Mozf3qjmGR9by9ZJlrWTSbvVjAM%2BTxcTSmfQrjBFNmR%2BufbstUknoHi52uQ69nCgb4UspHPaBbgrvdhHEGKe%2BZaRx1Kef39N7OBS%2BZykfBnBEutYwt4XJc0w3K2gzWufouZkIeCNbipE7YExQgKHaSaFMAXv2mYoFpV8Vw8ex6J%2Fu5H%2F84erlMNU5hqp2GzsW%2F3FSTKbITK7u5G2qJ1Mfd3ehEW58R6y81PQqkBhMEWqO%2BLsA02hyF8y%2BRWYR6Igiq9oNWsM2j74w%3D%3D (Caused by NewConnectionError('<urllib3.connection.HTTPSConnection object at 0x2b9ca2705730>: Failed to establish a new connection: [Errno 101] Network is unreachable'))
2023-12-08 20:21:13,097 ERROR   wandb-upload_2:27837 [internal_api.py:upload_file():2558] upload_file request headers: {'User-Agent': 'python-requests/2.28.1', 'Accept-Encoding': 'gzip, deflate, br', 'Accept': '*/*', 'Connection': 'keep-alive', 'Content-MD5': 'fUA5YMx47lFQGQH07/r4BA==', 'Content-Type': 'application/json', 'Content-Length': '648'}
2023-12-08 20:21:13,097 ERROR   wandb-upload_2:27837 [internal_api.py:upload_file():2560] upload_file response body: 
2023-12-08 20:21:13,098 ERROR   wandb-upload_1:27837 [internal_api.py:upload_file():2556] upload_file exception https://storage.googleapis.com/wandb-artifacts-prod/wandb_artifacts/120300447/661768373/521e54ab95c254e02c4ef790d5def9ec?Expires=1702149673&GoogleAccessId=gorilla-files-url-signer-man%40wandb-production.iam.gserviceaccount.com&Signature=fWMKl4WNB7xDCuLXBlggttukI7S73o1o80R8hwoAZc9W3aRVkaYs%2Fhst3TPscj%2FmgkAh0M6A9LES6yGp3VfKFaPXlqodVITaQLFDuA1LWtf8MRVI9%2BLOctn%2FHua6A0SVsRtUy51HHiWxtL5LKSG1t8DXe7zUPnh56ZqU5pi8Iu45rJYbTwKAXGQt%2BeijthqK5KuAaf9xYNyodmN3ekpf0CDvVesBtpOHO5H%2FJIfa%2BhCYqLI6vv%2FwJrxbraOPCvjV7TFeSniocFLLNWi9vHdmucdnGkNGDFZXFMsSbzsLTW3EMXKk%2BUOHXDiUZvKn6lXv2m1Odl65rQnXo5ICeD7%2BmA%3D%3D: HTTPSConnectionPool(host='storage.googleapis.com', port=443): Max retries exceeded with url: /wandb-artifacts-prod/wandb_artifacts/120300447/661768373/521e54ab95c254e02c4ef790d5def9ec?Expires=1702149673&GoogleAccessId=gorilla-files-url-signer-man%40wandb-production.iam.gserviceaccount.com&Signature=fWMKl4WNB7xDCuLXBlggttukI7S73o1o80R8hwoAZc9W3aRVkaYs%2Fhst3TPscj%2FmgkAh0M6A9LES6yGp3VfKFaPXlqodVITaQLFDuA1LWtf8MRVI9%2BLOctn%2FHua6A0SVsRtUy51HHiWxtL5LKSG1t8DXe7zUPnh56ZqU5pi8Iu45rJYbTwKAXGQt%2BeijthqK5KuAaf9xYNyodmN3ekpf0CDvVesBtpOHO5H%2FJIfa%2BhCYqLI6vv%2FwJrxbraOPCvjV7TFeSniocFLLNWi9vHdmucdnGkNGDFZXFMsSbzsLTW3EMXKk%2BUOHXDiUZvKn6lXv2m1Odl65rQnXo5ICeD7%2BmA%3D%3D (Caused by NewConnectionError('<urllib3.connection.HTTPSConnection object at 0x2b9ca27058e0>: Failed to establish a new connection: [Errno 101] Network is unreachable'))
2023-12-08 20:21:13,098 ERROR   wandb-upload_1:27837 [internal_api.py:upload_file():2558] upload_file request headers: {'User-Agent': 'python-requests/2.28.1', 'Accept-Encoding': 'gzip, deflate, br', 'Accept': '*/*', 'Connection': 'keep-alive', 'Content-MD5': 'Uh5Uq5XCVOAsTveQ1d757A==', 'Content-Type': 'text/plain; charset=utf-8', 'Content-Length': '1820'}
2023-12-08 20:21:13,098 ERROR   wandb-upload_1:27837 [internal_api.py:upload_file():2560] upload_file response body: 
2023-12-08 20:21:14,166 ERROR   wandb-upload_2:27837 [internal_api.py:upload_file():2556] upload_file exception https://storage.googleapis.com/wandb-artifacts-prod/wandb_artifacts/120300447/661768373/7d403960cc78ee51501901f4effaf804?Expires=1702149673&GoogleAccessId=gorilla-files-url-signer-man%40wandb-production.iam.gserviceaccount.com&Signature=L8AQMQPD7qLLhZtGhc3fzIzQX9C9uQJUI2jyh%2BJsrZF63PAECSlMX8H6XhBEPdkG8nFmOHXM9Mozf3qjmGR9by9ZJlrWTSbvVjAM%2BTxcTSmfQrjBFNmR%2BufbstUknoHi52uQ69nCgb4UspHPaBbgrvdhHEGKe%2BZaRx1Kef39N7OBS%2BZykfBnBEutYwt4XJc0w3K2gzWufouZkIeCNbipE7YExQgKHaSaFMAXv2mYoFpV8Vw8ex6J%2Fu5H%2F84erlMNU5hqp2GzsW%2F3FSTKbITK7u5G2qJ1Mfd3ehEW58R6y81PQqkBhMEWqO%2BLsA02hyF8y%2BRWYR6Igiq9oNWsM2j74w%3D%3D: HTTPSConnectionPool(host='storage.googleapis.com', port=443): Max retries exceeded with url: /wandb-artifacts-prod/wandb_artifacts/120300447/661768373/7d403960cc78ee51501901f4effaf804?Expires=1702149673&GoogleAccessId=gorilla-files-url-signer-man%40wandb-production.iam.gserviceaccount.com&Signature=L8AQMQPD7qLLhZtGhc3fzIzQX9C9uQJUI2jyh%2BJsrZF63PAECSlMX8H6XhBEPdkG8nFmOHXM9Mozf3qjmGR9by9ZJlrWTSbvVjAM%2BTxcTSmfQrjBFNmR%2BufbstUknoHi52uQ69nCgb4UspHPaBbgrvdhHEGKe%2BZaRx1Kef39N7OBS%2BZykfBnBEutYwt4XJc0w3K2gzWufouZkIeCNbipE7YExQgKHaSaFMAXv2mYoFpV8Vw8ex6J%2Fu5H%2F84erlMNU5hqp2GzsW%2F3FSTKbITK7u5G2qJ1Mfd3ehEW58R6y81PQqkBhMEWqO%2BLsA02hyF8y%2BRWYR6Igiq9oNWsM2j74w%3D%3D (Caused by NewConnectionError('<urllib3.connection.HTTPSConnection object at 0x2b9ca22f00d0>: Failed to establish a new connection: [Errno 101] Network is unreachable'))
2023-12-08 20:21:14,166 ERROR   wandb-upload_2:27837 [internal_api.py:upload_file():2558] upload_file request headers: {'User-Agent': 'python-requests/2.28.1', 'Accept-Encoding': 'gzip, deflate, br', 'Accept': '*/*', 'Connection': 'keep-alive', 'Content-MD5': 'fUA5YMx47lFQGQH07/r4BA==', 'Content-Type': 'application/json', 'Content-Length': '648'}
2023-12-08 20:21:14,167 ERROR   wandb-upload_2:27837 [internal_api.py:upload_file():2560] upload_file response body: 
2023-12-08 20:21:14,248 ERROR   wandb-upload_1:27837 [internal_api.py:upload_file():2556] upload_file exception https://storage.googleapis.com/wandb-artifacts-prod/wandb_artifacts/120300447/661768373/521e54ab95c254e02c4ef790d5def9ec?Expires=1702149673&GoogleAccessId=gorilla-files-url-signer-man%40wandb-production.iam.gserviceaccount.com&Signature=fWMKl4WNB7xDCuLXBlggttukI7S73o1o80R8hwoAZc9W3aRVkaYs%2Fhst3TPscj%2FmgkAh0M6A9LES6yGp3VfKFaPXlqodVITaQLFDuA1LWtf8MRVI9%2BLOctn%2FHua6A0SVsRtUy51HHiWxtL5LKSG1t8DXe7zUPnh56ZqU5pi8Iu45rJYbTwKAXGQt%2BeijthqK5KuAaf9xYNyodmN3ekpf0CDvVesBtpOHO5H%2FJIfa%2BhCYqLI6vv%2FwJrxbraOPCvjV7TFeSniocFLLNWi9vHdmucdnGkNGDFZXFMsSbzsLTW3EMXKk%2BUOHXDiUZvKn6lXv2m1Odl65rQnXo5ICeD7%2BmA%3D%3D: HTTPSConnectionPool(host='storage.googleapis.com', port=443): Max retries exceeded with url: /wandb-artifacts-prod/wandb_artifacts/120300447/661768373/521e54ab95c254e02c4ef790d5def9ec?Expires=1702149673&GoogleAccessId=gorilla-files-url-signer-man%40wandb-production.iam.gserviceaccount.com&Signature=fWMKl4WNB7xDCuLXBlggttukI7S73o1o80R8hwoAZc9W3aRVkaYs%2Fhst3TPscj%2FmgkAh0M6A9LES6yGp3VfKFaPXlqodVITaQLFDuA1LWtf8MRVI9%2BLOctn%2FHua6A0SVsRtUy51HHiWxtL5LKSG1t8DXe7zUPnh56ZqU5pi8Iu45rJYbTwKAXGQt%2BeijthqK5KuAaf9xYNyodmN3ekpf0CDvVesBtpOHO5H%2FJIfa%2BhCYqLI6vv%2FwJrxbraOPCvjV7TFeSniocFLLNWi9vHdmucdnGkNGDFZXFMsSbzsLTW3EMXKk%2BUOHXDiUZvKn6lXv2m1Odl65rQnXo5ICeD7%2BmA%3D%3D (Caused by NewConnectionError('<urllib3.connection.HTTPSConnection object at 0x2b9ca27057c0>: Failed to establish a new connection: [Errno 101] Network is unreachable'))
2023-12-08 20:21:14,248 ERROR   wandb-upload_1:27837 [internal_api.py:upload_file():2558] upload_file request headers: {'User-Agent': 'python-requests/2.28.1', 'Accept-Encoding': 'gzip, deflate, br', 'Accept': '*/*', 'Connection': 'keep-alive', 'Content-MD5': 'Uh5Uq5XCVOAsTveQ1d757A==', 'Content-Type': 'text/plain; charset=utf-8', 'Content-Length': '1820'}
2023-12-08 20:21:14,248 ERROR   wandb-upload_1:27837 [internal_api.py:upload_file():2560] upload_file response body: 
2023-12-08 20:21:15,068 DEBUG   HandlerThread:27837 [handler.py:handle_request():146] handle_request: keepalive
2023-12-08 20:21:16,379 ERROR   wandb-upload_1:27837 [internal_api.py:upload_file():2556] upload_file exception https://storage.googleapis.com/wandb-artifacts-prod/wandb_artifacts/120300447/661768373/521e54ab95c254e02c4ef790d5def9ec?Expires=1702149673&GoogleAccessId=gorilla-files-url-signer-man%40wandb-production.iam.gserviceaccount.com&Signature=fWMKl4WNB7xDCuLXBlggttukI7S73o1o80R8hwoAZc9W3aRVkaYs%2Fhst3TPscj%2FmgkAh0M6A9LES6yGp3VfKFaPXlqodVITaQLFDuA1LWtf8MRVI9%2BLOctn%2FHua6A0SVsRtUy51HHiWxtL5LKSG1t8DXe7zUPnh56ZqU5pi8Iu45rJYbTwKAXGQt%2BeijthqK5KuAaf9xYNyodmN3ekpf0CDvVesBtpOHO5H%2FJIfa%2BhCYqLI6vv%2FwJrxbraOPCvjV7TFeSniocFLLNWi9vHdmucdnGkNGDFZXFMsSbzsLTW3EMXKk%2BUOHXDiUZvKn6lXv2m1Odl65rQnXo5ICeD7%2BmA%3D%3D: HTTPSConnectionPool(host='storage.googleapis.com', port=443): Max retries exceeded with url: /wandb-artifacts-prod/wandb_artifacts/120300447/661768373/521e54ab95c254e02c4ef790d5def9ec?Expires=1702149673&GoogleAccessId=gorilla-files-url-signer-man%40wandb-production.iam.gserviceaccount.com&Signature=fWMKl4WNB7xDCuLXBlggttukI7S73o1o80R8hwoAZc9W3aRVkaYs%2Fhst3TPscj%2FmgkAh0M6A9LES6yGp3VfKFaPXlqodVITaQLFDuA1LWtf8MRVI9%2BLOctn%2FHua6A0SVsRtUy51HHiWxtL5LKSG1t8DXe7zUPnh56ZqU5pi8Iu45rJYbTwKAXGQt%2BeijthqK5KuAaf9xYNyodmN3ekpf0CDvVesBtpOHO5H%2FJIfa%2BhCYqLI6vv%2FwJrxbraOPCvjV7TFeSniocFLLNWi9vHdmucdnGkNGDFZXFMsSbzsLTW3EMXKk%2BUOHXDiUZvKn6lXv2m1Odl65rQnXo5ICeD7%2BmA%3D%3D (Caused by NewConnectionError('<urllib3.connection.HTTPSConnection object at 0x2b9ca270d340>: Failed to establish a new connection: [Errno 101] Network is unreachable'))
2023-12-08 20:21:16,380 ERROR   wandb-upload_1:27837 [internal_api.py:upload_file():2558] upload_file request headers: {'User-Agent': 'python-requests/2.28.1', 'Accept-Encoding': 'gzip, deflate, br', 'Accept': '*/*', 'Connection': 'keep-alive', 'Content-MD5': 'Uh5Uq5XCVOAsTveQ1d757A==', 'Content-Type': 'text/plain; charset=utf-8', 'Content-Length': '1820'}
2023-12-08 20:21:16,380 ERROR   wandb-upload_1:27837 [internal_api.py:upload_file():2560] upload_file response body: 
2023-12-08 20:21:16,380 INFO    wandb-upload_1:27837 [retry.py:__call__():172] Retry attempt failed:
Traceback (most recent call last):
  File "/cluster/home/yutang/miniconda3/lib/python3.9/site-packages/urllib3/connection.py", line 174, in _new_conn
    conn = connection.create_connection(
  File "/cluster/home/yutang/miniconda3/lib/python3.9/site-packages/urllib3/util/connection.py", line 95, in create_connection
    raise err
  File "/cluster/home/yutang/miniconda3/lib/python3.9/site-packages/urllib3/util/connection.py", line 85, in create_connection
    sock.connect(sa)
OSError: [Errno 101] Network is unreachable

During handling of the above exception, another exception occurred:

Traceback (most recent call last):
  File "/cluster/home/yutang/miniconda3/lib/python3.9/site-packages/urllib3/connectionpool.py", line 703, in urlopen
    httplib_response = self._make_request(
  File "/cluster/home/yutang/miniconda3/lib/python3.9/site-packages/urllib3/connectionpool.py", line 386, in _make_request
    self._validate_conn(conn)
  File "/cluster/home/yutang/miniconda3/lib/python3.9/site-packages/urllib3/connectionpool.py", line 1042, in _validate_conn
    conn.connect()
  File "/cluster/home/yutang/miniconda3/lib/python3.9/site-packages/urllib3/connection.py", line 358, in connect
    self.sock = conn = self._new_conn()
  File "/cluster/home/yutang/miniconda3/lib/python3.9/site-packages/urllib3/connection.py", line 186, in _new_conn
    raise NewConnectionError(
urllib3.exceptions.NewConnectionError: <urllib3.connection.HTTPSConnection object at 0x2b9ca270d340>: Failed to establish a new connection: [Errno 101] Network is unreachable

During handling of the above exception, another exception occurred:

Traceback (most recent call last):
  File "/cluster/home/yutang/miniconda3/lib/python3.9/site-packages/requests/adapters.py", line 489, in send
    resp = conn.urlopen(
  File "/cluster/home/yutang/miniconda3/lib/python3.9/site-packages/urllib3/connectionpool.py", line 787, in urlopen
    retries = retries.increment(
  File "/cluster/home/yutang/miniconda3/lib/python3.9/site-packages/urllib3/util/retry.py", line 592, in increment
    raise MaxRetryError(_pool, url, error or ResponseError(cause))
urllib3.exceptions.MaxRetryError: HTTPSConnectionPool(host='storage.googleapis.com', port=443): Max retries exceeded with url: /wandb-artifacts-prod/wandb_artifacts/120300447/661768373/521e54ab95c254e02c4ef790d5def9ec?Expires=1702149673&GoogleAccessId=gorilla-files-url-signer-man%40wandb-production.iam.gserviceaccount.com&Signature=fWMKl4WNB7xDCuLXBlggttukI7S73o1o80R8hwoAZc9W3aRVkaYs%2Fhst3TPscj%2FmgkAh0M6A9LES6yGp3VfKFaPXlqodVITaQLFDuA1LWtf8MRVI9%2BLOctn%2FHua6A0SVsRtUy51HHiWxtL5LKSG1t8DXe7zUPnh56ZqU5pi8Iu45rJYbTwKAXGQt%2BeijthqK5KuAaf9xYNyodmN3ekpf0CDvVesBtpOHO5H%2FJIfa%2BhCYqLI6vv%2FwJrxbraOPCvjV7TFeSniocFLLNWi9vHdmucdnGkNGDFZXFMsSbzsLTW3EMXKk%2BUOHXDiUZvKn6lXv2m1Odl65rQnXo5ICeD7%2BmA%3D%3D (Caused by NewConnectionError('<urllib3.connection.HTTPSConnection object at 0x2b9ca270d340>: Failed to establish a new connection: [Errno 101] Network is unreachable'))

During handling of the above exception, another exception occurred:

Traceback (most recent call last):
  File "/cluster/home/yutang/miniconda3/lib/python3.9/site-packages/wandb/sdk/internal/internal_api.py", line 2549, in upload_file
    response = self._upload_file_session.put(
  File "/cluster/home/yutang/miniconda3/lib/python3.9/site-packages/requests/sessions.py", line 647, in put
    return self.request("PUT", url, data=data, **kwargs)
  File "/cluster/home/yutang/miniconda3/lib/python3.9/site-packages/requests/sessions.py", line 587, in request
    resp = self.send(prep, **send_kwargs)
  File "/cluster/home/yutang/miniconda3/lib/python3.9/site-packages/requests/sessions.py", line 701, in send
    r = adapter.send(request, **kwargs)
  File "/cluster/home/yutang/miniconda3/lib/python3.9/site-packages/requests/adapters.py", line 565, in send
    raise ConnectionError(e, request=request)
requests.exceptions.ConnectionError: HTTPSConnectionPool(host='storage.googleapis.com', port=443): Max retries exceeded with url: /wandb-artifacts-prod/wandb_artifacts/120300447/661768373/521e54ab95c254e02c4ef790d5def9ec?Expires=1702149673&GoogleAccessId=gorilla-files-url-signer-man%40wandb-production.iam.gserviceaccount.com&Signature=fWMKl4WNB7xDCuLXBlggttukI7S73o1o80R8hwoAZc9W3aRVkaYs%2Fhst3TPscj%2FmgkAh0M6A9LES6yGp3VfKFaPXlqodVITaQLFDuA1LWtf8MRVI9%2BLOctn%2FHua6A0SVsRtUy51HHiWxtL5LKSG1t8DXe7zUPnh56ZqU5pi8Iu45rJYbTwKAXGQt%2BeijthqK5KuAaf9xYNyodmN3ekpf0CDvVesBtpOHO5H%2FJIfa%2BhCYqLI6vv%2FwJrxbraOPCvjV7TFeSniocFLLNWi9vHdmucdnGkNGDFZXFMsSbzsLTW3EMXKk%2BUOHXDiUZvKn6lXv2m1Odl65rQnXo5ICeD7%2BmA%3D%3D (Caused by NewConnectionError('<urllib3.connection.HTTPSConnection object at 0x2b9ca270d340>: Failed to establish a new connection: [Errno 101] Network is unreachable'))

During handling of the above exception, another exception occurred:

Traceback (most recent call last):
  File "/cluster/home/yutang/miniconda3/lib/python3.9/site-packages/wandb/sdk/lib/retry.py", line 131, in __call__
    result = self._call_fn(*args, **kwargs)
  File "/cluster/home/yutang/miniconda3/lib/python3.9/site-packages/wandb/sdk/internal/internal_api.py", line 2580, in upload_file
    raise _e.with_traceback(sys.exc_info()[2])
  File "/cluster/home/yutang/miniconda3/lib/python3.9/site-packages/wandb/sdk/internal/internal_api.py", line 2549, in upload_file
    response = self._upload_file_session.put(
  File "/cluster/home/yutang/miniconda3/lib/python3.9/site-packages/requests/sessions.py", line 647, in put
    return self.request("PUT", url, data=data, **kwargs)
  File "/cluster/home/yutang/miniconda3/lib/python3.9/site-packages/requests/sessions.py", line 587, in request
    resp = self.send(prep, **send_kwargs)
  File "/cluster/home/yutang/miniconda3/lib/python3.9/site-packages/requests/sessions.py", line 701, in send
    r = adapter.send(request, **kwargs)
  File "/cluster/home/yutang/miniconda3/lib/python3.9/site-packages/requests/adapters.py", line 565, in send
    raise ConnectionError(e, request=request)
wandb.sdk.lib.retry.TransientError: None
2023-12-08 20:21:16,380 ERROR   wandb-upload_2:27837 [internal_api.py:upload_file():2556] upload_file exception https://storage.googleapis.com/wandb-artifacts-prod/wandb_artifacts/120300447/661768373/7d403960cc78ee51501901f4effaf804?Expires=1702149673&GoogleAccessId=gorilla-files-url-signer-man%40wandb-production.iam.gserviceaccount.com&Signature=L8AQMQPD7qLLhZtGhc3fzIzQX9C9uQJUI2jyh%2BJsrZF63PAECSlMX8H6XhBEPdkG8nFmOHXM9Mozf3qjmGR9by9ZJlrWTSbvVjAM%2BTxcTSmfQrjBFNmR%2BufbstUknoHi52uQ69nCgb4UspHPaBbgrvdhHEGKe%2BZaRx1Kef39N7OBS%2BZykfBnBEutYwt4XJc0w3K2gzWufouZkIeCNbipE7YExQgKHaSaFMAXv2mYoFpV8Vw8ex6J%2Fu5H%2F84erlMNU5hqp2GzsW%2F3FSTKbITK7u5G2qJ1Mfd3ehEW58R6y81PQqkBhMEWqO%2BLsA02hyF8y%2BRWYR6Igiq9oNWsM2j74w%3D%3D: HTTPSConnectionPool(host='storage.googleapis.com', port=443): Max retries exceeded with url: /wandb-artifacts-prod/wandb_artifacts/120300447/661768373/7d403960cc78ee51501901f4effaf804?Expires=1702149673&GoogleAccessId=gorilla-files-url-signer-man%40wandb-production.iam.gserviceaccount.com&Signature=L8AQMQPD7qLLhZtGhc3fzIzQX9C9uQJUI2jyh%2BJsrZF63PAECSlMX8H6XhBEPdkG8nFmOHXM9Mozf3qjmGR9by9ZJlrWTSbvVjAM%2BTxcTSmfQrjBFNmR%2BufbstUknoHi52uQ69nCgb4UspHPaBbgrvdhHEGKe%2BZaRx1Kef39N7OBS%2BZykfBnBEutYwt4XJc0w3K2gzWufouZkIeCNbipE7YExQgKHaSaFMAXv2mYoFpV8Vw8ex6J%2Fu5H%2F84erlMNU5hqp2GzsW%2F3FSTKbITK7u5G2qJ1Mfd3ehEW58R6y81PQqkBhMEWqO%2BLsA02hyF8y%2BRWYR6Igiq9oNWsM2j74w%3D%3D (Caused by NewConnectionError('<urllib3.connection.HTTPSConnection object at 0x2b9ca270d580>: Failed to establish a new connection: [Errno 101] Network is unreachable'))
2023-12-08 20:21:16,381 ERROR   wandb-upload_2:27837 [internal_api.py:upload_file():2558] upload_file request headers: {'User-Agent': 'python-requests/2.28.1', 'Accept-Encoding': 'gzip, deflate, br', 'Accept': '*/*', 'Connection': 'keep-alive', 'Content-MD5': 'fUA5YMx47lFQGQH07/r4BA==', 'Content-Type': 'application/json', 'Content-Length': '648'}
2023-12-08 20:21:16,381 ERROR   wandb-upload_2:27837 [internal_api.py:upload_file():2560] upload_file response body: 
2023-12-08 20:21:16,381 INFO    wandb-upload_2:27837 [retry.py:__call__():172] Retry attempt failed:
Traceback (most recent call last):
  File "/cluster/home/yutang/miniconda3/lib/python3.9/site-packages/urllib3/connection.py", line 174, in _new_conn
    conn = connection.create_connection(
  File "/cluster/home/yutang/miniconda3/lib/python3.9/site-packages/urllib3/util/connection.py", line 95, in create_connection
    raise err
  File "/cluster/home/yutang/miniconda3/lib/python3.9/site-packages/urllib3/util/connection.py", line 85, in create_connection
    sock.connect(sa)
OSError: [Errno 101] Network is unreachable

During handling of the above exception, another exception occurred:

Traceback (most recent call last):
  File "/cluster/home/yutang/miniconda3/lib/python3.9/site-packages/urllib3/connectionpool.py", line 703, in urlopen
    httplib_response = self._make_request(
  File "/cluster/home/yutang/miniconda3/lib/python3.9/site-packages/urllib3/connectionpool.py", line 386, in _make_request
    self._validate_conn(conn)
  File "/cluster/home/yutang/miniconda3/lib/python3.9/site-packages/urllib3/connectionpool.py", line 1042, in _validate_conn
    conn.connect()
  File "/cluster/home/yutang/miniconda3/lib/python3.9/site-packages/urllib3/connection.py", line 358, in connect
    self.sock = conn = self._new_conn()
  File "/cluster/home/yutang/miniconda3/lib/python3.9/site-packages/urllib3/connection.py", line 186, in _new_conn
    raise NewConnectionError(
urllib3.exceptions.NewConnectionError: <urllib3.connection.HTTPSConnection object at 0x2b9ca270d580>: Failed to establish a new connection: [Errno 101] Network is unreachable

During handling of the above exception, another exception occurred:

Traceback (most recent call last):
  File "/cluster/home/yutang/miniconda3/lib/python3.9/site-packages/requests/adapters.py", line 489, in send
    resp = conn.urlopen(
  File "/cluster/home/yutang/miniconda3/lib/python3.9/site-packages/urllib3/connectionpool.py", line 787, in urlopen
    retries = retries.increment(
  File "/cluster/home/yutang/miniconda3/lib/python3.9/site-packages/urllib3/util/retry.py", line 592, in increment
    raise MaxRetryError(_pool, url, error or ResponseError(cause))
urllib3.exceptions.MaxRetryError: HTTPSConnectionPool(host='storage.googleapis.com', port=443): Max retries exceeded with url: /wandb-artifacts-prod/wandb_artifacts/120300447/661768373/7d403960cc78ee51501901f4effaf804?Expires=1702149673&GoogleAccessId=gorilla-files-url-signer-man%40wandb-production.iam.gserviceaccount.com&Signature=L8AQMQPD7qLLhZtGhc3fzIzQX9C9uQJUI2jyh%2BJsrZF63PAECSlMX8H6XhBEPdkG8nFmOHXM9Mozf3qjmGR9by9ZJlrWTSbvVjAM%2BTxcTSmfQrjBFNmR%2BufbstUknoHi52uQ69nCgb4UspHPaBbgrvdhHEGKe%2BZaRx1Kef39N7OBS%2BZykfBnBEutYwt4XJc0w3K2gzWufouZkIeCNbipE7YExQgKHaSaFMAXv2mYoFpV8Vw8ex6J%2Fu5H%2F84erlMNU5hqp2GzsW%2F3FSTKbITK7u5G2qJ1Mfd3ehEW58R6y81PQqkBhMEWqO%2BLsA02hyF8y%2BRWYR6Igiq9oNWsM2j74w%3D%3D (Caused by NewConnectionError('<urllib3.connection.HTTPSConnection object at 0x2b9ca270d580>: Failed to establish a new connection: [Errno 101] Network is unreachable'))

During handling of the above exception, another exception occurred:

Traceback (most recent call last):
  File "/cluster/home/yutang/miniconda3/lib/python3.9/site-packages/wandb/sdk/internal/internal_api.py", line 2549, in upload_file
    response = self._upload_file_session.put(
  File "/cluster/home/yutang/miniconda3/lib/python3.9/site-packages/requests/sessions.py", line 647, in put
    return self.request("PUT", url, data=data, **kwargs)
  File "/cluster/home/yutang/miniconda3/lib/python3.9/site-packages/requests/sessions.py", line 587, in request
    resp = self.send(prep, **send_kwargs)
  File "/cluster/home/yutang/miniconda3/lib/python3.9/site-packages/requests/sessions.py", line 701, in send
    r = adapter.send(request, **kwargs)
  File "/cluster/home/yutang/miniconda3/lib/python3.9/site-packages/requests/adapters.py", line 565, in send
    raise ConnectionError(e, request=request)
requests.exceptions.ConnectionError: HTTPSConnectionPool(host='storage.googleapis.com', port=443): Max retries exceeded with url: /wandb-artifacts-prod/wandb_artifacts/120300447/661768373/7d403960cc78ee51501901f4effaf804?Expires=1702149673&GoogleAccessId=gorilla-files-url-signer-man%40wandb-production.iam.gserviceaccount.com&Signature=L8AQMQPD7qLLhZtGhc3fzIzQX9C9uQJUI2jyh%2BJsrZF63PAECSlMX8H6XhBEPdkG8nFmOHXM9Mozf3qjmGR9by9ZJlrWTSbvVjAM%2BTxcTSmfQrjBFNmR%2BufbstUknoHi52uQ69nCgb4UspHPaBbgrvdhHEGKe%2BZaRx1Kef39N7OBS%2BZykfBnBEutYwt4XJc0w3K2gzWufouZkIeCNbipE7YExQgKHaSaFMAXv2mYoFpV8Vw8ex6J%2Fu5H%2F84erlMNU5hqp2GzsW%2F3FSTKbITK7u5G2qJ1Mfd3ehEW58R6y81PQqkBhMEWqO%2BLsA02hyF8y%2BRWYR6Igiq9oNWsM2j74w%3D%3D (Caused by NewConnectionError('<urllib3.connection.HTTPSConnection object at 0x2b9ca270d580>: Failed to establish a new connection: [Errno 101] Network is unreachable'))

During handling of the above exception, another exception occurred:

Traceback (most recent call last):
  File "/cluster/home/yutang/miniconda3/lib/python3.9/site-packages/wandb/sdk/lib/retry.py", line 131, in __call__
    result = self._call_fn(*args, **kwargs)
  File "/cluster/home/yutang/miniconda3/lib/python3.9/site-packages/wandb/sdk/internal/internal_api.py", line 2580, in upload_file
    raise _e.with_traceback(sys.exc_info()[2])
  File "/cluster/home/yutang/miniconda3/lib/python3.9/site-packages/wandb/sdk/internal/internal_api.py", line 2549, in upload_file
    response = self._upload_file_session.put(
  File "/cluster/home/yutang/miniconda3/lib/python3.9/site-packages/requests/sessions.py", line 647, in put
    return self.request("PUT", url, data=data, **kwargs)
  File "/cluster/home/yutang/miniconda3/lib/python3.9/site-packages/requests/sessions.py", line 587, in request
    resp = self.send(prep, **send_kwargs)
  File "/cluster/home/yutang/miniconda3/lib/python3.9/site-packages/requests/sessions.py", line 701, in send
    r = adapter.send(request, **kwargs)
  File "/cluster/home/yutang/miniconda3/lib/python3.9/site-packages/requests/adapters.py", line 565, in send
    raise ConnectionError(e, request=request)
wandb.sdk.lib.retry.TransientError: None
2023-12-08 20:21:19,161 ERROR   wandb-upload_0:27837 [internal_api.py:upload_file():2556] upload_file exception https://storage.googleapis.com/wandb-production.appspot.com/bryant-tang-ethz/DKT-trial%201/c30p1g8z/wandb-metadata.json?Expires=1702149661&GoogleAccessId=gorilla-files-url-signer-man%40wandb-production.iam.gserviceaccount.com&Signature=KexFrx2bT1sRpPrCOnyFHTll42CAL7GxpXaMUOibyXhHbJN9T9Y%2FkSS2BhtTRt%2BioM0ny%2BCcaNtgQZe%2FzjvryjM0lcTOFtJCbc1Gxa278S7GHDcQF7PcW2QxQJ3VIijjPFkEf%2Br%2F%2By0fGDwyCbb%2BtkeUCSjgwdPwykXxdGyTgGmZa13eMGWnGiDKtOaji3FpdhOF4OI3LTDBARhwUEsu8yoCFTi9RVUMEVuOt7rquhqaIfYBWN53r2CGofT7pRk%2BM0WftI%2B3m%2F9qIDWDvz9lu6sRo8u2sZuHUspSYiQBAnUKOOy5lRwySufIHuk1SVhkU1Z%2F4pqKPW%2B%2B1SX6i7iqJg%3D%3D: HTTPSConnectionPool(host='storage.googleapis.com', port=443): Max retries exceeded with url: /wandb-production.appspot.com/bryant-tang-ethz/DKT-trial%201/c30p1g8z/wandb-metadata.json?Expires=1702149661&GoogleAccessId=gorilla-files-url-signer-man%40wandb-production.iam.gserviceaccount.com&Signature=KexFrx2bT1sRpPrCOnyFHTll42CAL7GxpXaMUOibyXhHbJN9T9Y%2FkSS2BhtTRt%2BioM0ny%2BCcaNtgQZe%2FzjvryjM0lcTOFtJCbc1Gxa278S7GHDcQF7PcW2QxQJ3VIijjPFkEf%2Br%2F%2By0fGDwyCbb%2BtkeUCSjgwdPwykXxdGyTgGmZa13eMGWnGiDKtOaji3FpdhOF4OI3LTDBARhwUEsu8yoCFTi9RVUMEVuOt7rquhqaIfYBWN53r2CGofT7pRk%2BM0WftI%2B3m%2F9qIDWDvz9lu6sRo8u2sZuHUspSYiQBAnUKOOy5lRwySufIHuk1SVhkU1Z%2F4pqKPW%2B%2B1SX6i7iqJg%3D%3D (Caused by NewConnectionError('<urllib3.connection.HTTPSConnection object at 0x2b9ca270d0a0>: Failed to establish a new connection: [Errno 101] Network is unreachable'))
2023-12-08 20:21:19,162 ERROR   wandb-upload_0:27837 [internal_api.py:upload_file():2558] upload_file request headers: {'User-Agent': 'python-requests/2.28.1', 'Accept-Encoding': 'gzip, deflate, br', 'Accept': '*/*', 'Connection': 'keep-alive', 'Content-Length': '14827'}
2023-12-08 20:21:19,162 ERROR   wandb-upload_0:27837 [internal_api.py:upload_file():2560] upload_file response body: 
2023-12-08 20:21:20,070 DEBUG   HandlerThread:27837 [handler.py:handle_request():146] handle_request: keepalive
2023-12-08 20:21:20,483 ERROR   wandb-upload_1:27837 [internal_api.py:upload_file():2556] upload_file exception https://storage.googleapis.com/wandb-artifacts-prod/wandb_artifacts/120300447/661768373/521e54ab95c254e02c4ef790d5def9ec?Expires=1702149673&GoogleAccessId=gorilla-files-url-signer-man%40wandb-production.iam.gserviceaccount.com&Signature=fWMKl4WNB7xDCuLXBlggttukI7S73o1o80R8hwoAZc9W3aRVkaYs%2Fhst3TPscj%2FmgkAh0M6A9LES6yGp3VfKFaPXlqodVITaQLFDuA1LWtf8MRVI9%2BLOctn%2FHua6A0SVsRtUy51HHiWxtL5LKSG1t8DXe7zUPnh56ZqU5pi8Iu45rJYbTwKAXGQt%2BeijthqK5KuAaf9xYNyodmN3ekpf0CDvVesBtpOHO5H%2FJIfa%2BhCYqLI6vv%2FwJrxbraOPCvjV7TFeSniocFLLNWi9vHdmucdnGkNGDFZXFMsSbzsLTW3EMXKk%2BUOHXDiUZvKn6lXv2m1Odl65rQnXo5ICeD7%2BmA%3D%3D: HTTPSConnectionPool(host='storage.googleapis.com', port=443): Max retries exceeded with url: /wandb-artifacts-prod/wandb_artifacts/120300447/661768373/521e54ab95c254e02c4ef790d5def9ec?Expires=1702149673&GoogleAccessId=gorilla-files-url-signer-man%40wandb-production.iam.gserviceaccount.com&Signature=fWMKl4WNB7xDCuLXBlggttukI7S73o1o80R8hwoAZc9W3aRVkaYs%2Fhst3TPscj%2FmgkAh0M6A9LES6yGp3VfKFaPXlqodVITaQLFDuA1LWtf8MRVI9%2BLOctn%2FHua6A0SVsRtUy51HHiWxtL5LKSG1t8DXe7zUPnh56ZqU5pi8Iu45rJYbTwKAXGQt%2BeijthqK5KuAaf9xYNyodmN3ekpf0CDvVesBtpOHO5H%2FJIfa%2BhCYqLI6vv%2FwJrxbraOPCvjV7TFeSniocFLLNWi9vHdmucdnGkNGDFZXFMsSbzsLTW3EMXKk%2BUOHXDiUZvKn6lXv2m1Odl65rQnXo5ICeD7%2BmA%3D%3D (Caused by NewConnectionError('<urllib3.connection.HTTPSConnection object at 0x2b9ca270dcd0>: Failed to establish a new connection: [Errno 101] Network is unreachable'))
2023-12-08 20:21:20,483 ERROR   wandb-upload_1:27837 [internal_api.py:upload_file():2558] upload_file request headers: {'User-Agent': 'python-requests/2.28.1', 'Accept-Encoding': 'gzip, deflate, br', 'Accept': '*/*', 'Connection': 'keep-alive', 'Content-MD5': 'Uh5Uq5XCVOAsTveQ1d757A==', 'Content-Type': 'text/plain; charset=utf-8', 'Content-Length': '1820'}
2023-12-08 20:21:20,483 ERROR   wandb-upload_1:27837 [internal_api.py:upload_file():2560] upload_file response body: 
2023-12-08 20:21:20,802 ERROR   wandb-upload_2:27837 [internal_api.py:upload_file():2556] upload_file exception https://storage.googleapis.com/wandb-artifacts-prod/wandb_artifacts/120300447/661768373/7d403960cc78ee51501901f4effaf804?Expires=1702149673&GoogleAccessId=gorilla-files-url-signer-man%40wandb-production.iam.gserviceaccount.com&Signature=L8AQMQPD7qLLhZtGhc3fzIzQX9C9uQJUI2jyh%2BJsrZF63PAECSlMX8H6XhBEPdkG8nFmOHXM9Mozf3qjmGR9by9ZJlrWTSbvVjAM%2BTxcTSmfQrjBFNmR%2BufbstUknoHi52uQ69nCgb4UspHPaBbgrvdhHEGKe%2BZaRx1Kef39N7OBS%2BZykfBnBEutYwt4XJc0w3K2gzWufouZkIeCNbipE7YExQgKHaSaFMAXv2mYoFpV8Vw8ex6J%2Fu5H%2F84erlMNU5hqp2GzsW%2F3FSTKbITK7u5G2qJ1Mfd3ehEW58R6y81PQqkBhMEWqO%2BLsA02hyF8y%2BRWYR6Igiq9oNWsM2j74w%3D%3D: HTTPSConnectionPool(host='storage.googleapis.com', port=443): Max retries exceeded with url: /wandb-artifacts-prod/wandb_artifacts/120300447/661768373/7d403960cc78ee51501901f4effaf804?Expires=1702149673&GoogleAccessId=gorilla-files-url-signer-man%40wandb-production.iam.gserviceaccount.com&Signature=L8AQMQPD7qLLhZtGhc3fzIzQX9C9uQJUI2jyh%2BJsrZF63PAECSlMX8H6XhBEPdkG8nFmOHXM9Mozf3qjmGR9by9ZJlrWTSbvVjAM%2BTxcTSmfQrjBFNmR%2BufbstUknoHi52uQ69nCgb4UspHPaBbgrvdhHEGKe%2BZaRx1Kef39N7OBS%2BZykfBnBEutYwt4XJc0w3K2gzWufouZkIeCNbipE7YExQgKHaSaFMAXv2mYoFpV8Vw8ex6J%2Fu5H%2F84erlMNU5hqp2GzsW%2F3FSTKbITK7u5G2qJ1Mfd3ehEW58R6y81PQqkBhMEWqO%2BLsA02hyF8y%2BRWYR6Igiq9oNWsM2j74w%3D%3D (Caused by NewConnectionError('<urllib3.connection.HTTPSConnection object at 0x2b9ca2713a00>: Failed to establish a new connection: [Errno 101] Network is unreachable'))
2023-12-08 20:21:20,802 ERROR   wandb-upload_2:27837 [internal_api.py:upload_file():2558] upload_file request headers: {'User-Agent': 'python-requests/2.28.1', 'Accept-Encoding': 'gzip, deflate, br', 'Accept': '*/*', 'Connection': 'keep-alive', 'Content-MD5': 'fUA5YMx47lFQGQH07/r4BA==', 'Content-Type': 'application/json', 'Content-Length': '648'}
2023-12-08 20:21:20,802 ERROR   wandb-upload_2:27837 [internal_api.py:upload_file():2560] upload_file response body: 
2023-12-08 20:21:25,072 DEBUG   HandlerThread:27837 [handler.py:handle_request():146] handle_request: keepalive
2023-12-08 20:21:30,073 DEBUG   HandlerThread:27837 [handler.py:handle_request():146] handle_request: keepalive
2023-12-08 20:21:30,097 ERROR   wandb-upload_1:27837 [internal_api.py:upload_file():2556] upload_file exception https://storage.googleapis.com/wandb-artifacts-prod/wandb_artifacts/120300447/661768373/521e54ab95c254e02c4ef790d5def9ec?Expires=1702149673&GoogleAccessId=gorilla-files-url-signer-man%40wandb-production.iam.gserviceaccount.com&Signature=fWMKl4WNB7xDCuLXBlggttukI7S73o1o80R8hwoAZc9W3aRVkaYs%2Fhst3TPscj%2FmgkAh0M6A9LES6yGp3VfKFaPXlqodVITaQLFDuA1LWtf8MRVI9%2BLOctn%2FHua6A0SVsRtUy51HHiWxtL5LKSG1t8DXe7zUPnh56ZqU5pi8Iu45rJYbTwKAXGQt%2BeijthqK5KuAaf9xYNyodmN3ekpf0CDvVesBtpOHO5H%2FJIfa%2BhCYqLI6vv%2FwJrxbraOPCvjV7TFeSniocFLLNWi9vHdmucdnGkNGDFZXFMsSbzsLTW3EMXKk%2BUOHXDiUZvKn6lXv2m1Odl65rQnXo5ICeD7%2BmA%3D%3D: HTTPSConnectionPool(host='storage.googleapis.com', port=443): Max retries exceeded with url: /wandb-artifacts-prod/wandb_artifacts/120300447/661768373/521e54ab95c254e02c4ef790d5def9ec?Expires=1702149673&GoogleAccessId=gorilla-files-url-signer-man%40wandb-production.iam.gserviceaccount.com&Signature=fWMKl4WNB7xDCuLXBlggttukI7S73o1o80R8hwoAZc9W3aRVkaYs%2Fhst3TPscj%2FmgkAh0M6A9LES6yGp3VfKFaPXlqodVITaQLFDuA1LWtf8MRVI9%2BLOctn%2FHua6A0SVsRtUy51HHiWxtL5LKSG1t8DXe7zUPnh56ZqU5pi8Iu45rJYbTwKAXGQt%2BeijthqK5KuAaf9xYNyodmN3ekpf0CDvVesBtpOHO5H%2FJIfa%2BhCYqLI6vv%2FwJrxbraOPCvjV7TFeSniocFLLNWi9vHdmucdnGkNGDFZXFMsSbzsLTW3EMXKk%2BUOHXDiUZvKn6lXv2m1Odl65rQnXo5ICeD7%2BmA%3D%3D (Caused by NewConnectionError('<urllib3.connection.HTTPSConnection object at 0x2b9ca271d2e0>: Failed to establish a new connection: [Errno 101] Network is unreachable'))
2023-12-08 20:21:30,097 ERROR   wandb-upload_1:27837 [internal_api.py:upload_file():2558] upload_file request headers: {'User-Agent': 'python-requests/2.28.1', 'Accept-Encoding': 'gzip, deflate, br', 'Accept': '*/*', 'Connection': 'keep-alive', 'Content-MD5': 'Uh5Uq5XCVOAsTveQ1d757A==', 'Content-Type': 'text/plain; charset=utf-8', 'Content-Length': '1820'}
2023-12-08 20:21:30,097 ERROR   wandb-upload_1:27837 [internal_api.py:upload_file():2560] upload_file response body: 
2023-12-08 20:21:30,556 ERROR   wandb-upload_2:27837 [internal_api.py:upload_file():2556] upload_file exception https://storage.googleapis.com/wandb-artifacts-prod/wandb_artifacts/120300447/661768373/7d403960cc78ee51501901f4effaf804?Expires=1702149673&GoogleAccessId=gorilla-files-url-signer-man%40wandb-production.iam.gserviceaccount.com&Signature=L8AQMQPD7qLLhZtGhc3fzIzQX9C9uQJUI2jyh%2BJsrZF63PAECSlMX8H6XhBEPdkG8nFmOHXM9Mozf3qjmGR9by9ZJlrWTSbvVjAM%2BTxcTSmfQrjBFNmR%2BufbstUknoHi52uQ69nCgb4UspHPaBbgrvdhHEGKe%2BZaRx1Kef39N7OBS%2BZykfBnBEutYwt4XJc0w3K2gzWufouZkIeCNbipE7YExQgKHaSaFMAXv2mYoFpV8Vw8ex6J%2Fu5H%2F84erlMNU5hqp2GzsW%2F3FSTKbITK7u5G2qJ1Mfd3ehEW58R6y81PQqkBhMEWqO%2BLsA02hyF8y%2BRWYR6Igiq9oNWsM2j74w%3D%3D: HTTPSConnectionPool(host='storage.googleapis.com', port=443): Max retries exceeded with url: /wandb-artifacts-prod/wandb_artifacts/120300447/661768373/7d403960cc78ee51501901f4effaf804?Expires=1702149673&GoogleAccessId=gorilla-files-url-signer-man%40wandb-production.iam.gserviceaccount.com&Signature=L8AQMQPD7qLLhZtGhc3fzIzQX9C9uQJUI2jyh%2BJsrZF63PAECSlMX8H6XhBEPdkG8nFmOHXM9Mozf3qjmGR9by9ZJlrWTSbvVjAM%2BTxcTSmfQrjBFNmR%2BufbstUknoHi52uQ69nCgb4UspHPaBbgrvdhHEGKe%2BZaRx1Kef39N7OBS%2BZykfBnBEutYwt4XJc0w3K2gzWufouZkIeCNbipE7YExQgKHaSaFMAXv2mYoFpV8Vw8ex6J%2Fu5H%2F84erlMNU5hqp2GzsW%2F3FSTKbITK7u5G2qJ1Mfd3ehEW58R6y81PQqkBhMEWqO%2BLsA02hyF8y%2BRWYR6Igiq9oNWsM2j74w%3D%3D (Caused by NewConnectionError('<urllib3.connection.HTTPSConnection object at 0x2b9ca2713430>: Failed to establish a new connection: [Errno 101] Network is unreachable'))
2023-12-08 20:21:30,556 ERROR   wandb-upload_2:27837 [internal_api.py:upload_file():2558] upload_file request headers: {'User-Agent': 'python-requests/2.28.1', 'Accept-Encoding': 'gzip, deflate, br', 'Accept': '*/*', 'Connection': 'keep-alive', 'Content-MD5': 'fUA5YMx47lFQGQH07/r4BA==', 'Content-Type': 'application/json', 'Content-Length': '648'}
2023-12-08 20:21:30,556 ERROR   wandb-upload_2:27837 [internal_api.py:upload_file():2560] upload_file response body: 
2023-12-08 20:21:35,074 DEBUG   HandlerThread:27837 [handler.py:handle_request():146] handle_request: keepalive
2023-12-08 20:21:36,759 ERROR   wandb-upload_0:27837 [internal_api.py:upload_file():2556] upload_file exception https://storage.googleapis.com/wandb-production.appspot.com/bryant-tang-ethz/DKT-trial%201/c30p1g8z/wandb-metadata.json?Expires=1702149661&GoogleAccessId=gorilla-files-url-signer-man%40wandb-production.iam.gserviceaccount.com&Signature=KexFrx2bT1sRpPrCOnyFHTll42CAL7GxpXaMUOibyXhHbJN9T9Y%2FkSS2BhtTRt%2BioM0ny%2BCcaNtgQZe%2FzjvryjM0lcTOFtJCbc1Gxa278S7GHDcQF7PcW2QxQJ3VIijjPFkEf%2Br%2F%2By0fGDwyCbb%2BtkeUCSjgwdPwykXxdGyTgGmZa13eMGWnGiDKtOaji3FpdhOF4OI3LTDBARhwUEsu8yoCFTi9RVUMEVuOt7rquhqaIfYBWN53r2CGofT7pRk%2BM0WftI%2B3m%2F9qIDWDvz9lu6sRo8u2sZuHUspSYiQBAnUKOOy5lRwySufIHuk1SVhkU1Z%2F4pqKPW%2B%2B1SX6i7iqJg%3D%3D: HTTPSConnectionPool(host='storage.googleapis.com', port=443): Max retries exceeded with url: /wandb-production.appspot.com/bryant-tang-ethz/DKT-trial%201/c30p1g8z/wandb-metadata.json?Expires=1702149661&GoogleAccessId=gorilla-files-url-signer-man%40wandb-production.iam.gserviceaccount.com&Signature=KexFrx2bT1sRpPrCOnyFHTll42CAL7GxpXaMUOibyXhHbJN9T9Y%2FkSS2BhtTRt%2BioM0ny%2BCcaNtgQZe%2FzjvryjM0lcTOFtJCbc1Gxa278S7GHDcQF7PcW2QxQJ3VIijjPFkEf%2Br%2F%2By0fGDwyCbb%2BtkeUCSjgwdPwykXxdGyTgGmZa13eMGWnGiDKtOaji3FpdhOF4OI3LTDBARhwUEsu8yoCFTi9RVUMEVuOt7rquhqaIfYBWN53r2CGofT7pRk%2BM0WftI%2B3m%2F9qIDWDvz9lu6sRo8u2sZuHUspSYiQBAnUKOOy5lRwySufIHuk1SVhkU1Z%2F4pqKPW%2B%2B1SX6i7iqJg%3D%3D (Caused by NewConnectionError('<urllib3.connection.HTTPSConnection object at 0x2b9ca2713790>: Failed to establish a new connection: [Errno 101] Network is unreachable'))
2023-12-08 20:21:36,759 ERROR   wandb-upload_0:27837 [internal_api.py:upload_file():2558] upload_file request headers: {'User-Agent': 'python-requests/2.28.1', 'Accept-Encoding': 'gzip, deflate, br', 'Accept': '*/*', 'Connection': 'keep-alive', 'Content-Length': '14827'}
2023-12-08 20:21:36,760 ERROR   wandb-upload_0:27837 [internal_api.py:upload_file():2560] upload_file response body: 
2023-12-08 20:21:40,075 DEBUG   HandlerThread:27837 [handler.py:handle_request():146] handle_request: keepalive
2023-12-08 20:21:45,077 DEBUG   HandlerThread:27837 [handler.py:handle_request():146] handle_request: keepalive
2023-12-08 20:21:48,398 ERROR   wandb-upload_2:27837 [internal_api.py:upload_file():2556] upload_file exception https://storage.googleapis.com/wandb-artifacts-prod/wandb_artifacts/120300447/661768373/7d403960cc78ee51501901f4effaf804?Expires=1702149673&GoogleAccessId=gorilla-files-url-signer-man%40wandb-production.iam.gserviceaccount.com&Signature=L8AQMQPD7qLLhZtGhc3fzIzQX9C9uQJUI2jyh%2BJsrZF63PAECSlMX8H6XhBEPdkG8nFmOHXM9Mozf3qjmGR9by9ZJlrWTSbvVjAM%2BTxcTSmfQrjBFNmR%2BufbstUknoHi52uQ69nCgb4UspHPaBbgrvdhHEGKe%2BZaRx1Kef39N7OBS%2BZykfBnBEutYwt4XJc0w3K2gzWufouZkIeCNbipE7YExQgKHaSaFMAXv2mYoFpV8Vw8ex6J%2Fu5H%2F84erlMNU5hqp2GzsW%2F3FSTKbITK7u5G2qJ1Mfd3ehEW58R6y81PQqkBhMEWqO%2BLsA02hyF8y%2BRWYR6Igiq9oNWsM2j74w%3D%3D: HTTPSConnectionPool(host='storage.googleapis.com', port=443): Max retries exceeded with url: /wandb-artifacts-prod/wandb_artifacts/120300447/661768373/7d403960cc78ee51501901f4effaf804?Expires=1702149673&GoogleAccessId=gorilla-files-url-signer-man%40wandb-production.iam.gserviceaccount.com&Signature=L8AQMQPD7qLLhZtGhc3fzIzQX9C9uQJUI2jyh%2BJsrZF63PAECSlMX8H6XhBEPdkG8nFmOHXM9Mozf3qjmGR9by9ZJlrWTSbvVjAM%2BTxcTSmfQrjBFNmR%2BufbstUknoHi52uQ69nCgb4UspHPaBbgrvdhHEGKe%2BZaRx1Kef39N7OBS%2BZykfBnBEutYwt4XJc0w3K2gzWufouZkIeCNbipE7YExQgKHaSaFMAXv2mYoFpV8Vw8ex6J%2Fu5H%2F84erlMNU5hqp2GzsW%2F3FSTKbITK7u5G2qJ1Mfd3ehEW58R6y81PQqkBhMEWqO%2BLsA02hyF8y%2BRWYR6Igiq9oNWsM2j74w%3D%3D (Caused by NewConnectionError('<urllib3.connection.HTTPSConnection object at 0x2b9ca2705e20>: Failed to establish a new connection: [Errno 101] Network is unreachable'))
2023-12-08 20:21:48,398 ERROR   wandb-upload_2:27837 [internal_api.py:upload_file():2558] upload_file request headers: {'User-Agent': 'python-requests/2.28.1', 'Accept-Encoding': 'gzip, deflate, br', 'Accept': '*/*', 'Connection': 'keep-alive', 'Content-MD5': 'fUA5YMx47lFQGQH07/r4BA==', 'Content-Type': 'application/json', 'Content-Length': '648'}
2023-12-08 20:21:48,398 ERROR   wandb-upload_2:27837 [internal_api.py:upload_file():2560] upload_file response body: 
2023-12-08 20:21:49,808 ERROR   wandb-upload_1:27837 [internal_api.py:upload_file():2556] upload_file exception https://storage.googleapis.com/wandb-artifacts-prod/wandb_artifacts/120300447/661768373/521e54ab95c254e02c4ef790d5def9ec?Expires=1702149673&GoogleAccessId=gorilla-files-url-signer-man%40wandb-production.iam.gserviceaccount.com&Signature=fWMKl4WNB7xDCuLXBlggttukI7S73o1o80R8hwoAZc9W3aRVkaYs%2Fhst3TPscj%2FmgkAh0M6A9LES6yGp3VfKFaPXlqodVITaQLFDuA1LWtf8MRVI9%2BLOctn%2FHua6A0SVsRtUy51HHiWxtL5LKSG1t8DXe7zUPnh56ZqU5pi8Iu45rJYbTwKAXGQt%2BeijthqK5KuAaf9xYNyodmN3ekpf0CDvVesBtpOHO5H%2FJIfa%2BhCYqLI6vv%2FwJrxbraOPCvjV7TFeSniocFLLNWi9vHdmucdnGkNGDFZXFMsSbzsLTW3EMXKk%2BUOHXDiUZvKn6lXv2m1Odl65rQnXo5ICeD7%2BmA%3D%3D: HTTPSConnectionPool(host='storage.googleapis.com', port=443): Max retries exceeded with url: /wandb-artifacts-prod/wandb_artifacts/120300447/661768373/521e54ab95c254e02c4ef790d5def9ec?Expires=1702149673&GoogleAccessId=gorilla-files-url-signer-man%40wandb-production.iam.gserviceaccount.com&Signature=fWMKl4WNB7xDCuLXBlggttukI7S73o1o80R8hwoAZc9W3aRVkaYs%2Fhst3TPscj%2FmgkAh0M6A9LES6yGp3VfKFaPXlqodVITaQLFDuA1LWtf8MRVI9%2BLOctn%2FHua6A0SVsRtUy51HHiWxtL5LKSG1t8DXe7zUPnh56ZqU5pi8Iu45rJYbTwKAXGQt%2BeijthqK5KuAaf9xYNyodmN3ekpf0CDvVesBtpOHO5H%2FJIfa%2BhCYqLI6vv%2FwJrxbraOPCvjV7TFeSniocFLLNWi9vHdmucdnGkNGDFZXFMsSbzsLTW3EMXKk%2BUOHXDiUZvKn6lXv2m1Odl65rQnXo5ICeD7%2BmA%3D%3D (Caused by NewConnectionError('<urllib3.connection.HTTPSConnection object at 0x2b9ca2705df0>: Failed to establish a new connection: [Errno 101] Network is unreachable'))
2023-12-08 20:21:49,808 ERROR   wandb-upload_1:27837 [internal_api.py:upload_file():2558] upload_file request headers: {'User-Agent': 'python-requests/2.28.1', 'Accept-Encoding': 'gzip, deflate, br', 'Accept': '*/*', 'Connection': 'keep-alive', 'Content-MD5': 'Uh5Uq5XCVOAsTveQ1d757A==', 'Content-Type': 'text/plain; charset=utf-8', 'Content-Length': '1820'}
2023-12-08 20:21:49,808 ERROR   wandb-upload_1:27837 [internal_api.py:upload_file():2560] upload_file response body: 
2023-12-08 20:21:50,078 DEBUG   HandlerThread:27837 [handler.py:handle_request():146] handle_request: keepalive
2023-12-08 20:21:55,080 DEBUG   HandlerThread:27837 [handler.py:handle_request():146] handle_request: keepalive
2023-12-08 20:22:00,081 DEBUG   HandlerThread:27837 [handler.py:handle_request():146] handle_request: keepalive
2023-12-08 20:22:05,083 DEBUG   HandlerThread:27837 [handler.py:handle_request():146] handle_request: keepalive
2023-12-08 20:22:10,084 DEBUG   HandlerThread:27837 [handler.py:handle_request():146] handle_request: keepalive
2023-12-08 20:22:15,086 DEBUG   HandlerThread:27837 [handler.py:handle_request():146] handle_request: keepalive
2023-12-08 20:22:16,359 ERROR   wandb-upload_0:27837 [internal_api.py:upload_file():2556] upload_file exception https://storage.googleapis.com/wandb-production.appspot.com/bryant-tang-ethz/DKT-trial%201/c30p1g8z/wandb-metadata.json?Expires=1702149661&GoogleAccessId=gorilla-files-url-signer-man%40wandb-production.iam.gserviceaccount.com&Signature=KexFrx2bT1sRpPrCOnyFHTll42CAL7GxpXaMUOibyXhHbJN9T9Y%2FkSS2BhtTRt%2BioM0ny%2BCcaNtgQZe%2FzjvryjM0lcTOFtJCbc1Gxa278S7GHDcQF7PcW2QxQJ3VIijjPFkEf%2Br%2F%2By0fGDwyCbb%2BtkeUCSjgwdPwykXxdGyTgGmZa13eMGWnGiDKtOaji3FpdhOF4OI3LTDBARhwUEsu8yoCFTi9RVUMEVuOt7rquhqaIfYBWN53r2CGofT7pRk%2BM0WftI%2B3m%2F9qIDWDvz9lu6sRo8u2sZuHUspSYiQBAnUKOOy5lRwySufIHuk1SVhkU1Z%2F4pqKPW%2B%2B1SX6i7iqJg%3D%3D: HTTPSConnectionPool(host='storage.googleapis.com', port=443): Max retries exceeded with url: /wandb-production.appspot.com/bryant-tang-ethz/DKT-trial%201/c30p1g8z/wandb-metadata.json?Expires=1702149661&GoogleAccessId=gorilla-files-url-signer-man%40wandb-production.iam.gserviceaccount.com&Signature=KexFrx2bT1sRpPrCOnyFHTll42CAL7GxpXaMUOibyXhHbJN9T9Y%2FkSS2BhtTRt%2BioM0ny%2BCcaNtgQZe%2FzjvryjM0lcTOFtJCbc1Gxa278S7GHDcQF7PcW2QxQJ3VIijjPFkEf%2Br%2F%2By0fGDwyCbb%2BtkeUCSjgwdPwykXxdGyTgGmZa13eMGWnGiDKtOaji3FpdhOF4OI3LTDBARhwUEsu8yoCFTi9RVUMEVuOt7rquhqaIfYBWN53r2CGofT7pRk%2BM0WftI%2B3m%2F9qIDWDvz9lu6sRo8u2sZuHUspSYiQBAnUKOOy5lRwySufIHuk1SVhkU1Z%2F4pqKPW%2B%2B1SX6i7iqJg%3D%3D (Caused by NewConnectionError('<urllib3.connection.HTTPSConnection object at 0x2b9ca270b250>: Failed to establish a new connection: [Errno 101] Network is unreachable'))
2023-12-08 20:22:16,359 ERROR   wandb-upload_0:27837 [internal_api.py:upload_file():2558] upload_file request headers: {'User-Agent': 'python-requests/2.28.1', 'Accept-Encoding': 'gzip, deflate, br', 'Accept': '*/*', 'Connection': 'keep-alive', 'Content-Length': '14827'}
2023-12-08 20:22:16,359 ERROR   wandb-upload_0:27837 [internal_api.py:upload_file():2560] upload_file response body: 
2023-12-08 20:22:20,087 DEBUG   HandlerThread:27837 [handler.py:handle_request():146] handle_request: keepalive
2023-12-08 20:22:21,590 ERROR   wandb-upload_2:27837 [internal_api.py:upload_file():2556] upload_file exception https://storage.googleapis.com/wandb-artifacts-prod/wandb_artifacts/120300447/661768373/7d403960cc78ee51501901f4effaf804?Expires=1702149673&GoogleAccessId=gorilla-files-url-signer-man%40wandb-production.iam.gserviceaccount.com&Signature=L8AQMQPD7qLLhZtGhc3fzIzQX9C9uQJUI2jyh%2BJsrZF63PAECSlMX8H6XhBEPdkG8nFmOHXM9Mozf3qjmGR9by9ZJlrWTSbvVjAM%2BTxcTSmfQrjBFNmR%2BufbstUknoHi52uQ69nCgb4UspHPaBbgrvdhHEGKe%2BZaRx1Kef39N7OBS%2BZykfBnBEutYwt4XJc0w3K2gzWufouZkIeCNbipE7YExQgKHaSaFMAXv2mYoFpV8Vw8ex6J%2Fu5H%2F84erlMNU5hqp2GzsW%2F3FSTKbITK7u5G2qJ1Mfd3ehEW58R6y81PQqkBhMEWqO%2BLsA02hyF8y%2BRWYR6Igiq9oNWsM2j74w%3D%3D: HTTPSConnectionPool(host='storage.googleapis.com', port=443): Max retries exceeded with url: /wandb-artifacts-prod/wandb_artifacts/120300447/661768373/7d403960cc78ee51501901f4effaf804?Expires=1702149673&GoogleAccessId=gorilla-files-url-signer-man%40wandb-production.iam.gserviceaccount.com&Signature=L8AQMQPD7qLLhZtGhc3fzIzQX9C9uQJUI2jyh%2BJsrZF63PAECSlMX8H6XhBEPdkG8nFmOHXM9Mozf3qjmGR9by9ZJlrWTSbvVjAM%2BTxcTSmfQrjBFNmR%2BufbstUknoHi52uQ69nCgb4UspHPaBbgrvdhHEGKe%2BZaRx1Kef39N7OBS%2BZykfBnBEutYwt4XJc0w3K2gzWufouZkIeCNbipE7YExQgKHaSaFMAXv2mYoFpV8Vw8ex6J%2Fu5H%2F84erlMNU5hqp2GzsW%2F3FSTKbITK7u5G2qJ1Mfd3ehEW58R6y81PQqkBhMEWqO%2BLsA02hyF8y%2BRWYR6Igiq9oNWsM2j74w%3D%3D (Caused by NewConnectionError('<urllib3.connection.HTTPSConnection object at 0x2b9ca270b190>: Failed to establish a new connection: [Errno 101] Network is unreachable'))
2023-12-08 20:22:21,590 ERROR   wandb-upload_2:27837 [internal_api.py:upload_file():2558] upload_file request headers: {'User-Agent': 'python-requests/2.28.1', 'Accept-Encoding': 'gzip, deflate, br', 'Accept': '*/*', 'Connection': 'keep-alive', 'Content-MD5': 'fUA5YMx47lFQGQH07/r4BA==', 'Content-Type': 'application/json', 'Content-Length': '648'}
2023-12-08 20:22:21,590 ERROR   wandb-upload_2:27837 [internal_api.py:upload_file():2560] upload_file response body: 
2023-12-08 20:22:25,089 DEBUG   HandlerThread:27837 [handler.py:handle_request():146] handle_request: keepalive
2023-12-08 20:22:27,173 ERROR   wandb-upload_1:27837 [internal_api.py:upload_file():2556] upload_file exception https://storage.googleapis.com/wandb-artifacts-prod/wandb_artifacts/120300447/661768373/521e54ab95c254e02c4ef790d5def9ec?Expires=1702149673&GoogleAccessId=gorilla-files-url-signer-man%40wandb-production.iam.gserviceaccount.com&Signature=fWMKl4WNB7xDCuLXBlggttukI7S73o1o80R8hwoAZc9W3aRVkaYs%2Fhst3TPscj%2FmgkAh0M6A9LES6yGp3VfKFaPXlqodVITaQLFDuA1LWtf8MRVI9%2BLOctn%2FHua6A0SVsRtUy51HHiWxtL5LKSG1t8DXe7zUPnh56ZqU5pi8Iu45rJYbTwKAXGQt%2BeijthqK5KuAaf9xYNyodmN3ekpf0CDvVesBtpOHO5H%2FJIfa%2BhCYqLI6vv%2FwJrxbraOPCvjV7TFeSniocFLLNWi9vHdmucdnGkNGDFZXFMsSbzsLTW3EMXKk%2BUOHXDiUZvKn6lXv2m1Odl65rQnXo5ICeD7%2BmA%3D%3D: HTTPSConnectionPool(host='storage.googleapis.com', port=443): Max retries exceeded with url: /wandb-artifacts-prod/wandb_artifacts/120300447/661768373/521e54ab95c254e02c4ef790d5def9ec?Expires=1702149673&GoogleAccessId=gorilla-files-url-signer-man%40wandb-production.iam.gserviceaccount.com&Signature=fWMKl4WNB7xDCuLXBlggttukI7S73o1o80R8hwoAZc9W3aRVkaYs%2Fhst3TPscj%2FmgkAh0M6A9LES6yGp3VfKFaPXlqodVITaQLFDuA1LWtf8MRVI9%2BLOctn%2FHua6A0SVsRtUy51HHiWxtL5LKSG1t8DXe7zUPnh56ZqU5pi8Iu45rJYbTwKAXGQt%2BeijthqK5KuAaf9xYNyodmN3ekpf0CDvVesBtpOHO5H%2FJIfa%2BhCYqLI6vv%2FwJrxbraOPCvjV7TFeSniocFLLNWi9vHdmucdnGkNGDFZXFMsSbzsLTW3EMXKk%2BUOHXDiUZvKn6lXv2m1Odl65rQnXo5ICeD7%2BmA%3D%3D (Caused by NewConnectionError('<urllib3.connection.HTTPSConnection object at 0x2b9ca270b070>: Failed to establish a new connection: [Errno 101] Network is unreachable'))
2023-12-08 20:22:27,173 ERROR   wandb-upload_1:27837 [internal_api.py:upload_file():2558] upload_file request headers: {'User-Agent': 'python-requests/2.28.1', 'Accept-Encoding': 'gzip, deflate, br', 'Accept': '*/*', 'Connection': 'keep-alive', 'Content-MD5': 'Uh5Uq5XCVOAsTveQ1d757A==', 'Content-Type': 'text/plain; charset=utf-8', 'Content-Length': '1820'}
2023-12-08 20:22:27,173 ERROR   wandb-upload_1:27837 [internal_api.py:upload_file():2560] upload_file response body: 
2023-12-08 20:22:30,090 DEBUG   HandlerThread:27837 [handler.py:handle_request():146] handle_request: keepalive
2023-12-08 20:22:35,091 DEBUG   HandlerThread:27837 [handler.py:handle_request():146] handle_request: keepalive
2023-12-08 20:22:40,093 DEBUG   HandlerThread:27837 [handler.py:handle_request():146] handle_request: keepalive
2023-12-08 20:22:45,094 DEBUG   HandlerThread:27837 [handler.py:handle_request():146] handle_request: keepalive
2023-12-08 20:22:50,096 DEBUG   HandlerThread:27837 [handler.py:handle_request():146] handle_request: keepalive
2023-12-08 20:22:55,097 DEBUG   HandlerThread:27837 [handler.py:handle_request():146] handle_request: keepalive
2023-12-08 20:23:00,099 DEBUG   HandlerThread:27837 [handler.py:handle_request():146] handle_request: keepalive
2023-12-08 20:23:05,100 DEBUG   HandlerThread:27837 [handler.py:handle_request():146] handle_request: keepalive
2023-12-08 20:23:10,101 DEBUG   HandlerThread:27837 [handler.py:handle_request():146] handle_request: keepalive
2023-12-08 20:23:15,103 DEBUG   HandlerThread:27837 [handler.py:handle_request():146] handle_request: keepalive
2023-12-08 20:23:20,105 DEBUG   HandlerThread:27837 [handler.py:handle_request():146] handle_request: keepalive
2023-12-08 20:23:25,107 DEBUG   HandlerThread:27837 [handler.py:handle_request():146] handle_request: keepalive
2023-12-08 20:23:30,108 DEBUG   HandlerThread:27837 [handler.py:handle_request():146] handle_request: keepalive
2023-12-08 20:23:31,123 ERROR   wandb-upload_2:27837 [internal_api.py:upload_file():2556] upload_file exception https://storage.googleapis.com/wandb-artifacts-prod/wandb_artifacts/120300447/661768373/7d403960cc78ee51501901f4effaf804?Expires=1702149673&GoogleAccessId=gorilla-files-url-signer-man%40wandb-production.iam.gserviceaccount.com&Signature=L8AQMQPD7qLLhZtGhc3fzIzQX9C9uQJUI2jyh%2BJsrZF63PAECSlMX8H6XhBEPdkG8nFmOHXM9Mozf3qjmGR9by9ZJlrWTSbvVjAM%2BTxcTSmfQrjBFNmR%2BufbstUknoHi52uQ69nCgb4UspHPaBbgrvdhHEGKe%2BZaRx1Kef39N7OBS%2BZykfBnBEutYwt4XJc0w3K2gzWufouZkIeCNbipE7YExQgKHaSaFMAXv2mYoFpV8Vw8ex6J%2Fu5H%2F84erlMNU5hqp2GzsW%2F3FSTKbITK7u5G2qJ1Mfd3ehEW58R6y81PQqkBhMEWqO%2BLsA02hyF8y%2BRWYR6Igiq9oNWsM2j74w%3D%3D: HTTPSConnectionPool(host='storage.googleapis.com', port=443): Max retries exceeded with url: /wandb-artifacts-prod/wandb_artifacts/120300447/661768373/7d403960cc78ee51501901f4effaf804?Expires=1702149673&GoogleAccessId=gorilla-files-url-signer-man%40wandb-production.iam.gserviceaccount.com&Signature=L8AQMQPD7qLLhZtGhc3fzIzQX9C9uQJUI2jyh%2BJsrZF63PAECSlMX8H6XhBEPdkG8nFmOHXM9Mozf3qjmGR9by9ZJlrWTSbvVjAM%2BTxcTSmfQrjBFNmR%2BufbstUknoHi52uQ69nCgb4UspHPaBbgrvdhHEGKe%2BZaRx1Kef39N7OBS%2BZykfBnBEutYwt4XJc0w3K2gzWufouZkIeCNbipE7YExQgKHaSaFMAXv2mYoFpV8Vw8ex6J%2Fu5H%2F84erlMNU5hqp2GzsW%2F3FSTKbITK7u5G2qJ1Mfd3ehEW58R6y81PQqkBhMEWqO%2BLsA02hyF8y%2BRWYR6Igiq9oNWsM2j74w%3D%3D (Caused by NewConnectionError('<urllib3.connection.HTTPSConnection object at 0x2b9ca27136a0>: Failed to establish a new connection: [Errno 101] Network is unreachable'))
2023-12-08 20:23:31,123 ERROR   wandb-upload_2:27837 [internal_api.py:upload_file():2558] upload_file request headers: {'User-Agent': 'python-requests/2.28.1', 'Accept-Encoding': 'gzip, deflate, br', 'Accept': '*/*', 'Connection': 'keep-alive', 'Content-MD5': 'fUA5YMx47lFQGQH07/r4BA==', 'Content-Type': 'application/json', 'Content-Length': '648'}
2023-12-08 20:23:31,123 ERROR   wandb-upload_2:27837 [internal_api.py:upload_file():2560] upload_file response body: 
2023-12-08 20:23:31,512 ERROR   wandb-upload_0:27837 [internal_api.py:upload_file():2556] upload_file exception https://storage.googleapis.com/wandb-production.appspot.com/bryant-tang-ethz/DKT-trial%201/c30p1g8z/wandb-metadata.json?Expires=1702149661&GoogleAccessId=gorilla-files-url-signer-man%40wandb-production.iam.gserviceaccount.com&Signature=KexFrx2bT1sRpPrCOnyFHTll42CAL7GxpXaMUOibyXhHbJN9T9Y%2FkSS2BhtTRt%2BioM0ny%2BCcaNtgQZe%2FzjvryjM0lcTOFtJCbc1Gxa278S7GHDcQF7PcW2QxQJ3VIijjPFkEf%2Br%2F%2By0fGDwyCbb%2BtkeUCSjgwdPwykXxdGyTgGmZa13eMGWnGiDKtOaji3FpdhOF4OI3LTDBARhwUEsu8yoCFTi9RVUMEVuOt7rquhqaIfYBWN53r2CGofT7pRk%2BM0WftI%2B3m%2F9qIDWDvz9lu6sRo8u2sZuHUspSYiQBAnUKOOy5lRwySufIHuk1SVhkU1Z%2F4pqKPW%2B%2B1SX6i7iqJg%3D%3D: HTTPSConnectionPool(host='storage.googleapis.com', port=443): Max retries exceeded with url: /wandb-production.appspot.com/bryant-tang-ethz/DKT-trial%201/c30p1g8z/wandb-metadata.json?Expires=1702149661&GoogleAccessId=gorilla-files-url-signer-man%40wandb-production.iam.gserviceaccount.com&Signature=KexFrx2bT1sRpPrCOnyFHTll42CAL7GxpXaMUOibyXhHbJN9T9Y%2FkSS2BhtTRt%2BioM0ny%2BCcaNtgQZe%2FzjvryjM0lcTOFtJCbc1Gxa278S7GHDcQF7PcW2QxQJ3VIijjPFkEf%2Br%2F%2By0fGDwyCbb%2BtkeUCSjgwdPwykXxdGyTgGmZa13eMGWnGiDKtOaji3FpdhOF4OI3LTDBARhwUEsu8yoCFTi9RVUMEVuOt7rquhqaIfYBWN53r2CGofT7pRk%2BM0WftI%2B3m%2F9qIDWDvz9lu6sRo8u2sZuHUspSYiQBAnUKOOy5lRwySufIHuk1SVhkU1Z%2F4pqKPW%2B%2B1SX6i7iqJg%3D%3D (Caused by NewConnectionError('<urllib3.connection.HTTPSConnection object at 0x2b9ca2713430>: Failed to establish a new connection: [Errno 101] Network is unreachable'))
2023-12-08 20:23:31,512 ERROR   wandb-upload_0:27837 [internal_api.py:upload_file():2558] upload_file request headers: {'User-Agent': 'python-requests/2.28.1', 'Accept-Encoding': 'gzip, deflate, br', 'Accept': '*/*', 'Connection': 'keep-alive', 'Content-Length': '14827'}
2023-12-08 20:23:31,512 ERROR   wandb-upload_0:27837 [internal_api.py:upload_file():2560] upload_file response body: 
2023-12-08 20:23:35,110 DEBUG   HandlerThread:27837 [handler.py:handle_request():146] handle_request: keepalive
2023-12-08 20:23:40,111 DEBUG   HandlerThread:27837 [handler.py:handle_request():146] handle_request: keepalive
2023-12-08 20:23:45,113 DEBUG   HandlerThread:27837 [handler.py:handle_request():146] handle_request: keepalive
2023-12-08 20:23:45,239 ERROR   wandb-upload_1:27837 [internal_api.py:upload_file():2556] upload_file exception https://storage.googleapis.com/wandb-artifacts-prod/wandb_artifacts/120300447/661768373/521e54ab95c254e02c4ef790d5def9ec?Expires=1702149673&GoogleAccessId=gorilla-files-url-signer-man%40wandb-production.iam.gserviceaccount.com&Signature=fWMKl4WNB7xDCuLXBlggttukI7S73o1o80R8hwoAZc9W3aRVkaYs%2Fhst3TPscj%2FmgkAh0M6A9LES6yGp3VfKFaPXlqodVITaQLFDuA1LWtf8MRVI9%2BLOctn%2FHua6A0SVsRtUy51HHiWxtL5LKSG1t8DXe7zUPnh56ZqU5pi8Iu45rJYbTwKAXGQt%2BeijthqK5KuAaf9xYNyodmN3ekpf0CDvVesBtpOHO5H%2FJIfa%2BhCYqLI6vv%2FwJrxbraOPCvjV7TFeSniocFLLNWi9vHdmucdnGkNGDFZXFMsSbzsLTW3EMXKk%2BUOHXDiUZvKn6lXv2m1Odl65rQnXo5ICeD7%2BmA%3D%3D: HTTPSConnectionPool(host='storage.googleapis.com', port=443): Max retries exceeded with url: /wandb-artifacts-prod/wandb_artifacts/120300447/661768373/521e54ab95c254e02c4ef790d5def9ec?Expires=1702149673&GoogleAccessId=gorilla-files-url-signer-man%40wandb-production.iam.gserviceaccount.com&Signature=fWMKl4WNB7xDCuLXBlggttukI7S73o1o80R8hwoAZc9W3aRVkaYs%2Fhst3TPscj%2FmgkAh0M6A9LES6yGp3VfKFaPXlqodVITaQLFDuA1LWtf8MRVI9%2BLOctn%2FHua6A0SVsRtUy51HHiWxtL5LKSG1t8DXe7zUPnh56ZqU5pi8Iu45rJYbTwKAXGQt%2BeijthqK5KuAaf9xYNyodmN3ekpf0CDvVesBtpOHO5H%2FJIfa%2BhCYqLI6vv%2FwJrxbraOPCvjV7TFeSniocFLLNWi9vHdmucdnGkNGDFZXFMsSbzsLTW3EMXKk%2BUOHXDiUZvKn6lXv2m1Odl65rQnXo5ICeD7%2BmA%3D%3D (Caused by NewConnectionError('<urllib3.connection.HTTPSConnection object at 0x2b9ca2725280>: Failed to establish a new connection: [Errno 101] Network is unreachable'))
2023-12-08 20:23:45,239 ERROR   wandb-upload_1:27837 [internal_api.py:upload_file():2558] upload_file request headers: {'User-Agent': 'python-requests/2.28.1', 'Accept-Encoding': 'gzip, deflate, br', 'Accept': '*/*', 'Connection': 'keep-alive', 'Content-MD5': 'Uh5Uq5XCVOAsTveQ1d757A==', 'Content-Type': 'text/plain; charset=utf-8', 'Content-Length': '1820'}
2023-12-08 20:23:45,239 ERROR   wandb-upload_1:27837 [internal_api.py:upload_file():2560] upload_file response body: 
2023-12-08 20:23:50,114 DEBUG   HandlerThread:27837 [handler.py:handle_request():146] handle_request: keepalive
